Workbook
Name OHPMAX: 'Empezar aqui'!$G$13
Name DLMAX: 'Empezar aqui'!$G$14
Name BBRMAX: 'Empezar aqui'!$G$12
Name BPTON: 'Empezar aqui'!$F$11
Name BBR: 'Empezar aqui'!$I$12
Name DLINT: 'Empezar aqui'!$E$14
Name SQINT: 'Empezar aqui'!$E$10
Name DLTON: 'Empezar aqui'!$F$14
Name DL: 'Empezar aqui'!$I$14
Name SQ: 'Empezar aqui'!$I$10
Name OHP: 'Empezar aqui'!$I$13
Name SQTON: 'Empezar aqui'!$F$10
Name BPINT: 'Empezar aqui'!$E$11
Name PLATE: 'Empezar aqui'!$D$16
Name SQMAX: 'Empezar aqui'!$G$10
Name PRWEEK: 'Empezar aqui'!$D$17
Name BBRINT: 'Empezar aqui'!$E$12
Name BBRTON: 'Empezar aqui'!$F$12
Name OHPINT: 'Empezar aqui'!$E$13
Name OHPTON: 'Empezar aqui'!$F$13
Name BP: 'Empezar aqui'!$I$11
Name BPMAX: 'Empezar aqui'!$G$11

Sheet Empezar aqui
B1: BIBLIOTECADERUTINAS.COM
B6: Madcow 5x5
B9: Ejercicio | C9: Peso de prueba | D9: Reps | E9: Intervalos | F9: Tonelaje | G9: 1RM | H9: 5RM | I9: Peso inicial
B10: Sentadilla | C10: 100 | D10: 5 | E10: 0.125 | F10: 0.6 | G10: =(C10)/(1.0278-(0.0278*D10)) -> 112.51125 | H10: =G10*(1.0278-(0.0278*5)) -> 100 | I10: =ROUND(H10*((1/1.025)^(PRWEEK-1))/(2*PLATE),0)*2*PLATE -> 95
B11: Press de banca | C11: 100 | D11: 5 | E11: 0.125 | F11: 0.6 | G11: =(C11)/(1.0278-(0.0278*D11)) -> 112.51125 | H11: =G11*(1.0278-(0.0278*5)) -> 100 | I11: =ROUND(H11*((1/1.025)^(PRWEEK-1))/(2*PLATE),0)*2*PLATE -> 95
B12: Remo | C12: 100 | D12: 5 | E12: 0.125 | F12: 0.6 | G12: =(C12)/(1.0278-(0.0278*D12)) -> 112.51125 | H12: =G12*(1.0278-(0.0278*5)) -> 100 | I12: =ROUND(H12*((1/1.025)^(PRWEEK-1))/(2*PLATE),0)*2*PLATE -> 95
B13: Press militar | C13: 100 | D13: 5 | E13: 0.125 | F13: 0.6 | G13: =(C13)/(1.0278-(0.0278*D13)) -> 112.51125 | H13: =G13*(1.0278-(0.0278*5)) -> 100 | I13: =ROUND(H13*((1/1.025)^(PRWEEK-1))/(2*PLATE),0)*2*PLATE -> 95
B14: Peso muerto | C14: 100 | D14: 5 | E14: 0.125 | F14: 0.6 | G14: =(C14)/(1.0278-(0.0278*D14)) -> 112.51125 | H14: =G14*(1.0278-(0.0278*5)) -> 100 | I14: =ROUND(H14*((1/1.025)^(PRWEEK-1))/(2*PLATE),0)*2*PLATE -> 95
B16: Discos accesibles más pequeños | D16: 2.5
B17: Semana en la que se logrará el 5RM testeado# | D17: 4
B19: Rellenar las celdas turquesa

Sheet Programa
B5: Madcow 5x5 Intermedios
E8: Semana
B9: Dia | C9: Ejercicio | D9: Reps | E9: 1 | F9: 2 | G9: 3 | H9: 4 | I9: 5 | J9: 6 | K9: 7 | L9: 8 | M9: 9 | N9: 10 | O9: 11 | P9: 12
B10: Lunes | C10: Sentadilla | D10: 5 | E10: =ROUND(E14*(1-SQINT*4)/(2*PLATE),0)*2*PLATE -> 50 | F10: =ROUND(F14*(1-SQINT*4)/(2*PLATE),0)*2*PLATE -> 50 | G10: =ROUND(G14*(1-SQINT*4)/(2*PLATE),0)*2*PLATE -> 50 | H10: =ROUND(H14*(1-SQINT*4)/(2*PLATE),0)*2*PLATE -> 50 | I10: =ROUND(I14*(1-SQINT*4)/(2*PLATE),0)*2*PLATE -> 55 | J10: =ROUND(J14*(1-SQINT*4)/(2*PLATE),0)*2*PLATE -> 55 | K10: =ROUND(K14*(1-SQINT*4)/(2*PLATE),0)*2*PLATE -> 55 | L10: =ROUND(L14*(1-SQINT*4)/(2*PLATE),0)*2*PLATE -> 60 | ... P10: =ROUND(P14*(1-SQINT*4)/(2*PLATE),0)*2*PLATE -> 65
D11: 5 | E11: =ROUND(E14*(1-SQINT*3)/(2*PLATE),0)*2*PLATE -> 60 | F11: =ROUND(F14*(1-SQINT*3)/(2*PLATE),0)*2*PLATE -> 60 | G11: =ROUND(G14*(1-SQINT*3)/(2*PLATE),0)*2*PLATE -> 65 | H11: =ROUND(H14*(1-SQINT*3)/(2*PLATE),0)*2*PLATE -> 65 | I11: =ROUND(I14*(1-SQINT*3)/(2*PLATE),0)*2*PLATE -> 65 | J11: =ROUND(J14*(1-SQINT*3)/(2*PLATE),0)*2*PLATE -> 65 | K11: =ROUND(K14*(1-SQINT*3)/(2*PLATE),0)*2*PLATE -> 70 | L11: =ROUND(L14*(1-SQINT*3)/(2*PLATE),0)*2*PLATE -> 70 | ... P11: =ROUND(P14*(1-SQINT*3)/(2*PLATE),0)*2*PLATE -> 80
D12: 5 | E12: =ROUND(E14*(1-SQINT*2)/(2*PLATE),0)*2*PLATE -> 70 | F12: =ROUND(F14*(1-SQINT*2)/(2*PLATE),0)*2*PLATE -> 70 | G12: =ROUND(G14*(1-SQINT*2)/(2*PLATE),0)*2*PLATE -> 75 | H12: =ROUND(H14*(1-SQINT*2)/(2*PLATE),0)*2*PLATE -> 75 | I12: =ROUND(I14*(1-SQINT*2)/(2*PLATE),0)*2*PLATE -> 80 | J12: =ROUND(J14*(1-SQINT*2)/(2*PLATE),0)*2*PLATE -> 80 | K12: =ROUND(K14*(1-SQINT*2)/(2*PLATE),0)*2*PLATE -> 85 | L12: =ROUND(L14*(1-SQINT*2)/(2*PLATE),0)*2*PLATE -> 85 | ... P12: =ROUND(P14*(1-SQINT*2)/(2*PLATE),0)*2*PLATE -> 95
D13: 5 | E13: =ROUND(E14*(1-SQINT)/(2*PLATE),0)*2*PLATE -> 85 | F13: =ROUND(F14*(1-SQINT)/(2*PLATE),0)*2*PLATE -> 85 | G13: =ROUND(G14*(1-SQINT)/(2*PLATE),0)*2*PLATE -> 90 | H13: =ROUND(H14*(1-SQINT)/(2*PLATE),0)*2*PLATE -> 90 | I13: =ROUND(I14*(1-SQINT)/(2*PLATE),0)*2*PLATE -> 90 | J13: =ROUND(J14*(1-SQINT)/(2*PLATE),0)*2*PLATE -> 90 | K13: =ROUND(K14*(1-SQINT)/(2*PLATE),0)*2*PLATE -> 95 | L13: =ROUND(L14*(1-SQINT)/(2*PLATE),0)*2*PLATE -> 100 | ... P13: =ROUND(P14*(1-SQINT)/(2*PLATE),0)*2*PLATE -> 110
D14: 5 | E14: =SQ -> 95 | F14: =ROUND(SQ*(1.025^E9)/(2*PLATE),0)*2*PLATE -> 95 | G14: =ROUND(SQ*(1.025^F9)/(2*PLATE),0)*2*PLATE -> 100 | H14: =ROUND(SQ*(1.025^G9)/(2*PLATE),0)*2*PLATE -> 100 | I14: =ROUND(SQ*(1.025^H9)/(2*PLATE),0)*2*PLATE -> 105 | J14: =ROUND(SQ*(1.025^I9)/(2*PLATE),0)*2*PLATE -> 105 | K14: =ROUND(SQ*(1.025^J9)/(2*PLATE),0)*2*PLATE -> 110 | L14: =ROUND(SQ*(1.025^K9)/(2*PLATE),0)*2*PLATE -> 115 | M14: =ROUND(SQ*(1.025^L9)/(2*PLATE),0)*2*PLATE -> 115 | ... P14: =ROUND(SQ*(1.025^O9)/(2*PLATE),0)*2*PLATE -> 125
C15: Press de banca | D15: 5 | E15: =ROUND(E19*(1-BPINT*4)/(2*PLATE),0)*2*PLATE -> 50 | F15: =ROUND(F19*(1-BPINT*4)/(2*PLATE),0)*2*PLATE -> 50 | G15: =ROUND(G19*(1-BPINT*4)/(2*PLATE),0)*2*PLATE -> 50 | H15: =ROUND(H19*(1-BPINT*4)/(2*PLATE),0)*2*PLATE -> 50 | I15: =ROUND(I19*(1-BPINT*4)/(2*PLATE),0)*2*PLATE -> 55 | J15: =ROUND(J19*(1-BPINT*4)/(2*PLATE),0)*2*PLATE -> 55 | K15: =ROUND(K19*(1-BPINT*4)/(2*PLATE),0)*2*PLATE -> 55 | L15: =ROUND(L19*(1-BPINT*4)/(2*PLATE),0)*2*PLATE -> 60 | ... P15: =ROUND(P19*(1-BPINT*4)/(2*PLATE),0)*2*PLATE -> 65
D16: 5 | E16: =ROUND(E19*(1-BPINT*3)/(2*PLATE),0)*2*PLATE -> 60 | F16: =ROUND(F19*(1-BPINT*3)/(2*PLATE),0)*2*PLATE -> 60 | G16: =ROUND(G19*(1-BPINT*3)/(2*PLATE),0)*2*PLATE -> 65 | H16: =ROUND(H19*(1-BPINT*3)/(2*PLATE),0)*2*PLATE -> 65 | I16: =ROUND(I19*(1-BPINT*3)/(2*PLATE),0)*2*PLATE -> 65 | J16: =ROUND(J19*(1-BPINT*3)/(2*PLATE),0)*2*PLATE -> 65 | K16: =ROUND(K19*(1-BPINT*3)/(2*PLATE),0)*2*PLATE -> 70 | L16: =ROUND(L19*(1-BPINT*3)/(2*PLATE),0)*2*PLATE -> 70 | ... P16: =ROUND(P19*(1-BPINT*3)/(2*PLATE),0)*2*PLATE -> 80
D17: 5 | E17: =ROUND(E19*(1-BPINT*2)/(2*PLATE),0)*2*PLATE -> 70 | F17: =ROUND(F19*(1-BPINT*2)/(2*PLATE),0)*2*PLATE -> 70 | G17: =ROUND(G19*(1-BPINT*2)/(2*PLATE),0)*2*PLATE -> 75 | H17: =ROUND(H19*(1-BPINT*2)/(2*PLATE),0)*2*PLATE -> 75 | I17: =ROUND(I19*(1-BPINT*2)/(2*PLATE),0)*2*PLATE -> 80 | J17: =ROUND(J19*(1-BPINT*2)/(2*PLATE),0)*2*PLATE -> 80 | K17: =ROUND(K19*(1-BPINT*2)/(2*PLATE),0)*2*PLATE -> 85 | L17: =ROUND(L19*(1-BPINT*2)/(2*PLATE),0)*2*PLATE -> 85 | ... P17: =ROUND(P19*(1-BPINT*2)/(2*PLATE),0)*2*PLATE -> 95
D18: 5 | E18: =ROUND(E19*(1-BPINT)/(2*PLATE),0)*2*PLATE -> 85 | F18: =ROUND(F19*(1-BPINT)/(2*PLATE),0)*2*PLATE -> 85 | G18: =ROUND(G19*(1-BPINT)/(2*PLATE),0)*2*PLATE -> 90 | H18: =ROUND(H19*(1-BPINT)/(2*PLATE),0)*2*PLATE -> 90 | I18: =ROUND(I19*(1-BPINT)/(2*PLATE),0)*2*PLATE -> 90 | J18: =ROUND(J19*(1-BPINT)/(2*PLATE),0)*2*PLATE -> 90 | K18: =ROUND(K19*(1-BPINT)/(2*PLATE),0)*2*PLATE -> 95 | L18: =ROUND(L19*(1-BPINT)/(2*PLATE),0)*2*PLATE -> 100 | ... P18: =ROUND(P19*(1-BPINT)/(2*PLATE),0)*2*PLATE -> 110
D19: 5 | E19: =BP -> 95 | F19: =ROUND(BP*(1.025^E9)/(2*PLATE),0)*2*PLATE -> 95 | G19: =ROUND(BP*(1.025^F9)/(2*PLATE),0)*2*PLATE -> 100 | H19: =ROUND(BP*(1.025^G9)/(2*PLATE),0)*2*PLATE -> 100 | I19: =ROUND(BP*(1.025^H9)/(2*PLATE),0)*2*PLATE -> 105 | J19: =ROUND(BP*(1.025^I9)/(2*PLATE),0)*2*PLATE -> 105 | K19: =ROUND(BP*(1.025^J9)/(2*PLATE),0)*2*PLATE -> 110 | L19: =ROUND(BP*(1.025^K9)/(2*PLATE),0)*2*PLATE -> 115 | M19: =ROUND(BP*(1.025^L9)/(2*PLATE),0)*2*PLATE -> 115 | ... P19: =ROUND(BP*(1.025^O9)/(2*PLATE),0)*2*PLATE -> 125
C20: Remo | D20: 5 | E20: =ROUND(E24*(1-BBRINT*4)/(2*PLATE),0)*2*PLATE -> 50 | F20: =ROUND(F24*(1-BBRINT*4)/(2*PLATE),0)*2*PLATE -> 50 | G20: =ROUND(G24*(1-BBRINT*4)/(2*PLATE),0)*2*PLATE -> 50 | H20: =ROUND(H24*(1-BBRINT*4)/(2*PLATE),0)*2*PLATE -> 50 | I20: =ROUND(I24*(1-BBRINT*4)/(2*PLATE),0)*2*PLATE -> 55 | J20: =ROUND(J24*(1-BBRINT*4)/(2*PLATE),0)*2*PLATE -> 55 | K20: =ROUND(K24*(1-BBRINT*4)/(2*PLATE),0)*2*PLATE -> 55 | L20: =ROUND(L24*(1-BBRINT*4)/(2*PLATE),0)*2*PLATE -> 60 | ... P20: =ROUND(P24*(1-BBRINT*4)/(2*PLATE),0)*2*PLATE -> 65
D21: 5 | E21: =ROUND(E24*(1-BBRINT*3)/(2*PLATE),0)*2*PLATE -> 60 | F21: =ROUND(F24*(1-BBRINT*3)/(2*PLATE),0)*2*PLATE -> 60 | G21: =ROUND(G24*(1-BBRINT*3)/(2*PLATE),0)*2*PLATE -> 65 | H21: =ROUND(H24*(1-BBRINT*3)/(2*PLATE),0)*2*PLATE -> 65 | I21: =ROUND(I24*(1-BBRINT*3)/(2*PLATE),0)*2*PLATE -> 65 | J21: =ROUND(J24*(1-BBRINT*3)/(2*PLATE),0)*2*PLATE -> 65 | K21: =ROUND(K24*(1-BBRINT*3)/(2*PLATE),0)*2*PLATE -> 70 | L21: =ROUND(L24*(1-BBRINT*3)/(2*PLATE),0)*2*PLATE -> 70 | ... P21: =ROUND(P24*(1-BBRINT*3)/(2*PLATE),0)*2*PLATE -> 80
D22: 5 | E22: =ROUND(E24*(1-BBRINT*2)/(2*PLATE),0)*2*PLATE -> 70 | F22: =ROUND(F24*(1-BBRINT*2)/(2*PLATE),0)*2*PLATE -> 70 | G22: =ROUND(G24*(1-BBRINT*2)/(2*PLATE),0)*2*PLATE -> 75 | H22: =ROUND(H24*(1-BBRINT*2)/(2*PLATE),0)*2*PLATE -> 75 | I22: =ROUND(I24*(1-BBRINT*2)/(2*PLATE),0)*2*PLATE -> 80 | J22: =ROUND(J24*(1-BBRINT*2)/(2*PLATE),0)*2*PLATE -> 80 | K22: =ROUND(K24*(1-BBRINT*2)/(2*PLATE),0)*2*PLATE -> 85 | L22: =ROUND(L24*(1-BBRINT*2)/(2*PLATE),0)*2*PLATE -> 85 | ... P22: =ROUND(P24*(1-BBRINT*2)/(2*PLATE),0)*2*PLATE -> 95
D23: 5 | E23: =ROUND(E24*(1-BBRINT)/(2*PLATE),0)*2*PLATE -> 85 | F23: =ROUND(F24*(1-BBRINT)/(2*PLATE),0)*2*PLATE -> 85 | G23: =ROUND(G24*(1-BBRINT)/(2*PLATE),0)*2*PLATE -> 90 | H23: =ROUND(H24*(1-BBRINT)/(2*PLATE),0)*2*PLATE -> 90 | I23: =ROUND(I24*(1-BBRINT)/(2*PLATE),0)*2*PLATE -> 90 | J23: =ROUND(J24*(1-BBRINT)/(2*PLATE),0)*2*PLATE -> 90 | K23: =ROUND(K24*(1-BBRINT)/(2*PLATE),0)*2*PLATE -> 95 | L23: =ROUND(L24*(1-BBRINT)/(2*PLATE),0)*2*PLATE -> 100 | ... P23: =ROUND(P24*(1-BBRINT)/(2*PLATE),0)*2*PLATE -> 110
D24: 5 | E24: =BBR -> 95 | F24: =ROUND(BBR*(1.025^E9)/(2*PLATE),0)*2*PLATE -> 95 | G24: =ROUND(BBR*(1.025^F9)/(2*PLATE),0)*2*PLATE -> 100 | H24: =ROUND(BBR*(1.025^G9)/(2*PLATE),0)*2*PLATE -> 100 | I24: =ROUND(BBR*(1.025^H9)/(2*PLATE),0)*2*PLATE -> 105 | J24: =ROUND(BBR*(1.025^I9)/(2*PLATE),0)*2*PLATE -> 105 | K24: =ROUND(BBR*(1.025^J9)/(2*PLATE),0)*2*PLATE -> 110 | L24: =ROUND(BBR*(1.025^K9)/(2*PLATE),0)*2*PLATE -> 115 | M24: =ROUND(BBR*(1.025^L9)/(2*PLATE),0)*2*PLATE -> 115 | ... P24: =ROUND(BBR*(1.025^O9)/(2*PLATE),0)*2*PLATE -> 125
B25: Wednesday | C25: Sentadilla | D25: 5 | E25: =E10 -> 50 | F25: =F10 -> 50 | G25: =G10 -> 50 | H25: =H10 -> 50 | I25: =I10 -> 55 | J25: =J10 -> 55 | K25: =K10 -> 55 | L25: =L10 -> 60 | ... P25: =P10 -> 65
D26: 5 | E26: =E11 -> 60 | F26: =F11 -> 60 | G26: =G11 -> 65 | H26: =H11 -> 65 | I26: =I11 -> 65 | J26: =J11 -> 65 | K26: =K11 -> 70 | L26: =L11 -> 70 | ... P26: =P11 -> 80
D27: 5 | E27: =E12 -> 70 | F27: =F12 -> 70 | G27: =G12 -> 75 | H27: =H12 -> 75 | I27: =I12 -> 80 | J27: =J12 -> 80 | K27: =K12 -> 85 | L27: =L12 -> 85 | ... P27: =P12 -> 95
D28: 5 | E28: =E12 -> 70 | F28: =F12 -> 70 | G28: =G12 -> 75 | H28: =H12 -> 75 | I28: =I12 -> 80 | J28: =J12 -> 80 | K28: =K12 -> 85 | L28: =L12 -> 85 | ... P28: =P12 -> 95
C29: Press | D29: 5 | E29: =ROUND(E32*(1-OHPINT*3)/(2*PLATE),0)*2*PLATE -> 60 | F29: =ROUND(F32*(1-OHPINT*3)/(2*PLATE),0)*2*PLATE -> 60 | G29: =ROUND(G32*(1-OHPINT*3)/(2*PLATE),0)*2*PLATE -> 65 | H29: =ROUND(H32*(1-OHPINT*3)/(2*PLATE),0)*2*PLATE -> 65 | I29: =ROUND(I32*(1-OHPINT*3)/(2*PLATE),0)*2*PLATE -> 65 | J29: =ROUND(J32*(1-OHPINT*3)/(2*PLATE),0)*2*PLATE -> 65 | K29: =ROUND(K32*(1-OHPINT*3)/(2*PLATE),0)*2*PLATE -> 70 | L29: =ROUND(L32*(1-OHPINT*3)/(2*PLATE),0)*2*PLATE -> 70 | ... P29: =ROUND(P32*(1-OHPINT*3)/(2*PLATE),0)*2*PLATE -> 80
D30: 5 | E30: =ROUND(E32*(1-OHPINT*2)/(2*PLATE),0)*2*PLATE -> 70 | F30: =ROUND(F32*(1-OHPINT*2)/(2*PLATE),0)*2*PLATE -> 70 | G30: =ROUND(G32*(1-OHPINT*2)/(2*PLATE),0)*2*PLATE -> 75 | H30: =ROUND(H32*(1-OHPINT*2)/(2*PLATE),0)*2*PLATE -> 75 | I30: =ROUND(I32*(1-OHPINT*2)/(2*PLATE),0)*2*PLATE -> 80 | J30: =ROUND(J32*(1-OHPINT*2)/(2*PLATE),0)*2*PLATE -> 80 | K30: =ROUND(K32*(1-OHPINT*2)/(2*PLATE),0)*2*PLATE -> 85 | L30: =ROUND(L32*(1-OHPINT*2)/(2*PLATE),0)*2*PLATE -> 85 | ... P30: =ROUND(P32*(1-OHPINT*2)/(2*PLATE),0)*2*PLATE -> 95
D31: 5 | E31: =ROUND(E32*(1-OHPINT)/(2*PLATE),0)*2*PLATE -> 85 | F31: =ROUND(F32*(1-OHPINT)/(2*PLATE),0)*2*PLATE -> 85 | G31: =ROUND(G32*(1-OHPINT)/(2*PLATE),0)*2*PLATE -> 90 | H31: =ROUND(H32*(1-OHPINT)/(2*PLATE),0)*2*PLATE -> 90 | I31: =ROUND(I32*(1-OHPINT)/(2*PLATE),0)*2*PLATE -> 90 | J31: =ROUND(J32*(1-OHPINT)/(2*PLATE),0)*2*PLATE -> 90 | K31: =ROUND(K32*(1-OHPINT)/(2*PLATE),0)*2*PLATE -> 95 | L31: =ROUND(L32*(1-OHPINT)/(2*PLATE),0)*2*PLATE -> 100 | ... P31: =ROUND(P32*(1-OHPINT)/(2*PLATE),0)*2*PLATE -> 110
D32: 5 | E32: =OHP -> 95 | F32: =ROUND(OHP*(1.025^E9)/(2*PLATE),0)*2*PLATE -> 95 | G32: =ROUND(OHP*(1.025^F9)/(2*PLATE),0)*2*PLATE -> 100 | H32: =ROUND(OHP*(1.025^G9)/(2*PLATE),0)*2*PLATE -> 100 | I32: =ROUND(OHP*(1.025^H9)/(2*PLATE),0)*2*PLATE -> 105 | J32: =ROUND(OHP*(1.025^I9)/(2*PLATE),0)*2*PLATE -> 105 | K32: =ROUND(OHP*(1.025^J9)/(2*PLATE),0)*2*PLATE -> 110 | L32: =ROUND(OHP*(1.025^K9)/(2*PLATE),0)*2*PLATE -> 115 | M32: =ROUND(OHP*(1.025^L9)/(2*PLATE),0)*2*PLATE -> 115 | ... P32: =ROUND(OHP*(1.025^O9)/(2*PLATE),0)*2*PLATE -> 125
C33: Peso muerto | D33: 5 | E33: =ROUND(E36*(1-DLINT*3)/(2*PLATE),0)*2*PLATE -> 60 | F33: =ROUND(F36*(1-DLINT*3)/(2*PLATE),0)*2*PLATE -> 60 | G33: =ROUND(G36*(1-DLINT*3)/(2*PLATE),0)*2*PLATE -> 65 | H33: =ROUND(H36*(1-DLINT*3)/(2*PLATE),0)*2*PLATE -> 65 | I33: =ROUND(I36*(1-DLINT*3)/(2*PLATE),0)*2*PLATE -> 65 | J33: =ROUND(J36*(1-DLINT*3)/(2*PLATE),0)*2*PLATE -> 65 | K33: =ROUND(K36*(1-DLINT*3)/(2*PLATE),0)*2*PLATE -> 70 | L33: =ROUND(L36*(1-DLINT*3)/(2*PLATE),0)*2*PLATE -> 70 | ... P33: =ROUND(P36*(1-DLINT*3)/(2*PLATE),0)*2*PLATE -> 80
D34: 5 | E34: =ROUND(E36*(1-DLINT*2)/(2*PLATE),0)*2*PLATE -> 70 | F34: =ROUND(F36*(1-DLINT*2)/(2*PLATE),0)*2*PLATE -> 70 | G34: =ROUND(G36*(1-DLINT*2)/(2*PLATE),0)*2*PLATE -> 75 | H34: =ROUND(H36*(1-DLINT*2)/(2*PLATE),0)*2*PLATE -> 75 | I34: =ROUND(I36*(1-DLINT*2)/(2*PLATE),0)*2*PLATE -> 80 | J34: =ROUND(J36*(1-DLINT*2)/(2*PLATE),0)*2*PLATE -> 80 | K34: =ROUND(K36*(1-DLINT*2)/(2*PLATE),0)*2*PLATE -> 85 | L34: =ROUND(L36*(1-DLINT*2)/(2*PLATE),0)*2*PLATE -> 85 | ... P34: =ROUND(P36*(1-DLINT*2)/(2*PLATE),0)*2*PLATE -> 95
D35: 5 | E35: =ROUND(E36*(1-DLINT)/(2*PLATE),0)*2*PLATE -> 85 | F35: =ROUND(F36*(1-DLINT)/(2*PLATE),0)*2*PLATE -> 85 | G35: =ROUND(G36*(1-DLINT)/(2*PLATE),0)*2*PLATE -> 90 | H35: =ROUND(H36*(1-DLINT)/(2*PLATE),0)*2*PLATE -> 90 | I35: =ROUND(I36*(1-DLINT)/(2*PLATE),0)*2*PLATE -> 90 | J35: =ROUND(J36*(1-DLINT)/(2*PLATE),0)*2*PLATE -> 90 | K35: =ROUND(K36*(1-DLINT)/(2*PLATE),0)*2*PLATE -> 95 | L35: =ROUND(L36*(1-DLINT)/(2*PLATE),0)*2*PLATE -> 100 | ... P35: =ROUND(P36*(1-DLINT)/(2*PLATE),0)*2*PLATE -> 110
D36: 5 | E36: =DL -> 95 | F36: =ROUND(DL*(1.025^E9)/(2*PLATE),0)*2*PLATE -> 95 | G36: =ROUND(DL*(1.025^F9)/(2*PLATE),0)*2*PLATE -> 100 | H36: =ROUND(DL*(1.025^G9)/(2*PLATE),0)*2*PLATE -> 100 | I36: =ROUND(DL*(1.025^H9)/(2*PLATE),0)*2*PLATE -> 105 | J36: =ROUND(DL*(1.025^I9)/(2*PLATE),0)*2*PLATE -> 105 | K36: =ROUND(DL*(1.025^J9)/(2*PLATE),0)*2*PLATE -> 110 | L36: =ROUND(DL*(1.025^K9)/(2*PLATE),0)*2*PLATE -> 115 | M36: =ROUND(DL*(1.025^L9)/(2*PLATE),0)*2*PLATE -> 115 | ... P36: =ROUND(DL*(1.025^O9)/(2*PLATE),0)*2*PLATE -> 125
B37: Viernes | C37: Sentadilla | D37: 5 | E37: =E10 -> 50 | F37: =F10 -> 50 | G37: =G10 -> 50 | H37: =H10 -> 50 | I37: =I10 -> 55 | J37: =J10 -> 55 | K37: =K10 -> 55 | L37: =L10 -> 60 | ... P37: =P10 -> 65
D38: 5 | E38: =E11 -> 60 | F38: =F11 -> 60 | G38: =G11 -> 65 | H38: =H11 -> 65 | I38: =I11 -> 65 | J38: =J11 -> 65 | K38: =K11 -> 70 | L38: =L11 -> 70 | ... P38: =P11 -> 80
D39: 5 | E39: =E12 -> 70 | F39: =F12 -> 70 | G39: =G12 -> 75 | H39: =H12 -> 75 | I39: =I12 -> 80 | J39: =J12 -> 80 | K39: =K12 -> 85 | L39: =L12 -> 85 | ... P39: =P12 -> 95
D40: 5 | E40: =E13 -> 85 | F40: =F13 -> 85 | G40: =G13 -> 90 | H40: =H13 -> 90 | I40: =I13 -> 90 | J40: =J13 -> 90 | K40: =K13 -> 95 | L40: =L13 -> 100 | ... P40: =P13 -> 110
D41: 3 | E41: =ROUND(SQ*(1.025^E9)/(2*PLATE),0)*2*PLATE -> 95 | F41: =ROUND(SQ*(1.025^F9)/(2*PLATE),0)*2*PLATE -> 100 | G41: =ROUND(SQ*(1.025^G9)/(2*PLATE),0)*2*PLATE -> 100 | H41: =ROUND(SQ*(1.025^H9)/(2*PLATE),0)*2*PLATE -> 105 | I41: =ROUND(SQ*(1.025^I9)/(2*PLATE),0)*2*PLATE -> 105 | J41: =ROUND(SQ*(1.025^J9)/(2*PLATE),0)*2*PLATE -> 110 | K41: =ROUND(SQ*(1.025^K9)/(2*PLATE),0)*2*PLATE -> 115 | L41: =ROUND(SQ*(1.025^L9)/(2*PLATE),0)*2*PLATE -> 115 | ... P41: =ROUND(SQ*(1.025^P9)/(2*PLATE),0)*2*PLATE -> 130
D42: 8 | E42: =E12 -> 70 | F42: =F12 -> 70 | G42: =G12 -> 75 | H42: =H12 -> 75 | I42: =I12 -> 80 | J42: =J12 -> 80 | K42: =K12 -> 85 | L42: =L12 -> 85 | ... P42: =P12 -> 95
C43: Press de banca | D43: 5 | E43: =E15 -> 50 | F43: =F15 -> 50 | G43: =G15 -> 50 | H43: =H15 -> 50 | I43: =I15 -> 55 | J43: =J15 -> 55 | K43: =K15 -> 55 | L43: =L15 -> 60 | ... P43: =P15 -> 65
D44: 5 | E44: =E16 -> 60 | F44: =F16 -> 60 | G44: =G16 -> 65 | H44: =H16 -> 65 | I44: =I16 -> 65 | J44: =J16 -> 65 | K44: =K16 -> 70 | L44: =L16 -> 70 | ... P44: =P16 -> 80
D45: 5 | E45: =E17 -> 70 | F45: =F17 -> 70 | G45: =G17 -> 75 | H45: =H17 -> 75 | I45: =I17 -> 80 | J45: =J17 -> 80 | K45: =K17 -> 85 | L45: =L17 -> 85 | ... P45: =P17 -> 95
D46: 5 | E46: =E18 -> 85 | F46: =F18 -> 85 | G46: =G18 -> 90 | H46: =H18 -> 90 | I46: =I18 -> 90 | J46: =J18 -> 90 | K46: =K18 -> 95 | L46: =L18 -> 100 | ... P46: =P18 -> 110
...

Sheet Predicción 1RM
B5: Predicciones de 1RM y Volumen Total levantado
E8: Semana
B9: Dia | C9: Ejercicio | E9: 1 | F9: 2 | G9: 3 | H9: 4 | I9: 5 | J9: 6 | K9: 7 | L9: 8 | M9: 9 | N9: 10 | O9: 11 | P9: 12
B10: Lunes | C10: Sentadilla | D10: Relevant | E10: =IF(Programa!E10>=SQTON*E28,5*Programa!E10,0)+IF(Programa!E11>=SQTON*E28,5*Programa!E11,0)+IF(Programa!E12>=SQTON*E28,5*Programa!E12,0)+IF(Programa!E13>=SQTON*E28,5*Programa!E13,0)+IF(Programa!E14>=SQTON*E28,5*Programa!E14,0) -> 1250 | F10: =IF(Programa!F10>=SQTON*F28,5*Programa!F10,0)+IF(Programa!F11>=SQTON*F28,5*Programa!F11,0)+IF(Programa!F12>=SQTON*F28,5*Programa!F12,0)+IF(Programa!F13>=SQTON*F28,5*Programa!F13,0)+IF(Programa!F14>=SQTON*F28,5*Programa!F14,0) -> 1250 | G10: =IF(Programa!G10>=SQTON*G28,5*Programa!G10,0)+IF(Programa!G11>=SQTON*G28,5*Programa!G11,0)+IF(Programa!G12>=SQTON*G28,5*Programa!G12,0)+IF(Programa!G13>=SQTON*G28,5*Programa!G13,0)+IF(Programa!G14>=SQTON*G28,5*Programa!G14,0) -> 1325 | H10: =IF(Programa!H10>=SQTON*H28,5*Programa!H10,0)+IF(Programa!H11>=SQTON*H28,5*Programa!H11,0)+IF(Programa!H12>=SQTON*H28,5*Programa!H12,0)+IF(Programa!H13>=SQTON*H28,5*Programa!H13,0)+IF(Programa!H14>=SQTON*H28,5*Programa!H14,0) -> 1325 | I10: =IF(Programa!I10>=SQTON*I28,5*Programa!I10,0)+IF(Programa!I11>=SQTON*I28,5*Programa!I11,0)+IF(Programa!I12>=SQTON*I28,5*Programa!I12,0)+IF(Programa!I13>=SQTON*I28,5*Programa!I13,0)+IF(Programa!I14>=SQTON*I28,5*Programa!I14,0) -> 1375 | J10: =IF(Programa!J10>=SQTON*J28,5*Programa!J10,0)+IF(Programa!J11>=SQTON*J28,5*Programa!J11,0)+IF(Programa!J12>=SQTON*J28,5*Programa!J12,0)+IF(Programa!J13>=SQTON*J28,5*Programa!J13,0)+IF(Programa!J14>=SQTON*J28,5*Programa!J14,0) -> 1375 | K10: =IF(Programa!K10>=SQTON*K28,5*Programa!K10,0)+IF(Programa!K11>=SQTON*K28,5*Programa!K11,0)+IF(Programa!K12>=SQTON*K28,5*Programa!K12,0)+IF(Programa!K13>=SQTON*K28,5*Programa!K13,0)+IF(Programa!K14>=SQTON*K28,5*Programa!K14,0) -> 1450 | L10: =IF(Programa!L10>=SQTON*L28,5*Programa!L10,0)+IF(Programa!L11>=SQTON*L28,5*Programa!L11,0)+IF(Programa!L12>=SQTON*L28,5*Programa!L12,0)+IF(Programa!L13>=SQTON*L28,5*Programa!L13,0)+IF(Programa!L14>=SQTON*L28,5*Programa!L14,0) -> 1500 | ... P10: =IF(Programa!P10>=SQTON*P28,5*Programa!P10,0)+IF(Programa!P11>=SQTON*P28,5*Programa!P11,0)+IF(Programa!P12>=SQTON*P28,5*Programa!P12,0)+IF(Programa!P13>=SQTON*P28,5*Programa!P13,0)+IF(Programa!P14>=SQTON*P28,5*Programa!P14,0) -> 1650
D11: Total | E11: =5*SUM(Programa!E10:E14) -> 1800 | F11: =5*SUM(Programa!F10:F14) -> 1800 | G11: =5*SUM(Programa!G10:G14) -> 1900 | H11: =5*SUM(Programa!H10:H14) -> 1900 | I11: =5*SUM(Programa!I10:I14) -> 1975 | J11: =5*SUM(Programa!J10:J14) -> 1975 | K11: =5*SUM(Programa!K10:K14) -> 2075 | L11: =5*SUM(Programa!L10:L14) -> 2150 | ... P11: =5*SUM(Programa!P10:P14) -> 2375
C12: Banca | D12: Relevant | E12: =IF(Programa!E15>=BPTON*E31,5*Programa!E15,0)+IF(Programa!E16>=BPTON*E31,5*Programa!E16,0)+IF(Programa!E17>=BPTON*E31,5*Programa!E17,0)+IF(Programa!E18>=BPTON*E31,5*Programa!E18,0)+IF(Programa!E19>=BPTON*E31,5*Programa!E19,0) -> 1250 | F12: =IF(Programa!F15>=BPTON*F31,5*Programa!F15,0)+IF(Programa!F16>=BPTON*F31,5*Programa!F16,0)+IF(Programa!F17>=BPTON*F31,5*Programa!F17,0)+IF(Programa!F18>=BPTON*F31,5*Programa!F18,0)+IF(Programa!F19>=BPTON*F31,5*Programa!F19,0) -> 1250 | G12: =IF(Programa!G15>=BPTON*G31,5*Programa!G15,0)+IF(Programa!G16>=BPTON*G31,5*Programa!G16,0)+IF(Programa!G17>=BPTON*G31,5*Programa!G17,0)+IF(Programa!G18>=BPTON*G31,5*Programa!G18,0)+IF(Programa!G19>=BPTON*G31,5*Programa!G19,0) -> 1325 | H12: =IF(Programa!H15>=BPTON*H31,5*Programa!H15,0)+IF(Programa!H16>=BPTON*H31,5*Programa!H16,0)+IF(Programa!H17>=BPTON*H31,5*Programa!H17,0)+IF(Programa!H18>=BPTON*H31,5*Programa!H18,0)+IF(Programa!H19>=BPTON*H31,5*Programa!H19,0) -> 1325 | I12: =IF(Programa!I15>=BPTON*I31,5*Programa!I15,0)+IF(Programa!I16>=BPTON*I31,5*Programa!I16,0)+IF(Programa!I17>=BPTON*I31,5*Programa!I17,0)+IF(Programa!I18>=BPTON*I31,5*Programa!I18,0)+IF(Programa!I19>=BPTON*I31,5*Programa!I19,0) -> 1375 | J12: =IF(Programa!J15>=BPTON*J31,5*Programa!J15,0)+IF(Programa!J16>=BPTON*J31,5*Programa!J16,0)+IF(Programa!J17>=BPTON*J31,5*Programa!J17,0)+IF(Programa!J18>=BPTON*J31,5*Programa!J18,0)+IF(Programa!J19>=BPTON*J31,5*Programa!J19,0) -> 1375 | K12: =IF(Programa!K15>=BPTON*K31,5*Programa!K15,0)+IF(Programa!K16>=BPTON*K31,5*Programa!K16,0)+IF(Programa!K17>=BPTON*K31,5*Programa!K17,0)+IF(Programa!K18>=BPTON*K31,5*Programa!K18,0)+IF(Programa!K19>=BPTON*K31,5*Programa!K19,0) -> 1450 | L12: =IF(Programa!L15>=BPTON*L31,5*Programa!L15,0)+IF(Programa!L16>=BPTON*L31,5*Programa!L16,0)+IF(Programa!L17>=BPTON*L31,5*Programa!L17,0)+IF(Programa!L18>=BPTON*L31,5*Programa!L18,0)+IF(Programa!L19>=BPTON*L31,5*Programa!L19,0) -> 1500 | ... P12: =IF(Programa!P15>=BPTON*P31,5*Programa!P15,0)+IF(Programa!P16>=BPTON*P31,5*Programa!P16,0)+IF(Programa!P17>=BPTON*P31,5*Programa!P17,0)+IF(Programa!P18>=BPTON*P31,5*Programa!P18,0)+IF(Programa!P19>=BPTON*P31,5*Programa!P19,0) -> 1650
D13: Total | E13: =5*SUM(Programa!E15:E19) -> 1800 | F13: =5*SUM(Programa!F15:F19) -> 1800 | G13: =5*SUM(Programa!G15:G19) -> 1900 | H13: =5*SUM(Programa!H15:H19) -> 1900 | I13: =5*SUM(Programa!I15:I19) -> 1975 | J13: =5*SUM(Programa!J15:J19) -> 1975 | K13: =5*SUM(Programa!K15:K19) -> 2075 | L13: =5*SUM(Programa!L15:L19) -> 2150 | ... P13: =5*SUM(Programa!P15:P19) -> 2375
C14: Remo | D14: Relevant | E14: =IF(Programa!E20>=BBRTON*E34,5*Programa!E20,0)+IF(Programa!E21>=BBRTON*E34,5*Programa!E21,0)+IF(Programa!E22>=BBRTON*E34,5*Programa!E22,0)+IF(Programa!E23>=BBRTON*E34,5*Programa!E23,0)+IF(Programa!E24>=BBRTON*E34,5*Programa!E24,0) -> 1250 | F14: =IF(Programa!F20>=BBRTON*F34,5*Programa!F20,0)+IF(Programa!F21>=BBRTON*F34,5*Programa!F21,0)+IF(Programa!F22>=BBRTON*F34,5*Programa!F22,0)+IF(Programa!F23>=BBRTON*F34,5*Programa!F23,0)+IF(Programa!F24>=BBRTON*F34,5*Programa!F24,0) -> 1250 | G14: =IF(Programa!G20>=BBRTON*G34,5*Programa!G20,0)+IF(Programa!G21>=BBRTON*G34,5*Programa!G21,0)+IF(Programa!G22>=BBRTON*G34,5*Programa!G22,0)+IF(Programa!G23>=BBRTON*G34,5*Programa!G23,0)+IF(Programa!G24>=BBRTON*G34,5*Programa!G24,0) -> 1325 | H14: =IF(Programa!H20>=BBRTON*H34,5*Programa!H20,0)+IF(Programa!H21>=BBRTON*H34,5*Programa!H21,0)+IF(Programa!H22>=BBRTON*H34,5*Programa!H22,0)+IF(Programa!H23>=BBRTON*H34,5*Programa!H23,0)+IF(Programa!H24>=BBRTON*H34,5*Programa!H24,0) -> 1325 | I14: =IF(Programa!I20>=BBRTON*I34,5*Programa!I20,0)+IF(Programa!I21>=BBRTON*I34,5*Programa!I21,0)+IF(Programa!I22>=BBRTON*I34,5*Programa!I22,0)+IF(Programa!I23>=BBRTON*I34,5*Programa!I23,0)+IF(Programa!I24>=BBRTON*I34,5*Programa!I24,0) -> 1375 | J14: =IF(Programa!J20>=BBRTON*J34,5*Programa!J20,0)+IF(Programa!J21>=BBRTON*J34,5*Programa!J21,0)+IF(Programa!J22>=BBRTON*J34,5*Programa!J22,0)+IF(Programa!J23>=BBRTON*J34,5*Programa!J23,0)+IF(Programa!J24>=BBRTON*J34,5*Programa!J24,0) -> 1375 | K14: =IF(Programa!K20>=BBRTON*K34,5*Programa!K20,0)+IF(Programa!K21>=BBRTON*K34,5*Programa!K21,0)+IF(Programa!K22>=BBRTON*K34,5*Programa!K22,0)+IF(Programa!K23>=BBRTON*K34,5*Programa!K23,0)+IF(Programa!K24>=BBRTON*K34,5*Programa!K24,0) -> 1450 | L14: =IF(Programa!L20>=BBRTON*L34,5*Programa!L20,0)+IF(Programa!L21>=BBRTON*L34,5*Programa!L21,0)+IF(Programa!L22>=BBRTON*L34,5*Programa!L22,0)+IF(Programa!L23>=BBRTON*L34,5*Programa!L23,0)+IF(Programa!L24>=BBRTON*L34,5*Programa!L24,0) -> 1500 | ... P14: =IF(Programa!P20>=BBRTON*P34,5*Programa!P20,0)+IF(Programa!P21>=BBRTON*P34,5*Programa!P21,0)+IF(Programa!P22>=BBRTON*P34,5*Programa!P22,0)+IF(Programa!P23>=BBRTON*P34,5*Programa!P23,0)+IF(Programa!P24>=BBRTON*P34,5*Programa!P24,0) -> 1650
D15: Total | E15: =5*SUM(Programa!E20:E24) -> 1800 | F15: =5*SUM(Programa!F20:F24) -> 1800 | G15: =5*SUM(Programa!G20:G24) -> 1900 | H15: =5*SUM(Programa!H20:H24) -> 1900 | I15: =5*SUM(Programa!I20:I24) -> 1975 | J15: =5*SUM(Programa!J20:J24) -> 1975 | K15: =5*SUM(Programa!K20:K24) -> 2075 | L15: =5*SUM(Programa!L20:L24) -> 2150 | ... P15: =5*SUM(Programa!P20:P24) -> 2375
B16: Miercoles | C16: Sentadilla | D16: Relevant | E16: =IF(Programa!E25>=SQTON*E28,5*Programa!E25,0)+IF(Programa!E26>=SQTON*E28,5*Programa!E26,0)+IF(Programa!E27>=SQTON*E28,5*Programa!E27,0)+IF(Programa!E28>=SQTON*E28,5*Programa!E28,0) -> 700 | F16: =IF(Programa!F25>=SQTON*F28,5*Programa!F25,0)+IF(Programa!F26>=SQTON*F28,5*Programa!F26,0)+IF(Programa!F27>=SQTON*F28,5*Programa!F27,0)+IF(Programa!F28>=SQTON*F28,5*Programa!F28,0) -> 700 | G16: =IF(Programa!G25>=SQTON*G28,5*Programa!G25,0)+IF(Programa!G26>=SQTON*G28,5*Programa!G26,0)+IF(Programa!G27>=SQTON*G28,5*Programa!G27,0)+IF(Programa!G28>=SQTON*G28,5*Programa!G28,0) -> 750 | H16: =IF(Programa!H25>=SQTON*H28,5*Programa!H25,0)+IF(Programa!H26>=SQTON*H28,5*Programa!H26,0)+IF(Programa!H27>=SQTON*H28,5*Programa!H27,0)+IF(Programa!H28>=SQTON*H28,5*Programa!H28,0) -> 750 | I16: =IF(Programa!I25>=SQTON*I28,5*Programa!I25,0)+IF(Programa!I26>=SQTON*I28,5*Programa!I26,0)+IF(Programa!I27>=SQTON*I28,5*Programa!I27,0)+IF(Programa!I28>=SQTON*I28,5*Programa!I28,0) -> 800 | J16: =IF(Programa!J25>=SQTON*J28,5*Programa!J25,0)+IF(Programa!J26>=SQTON*J28,5*Programa!J26,0)+IF(Programa!J27>=SQTON*J28,5*Programa!J27,0)+IF(Programa!J28>=SQTON*J28,5*Programa!J28,0) -> 800 | K16: =IF(Programa!K25>=SQTON*K28,5*Programa!K25,0)+IF(Programa!K26>=SQTON*K28,5*Programa!K26,0)+IF(Programa!K27>=SQTON*K28,5*Programa!K27,0)+IF(Programa!K28>=SQTON*K28,5*Programa!K28,0) -> 850 | L16: =IF(Programa!L25>=SQTON*L28,5*Programa!L25,0)+IF(Programa!L26>=SQTON*L28,5*Programa!L26,0)+IF(Programa!L27>=SQTON*L28,5*Programa!L27,0)+IF(Programa!L28>=SQTON*L28,5*Programa!L28,0) -> 850 | ... P16: =IF(Programa!P25>=SQTON*P28,5*Programa!P25,0)+IF(Programa!P26>=SQTON*P28,5*Programa!P26,0)+IF(Programa!P27>=SQTON*P28,5*Programa!P27,0)+IF(Programa!P28>=SQTON*P28,5*Programa!P28,0) -> 950
D17: Total | E17: =5*SUM(Programa!E25:E28) -> 1250 | F17: =5*SUM(Programa!F25:F28) -> 1250 | G17: =5*SUM(Programa!G25:G28) -> 1325 | H17: =5*SUM(Programa!H25:H28) -> 1325 | I17: =5*SUM(Programa!I25:I28) -> 1400 | J17: =5*SUM(Programa!J25:J28) -> 1400 | K17: =5*SUM(Programa!K25:K28) -> 1475 | L17: =5*SUM(Programa!L25:L28) -> 1500 | ... P17: =5*SUM(Programa!P25:P28) -> 1675
C18: Press militar | D18: Relevant | E18: =IF(Programa!E29>=OHPTON*E37,5*Programa!E29,0)+IF(Programa!E30>=OHPTON*E37,5*Programa!E30,0)+IF(Programa!E31>=OHPTON*E37,5*Programa!E31,0)+IF(Programa!E32>=OHPTON*E37,5*Programa!E32,0) -> 1250 | F18: =IF(Programa!F29>=OHPTON*F37,5*Programa!F29,0)+IF(Programa!F30>=OHPTON*F37,5*Programa!F30,0)+IF(Programa!F31>=OHPTON*F37,5*Programa!F31,0)+IF(Programa!F32>=OHPTON*F37,5*Programa!F32,0) -> 1250 | G18: =IF(Programa!G29>=OHPTON*G37,5*Programa!G29,0)+IF(Programa!G30>=OHPTON*G37,5*Programa!G30,0)+IF(Programa!G31>=OHPTON*G37,5*Programa!G31,0)+IF(Programa!G32>=OHPTON*G37,5*Programa!G32,0) -> 1325 | H18: =IF(Programa!H29>=OHPTON*H37,5*Programa!H29,0)+IF(Programa!H30>=OHPTON*H37,5*Programa!H30,0)+IF(Programa!H31>=OHPTON*H37,5*Programa!H31,0)+IF(Programa!H32>=OHPTON*H37,5*Programa!H32,0) -> 1325 | I18: =IF(Programa!I29>=OHPTON*I37,5*Programa!I29,0)+IF(Programa!I30>=OHPTON*I37,5*Programa!I30,0)+IF(Programa!I31>=OHPTON*I37,5*Programa!I31,0)+IF(Programa!I32>=OHPTON*I37,5*Programa!I32,0) -> 1375 | J18: =IF(Programa!J29>=OHPTON*J37,5*Programa!J29,0)+IF(Programa!J30>=OHPTON*J37,5*Programa!J30,0)+IF(Programa!J31>=OHPTON*J37,5*Programa!J31,0)+IF(Programa!J32>=OHPTON*J37,5*Programa!J32,0) -> 1375 | K18: =IF(Programa!K29>=OHPTON*K37,5*Programa!K29,0)+IF(Programa!K30>=OHPTON*K37,5*Programa!K30,0)+IF(Programa!K31>=OHPTON*K37,5*Programa!K31,0)+IF(Programa!K32>=OHPTON*K37,5*Programa!K32,0) -> 1450 | L18: =IF(Programa!L29>=OHPTON*L37,5*Programa!L29,0)+IF(Programa!L30>=OHPTON*L37,5*Programa!L30,0)+IF(Programa!L31>=OHPTON*L37,5*Programa!L31,0)+IF(Programa!L32>=OHPTON*L37,5*Programa!L32,0) -> 1500 | ... P18: =IF(Programa!P29>=OHPTON*P37,5*Programa!P29,0)+IF(Programa!P30>=OHPTON*P37,5*Programa!P30,0)+IF(Programa!P31>=OHPTON*P37,5*Programa!P31,0)+IF(Programa!P32>=OHPTON*P37,5*Programa!P32,0) -> 1650
D19: Total | E19: =5*SUM(Programa!E29:E32) -> 1550 | F19: =5*SUM(Programa!F29:F32) -> 1550 | G19: =5*SUM(Programa!G29:G32) -> 1650 | H19: =5*SUM(Programa!H29:H32) -> 1650 | I19: =5*SUM(Programa!I29:I32) -> 1700 | J19: =5*SUM(Programa!J29:J32) -> 1700 | K19: =5*SUM(Programa!K29:K32) -> 1800 | L19: =5*SUM(Programa!L29:L32) -> 1850 | ... P19: =5*SUM(Programa!P29:P32) -> 2050
C20: Peso muerto | D20: Relevant | E20: =IF(Programa!E33>=DLTON*E40,5*Programa!E33,0)+IF(Programa!E34>=DLTON*E40,5*Programa!E34,0)+IF(Programa!E35>=DLTON*E40,5*Programa!E35,0)+IF(Programa!E36>=DLTON*E40,5*Programa!E36,0) -> 1250 | F20: =IF(Programa!F33>=DLTON*F40,5*Programa!F33,0)+IF(Programa!F34>=DLTON*F40,5*Programa!F34,0)+IF(Programa!F35>=DLTON*F40,5*Programa!F35,0)+IF(Programa!F36>=DLTON*F40,5*Programa!F36,0) -> 1250 | G20: =IF(Programa!G33>=DLTON*G40,5*Programa!G33,0)+IF(Programa!G34>=DLTON*G40,5*Programa!G34,0)+IF(Programa!G35>=DLTON*G40,5*Programa!G35,0)+IF(Programa!G36>=DLTON*G40,5*Programa!G36,0) -> 1325 | H20: =IF(Programa!H33>=DLTON*H40,5*Programa!H33,0)+IF(Programa!H34>=DLTON*H40,5*Programa!H34,0)+IF(Programa!H35>=DLTON*H40,5*Programa!H35,0)+IF(Programa!H36>=DLTON*H40,5*Programa!H36,0) -> 1325 | I20: =IF(Programa!I33>=DLTON*I40,5*Programa!I33,0)+IF(Programa!I34>=DLTON*I40,5*Programa!I34,0)+IF(Programa!I35>=DLTON*I40,5*Programa!I35,0)+IF(Programa!I36>=DLTON*I40,5*Programa!I36,0) -> 1375 | J20: =IF(Programa!J33>=DLTON*J40,5*Programa!J33,0)+IF(Programa!J34>=DLTON*J40,5*Programa!J34,0)+IF(Programa!J35>=DLTON*J40,5*Programa!J35,0)+IF(Programa!J36>=DLTON*J40,5*Programa!J36,0) -> 1375 | K20: =IF(Programa!K33>=DLTON*K40,5*Programa!K33,0)+IF(Programa!K34>=DLTON*K40,5*Programa!K34,0)+IF(Programa!K35>=DLTON*K40,5*Programa!K35,0)+IF(Programa!K36>=DLTON*K40,5*Programa!K36,0) -> 1450 | L20: =IF(Programa!L33>=DLTON*L40,5*Programa!L33,0)+IF(Programa!L34>=DLTON*L40,5*Programa!L34,0)+IF(Programa!L35>=DLTON*L40,5*Programa!L35,0)+IF(Programa!L36>=DLTON*L40,5*Programa!L36,0) -> 1500 | ... P20: =IF(Programa!P33>=DLTON*P40,5*Programa!P33,0)+IF(Programa!P34>=DLTON*P40,5*Programa!P34,0)+IF(Programa!P35>=DLTON*P40,5*Programa!P35,0)+IF(Programa!P36>=DLTON*P40,5*Programa!P36,0) -> 1650
D21: Total | E21: =5*SUM(Programa!E33:E36) -> 1550 | F21: =5*SUM(Programa!F33:F36) -> 1550 | G21: =5*SUM(Programa!G33:G36) -> 1650 | H21: =5*SUM(Programa!H33:H36) -> 1650 | I21: =5*SUM(Programa!I33:I36) -> 1700 | J21: =5*SUM(Programa!J33:J36) -> 1700 | K21: =5*SUM(Programa!K33:K36) -> 1800 | L21: =5*SUM(Programa!L33:L36) -> 1850 | ... P21: =5*SUM(Programa!P33:P36) -> 2050
B22: Viernes | C22: Sentadilla | D22: Relevant | E22: =IF(Programa!E37>=SQTON*E28,5*Programa!E37,0)+IF(Programa!E38>=SQTON*E28,5*Programa!E38,0)+IF(Programa!E39>=SQTON*E28,5*Programa!E39,0)+IF(Programa!E40>=SQTON*E28,5*Programa!E40,0)+IF(Programa!E41>=SQTON*E28,3*Programa!E41,0)+IF(Programa!E42>=SQTON*E28,8*Programa!E42,0) -> 1620 | F22: =IF(Programa!F37>=SQTON*F28,5*Programa!F37,0)+IF(Programa!F38>=SQTON*F28,5*Programa!F38,0)+IF(Programa!F39>=SQTON*F28,5*Programa!F39,0)+IF(Programa!F40>=SQTON*F28,5*Programa!F40,0)+IF(Programa!F41>=SQTON*F28,3*Programa!F41,0)+IF(Programa!F42>=SQTON*F28,8*Programa!F42,0) -> 1635 | G22: =IF(Programa!G37>=SQTON*G28,5*Programa!G37,0)+IF(Programa!G38>=SQTON*G28,5*Programa!G38,0)+IF(Programa!G39>=SQTON*G28,5*Programa!G39,0)+IF(Programa!G40>=SQTON*G28,5*Programa!G40,0)+IF(Programa!G41>=SQTON*G28,3*Programa!G41,0)+IF(Programa!G42>=SQTON*G28,8*Programa!G42,0) -> 1725 | H22: =IF(Programa!H37>=SQTON*H28,5*Programa!H37,0)+IF(Programa!H38>=SQTON*H28,5*Programa!H38,0)+IF(Programa!H39>=SQTON*H28,5*Programa!H39,0)+IF(Programa!H40>=SQTON*H28,5*Programa!H40,0)+IF(Programa!H41>=SQTON*H28,3*Programa!H41,0)+IF(Programa!H42>=SQTON*H28,8*Programa!H42,0) -> 1740 | I22: =IF(Programa!I37>=SQTON*I28,5*Programa!I37,0)+IF(Programa!I38>=SQTON*I28,5*Programa!I38,0)+IF(Programa!I39>=SQTON*I28,5*Programa!I39,0)+IF(Programa!I40>=SQTON*I28,5*Programa!I40,0)+IF(Programa!I41>=SQTON*I28,3*Programa!I41,0)+IF(Programa!I42>=SQTON*I28,8*Programa!I42,0) -> 1805 | J22: =IF(Programa!J37>=SQTON*J28,5*Programa!J37,0)+IF(Programa!J38>=SQTON*J28,5*Programa!J38,0)+IF(Programa!J39>=SQTON*J28,5*Programa!J39,0)+IF(Programa!J40>=SQTON*J28,5*Programa!J40,0)+IF(Programa!J41>=SQTON*J28,3*Programa!J41,0)+IF(Programa!J42>=SQTON*J28,8*Programa!J42,0) -> 1820 | K22: =IF(Programa!K37>=SQTON*K28,5*Programa!K37,0)+IF(Programa!K38>=SQTON*K28,5*Programa!K38,0)+IF(Programa!K39>=SQTON*K28,5*Programa!K39,0)+IF(Programa!K40>=SQTON*K28,5*Programa!K40,0)+IF(Programa!K41>=SQTON*K28,3*Programa!K41,0)+IF(Programa!K42>=SQTON*K28,8*Programa!K42,0) -> 1925 | L22: =IF(Programa!L37>=SQTON*L28,5*Programa!L37,0)+IF(Programa!L38>=SQTON*L28,5*Programa!L38,0)+IF(Programa!L39>=SQTON*L28,5*Programa!L39,0)+IF(Programa!L40>=SQTON*L28,5*Programa!L40,0)+IF(Programa!L41>=SQTON*L28,3*Programa!L41,0)+IF(Programa!L42>=SQTON*L28,8*Programa!L42,0) -> 1950 | ... P22: =IF(Programa!P37>=SQTON*P28,5*Programa!P37,0)+IF(Programa!P38>=SQTON*P28,5*Programa!P38,0)+IF(Programa!P39>=SQTON*P28,5*Programa!P39,0)+IF(Programa!P40>=SQTON*P28,5*Programa!P40,0)+IF(Programa!P41>=SQTON*P28,3*Programa!P41,0)+IF(Programa!P42>=SQTON*P28,8*Programa!P42,0) -> 2175
D23: Total | E23: =5*SUM(Programa!E37:E40)+3*Programa!E41+8*Programa!E42 -> 2170 | F23: =5*SUM(Programa!F37:F40)+3*Programa!F41+8*Programa!F42 -> 2185 | G23: =5*SUM(Programa!G37:G40)+3*Programa!G41+8*Programa!G42 -> 2300 | H23: =5*SUM(Programa!H37:H40)+3*Programa!H41+8*Programa!H42 -> 2315 | I23: =5*SUM(Programa!I37:I40)+3*Programa!I41+8*Programa!I42 -> 2405 | J23: =5*SUM(Programa!J37:J40)+3*Programa!J41+8*Programa!J42 -> 2420 | K23: =5*SUM(Programa!K37:K40)+3*Programa!K41+8*Programa!K42 -> 2550 | L23: =5*SUM(Programa!L37:L40)+3*Programa!L41+8*Programa!L42 -> 2600 | ... P23: =5*SUM(Programa!P37:P40)+3*Programa!P41+8*Programa!P42 -> 2900
C24: Banca | D24: Relevant | E24: =IF(Programa!E43>=BPTON*E31,5*Programa!E43,0)+IF(Programa!E44>=BPTON*E31,5*Programa!E44,0)+IF(Programa!E45>=BPTON*E31,5*Programa!E45,0)+IF(Programa!E46>=BPTON*E31,5*Programa!E46,0)+IF(Programa!E47>=BPTON*E31,3*Programa!E47,0)+IF(Programa!E48>=BPTON*E31,8*Programa!E48,0) -> 1620 | F24: =IF(Programa!F43>=BPTON*F31,5*Programa!F43,0)+IF(Programa!F44>=BPTON*F31,5*Programa!F44,0)+IF(Programa!F45>=BPTON*F31,5*Programa!F45,0)+IF(Programa!F46>=BPTON*F31,5*Programa!F46,0)+IF(Programa!F47>=BPTON*F31,3*Programa!F47,0)+IF(Programa!F48>=BPTON*F31,8*Programa!F48,0) -> 1635 | G24: =IF(Programa!G43>=BPTON*G31,5*Programa!G43,0)+IF(Programa!G44>=BPTON*G31,5*Programa!G44,0)+IF(Programa!G45>=BPTON*G31,5*Programa!G45,0)+IF(Programa!G46>=BPTON*G31,5*Programa!G46,0)+IF(Programa!G47>=BPTON*G31,3*Programa!G47,0)+IF(Programa!G48>=BPTON*G31,8*Programa!G48,0) -> 1725 | H24: =IF(Programa!H43>=BPTON*H31,5*Programa!H43,0)+IF(Programa!H44>=BPTON*H31,5*Programa!H44,0)+IF(Programa!H45>=BPTON*H31,5*Programa!H45,0)+IF(Programa!H46>=BPTON*H31,5*Programa!H46,0)+IF(Programa!H47>=BPTON*H31,3*Programa!H47,0)+IF(Programa!H48>=BPTON*H31,8*Programa!H48,0) -> 1740 | I24: =IF(Programa!I43>=BPTON*I31,5*Programa!I43,0)+IF(Programa!I44>=BPTON*I31,5*Programa!I44,0)+IF(Programa!I45>=BPTON*I31,5*Programa!I45,0)+IF(Programa!I46>=BPTON*I31,5*Programa!I46,0)+IF(Programa!I47>=BPTON*I31,3*Programa!I47,0)+IF(Programa!I48>=BPTON*I31,8*Programa!I48,0) -> 1805 | J24: =IF(Programa!J43>=BPTON*J31,5*Programa!J43,0)+IF(Programa!J44>=BPTON*J31,5*Programa!J44,0)+IF(Programa!J45>=BPTON*J31,5*Programa!J45,0)+IF(Programa!J46>=BPTON*J31,5*Programa!J46,0)+IF(Programa!J47>=BPTON*J31,3*Programa!J47,0)+IF(Programa!J48>=BPTON*J31,8*Programa!J48,0) -> 1820 | K24: =IF(Programa!K43>=BPTON*K31,5*Programa!K43,0)+IF(Programa!K44>=BPTON*K31,5*Programa!K44,0)+IF(Programa!K45>=BPTON*K31,5*Programa!K45,0)+IF(Programa!K46>=BPTON*K31,5*Programa!K46,0)+IF(Programa!K47>=BPTON*K31,3*Programa!K47,0)+IF(Programa!K48>=BPTON*K31,8*Programa!K48,0) -> 1925 | L24: =IF(Programa!L43>=BPTON*L31,5*Programa!L43,0)+IF(Programa!L44>=BPTON*L31,5*Programa!L44,0)+IF(Programa!L45>=BPTON*L31,5*Programa!L45,0)+IF(Programa!L46>=BPTON*L31,5*Programa!L46,0)+IF(Programa!L47>=BPTON*L31,3*Programa!L47,0)+IF(Programa!L48>=BPTON*L31,8*Programa!L48,0) -> 1950 | ... P24: =IF(Programa!P43>=BPTON*P31,5*Programa!P43,0)+IF(Programa!P44>=BPTON*P31,5*Programa!P44,0)+IF(Programa!P45>=BPTON*P31,5*Programa!P45,0)+IF(Programa!P46>=BPTON*P31,5*Programa!P46,0)+IF(Programa!P47>=BPTON*P31,3*Programa!P47,0)+IF(Programa!P48>=BPTON*P31,8*Programa!P48,0) -> 2175
D25: Total | E25: =5*SUM(Programa!E43:E46)+3*Programa!E47+8*Programa!E48 -> 2170 | F25: =5*SUM(Programa!F43:F46)+3*Programa!F47+8*Programa!F48 -> 2185 | G25: =5*SUM(Programa!G43:G46)+3*Programa!G47+8*Programa!G48 -> 2300 | H25: =5*SUM(Programa!H43:H46)+3*Programa!H47+8*Programa!H48 -> 2315 | I25: =5*SUM(Programa!I43:I46)+3*Programa!I47+8*Programa!I48 -> 2405 | J25: =5*SUM(Programa!J43:J46)+3*Programa!J47+8*Programa!J48 -> 2420 | K25: =5*SUM(Programa!K43:K46)+3*Programa!K47+8*Programa!K48 -> 2550 | L25: =5*SUM(Programa!L43:L46)+3*Programa!L47+8*Programa!L48 -> 2600 | ... P25: =5*SUM(Programa!P43:P46)+3*Programa!P47+8*Programa!P48 -> 2900
C26: Remo | D26: Relevant | E26: =IF(Programa!E49>=BBRTON*E34,5*Programa!E49,0)+IF(Programa!E50>=BBRTON*E34,5*Programa!E50,0)+IF(Programa!E51>=BBRTON*E34,5*Programa!E51,0)+IF(Programa!E52>=BBRTON*E34,5*Programa!E52,0)+IF(Programa!E53>=BBRTON*E34,3*Programa!E53,0)+IF(Programa!E54>=BBRTON*E34,8*Programa!E54,0) -> 1620 | F26: =IF(Programa!F49>=BBRTON*F34,5*Programa!F49,0)+IF(Programa!F50>=BBRTON*F34,5*Programa!F50,0)+IF(Programa!F51>=BBRTON*F34,5*Programa!F51,0)+IF(Programa!F52>=BBRTON*F34,5*Programa!F52,0)+IF(Programa!F53>=BBRTON*F34,3*Programa!F53,0)+IF(Programa!F54>=BBRTON*F34,8*Programa!F54,0) -> 1635 | G26: =IF(Programa!G49>=BBRTON*G34,5*Programa!G49,0)+IF(Programa!G50>=BBRTON*G34,5*Programa!G50,0)+IF(Programa!G51>=BBRTON*G34,5*Programa!G51,0)+IF(Programa!G52>=BBRTON*G34,5*Programa!G52,0)+IF(Programa!G53>=BBRTON*G34,3*Programa!G53,0)+IF(Programa!G54>=BBRTON*G34,8*Programa!G54,0) -> 1725 | H26: =IF(Programa!H49>=BBRTON*H34,5*Programa!H49,0)+IF(Programa!H50>=BBRTON*H34,5*Programa!H50,0)+IF(Programa!H51>=BBRTON*H34,5*Programa!H51,0)+IF(Programa!H52>=BBRTON*H34,5*Programa!H52,0)+IF(Programa!H53>=BBRTON*H34,3*Programa!H53,0)+IF(Programa!H54>=BBRTON*H34,8*Programa!H54,0) -> 1740 | I26: =IF(Programa!I49>=BBRTON*I34,5*Programa!I49,0)+IF(Programa!I50>=BBRTON*I34,5*Programa!I50,0)+IF(Programa!I51>=BBRTON*I34,5*Programa!I51,0)+IF(Programa!I52>=BBRTON*I34,5*Programa!I52,0)+IF(Programa!I53>=BBRTON*I34,3*Programa!I53,0)+IF(Programa!I54>=BBRTON*I34,8*Programa!I54,0) -> 1805 | J26: =IF(Programa!J49>=BBRTON*J34,5*Programa!J49,0)+IF(Programa!J50>=BBRTON*J34,5*Programa!J50,0)+IF(Programa!J51>=BBRTON*J34,5*Programa!J51,0)+IF(Programa!J52>=BBRTON*J34,5*Programa!J52,0)+IF(Programa!J53>=BBRTON*J34,3*Programa!J53,0)+IF(Programa!J54>=BBRTON*J34,8*Programa!J54,0) -> 1820 | K26: =IF(Programa!K49>=BBRTON*K34,5*Programa!K49,0)+IF(Programa!K50>=BBRTON*K34,5*Programa!K50,0)+IF(Programa!K51>=BBRTON*K34,5*Programa!K51,0)+IF(Programa!K52>=BBRTON*K34,5*Programa!K52,0)+IF(Programa!K53>=BBRTON*K34,3*Programa!K53,0)+IF(Programa!K54>=BBRTON*K34,8*Programa!K54,0) -> 1925 | L26: =IF(Programa!L49>=BBRTON*L34,5*Programa!L49,0)+IF(Programa!L50>=BBRTON*L34,5*Programa!L50,0)+IF(Programa!L51>=BBRTON*L34,5*Programa!L51,0)+IF(Programa!L52>=BBRTON*L34,5*Programa!L52,0)+IF(Programa!L53>=BBRTON*L34,3*Programa!L53,0)+IF(Programa!L54>=BBRTON*L34,8*Programa!L54,0) -> 1950 | ... P26: =IF(Programa!P49>=BBRTON*P34,5*Programa!P49,0)+IF(Programa!P50>=BBRTON*P34,5*Programa!P50,0)+IF(Programa!P51>=BBRTON*P34,5*Programa!P51,0)+IF(Programa!P52>=BBRTON*P34,5*Programa!P52,0)+IF(Programa!P53>=BBRTON*P34,3*Programa!P53,0)+IF(Programa!P54>=BBRTON*P34,8*Programa!P54,0) -> 2175
D27: Total | E27: =5*SUM(Programa!E49:E52)+3*Programa!E53+8*Programa!E54 -> 2170 | F27: =5*SUM(Programa!F49:F52)+3*Programa!F53+8*Programa!F54 -> 2185 | G27: =5*SUM(Programa!G49:G52)+3*Programa!G53+8*Programa!G54 -> 2300 | H27: =5*SUM(Programa!H49:H52)+3*Programa!H53+8*Programa!H54 -> 2315 | I27: =5*SUM(Programa!I49:I52)+3*Programa!I53+8*Programa!I54 -> 2405 | J27: =5*SUM(Programa!J49:J52)+3*Programa!J53+8*Programa!J54 -> 2420 | K27: =5*SUM(Programa!K49:K52)+3*Programa!K53+8*Programa!K54 -> 2550 | L27: =5*SUM(Programa!L49:L52)+3*Programa!L53+8*Programa!L54 -> 2600 | ... P27: =5*SUM(Programa!P49:P52)+3*Programa!P53+8*Programa!P54 -> 2900
C28: Sentadilla | D28: 1RM | E28: =MAX(SQMAX,Programa!E14/(1.0278-(0.0278*5))) -> 112.51125 | F28: =MAX(SQMAX,Programa!F14/(1.0278-(0.0278*5))) -> 112.51125 | G28: =MAX(SQMAX,Programa!G14/(1.0278-(0.0278*5))) -> 112.51125 | H28: =MAX(SQMAX,Programa!H14/(1.0278-(0.0278*5))) -> 112.51125 | I28: =MAX(SQMAX,Programa!I14/(1.0278-(0.0278*5))) -> 118.13681 | J28: =MAX(SQMAX,Programa!J14/(1.0278-(0.0278*5))) -> 118.13681 | K28: =MAX(SQMAX,Programa!K14/(1.0278-(0.0278*5))) -> 123.76238 | L28: =MAX(SQMAX,Programa!L14/(1.0278-(0.0278*5))) -> 129.38794 | ... P28: =MAX(SQMAX,Programa!P14/(1.0278-(0.0278*5))) -> 140.63906
B29: Total semanal | D29: Relevant | E29: =E10+E16+E22 -> 3570 | F29: =F10+F16+F22 -> 3585 | G29: =G10+G16+G22 -> 3800 | H29: =H10+H16+H22 -> 3815 | I29: =I10+I16+I22 -> 3980 | J29: =J10+J16+J22 -> 3995 | K29: =K10+K16+K22 -> 4225 | L29: =L10+L16+L22 -> 4300 | ... P29: =P10+P16+P22 -> 4775
D30: Total | E30: =E11+E17+E23 -> 5220 | F30: =F11+F17+F23 -> 5235 | G30: =G11+G17+G23 -> 5525 | H30: =H11+H17+H23 -> 5540 | I30: =I11+I17+I23 -> 5780 | J30: =J11+J17+J23 -> 5795 | K30: =K11+K17+K23 -> 6100 | L30: =L11+L17+L23 -> 6250 | ... P30: =P11+P17+P23 -> 6950
C31: Banca | D31: 1RM | E31: =MAX(BPMAX,Programa!E19/(1.0278-(0.0278*5))) -> 112.51125 | F31: =MAX(BPMAX,Programa!F19/(1.0278-(0.0278*5))) -> 112.51125 | G31: =MAX(BPMAX,Programa!G19/(1.0278-(0.0278*5))) -> 112.51125 | H31: =MAX(BPMAX,Programa!H19/(1.0278-(0.0278*5))) -> 112.51125 | I31: =MAX(BPMAX,Programa!I19/(1.0278-(0.0278*5))) -> 118.13681 | J31: =MAX(BPMAX,Programa!J19/(1.0278-(0.0278*5))) -> 118.13681 | K31: =MAX(BPMAX,Programa!K19/(1.0278-(0.0278*5))) -> 123.76238 | L31: =MAX(BPMAX,Programa!L19/(1.0278-(0.0278*5))) -> 129.38794 | ... P31: =MAX(BPMAX,Programa!P19/(1.0278-(0.0278*5))) -> 140.63906
D32: Relevant | E32: =E12+E24 -> 2870 | F32: =F12+F24 -> 2885 | G32: =G12+G24 -> 3050 | H32: =H12+H24 -> 3065 | I32: =I12+I24 -> 3180 | J32: =J12+J24 -> 3195 | K32: =K12+K24 -> 3375 | L32: =L12+L24 -> 3450 | ... P32: =P12+P24 -> 3825
D33: Total | E33: =E13+E25 -> 3970 | F33: =F13+F25 -> 3985 | G33: =G13+G25 -> 4200 | H33: =H13+H25 -> 4215 | I33: =I13+I25 -> 4380 | J33: =J13+J25 -> 4395 | K33: =K13+K25 -> 4625 | L33: =L13+L25 -> 4750 | ... P33: =P13+P25 -> 5275
C34: Remo | D34: 1RM | E34: =MAX(BBRMAX,Programa!E24/(1.0278-(0.0278*5))) -> 112.51125 | F34: =MAX(BBRMAX,Programa!F24/(1.0278-(0.0278*5))) -> 112.51125 | G34: =MAX(BBRMAX,Programa!G24/(1.0278-(0.0278*5))) -> 112.51125 | H34: =MAX(BBRMAX,Programa!H24/(1.0278-(0.0278*5))) -> 112.51125 | I34: =MAX(BBRMAX,Programa!I24/(1.0278-(0.0278*5))) -> 118.13681 | J34: =MAX(BBRMAX,Programa!J24/(1.0278-(0.0278*5))) -> 118.13681 | K34: =MAX(BBRMAX,Programa!K24/(1.0278-(0.0278*5))) -> 123.76238 | L34: =MAX(BBRMAX,Programa!L24/(1.0278-(0.0278*5))) -> 129.38794 | ... P34: =MAX(BBRMAX,Programa!P24/(1.0278-(0.0278*5))) -> 140.63906
D35: Relevant | E35: =E14+E26 -> 2870 | F35: =F14+F26 -> 2885 | G35: =G14+G26 -> 3050 | H35: =H14+H26 -> 3065 | I35: =I14+I26 -> 3180 | J35: =J14+J26 -> 3195 | K35: =K14+K26 -> 3375 | L35: =L14+L26 -> 3450 | ... P35: =P14+P26 -> 3825
D36: Total | E36: =E15+E27 -> 3970 | F36: =F15+F27 -> 3985 | G36: =G15+G27 -> 4200 | H36: =H15+H27 -> 4215 | I36: =I15+I27 -> 4380 | J36: =J15+J27 -> 4395 | K36: =K15+K27 -> 4625 | L36: =L15+L27 -> 4750 | ... P36: =P15+P27 -> 5275
C37: Press militar | D37: 1RM | E37: =MAX(OHPMAX,Programa!E32/(1.0278-(0.0278*5))) -> 112.51125 | F37: =MAX(OHPMAX,Programa!F32/(1.0278-(0.0278*5))) -> 112.51125 | G37: =MAX(OHPMAX,Programa!G32/(1.0278-(0.0278*5))) -> 112.51125 | H37: =MAX(OHPMAX,Programa!H32/(1.0278-(0.0278*5))) -> 112.51125 | I37: =MAX(OHPMAX,Programa!I32/(1.0278-(0.0278*5))) -> 118.13681 | J37: =MAX(OHPMAX,Programa!J32/(1.0278-(0.0278*5))) -> 118.13681 | K37: =MAX(OHPMAX,Programa!K32/(1.0278-(0.0278*5))) -> 123.76238 | L37: =MAX(OHPMAX,Programa!L32/(1.0278-(0.0278*5))) -> 129.38794 | ... P37: =MAX(OHPMAX,Programa!P32/(1.0278-(0.0278*5))) -> 140.63906
D38: Relevant | E38: =E18 -> 1250 | F38: =F18 -> 1250 | G38: =G18 -> 1325 | H38: =H18 -> 1325 | I38: =I18 -> 1375 | J38: =J18 -> 1375 | K38: =K18 -> 1450 | L38: =L18 -> 1500 | ... P38: =P18 -> 1650
D39: Total | E39: =E19 -> 1550 | F39: =F19 -> 1550 | G39: =G19 -> 1650 | H39: =H19 -> 1650 | I39: =I19 -> 1700 | J39: =J19 -> 1700 | K39: =K19 -> 1800 | L39: =L19 -> 1850 | ... P39: =P19 -> 2050
C40: Peso muerto | D40: 1RM | E40: =MAX(DLMAX,Programa!E36/(1.0278-(0.0278*5))) -> 112.51125 | F40: =MAX(DLMAX,Programa!F36/(1.0278-(0.0278*5))) -> 112.51125 | G40: =MAX(DLMAX,Programa!G36/(1.0278-(0.0278*5))) -> 112.51125 | H40: =MAX(DLMAX,Programa!H36/(1.0278-(0.0278*5))) -> 112.51125 | I40: =MAX(DLMAX,Programa!I36/(1.0278-(0.0278*5))) -> 118.13681 | J40: =MAX(DLMAX,Programa!J36/(1.0278-(0.0278*5))) -> 118.13681 | K40: =MAX(DLMAX,Programa!K36/(1.0278-(0.0278*5))) -> 123.76238 | L40: =MAX(DLMAX,Programa!L36/(1.0278-(0.0278*5))) -> 129.38794 | ... P40: =MAX(DLMAX,Programa!P36/(1.0278-(0.0278*5))) -> 140.63906
D41: Relevant | E41: =E20 -> 1250 | F41: =F20 -> 1250 | G41: =G20 -> 1325 | H41: =H20 -> 1325 | I41: =I20 -> 1375 | J41: =J20 -> 1375 | K41: =K20 -> 1450 | L41: =L20 -> 1500 | ... P41: =P20 -> 1650
D42: Total | E42: =E21 -> 1550 | F42: =F21 -> 1550 | G42: =G21 -> 1650 | H42: =H21 -> 1650 | I42: =I21 -> 1700 | J42: =J21 -> 1700 | K42: =K21 -> 1800 | L42: =L21 -> 1850 | ... P42: =P21 -> 2050
C43: Total | D43: Relevant | E43: =E29+E32+E35+E38+E41 -> 11810 | F43: =F29+F32+F35+F38+F41 -> 11855 | G43: =G29+G32+G35+G38+G41 -> 12550 | H43: =H29+H32+H35+H38+H41 -> 12595 | I43: =I29+I32+I35+I38+I41 -> 13090 | J43: =J29+J32+J35+J38+J41 -> 13135 | K43: =K29+K32+K35+K38+K41 -> 13875 | L43: =L29+L32+L35+L38+L41 -> 14200 | ... P43: =P29+P32+P35+P38+P41 -> 15725
D44: Total | E44: =E30+E33+E36+E39+E42 -> 16260 | F44: =F30+F33+F36+F39+F42 -> 16305 | G44: =G30+G33+G36+G39+G42 -> 17225 | H44: =H30+H33+H36+H39+H42 -> 17270 | I44: =I30+I33+I36+I39+I42 -> 17940 | J44: =J30+J33+J36+J39+J42 -> 17985 | K44: =K30+K33+K36+K39+K42 -> 18950 | L44: =L30+L33+L36+L39+L42 -> 19450 | ... P44: =P30+P33+P36+P39+P42 -> 21600
