Workbook

Sheet OverviewData
B1: =HYPERLINK("https://www.the-pomp-official.com/home/2018/7/1/power-hypertrophy-program","13 Week Power-Hypertrophy Program with Upper-Lower Body Split by J. Bui") -> 13 Week Power-Hypertrophy Program with Upper-Lower Body Split by J. Bui
B2: Phase 1 (Current) | C2: Phase 2 (Estimated) | D2: Phase 3 (Estimated) | E2: Phase 4 (New)
A3: Squat | B3: 355 | C3: =B3 -> 355 | D3: =C3 -> 355 | F3: <----- UPDATE ALL NUMBERS IN PINK AND ALL OTHERS WILL ADJUST
A4: Bench | B4: 230 | C4: =B4 -> 230 | D4: =C4 -> 230
A5: Deadlift | B5: 405 | C5: =B5 -> 405 | D5: =C5 -> 405
A6: Shoulder Press | B6: 150 | C6: =B6 -> 150 | D6: =C6 -> 150 | F6: Make a copy via File > Download As...
B8: Modified Prilepin's Table (Hypertrophy)
B9: Percentage | C9: Rep(s) | D9: Optimal Total Reps | E9: Rep Range | F9: Rest Period Length | G9: Tempo Range (TUT)
B10: < 70% | C10: 6 - 10 | D10: 32 | E10: 20 - 40 | F10: 45s - 75s | G10: 4111 - 3101
B11: 70% - 80% | C11: 5 - 8 | D11: 30 | E11: 20 - 30 | F11: 60s - 90s | G11: 4101 - 3101
B12: 81% - 90% | C12: 5 - 7 | D12: 21 | E12: 15 - 25 | F12: 75s - 120s | G12: 4101
B13: > 90% | C13: 1 - 2 | D13: 7 | E13: 4 - 10 | F13: 90s - 180s | G13: -
B15: Abbreviation Definitions
B16: AMRAP | C16: As Many Reps As Possible
B17: TUT | C17: Time Under Tension (Tempo)
B18: RPS | C18: Rest Per Set
B19: RPE | C19: Rating of Perceived Exertion
B20: DB | C20: Dumbbell (Record weight PER SINGLE side)

Sheet Monday
A1: Week | B1: 1 | C1: 2 | D1: 3 | E1: 4 | F1: 5 | G1: 6 | H1: 7 | I1: 8 | J1: 9 | K1: 10 | L1: 11 | M1: 12 | N1: 13
A2: Date | B2: =DATE(2018, 7, 2) -> 43283 | C2: =B2+7 -> 43290 | D2: =C2+7 -> 43297 | E2: =D2+7 -> 43304 | F2: =E2+7 -> 43311 | G2: =F2+7 -> 43318 | H2: =G2+7 -> 43325 | I2: =H2+7 -> 43332 | J2: =I2+7 -> 43339 | ... N2: =M2+7 -> 43367
A4: Squat
A5: Target | B5: =mround(B8*OverviewData!$B$3,5) -> 255 | C5: =mround(C8*OverviewData!$B$3,5) -> 255 | D5: =mround(D8*OverviewData!$B$3,5) -> 255 | E5: =mround(E8*OverviewData!$B$3,5) -> 285 | F5: =mround(F8*OverviewData!$C$3,5) -> 265 | G5: =mround(G8*OverviewData!$C$3,5) -> 265 | H5: =mround(H8*OverviewData!$C$3,5) -> 265 | I5: =mround(I8*OverviewData!$C$3,5) -> 295 | J5: =mround(J8*OverviewData!$D$3,5) -> 275 | K5: =mround(K8*OverviewData!$D$3,5) -> 275 | L5: =mround(L8*OverviewData!$D$3,5) -> 275 | M5: =mround(M8*OverviewData!$D$3,5) -> 255 | N5: =mround(N8*OverviewData!$D$3,5) -> 295
A6: Set(s) | B6: 2 | C6: 3 | D6: 3 | E6: 4 | F6: 2 | G6: 3 | H6: 4 | I6: 5 | J6: 3 | K6: 4 | L6: 5 | M6: 5 | N6: 5
A7: Rep(s) | B7: 9 | C7: 9 | D7: 9 | E7: 4 | F7: 8 | G7: 8 | H7: 8 | I7: 3 | J7: 7 | K7: 7 | L7: 7 | M7: 7 | N7: 3
A8: Percentage | B8: 0.725 | C8: 0.725 | D8: 0.725 | E8: 0.8 | F8: 0.75 | G8: 0.75 | H8: 0.75 | I8: 0.825 | J8: 0.775 | K8: 0.775 | L8: 0.775 | M8: 0.725 | N8: 0.825
A10: Bench
A11: Target | B11: =mround(B14*OverviewData!$B$4,5) -> 165 | C11: =mround(C14*OverviewData!$B$4,5) -> 165 | D11: =mround(D14*OverviewData!$B$4,5) -> 165 | E11: =mround(E14*OverviewData!$B$4,5) -> 185 | F11: =mround(F14*OverviewData!$C$4,5) -> 175 | G11: =mround(G14*OverviewData!$C$4,5) -> 175 | H11: =mround(H14*OverviewData!$C$4,5) -> 175 | I11: =mround(I14*OverviewData!$C$4,5) -> 190 | J11: =mround(J14*OverviewData!$D$4,5) -> 180 | K11: =mround(K14*OverviewData!$D$4,5) -> 180 | L11: =mround(L14*OverviewData!$D$4,5) -> 180 | M11: =mround(M14*OverviewData!$D$4,5) -> 165 | N11: =mround(N14*OverviewData!$D$4,5) -> 190
A12: Set(s) | B12: 2 | C12: 3 | D12: 3 | E12: 4 | F12: 2 | G12: 3 | H12: 4 | I12: 5 | J12: 3 | K12: 4 | L12: 5 | M12: 5 | N12: 5
A13: Rep(s) | B13: 9 | C13: 9 | D13: 9 | E13: 4 | F13: 8 | G13: 8 | H13: 8 | I13: 3 | J13: 7 | K13: 7 | L13: 7 | M13: 7 | N13: 3
A14: Percentage | B14: 0.725 | C14: 0.725 | D14: 0.725 | E14: 0.8 | F14: 0.75 | G14: 0.75 | H14: 0.75 | I14: 0.825 | J14: 0.775 | K14: 0.775 | L14: 0.775 | M14: 0.725 | N14: 0.825
A16: Deadlift
A17: Target | B17: =mround(B20*OverviewData!$B$5,5) -> 295 | C17: =mround(C20*OverviewData!$B$5,5) -> 295 | D17: =mround(D20*OverviewData!$B$5,5) -> 295 | E17: =mround(E20*OverviewData!$B$5,5) -> 325 | F17: =mround(F20*OverviewData!$C$5,5) -> 305 | G17: =mround(G20*OverviewData!$C$5,5) -> 305 | H17: =mround(H20*OverviewData!$C$5,5) -> 305 | I17: =mround(I20*OverviewData!$C$5,5) -> 335 | J17: =mround(J20*OverviewData!$D$5,5) -> 315 | K17: =mround(K20*OverviewData!$D$5,5) -> 315 | L17: =mround(L20*OverviewData!$D$5,5) -> 315 | M17: =mround(M20*OverviewData!$D$5,5) -> 295 | N17: =mround(N20*OverviewData!$D$5,5) -> 335
A18: Set(s) | B18: 2 | C18: 3 | D18: 3 | E18: 4 | F18: 2 | G18: 3 | H18: 4 | I18: 5 | J18: 3 | K18: 4 | L18: 5 | M18: 5 | N18: 5
A19: Rep(s) | B19: 9 | C19: 9 | D19: 9 | E19: 4 | F19: 8 | G19: 8 | H19: 8 | I19: 3 | J19: 7 | K19: 7 | L19: 7 | M19: 7 | N19: 3
A20: Percentage | B20: 0.725 | C20: 0.725 | D20: 0.725 | E20: 0.8 | F20: 0.75 | G20: 0.75 | H20: 0.75 | I20: 0.825 | J20: 0.775 | K20: 0.775 | L20: 0.775 | M20: 0.725 | N20: 0.825
A22: REACTION (RPE)
A23: TOO EASY (3+)
A24: EASY (2)
A25: MEDIUM (1)
A26: HARD (0)
A27: GRIND (-)

Sheet Tuesday
A1: Week | B1: 1 | C1: 2 | D1: 3 | E1: 4 | F1: 5 | G1: 6 | H1: 7 | I1: 8 | J1: 9 | K1: 10 | L1: 11 | M1: 12 | N1: 13
A2: Date | B2: =Monday!B2+1 -> 43284 | C2: =B2+7 -> 43291 | D2: =C2+7 -> 43298 | E2: =D2+7 -> 43305 | F2: =E2+7 -> 43312 | G2: =F2+7 -> 43319 | H2: =G2+7 -> 43326 | I2: =H2+7 -> 43333 | J2: =I2+7 -> 43340 | ... N2: =M2+7 -> 43368
A4: DB Bench Press
A5: Target | B5: 75 | C5: =B5 -> 75 | D5: =C5 -> 75 | E5: =D5 -> 75 | F5: =E5+5 -> 80 | G5: =F5 -> 80 | H5: =G5 -> 80 | I5: =H5 -> 80 | J5: =I5+5 -> 85 | K5: =J5 -> 85 | L5: =K5 -> 85 | M5: =L5 -> 85 | N5: =M5+5 -> 90
A6: TUT | B6: 4111 | C6: 4111 | D6: 4101 | E6: 4101 | F6: 4111 | G6: 4111 | H6: 4101 | I6: 4101 | J6: 3111 | K6: 3111 | L6: 3101 | M6: 3101 | N6: 4101
A7: RPS | B7: 75 | C7: 75 | D7: 60 | E7: 60 | F7: 75 | G7: 75 | H7: 60 | I7: 60 | J7: 75 | K7: 75 | L7: 60 | M7: 60 | N7: 120
A8: Set(s) | B8: 6 | C8: 5 | D8: 4 | E8: 4 | F8: 6 | G8: 5 | H8: 4 | I8: 4 | J8: 6 | K8: 5 | L8: 4 | M8: 4 | N8: 7
A9: Rep(s) | B9: 6 | C9: 7 | D9: 8 | E9: 9 | F9: 6 | G9: 7 | H9: 8 | I9: 9 | J9: 6 | K9: 7 | L9: 8 | M9: 9 | N9: 3
A10: Approx. Percentage | B10: 0.7 | C10: =B10 -> 0.7 | D10: =B10 -> 0.7 | E10: =B10 -> 0.7 | F10: 0.75 | G10: =F10 -> 0.75 | H10: =F10 -> 0.75 | I10: =F10 -> 0.75 | J10: 0.8 | K10: =J10 -> 0.8 | L10: =J10 -> 0.8 | M10: =J10 -> 0.8 | N10: 0.85
A12: One-Arm DB Rows
A13: Target | B13: 75 | C13: =B13 -> 75 | D13: =C13 -> 75 | E13: =D13 -> 75 | F13: =E13+5 -> 80 | G13: =F13 -> 80 | H13: =G13 -> 80 | I13: =H13 -> 80 | J13: =I13+5 -> 85 | K13: =J13 -> 85 | L13: =K13 -> 85 | M13: =L13 -> 85 | N13: =M13+5 -> 90
A14: TUT | B14: 4111 | C14: 4111 | D14: 4101 | E14: 4101 | F14: 4111 | G14: 4111 | H14: 4101 | I14: 4101 | J14: 3111 | K14: 3111 | L14: 3101 | M14: 3101 | N14: 4101
A15: RPS | B15: 75 | C15: 75 | D15: 60 | E15: 60 | F15: 75 | G15: 75 | H15: 60 | I15: 60 | J15: 75 | K15: 75 | L15: 60 | M15: 60 | N15: 120
A16: Set(s) | B16: 6 | C16: 5 | D16: 4 | E16: 4 | F16: 6 | G16: 5 | H16: 4 | I16: 4 | J16: 6 | K16: 5 | L16: 4 | M16: 4 | N16: 7
A17: Rep(s) | B17: 6 | C17: 7 | D17: 8 | E17: 9 | F17: 6 | G17: 7 | H17: 8 | I17: 9 | J17: 6 | K17: 7 | L17: 8 | M17: 9 | N17: 3
A18: Approx. Percentage | B18: 0.7 | C18: =B18 -> 0.7 | D18: =B18 -> 0.7 | E18: =B18 -> 0.7 | F18: 0.75 | G18: =F18 -> 0.75 | H18: =F18 -> 0.75 | I18: =F18 -> 0.75 | J18: 0.8 | K18: =J18 -> 0.8 | L18: =J18 -> 0.8 | M18: =J18 -> 0.8 | N18: 0.85
A20: Decline DB Bench Press
A21: Target | B21: 70 | C21: =B21 -> 70 | D21: =C21 -> 70 | E21: =D21 -> 70 | F21: =E21+5 -> 75 | G21: =F21 -> 75 | H21: =G21 -> 75 | I21: =H21 -> 75 | J21: =I21+5 -> 80 | K21: =J21 -> 80 | L21: =K21 -> 80 | M21: =L21 -> 80 | N21: =M21+5 -> 85
A22: TUT | B22: 4111 | C22: 4111 | D22: 4101 | E22: 4101 | F22: 4111 | G22: 4111 | H22: 4101 | I22: 4101 | J22: 3111 | K22: 3111 | L22: 3101 | M22: 3101 | N22: 4101
A23: RPS | B23: 75 | C23: 75 | D23: 60 | E23: 60 | F23: 75 | G23: 75 | H23: 60 | I23: 60 | J23: 75 | K23: 75 | L23: 60 | M23: 60 | N23: 120
A24: Set(s) | B24: 6 | C24: 5 | D24: 4 | E24: 4 | F24: 6 | G24: 5 | H24: 4 | I24: 4 | J24: 6 | K24: 5 | L24: 4 | M24: 4 | N24: 7
A25: Rep(s) | B25: 6 | C25: 7 | D25: 8 | E25: 9 | F25: 6 | G25: 7 | H25: 8 | I25: 9 | J25: 6 | K25: 7 | L25: 8 | M25: 9 | N25: 3
A26: Approx. Percentage | B26: 0.7 | C26: =B26 -> 0.7 | D26: =B26 -> 0.7 | E26: =B26 -> 0.7 | F26: 0.75 | G26: =F26 -> 0.75 | H26: =F26 -> 0.75 | I26: =F26 -> 0.75 | J26: 0.8 | K26: =J26 -> 0.8 | L26: =J26 -> 0.8 | M26: =J26 -> 0.8 | N26: 0.85
A28: Incline Inner Biceps Curl
A29: Target | B29: 25 | C29: =B29 -> 25 | D29: =C29 -> 25 | E29: =D29 -> 25 | F29: =E29+2.5 -> 27.5 | G29: =F29 -> 27.5 | H29: =G29 -> 27.5 | I29: =H29 -> 27.5 | J29: =I29+5 -> 32.5 | K29: =J29 -> 32.5 | L29: =K29 -> 32.5 | M29: =L29 -> 32.5 | N29: =M29+2.5 -> 35
A30: TUT | B30: 4111 | C30: 4111 | D30: 4101 | E30: 4101 | F30: 4111 | G30: 4111 | H30: 4101 | I30: 4101 | J30: 3111 | K30: 3111 | L30: 3101 | M30: 3101 | N30: 4101
A31: RPS | B31: 75 | C31: 75 | D31: 60 | E31: 60 | F31: 75 | G31: 75 | H31: 60 | I31: 60 | J31: 75 | K31: 75 | L31: 60 | M31: 60 | N31: 60
A32: Set(s) | B32: 6 | C32: 5 | D32: 4 | E32: 4 | F32: 6 | G32: 5 | H32: 4 | I32: 4 | J32: 6 | K32: 5 | L32: 4 | M32: 4 | N32: 4
A33: Rep(s) | B33: 6 | C33: 7 | D33: 8 | E33: 9 | F33: 6 | G33: 7 | H33: 8 | I33: 9 | J33: 6 | K33: 7 | L33: 8 | M33: 9 | N33: 5
A34: Approx. Percentage | B34: 0.7 | C34: =B34 -> 0.7 | D34: =B34 -> 0.7 | E34: =B34 -> 0.7 | F34: 0.75 | G34: =F34 -> 0.75 | H34: =F34 -> 0.75 | I34: =F34 -> 0.75 | J34: 0.8 | K34: =J34 -> 0.8 | L34: =J34 -> 0.8 | M34: =J34 -> 0.8 | N34: 0.85
A36: Weighted Chest Dips
A37: Target | B37: 60 | C37: =B37 -> 60 | D37: =C37 -> 60 | E37: =D37 -> 60 | F37: =E37+5 -> 65 | G37: =F37 -> 65 | H37: =G37 -> 65 | I37: =H37 -> 65 | J37: =I37+5 -> 70 | K37: =J37 -> 70 | L37: =K37 -> 70 | M37: =L37 -> 70 | N37: =M37+5 -> 75
A38: TUT | B38: 4111 | C38: 4111 | D38: 4101 | E38: 4101 | F38: 4111 | G38: 4111 | H38: 4101 | I38: 4101 | J38: 3111 | K38: 3111 | L38: 3101 | M38: 3101 | N38: 4101
A39: RPS | B39: 75 | C39: 75 | D39: 60 | E39: 60 | F39: 75 | G39: 75 | H39: 60 | I39: 60 | J39: 75 | K39: 75 | L39: 60 | M39: 60 | N39: 120
A40: Set(s) | B40: 6 | C40: 5 | D40: 4 | E40: 4 | F40: 6 | G40: 5 | H40: 4 | I40: 4 | J40: 6 | K40: 5 | L40: 4 | M40: 4 | N40: 7
A41: Rep(s) | B41: 6 | C41: 7 | D41: 8 | E41: 9 | F41: 6 | G41: 7 | H41: 8 | I41: 9 | J41: 6 | K41: 7 | L41: 8 | M41: 9 | N41: 3
A42: Approx. Percentage | B42: 0.7 | C42: =B42 -> 0.7 | D42: =B42 -> 0.7 | E42: =B42 -> 0.7 | F42: 0.75 | G42: =F42 -> 0.75 | H42: =F42 -> 0.75 | I42: =F42 -> 0.75 | J42: 0.8 | K42: =J42 -> 0.8 | L42: =J42 -> 0.8 | M42: =J42 -> 0.8 | N42: 0.85
A44: DB Concentration Curl
A45: Target | B45: 27.5 | C45: =B45 -> 27.5 | D45: =C45 -> 27.5 | E45: =D45 -> 27.5 | F45: =E45+2.5 -> 30 | G45: =F45 -> 30 | H45: =G45 -> 30 | I45: =H45 -> 30 | J45: =I45+2.5 -> 32.5 | K45: =J45 -> 32.5 | L45: =K45 -> 32.5 | M45: =L45 -> 32.5 | N45: =M45+2.5 -> 35
A46: TUT | B46: 4111 | C46: 4111 | D46: 4101 | E46: 4101 | F46: 4111 | G46: 4111 | H46: 4101 | I46: 4101 | J46: 4111 | K46: 4111 | L46: 4101 | M46: 4101 | N46: 4101
...

Sheet Wednesday
A1: Week | B1: 1 | C1: 2 | D1: 3 | E1: 4 | F1: 5 | G1: 6 | H1: 7 | I1: 8 | J1: 9 | K1: 10 | L1: 11 | M1: 12 | N1: 13
A2: Date | B2: =Monday!B2+2 -> 43285 | C2: =B2+7 -> 43292 | D2: =C2+7 -> 43299 | E2: =D2+7 -> 43306 | F2: =E2+7 -> 43313 | G2: =F2+7 -> 43320 | H2: =G2+7 -> 43327 | I2: =H2+7 -> 43334 | J2: =I2+7 -> 43341 | ... N2: =M2+7 -> 43369
A4: Squat
A5: Target | B5: =mround(B8*OverviewData!$B$3,5) -> 275 | C5: =mround(C8*OverviewData!$B$3,5) -> 275 | D5: =mround(D8*OverviewData!$B$3,5) -> 275 | E5: =mround(E8*OverviewData!$B$3,5) -> 250 | F5: =mround(F8*OverviewData!$C$3,5) -> 285 | G5: =mround(G8*OverviewData!$C$3,5) -> 285 | H5: =mround(H8*OverviewData!$C$3,5) -> 285 | I5: =mround(I8*OverviewData!$C$3,5) -> 250 | J5: =mround(J8*OverviewData!$D$3,5) -> 295 | K5: =mround(K8*OverviewData!$D$3,5) -> 295 | L5: =mround(L8*OverviewData!$D$3,5) -> 295 | M5: =mround(M8*OverviewData!$D$3,5) -> 295 | N5: =mround(N8*OverviewData!$D$3,5) -> 255
A6: Set(s) | B6: 3 | C6: 3 | D6: 4 | E6: 3 | F6: 3 | G6: 4 | H6: 5 | I6: 4 | J6: 3 | K6: 4 | L6: 5 | M6: 6 | N6: 4
A7: Rep(s) | B7: 7 | C7: 7 | D7: 7 | E7: 5 | F7: 6 | G7: 6 | H7: 6 | I7: 4 | J7: 5 | K7: 5 | L7: 5 | M7: 5 | N7: 4
A8: Percentage | B8: 0.775 | C8: 0.775 | D8: 0.775 | E8: 0.7 | F8: 0.8 | G8: 0.8 | H8: 0.8 | I8: 0.7 | J8: 0.825 | K8: 0.825 | L8: 0.825 | M8: 0.825 | N8: 0.725
A10: Bench
A11: Target | B11: =mround(B14*OverviewData!$B$4,5) -> 185 | C11: =mround(C14*OverviewData!$B$4,5) -> 185 | D11: =mround(D14*OverviewData!$B$4,5) -> 185 | E11: =mround(E14*OverviewData!$B$4,5) -> 160 | F11: =mround(F14*OverviewData!$C$4,5) -> 190 | G11: =mround(G14*OverviewData!$C$4,5) -> 190 | H11: =mround(H14*OverviewData!$C$4,5) -> 190 | I11: =mround(I14*OverviewData!$C$4,5) -> 160 | J11: =mround(J14*OverviewData!$D$4,5) -> 195 | K11: =mround(K14*OverviewData!$D$4,5) -> 195 | L11: =mround(L14*OverviewData!$D$4,5) -> 195 | M11: =mround(M14*OverviewData!$D$4,5) -> 195 | N11: =mround(N14*OverviewData!$D$4,5) -> 165
A12: Set(s) | B12: 3 | C12: 3 | D12: 4 | E12: 3 | F12: 3 | G12: 4 | H12: 5 | I12: 4 | J12: 3 | K12: 4 | L12: 5 | M12: 6 | N12: 4
A13: Rep(s) | B13: 7 | C13: 7 | D13: 7 | E13: 5 | F13: 6 | G13: 6 | H13: 6 | I13: 4 | J13: 5 | K13: 5 | L13: 5 | M13: 5 | N13: 4
A14: Percentage | B14: 0.8 | C14: 0.8 | D14: 0.8 | E14: 0.7 | F14: 0.825 | G14: 0.825 | H14: 0.825 | I14: 0.7 | J14: 0.85 | K14: 0.85 | L14: 0.85 | M14: 0.85 | N14: 0.725
A16: Deadlift
A17: Target | B17: - | C17: - | D17: - | E17: =mround(E20*OverviewData!$B$5,5) -> 285 | F17: - | G17: - | H17: - | I17: =mround(I20*OverviewData!$C$5,5) -> 285 | J17: - | K17: - | L17: - | M17: - | N17: =mround(N20*OverviewData!$D$5,5) -> 295
A18: Set(s) | E18: 3 | I18: 4 | N18: 4
A19: Rep(s) | E19: 5 | I19: 4 | N19: 4
A20: Percentage | E20: 0.7 | I20: 0.7 | N20: 0.725
A22: Romanian Deadlift
A23: Target | B23: 235 | C23: =B23 -> 235 | D23: =C23 -> 235 | E23: - | F23: =D23+5 -> 240 | G23: =F23 -> 240 | H23: =G23 -> 240 | I23: - | J23: =H23+5 -> 245 | K23: =J23 -> 245 | L23: =K23 -> 245 | M23: =L23 -> 245 | N23: -
A24: TUT | B24: 4111 | C24: 4111 | D24: 4101 | F24: 4111 | G24: 4111 | H24: 4101 | J24: 3111 | K24: 3111 | L24: 3101 | M24: 3101
A25: RPS | B25: 75 | C25: 75 | D25: 60 | F25: 75 | G25: 75 | H25: 60 | J25: 75 | K25: 75 | L25: 60 | M25: 60
A26: Set(s) | B26: 6 | C26: 5 | D26: 4 | F26: 6 | G26: 5 | H26: 4 | J26: 6 | K26: 5 | L26: 4 | M26: 4
A27: Rep(s) | B27: 6 | C27: 7 | D27: 8 | F27: 6 | G27: 7 | H27: 8 | J27: 6 | K27: 7 | L27: 8 | M27: 9
A28: Approx. Percentage | B28: 0.7 | C28: =B28 -> 0.7 | D28: =B28 -> 0.7 | F28: 0.75 | G28: =F28 -> 0.75 | H28: =F28 -> 0.75 | J28: 0.8 | K28: =J28 -> 0.8 | L28: =J28 -> 0.8 | M28: =J28 -> 0.8
A30: Standing Barbell Calf Raise
A31: Target | B31: 315 | C31: =B31 -> 315 | D31: =C31 -> 315 | E31: - | F31: =D31+5 -> 320 | G31: =F31 -> 320 | H31: =G31 -> 320 | I31: - | J31: =H31+5 -> 325 | K31: =J31 -> 325 | L31: =K31 -> 325 | M31: =L31 -> 325 | N31: -
A32: TUT | B32: 4111 | C32: 4111 | D32: 4101 | F32: 4111 | G32: 4111 | H32: 4101 | J32: 3111 | K32: 3111 | L32: 3101 | M32: 3101
A33: RPS | B33: 75 | C33: 75 | D33: 60 | F33: 75 | G33: 75 | H33: 60 | J33: 75 | K33: 75 | L33: 60 | M33: 60
A34: Set(s) | B34: 6 | C34: 5 | D34: 4 | F34: 6 | G34: 5 | H34: 4 | J34: 6 | K34: 5 | L34: 4 | M34: 4
A35: Rep(s) | B35: 6 | C35: 7 | D35: 8 | F35: 6 | G35: 7 | H35: 8 | J35: 6 | K35: 7 | L35: 8 | M35: 9
A36: Approx. Percentage | B36: 0.7 | C36: =B36 -> 0.7 | D36: =B36 -> 0.7 | F36: 0.75 | G36: =F36 -> 0.75 | H36: =F36 -> 0.75 | J36: 0.8 | K36: =J36 -> 0.8 | L36: =J36 -> 0.8 | M36: =J36 -> 0.8
A38: Hip Adductor (Machine)
A39: Target | B39: 110 | C39: =B39 -> 110 | D39: =C39 -> 110 | E39: - | F39: =D39+10 -> 120 | G39: =F39 -> 120 | H39: =G39 -> 120 | I39: - | J39: =H39+10 -> 130 | K39: =J39 -> 130 | L39: =K39 -> 130 | M39: =L39 -> 130 | N39: -
A40: TUT | B40: 4111 | C40: 4111 | D40: 4101 | F40: 4111 | G40: 4111 | H40: 4101 | J40: 3111 | K40: 3111 | L40: 3101 | M40: 3101
A41: RPS | B41: 75 | C41: 75 | D41: 60 | F41: 75 | G41: 75 | H41: 60 | J41: 75 | K41: 75 | L41: 60 | M41: 60
A42: Set(s) | B42: 6 | C42: 5 | D42: 4 | F42: 6 | G42: 5 | H42: 4 | J42: 6 | K42: 5 | L42: 4 | M42: 4
A43: Rep(s) | B43: 6 | C43: 7 | D43: 8 | F43: 6 | G43: 7 | H43: 8 | J43: 6 | K43: 7 | L43: 8 | M43: 9
A44: Approx. Percentage | B44: 0.5 | C44: 0.5 | D44: =C44 -> 0.5 | F44: 0.75 | G44: =F44 -> 0.75 | H44: =F44 -> 0.75 | J44: 0.8 | K44: =J44 -> 0.8 | L44: =J44 -> 0.8 | M44: =J44 -> 0.8
A46: Hip Abductor (Machine)
A47: Target | B47: 90 | C47: =B47 -> 90 | D47: =C47 -> 90 | E47: - | F47: =D47+10 -> 100 | G47: =F47 -> 100 | H47: =G47 -> 100 | I47: - | J47: =H47+10 -> 110 | K47: =J47 -> 110 | L47: =K47 -> 110 | M47: =L47 -> 110 | N47: -
...

Sheet Thursday
A1: Week | B1: 1 | C1: 2 | D1: 3 | E1: 4 | F1: 5 | G1: 6 | H1: 7 | I1: 8 | J1: 9 | K1: 10 | L1: 11 | M1: 12 | N1: 13
A2: Date | B2: =Monday!B2+3 -> 43286 | C2: =B2+7 -> 43293 | D2: =C2+7 -> 43300 | E2: =D2+7 -> 43307 | F2: =E2+7 -> 43314 | G2: =F2+7 -> 43321 | H2: =G2+7 -> 43328 | I2: =H2+7 -> 43335 | J2: =I2+7 -> 43342 | ... N2: =M2+7 -> 43370
A4: Deadlift
A5: Target | B5: =mround(B8*OverviewData!$B$5,5) -> 335 | C5: =mround(C8*OverviewData!$B$5,5) -> 335 | D5: =mround(D8*OverviewData!$B$5,5) -> 350 | E5: - | F5: =mround(F8*OverviewData!$C$5,5) -> 345 | G5: =mround(G8*OverviewData!$C$5,5) -> 345 | H5: =mround(H8*OverviewData!$C$5,5) -> 360 | I5: - | J5: =mround(J8*OverviewData!$D$5,5) -> 355 | K5: =mround(K8*OverviewData!$D$5,5) -> 355 | L5: =mround(L8*OverviewData!$D$5,5) -> 370 | M5: =mround(M8*OverviewData!$D$5,5) -> 385 | N5: -
A6: Set(s) | B6: 3 | C6: 3 + AMRAP | D6: 3 + AMRAP | F6: 4 | G6: 4 + AMRAP | H6: 4 + AMRAP | J6: 4 | K6: 4 + AMRAP | L6: 4 + AMRAP | M6: 4 + AMRAP
A7: Rep(s) | B7: 5 | C7: 5 | D7: 5 | F7: 4 | G7: 4 | H7: 4 | J7: 3 | K7: 3 | L7: 3 | M7: 3
A8: Percentage | B8: 0.825 | C8: 0.825 | D8: 0.865 | F8: 0.85 | G8: 0.85 | H8: 0.89 | J8: 0.875 | K8: 0.875 | L8: 0.915 | M8: 0.955
A10: Lat Pulldown
A11: Target | B11: 130 | C11: =B11 -> 130 | D11: =C11 -> 130 | E11: =D11 -> 130 | F11: =E11+10 -> 140 | G11: =F11 -> 140 | H11: =G11 -> 140 | I11: =H11 -> 140 | J11: =I11+10 -> 150 | K11: =J11 -> 150 | L11: =K11 -> 150 | M11: =L11 -> 150 | N11: =M11+10 -> 160
A12: TUT | B12: 4111 | C12: 4111 | D12: 4101 | E12: 4101 | F12: 4111 | G12: 4111 | H12: 4101 | I12: 4101 | J12: 3111 | K12: 3111 | L12: 3101 | M12: 3101 | N12: 4101
A13: RPS | B13: 75 | C13: 75 | D13: 60 | E13: 60 | F13: 75 | G13: 75 | H13: 60 | I13: 60 | J13: 75 | K13: 75 | L13: 60 | M13: 60 | N13: 120
A14: Set(s) | B14: 6 | C14: 5 | D14: 4 | E14: 4 | F14: 6 | G14: 5 | H14: 4 | I14: 4 | J14: 6 | K14: 5 | L14: 4 | M14: 4 | N14: 7
A15: Rep(s) | B15: 6 | C15: 7 | D15: 8 | E15: 9 | F15: 6 | G15: 7 | H15: 8 | I15: 9 | J15: 6 | K15: 7 | L15: 8 | M15: 9 | N15: 3
A16: Approx. Percentage | B16: 0.7 | C16: =B16 -> 0.7 | D16: =B16 -> 0.7 | E16: =B16 -> 0.7 | F16: 0.75 | G16: =F16 -> 0.75 | H16: =F16 -> 0.75 | I16: =F16 -> 0.75 | J16: 0.8 | K16: =J16 -> 0.8 | L16: =J16 -> 0.8 | M16: =J16 -> 0.8 | N16: 0.85
A18: Straight Arm Pulldown
A19: Target | B19: 130 | C19: =B19 -> 130 | D19: =C19 -> 130 | E19: =D19 -> 130 | F19: =E19+10 -> 140 | G19: =F19 -> 140 | H19: =G19 -> 140 | I19: =H19 -> 140 | J19: =I19+10 -> 150 | K19: =J19 -> 150 | L19: =K19 -> 150 | M19: =L19 -> 150 | N19: =M19+10 -> 160
A20: TUT | B20: 4111 | C20: 4111 | D20: 4101 | E20: 4101 | F20: 4111 | G20: 4111 | H20: 4101 | I20: 4101 | J20: 3111 | K20: 3111 | L20: 3101 | M20: 3101 | N20: 4101
A21: RPS | B21: 75 | C21: 75 | D21: 60 | E21: 60 | F21: 75 | G21: 75 | H21: 60 | I21: 60 | J21: 75 | K21: 75 | L21: 60 | M21: 60 | N21: 120
A22: Set(s) | B22: 6 | C22: 5 | D22: 4 | E22: 4 | F22: 6 | G22: 5 | H22: 4 | I22: 4 | J22: 6 | K22: 5 | L22: 4 | M22: 4 | N22: 7
A23: Rep(s) | B23: 6 | C23: 7 | D23: 8 | E23: 9 | F23: 6 | G23: 7 | H23: 8 | I23: 9 | J23: 6 | K23: 7 | L23: 8 | M23: 9 | N23: 3
A24: Approx. Percentage | B24: 0.7 | C24: =B24 -> 0.7 | D24: =B24 -> 0.7 | E24: =B24 -> 0.7 | F24: 0.75 | G24: =F24 -> 0.75 | H24: =F24 -> 0.75 | I24: =F24 -> 0.75 | J24: 0.8 | K24: =J24 -> 0.8 | L24: =J24 -> 0.8 | M24: =J24 -> 0.8 | N24: 0.85
A26: Wide-Grip Cable Row
A27: Target | B27: 120 | C27: =B27 -> 120 | D27: =C27 -> 120 | E27: =D27 -> 120 | F27: =E27+10 -> 130 | G27: =F27 -> 130 | H27: =G27 -> 130 | I27: =H27 -> 130 | J27: =I27+10 -> 140 | K27: =J27 -> 140 | L27: =K27 -> 140 | M27: =L27 -> 140 | N27: =M27+10 -> 150
A28: TUT | B28: 4111 | C28: 4111 | D28: 4101 | E28: 4101 | F28: 4111 | G28: 4111 | H28: 4101 | I28: 4101 | J28: 3111 | K28: 3111 | L28: 3101 | M28: 3101 | N28: 4101
A29: RPS | B29: 75 | C29: 75 | D29: 60 | E29: 60 | F29: 75 | G29: 75 | H29: 60 | I29: 60 | J29: 75 | K29: 75 | L29: 60 | M29: 60 | N29: 120
A30: Set(s) | B30: 6 | C30: 5 | D30: 4 | E30: 4 | F30: 6 | G30: 5 | H30: 4 | I30: 4 | J30: 6 | K30: 5 | L30: 4 | M30: 4 | N30: 7
A31: Rep(s) | B31: 6 | C31: 7 | D31: 8 | E31: 9 | F31: 6 | G31: 7 | H31: 8 | I31: 9 | J31: 6 | K31: 7 | L31: 8 | M31: 9 | N31: 3
A32: Approx. Percentage | B32: 0.7 | C32: =B32 -> 0.7 | D32: =B32 -> 0.7 | E32: =B32 -> 0.7 | F32: 0.75 | G32: =F32 -> 0.75 | H32: =F32 -> 0.75 | I32: =F32 -> 0.75 | J32: 0.8 | K32: =J32 -> 0.8 | L32: =J32 -> 0.8 | M32: =J32 -> 0.8 | N32: 0.85
A34: Straight Bar Curl
A35: Target | B35: 65 | C35: =B35 -> 65 | D35: =C35 -> 65 | E35: =D35 -> 65 | F35: =E35+5 -> 70 | G35: =F35 -> 70 | H35: =G35 -> 70 | I35: =H35 -> 70 | J35: =I35+5 -> 75 | K35: =J35 -> 75 | L35: =K35 -> 75 | M35: =L35 -> 75 | N35: =M35+5 -> 80
A36: TUT | B36: 4111 | C36: 4111 | D36: 4101 | E36: 4101 | F36: 4111 | G36: 4111 | H36: 4101 | I36: 4101 | J36: 3111 | K36: 3111 | L36: 3101 | M36: 3101 | N36: 4101
A37: RPS | B37: 75 | C37: 75 | D37: 60 | E37: 60 | F37: 75 | G37: 75 | H37: 60 | I37: 60 | J37: 75 | K37: 75 | L37: 60 | M37: 60 | N37: 120
A38: Set(s) | B38: 6 | C38: 5 | D38: 4 | E38: 4 | F38: 6 | G38: 5 | H38: 4 | I38: 4 | J38: 6 | K38: 5 | L38: 4 | M38: 4 | N38: 7
A39: Rep(s) | B39: 6 | C39: 7 | D39: 8 | E39: 9 | F39: 6 | G39: 7 | H39: 8 | I39: 9 | J39: 6 | K39: 7 | L39: 8 | M39: 9 | N39: 3
A40: Approx. Percentage | B40: 0.7 | C40: =B40 -> 0.7 | D40: =B40 -> 0.7 | E40: =B40 -> 0.7 | F40: 0.75 | G40: =F40 -> 0.75 | H40: =F40 -> 0.75 | I40: =F40 -> 0.75 | J40: 0.8 | K40: =J40 -> 0.8 | L40: =J40 -> 0.8 | M40: =J40 -> 0.8 | N40: 0.85
A42: Romanian Deadlift
A43: Target | B43: - | C43: - | D43: - | E43: =Wednesday!D23 -> 235 | F43: - | G43: - | H43: - | I43: =Wednesday!H23 -> 240 | J43: - | K43: - | L43: - | M43: =Wednesday!L23 -> 245 | N43: -
A44: TUT | E44: 3101 | I44: 3101 | M44: 3101
A45: RPS | E45: 60 | I45: 60 | M45: 60
A46: Set(s) | E46: 4 | I46: 4 | M46: 4
...

Sheet Friday
A1: Week | B1: 1 | C1: 2 | D1: 3 | E1: 4 | F1: 5 | G1: 6 | H1: 7 | I1: 8 | J1: 9 | K1: 10 | L1: 11 | M1: 12 | N1: 13
A2: Date | B2: =Monday!B2+4 -> 43287 | C2: =B2+7 -> 43294 | D2: =C2+7 -> 43301 | E2: =D2+7 -> 43308 | F2: =E2+7 -> 43315 | G2: =F2+7 -> 43322 | H2: =G2+7 -> 43329 | I2: =H2+7 -> 43336 | J2: =I2+7 -> 43343 | ... N2: =M2+7 -> 43371
E3: .
A4: Squat
A5: Target | B5: =mround(B8*OverviewData!$B$3,5) -> 295 | C5: =mround(C8*OverviewData!$B$3,5) -> 295 | D5: =mround(D8*OverviewData!$B$3,5) -> 305 | E5: =mround(E8*OverviewData!$B$3,5) -> 300 | F5: =mround(F8*OverviewData!$C$3,5) -> 300 | G5: =mround(G8*OverviewData!$C$3,5) -> 300 | H5: =mround(H8*OverviewData!$C$3,5) -> 315 | I5: =mround(I8*OverviewData!$C$3,5) -> 310 | J5: =mround(J8*OverviewData!$D$3,5) -> 310 | K5: =mround(K8*OverviewData!$D$3,5) -> 310 | L5: =mround(L8*OverviewData!$D$3,5) -> 325 | M5: =mround(M8*OverviewData!$D$3,5) -> 340 | N5: =mround(N8*OverviewData!$D$3,5) -> 320 | O5: =mround(O8*OverviewData!$D$3,5) -> 345 | P5: =mround(P8*OverviewData!$D$3,5) -> 365
A6: Set(s) | B6: 3 | C6: 3 + AMRAP | D6: 3 + AMRAP | E6: AMRAP | F6: 4 | G6: 4 + AMRAP | H6: 4 + AMRAP | I6: AMRAP | J6: 4 | K6: 4 + AMRAP | L6: 4 + AMRAP | M6: 4 + AMRAP | N6: 1 | O6: 1 | P6: 1
A7: Rep(s) | B7: 5 | C7: 5 | D7: 5 | E7: - | F7: 4 | G7: 4 | H7: 4 | I7: - | J7: 3 | K7: 3 | L7: 3 | M7: 3 | N7: 1 | O7: 1 | P7: 1
A8: Percentage | B8: 0.825 | C8: 0.825 | D8: 0.865 | E8: 0.85 | F8: 0.85 | G8: 0.85 | H8: 0.89 | I8: 0.875 | J8: 0.875 | K8: 0.875 | L8: 0.915 | M8: 0.955 | N8: 0.9 | O8: 0.975 | P8: 1.025
A10: Bench
A11: Target | B11: =mround(B14*OverviewData!$B$4,5) -> 190 | C11: =mround(C14*OverviewData!$B$4,5) -> 190 | D11: =mround(D14*OverviewData!$B$4,5) -> 200 | E11: =mround(E14*OverviewData!$B$4,5) -> 195 | F11: =mround(F14*OverviewData!$C$4,5) -> 195 | G11: =mround(G14*OverviewData!$C$4,5) -> 195 | H11: =mround(H14*OverviewData!$C$4,5) -> 205 | I11: =mround(I14*OverviewData!$C$4,5) -> 200 | J11: =mround(J14*OverviewData!$D$4,5) -> 200 | K11: =mround(K14*OverviewData!$D$4,5) -> 200 | L11: =mround(L14*OverviewData!$D$4,5) -> 210 | M11: =mround(M14*OverviewData!$D$4,5) -> 220 | N11: =mround(N14*OverviewData!$D$4,5) -> 205 | O11: =mround(O14*OverviewData!$D$4,5) -> 225 | P11: =mround(P14*OverviewData!$D$4,5) -> 235
A12: Set(s) | B12: 3 | C12: 3 + AMRAP | D12: 3 + AMRAP | E12: AMRAP | F12: 4 | G12: 4 + AMRAP | H12: 4 + AMRAP | I12: AMRAP | J12: 4 | K12: 4 + AMRAP | L12: 4 + AMRAP | M12: 4 + AMRAP | N12: 1 | O12: 1 | P12: 1
A13: Rep(s) | B13: 5 | C13: 5 | D13: 5 | E13: - | F13: 4 | G13: 4 | H13: 4 | I13: - | J13: 3 | K13: 3 | L13: 3 | M13: 3 | N13: 1 | O13: 1 | P13: 1
A14: Percentage | B14: 0.825 | C14: 0.825 | D14: 0.865 | E14: 0.85 | F14: 0.85 | G14: 0.85 | H14: 0.89 | I14: 0.875 | J14: 0.875 | K14: 0.875 | L14: 0.915 | M14: 0.955 | N14: 0.9 | O14: 0.975 | P14: 1.025
A16: Deadlift
A17: Target | B17: - | C17: - | D17: - | E17: =mround(E20*OverviewData!$B$5,5) -> 345 | F17: - | G17: - | H17: - | I17: =mround(I20*OverviewData!$C$5,5) -> 355 | J17: - | K17: - | L17: - | M17: - | N17: =mround(N20*OverviewData!$D$5,5) -> 365 | O17: =mround(O20*OverviewData!$D$5,5) -> 395 | P17: =mround(P20*OverviewData!$D$5,5) -> 415
A18: Set(s) | E18: AMRAP | I18: AMRAP | N18: 1 | O18: 1 | P18: 1
A19: Rep(s) | E19: - | I19: - | N19: 1 | O19: 1 | P19: 1
A20: Percentage | E20: 0.85 | I20: 0.875 | N20: 0.9 | O20: 0.975 | P20: 1.025
A22: Front Squat
A23: Target | B23: 150 | C23: =B23 -> 150 | D23: =C23 -> 150 | E23: - | F23: =D23+5 -> 155 | G23: =F23 -> 155 | H23: =G23 -> 155 | I23: - | J23: =H23+5 -> 160 | K23: =J23 -> 160 | L23: =K23 -> 160 | M23: =L23 -> 160 | N23: -
A24: TUT | B24: 4111 | C24: 4111 | D24: 4101 | F24: 4111 | G24: 4111 | H24: 4101 | J24: 3111 | K24: 3111 | L24: 3101 | M24: 3101
A25: RPS | B25: 75 | C25: 75 | D25: 60 | F25: 75 | G25: 75 | H25: 60 | J25: 75 | K25: 75 | L25: 60 | M25: 60
A26: Set(s) | B26: 6 | C26: 5 | D26: 4 | F26: 6 | G26: 5 | H26: 4 | J26: 6 | K26: 5 | L26: 4 | M26: 4
A27: Rep(s) | B27: 6 | C27: 7 | D27: 8 | F27: 6 | G27: 7 | H27: 8 | J27: 6 | K27: 7 | L27: 8 | M27: 9
A28: Approx. Percentage | B28: 0.7 | C28: =B28 -> 0.7 | D28: =B28 -> 0.7 | F28: 0.75 | G28: =F28 -> 0.75 | H28: =F28 -> 0.75 | J28: 0.8 | K28: =J28 -> 0.8 | L28: =J28 -> 0.8 | M28: =J28 -> 0.8
A30: Hip Thrust
A31: Target | B31: 150 | C31: =B31 -> 150 | D31: =C31 -> 150 | E31: - | F31: =D31+5 -> 155 | G31: =F31 -> 155 | H31: =G31 -> 155 | I31: - | J31: =H31+5 -> 160 | K31: =J31 -> 160 | L31: =K31 -> 160 | M31: =L31 -> 160 | N31: -
A32: TUT | B32: 4111 | C32: 4111 | D32: 4101 | F32: 4111 | G32: 4111 | H32: 4101 | J32: 3111 | K32: 3111 | L32: 3101 | M32: 3101
A33: RPS | B33: 75 | C33: 75 | D33: 60 | F33: 75 | G33: 75 | H33: 60 | J33: 75 | K33: 75 | L33: 60 | M33: 60
A34: Set(s) | B34: 6 | C34: 5 | D34: 4 | F34: 6 | G34: 5 | H34: 4 | J34: 6 | K34: 5 | L34: 4 | M34: 4
A35: Rep(s) | B35: 6 | C35: 7 | D35: 8 | F35: 6 | G35: 7 | H35: 8 | J35: 6 | K35: 7 | L35: 8 | M35: 9
A36: Approx. Percentage | B36: 0.7 | C36: =B36 -> 0.7 | D36: =B36 -> 0.7 | F36: 0.75 | G36: =F36 -> 0.75 | H36: =F36 -> 0.75 | J36: 0.8 | K36: =J36 -> 0.8 | L36: =J36 -> 0.8 | M36: =J36 -> 0.8
A38: Leg Extension (Machine)
A39: Target | B39: 80 | C39: =B39 -> 80 | D39: =C39 -> 80 | E39: - | F39: =D39+10 -> 90 | G39: =F39 -> 90 | H39: =G39 -> 90 | I39: - | J39: =H39+10 -> 100 | K39: =J39 -> 100 | L39: =K39 -> 100 | M39: =L39 -> 100 | N39: -
A40: TUT | B40: 4111 | C40: 4111 | D40: 4101 | F40: 4111 | G40: 4111 | H40: 4101 | J40: 3111 | K40: 3111 | L40: 3101 | M40: 3101
A41: RPS | B41: 75 | C41: 75 | D41: 60 | F41: 75 | G41: 75 | H41: 60 | J41: 75 | K41: 75 | L41: 60 | M41: 60
A42: Set(s) | B42: 6 | C42: 5 | D42: 4 | F42: 6 | G42: 5 | H42: 4 | J42: 6 | K42: 5 | L42: 4 | M42: 4
A43: Rep(s) | B43: 6 | C43: 7 | D43: 8 | F43: 6 | G43: 7 | H43: 8 | J43: 6 | K43: 7 | L43: 8 | M43: 9
A44: Approx. Percentage | B44: 0.7 | C44: =B44 -> 0.7 | D44: =B44 -> 0.7 | F44: 0.75 | G44: =F44 -> 0.75 | H44: =F44 -> 0.75 | J44: 0.8 | K44: =J44 -> 0.8 | L44: =J44 -> 0.8 | M44: =J44 -> 0.8
A46: Leg Curl (Machine)
...

Sheet Saturday
A1: Week | B1: 1 | C1: 2 | D1: 3 | E1: 4 | F1: 5 | G1: 6 | H1: 7 | I1: 8 | J1: 9 | K1: 10 | L1: 11 | M1: 12 | N1: 13
A2: Date | B2: =Monday!B2+5 -> 43288 | C2: =B2+7 -> 43295 | D2: =C2+7 -> 43302 | E2: =D2+7 -> 43309 | F2: =E2+7 -> 43316 | G2: =F2+7 -> 43323 | H2: =G2+7 -> 43330 | I2: =H2+7 -> 43337 | J2: =I2+7 -> 43344 | ... N2: =M2+7 -> 43372
A4: Shoulder Press
A5: Target | B5: =mround(B8*OverviewData!$B$6,5) -> 125 | C5: =mround(C8*OverviewData!$B$6,5) -> 125 | D5: =mround(D8*OverviewData!$B$6,5) -> 130 | E5: =mround(E8*OverviewData!$B$6,5) -> 130 | F5: =mround(F8*OverviewData!$B$6,5) -> 130 | G5: =mround(G8*OverviewData!$B$6,5) -> 130 | H5: =mround(H8*OverviewData!$B$6,5) -> 135 | I5: =mround(I8*OverviewData!$B$6,5) -> 130 | ... P5: =mround(P8*OverviewData!$B$6,5) -> 155
A6: Set(s) | B6: 3 | C6: 3 + AMRAP | D6: 3 + AMRAP | E6: AMRAP | F6: 4 | G6: 4 + AMRAP | H6: 4 + AMRAP | I6: AMRAP | J6: 4 | K6: 4 + AMRAP | L6: 4 + AMRAP | M6: 4 + AMRAP | N6: 1 | O6: 1 | P6: 1
A7: Rep(s) | B7: 5 | C7: 5 | D7: 5 | E7: - | F7: 4 | G7: 4 | H7: 4 | I7: - | J7: 3 | K7: 3 | L7: 3 | M7: 3 | N7: 1 | O7: 1 | P7: 1
A8: Percentage | B8: 0.825 | C8: 0.825 | D8: 0.865 | E8: 0.85 | F8: 0.85 | G8: 0.85 | H8: 0.89 | I8: 0.875 | J8: 0.875 | K8: 0.875 | L8: 0.915 | M8: 0.955 | N8: 0.9 | O8: 0.975 | P8: 1.025
A10: Sumo Deadlift
A11: Target | B11: =mround(B14*OverviewData!$B$5,5) -> 295 | C11: =mround(C14*OverviewData!$B$5,5) -> 295 | D11: =mround(D14*OverviewData!$B$5,5) -> 295 | E11: =mround(E14*OverviewData!$B$5,5) -> 335 | F11: =mround(F14*OverviewData!$C$5,5) -> 305 | G11: =mround(G14*OverviewData!$C$5,5) -> 305 | H11: =mround(H14*OverviewData!$C$5,5) -> 305 | I11: =mround(I14*OverviewData!$C$5,5) -> 335 | J11: =mround(J14*OverviewData!$D$5,5) -> 315 | K11: =mround(K14*OverviewData!$D$5,5) -> 315 | L11: =mround(L14*OverviewData!$D$5,5) -> 315 | M11: =mround(M14*OverviewData!$D$5,5) -> 295 | N11: -
A12: Set(s) | B12: 2 | C12: 3 | D12: 3 | E12: 4 | F12: 2 | G12: 3 | H12: 4 | I12: 5 | J12: 3 | K12: 4 | L12: 5 | M12: 5
A13: Rep(s) | B13: 9 | C13: 9 | D13: 9 | E13: 4 | F13: 8 | G13: 8 | H13: 8 | I13: 3 | J13: 7 | K13: 7 | L13: 7 | M13: 7
A14: Percentage | B14: 0.725 | C14: 0.725 | D14: 0.725 | E14: 0.825 | F14: 0.75 | G14: 0.75 | H14: 0.75 | I14: 0.825 | J14: 0.775 | K14: 0.775 | L14: 0.775 | M14: 0.725
A16: Seated Dumbbell Shoulder Press
A17: Target | B17: 50 | C17: =B17 -> 50 | D17: =C17 -> 50 | E17: =D17 -> 50 | F17: =E17+5 -> 55 | G17: =F17 -> 55 | H17: =G17 -> 55 | I17: =H17 -> 55 | J17: =I17+5 -> 60 | K17: =J17 -> 60 | L17: =K17 -> 60 | M17: =L17 -> 60 | N17: =M17+5 -> 65
A18: TUT | B18: 4111 | C18: 4111 | D18: 4101 | E18: 4101 | F18: 4111 | G18: 4111 | H18: 4101 | I18: 4101 | J18: 3111 | K18: 3111 | L18: 3101 | M18: 3101 | N18: 4101
A19: RPS | B19: 75 | C19: 75 | D19: 60 | E19: 60 | F19: 75 | G19: 75 | H19: 60 | I19: 60 | J19: 75 | K19: 75 | L19: 60 | M19: 60 | N19: 120
A20: Set(s) | B20: 6 | C20: 5 | D20: 4 | E20: 4 | F20: 6 | G20: 5 | H20: 4 | I20: 4 | J20: 6 | K20: 5 | L20: 4 | M20: 4 | N20: 7
A21: Rep(s) | B21: 6 | C21: 7 | D21: 8 | E21: 9 | F21: 6 | G21: 7 | H21: 8 | I21: 9 | J21: 6 | K21: 7 | L21: 8 | M21: 9 | N21: 3
A22: Approx. Percentage | B22: 0.7 | C22: =B22 -> 0.7 | D22: =B22 -> 0.7 | E22: =B22 -> 0.7 | F22: 0.75 | G22: =F22 -> 0.75 | H22: =F22 -> 0.75 | I22: =F22 -> 0.75 | J22: 0.8 | K22: =J22 -> 0.8 | L22: =J22 -> 0.8 | M22: =J22 -> 0.8 | N22: 0.85
A24: Incline DB Bench Press
A25: Target | B25: 55 | C25: =B25 -> 55 | D25: =C25 -> 55 | E25: =D25 -> 55 | F25: =E25+5 -> 60 | G25: =F25 -> 60 | H25: =G25 -> 60 | I25: =H25 -> 60 | J25: =I25+5 -> 65 | K25: =J25 -> 65 | L25: =K25 -> 65 | M25: =L25 -> 65 | N25: =M25+5 -> 70
A26: TUT | B26: 4111 | C26: 4111 | D26: 4101 | E26: 4101 | F26: 4111 | G26: 4111 | H26: 4101 | I26: 4101 | J26: 3111 | K26: 3111 | L26: 3101 | M26: 3101 | N26: 4101
A27: RPS | B27: 75 | C27: 75 | D27: 60 | E27: 60 | F27: 75 | G27: 75 | H27: 60 | I27: 60 | J27: 75 | K27: 75 | L27: 60 | M27: 60 | N27: 120
A28: Set(s) | B28: 6 | C28: 5 | D28: 4 | E28: 4 | F28: 6 | G28: 5 | H28: 4 | I28: 4 | J28: 6 | K28: 5 | L28: 4 | M28: 4 | N28: 7
A29: Rep(s) | B29: 6 | C29: 7 | D29: 8 | E29: 9 | F29: 6 | G29: 7 | H29: 8 | I29: 9 | J29: 6 | K29: 7 | L29: 8 | M29: 9 | N29: 3
A30: Approx. Percentage | B30: 0.7 | C30: =B30 -> 0.7 | D30: =B30 -> 0.7 | E30: =B30 -> 0.7 | F30: 0.75 | G30: =F30 -> 0.75 | H30: =F30 -> 0.75 | I30: =F30 -> 0.75 | J30: 0.8 | K30: =J30 -> 0.8 | L30: =J30 -> 0.8 | M30: =J30 -> 0.8 | N30: 0.85
A32: Dumbbell Preacher Curl
A33: Target | B33: 27.5 | C33: =B33 -> 27.5 | D33: =C33 -> 27.5 | E33: =D33 -> 27.5 | F33: =E33+2.5 -> 30 | G33: =F33 -> 30 | H33: =G33 -> 30 | I33: =H33 -> 30 | J33: =I33+2.5 -> 32.5 | K33: =J33 -> 32.5 | L33: =K33 -> 32.5 | M33: =L33 -> 32.5 | N33: =M33+2.5 -> 35
A34: TUT | B34: 4111 | C34: 4111 | D34: 4101 | E34: 4101 | F34: 4111 | G34: 4111 | H34: 4101 | I34: 4101 | J34: 3111 | K34: 3111 | L34: 3101 | M34: 3101 | N34: 4101
A35: RPS | B35: 75 | C35: 75 | D35: 60 | E35: 60 | F35: 75 | G35: 75 | H35: 60 | I35: 60 | J35: 75 | K35: 75 | L35: 60 | M35: 60 | N35: 60
A36: Set(s) | B36: 6 | C36: 5 | D36: 4 | E36: 4 | F36: 6 | G36: 5 | H36: 4 | I36: 4 | J36: 6 | K36: 5 | L36: 4 | M36: 4 | N36: 4
A37: Rep(s) | B37: 6 | C37: 7 | D37: 8 | E37: 9 | F37: 6 | G37: 7 | H37: 8 | I37: 9 | J37: 6 | K37: 7 | L37: 8 | M37: 9 | N37: 5
A38: Approx. Percentage | B38: 0.7 | C38: =B38 -> 0.7 | D38: =B38 -> 0.7 | E38: =B38 -> 0.7 | F38: 0.75 | G38: =F38 -> 0.75 | H38: =F38 -> 0.75 | I38: =F38 -> 0.75 | J38: 0.8 | K38: =J38 -> 0.8 | L38: =J38 -> 0.8 | M38: =J38 -> 0.8 | N38: 0.85
A40: Trap 3 Raise
A41: Target | B41: 15 | C41: =B41 -> 15 | D41: =C41 -> 15 | E41: =D41 -> 15 | F41: =E41+2.5 -> 17.5 | G41: =F41 -> 17.5 | H41: =G41 -> 17.5 | I41: =H41 -> 17.5 | J41: =I41+2.5 -> 20 | K41: =J41 -> 20 | L41: =K41 -> 20 | M41: =L41 -> 20 | N41: =M41+2.5 -> 22.5
A42: TUT | B42: 4111 | C42: 4111 | D42: 4101 | E42: 4101 | F42: 4111 | G42: 4111 | H42: 4101 | I42: 4101 | J42: 4111 | K42: 4111 | L42: 4101 | M42: 4101 | N42: 4101
A43: RPS | B43: 75 | C43: 75 | D43: 60 | E43: 60 | F43: 75 | G43: 75 | H43: 60 | I43: 60 | J43: 75 | K43: 75 | L43: 60 | M43: 60 | N43: 60
A44: Set(s) | B44: 6 | C44: 5 | D44: 4 | E44: 4 | F44: 6 | G44: 5 | H44: 4 | I44: 4 | J44: 6 | K44: 5 | L44: 4 | M44: 4 | N44: 4
A45: Rep(s) | B45: 6 | C45: 7 | D45: 8 | E45: 9 | F45: 6 | G45: 7 | H45: 8 | I45: 9 | J45: 6 | K45: 7 | L45: 8 | M45: 9 | N45: 5
A46: Approx. Percentage | B46: 0.5 | C46: =B46 -> 0.5 | D46: 0.6 | E46: 0.6 | F46: 0.7 | G46: =F46 -> 0.7 | H46: =F46 -> 0.7 | I46: =F46 -> 0.7 | J46: 0.75 | K46: =J46 -> 0.75 | L46: =J46 -> 0.75 | M46: =J46 -> 0.75 | N46: 0.85
...

Sheet Supplement Schedule
A1: Week | B1: 1 | C1: 2 | D1: 3 | E1: 4 | F1: 5 | G1: 6 | H1: 7 | I1: 8 | J1: 9 | K1: 10 | L1: 11 | M1: 12 | N1: 13
