Workbook
Name Phase2: 'Phase Creator'!$D$21:$Q$34
Name Peaking: 'Phase Creator'!$D$66:$Q$79
Name PrePeaking: 'Phase Creator'!$D$51:$Q$64
Name Phase6: 'Phase Creator'!$D$81:$Q$94
Name Phase1: 'Phase Creator'!$D$6:$Q$19
Name Phase3: 'Phase Creator'!$D$36:$Q$49

Sheet Phase Creator
B6: Phase 1 | D6: Day | E6: 1 | G6: Day | H6: 2 | J6: Day | K6: 3 | M6: Day | N6: 4 | P6: Day | Q6: 5
D7: Code | E7: Exercise Choice | G7: Code | H7: Exercise Choice | J7: Code | K7: Exercise Choice | M7: Code | N7: Exercise Choice | P7: Code | Q7: Exercise Choice
B8: A1 | C8: 3 | D8: A | E8: Beltless SSB | G8: A | H8: Dumbbell Squat | J8: A | K8: Beltless Stiff Bar Opposite Stance DL | M8: A | N8: Beltless Stiff Bar DL (opp stance) | P8: A | Q8: Wide Grip Feet Up Bench
B9: A2 | C9: 4 | D9: A | E9: Beltless SSB | G9: A | H9: Dumbbell Squat | J9: A | K9: Beltless Stiff Bar Opposite Stance DL | M9: A | N9: Beltless Stiff Bar DL (opp stance) | P9: A | Q9: Wide Grip Bench
B10: A3 | C10: 5 | D10: A | E10: Beltless High Bar Squat | G10: A | H10: Front Squat | J10: A | K10: Beltless DL | M10: A | N10: Beltless DL | P10: A | Q10: Close Grip Feet Up Bench
B11: A4 | C11: 6 | D11: A | E11: Beltless High Bar Squat | G11: A | H11: Front Squat | J11: A | K11: Beltless DL | M11: A | N11: Beltless DL | P11: A | Q11: Close Grip Bench
B12: B1 | C12: 7 | D12: B | E12: 3ct Pause Duffalo | G12: B | H12: 3ct Pause Neutral DB Press | J12: B | K12: Overhand Romanian DL | M12: B | N12: DB Belly Swing | P12: B | Q12: DB Incline Press
B13: B2 | C13: 8 | D13: B | E13: 3ct Pause Duffalo | G13: B | H13: 3ct Pause Neutral DB Press | J13: B | K13: Overhand Romanian DL | M13: B | N13: DB Belly Swing | P13: B | Q13: DB Incline Press
B14: B3 | C14: 9 | D14: B | E14: 3ct Pause Bench Press | G14: B | H14: Overhead Press | J14: B | K14: Overhand Romanian DL | M14: B | N14: Overhand Romanian DL | P14: B | Q14: Incline Bench Press
B15: B4 | C15: 10 | D15: B | E15: 3ct Pause Bench Press | G15: B | H15: Overhead Press | J15: B | K15: Overhand Romanian DL | M15: B | N15: Overhand Romanian DL | P15: B | Q15: Incline Bench Press
B16: C | C16: 11 | D16: C | E16: Short Side Plank Clamshell | G16: C | H16: DB 1 Arm Row w Pause | J16: C | K16: Plank | M16: C | N16: Plank | P16: C | Q16: Chest Supported Row
B17: D | C17: 12 | D17: D | E17: GHR or Back Extension | G17: D | H17: Rear Delt Raise | J17: D | K17: Band/Cable Row | M17: D | N17: Band/Cable Row | P17: D | Q17: Side Delt Raise
B18: E | C18: 13 | D18: E | E18: Slingshot Abduction/Hip Abduction | G18: E | H18: Band/Cable Curls Slow eccentric | J18: E | K18: Sit ups/Reverse Crunch slow eccentric | M18: E | N18: Sit ups/Reverse Crunch slow eccentric | P18: E | Q18: Tricep Extensions
B19: F | C19: 14 | D19: F | E19: Band Pullapart/Rear Delt | G19: F | H19: DB Neutral Deadstop Pushups | J19: F | K19: Reverse Lunge | M19: F | N19: Reverse Lunge | P19: F | Q19: Bicep Curls
B21: Phase 2 | D21: Day | E21: 1 | G21: Day | H21: 2 | J21: Day | K21: 3 | M21: Day | N21: 4 | P21: Day | Q21: 5
D22: Code | E22: Exercise Choice | G22: Code | H22: Exercise Choice | J22: Code | K22: Exercise Choice | M22: Code | N22: Exercise Choice | P22: Code | Q22: Exercise Choice
B23: A1 | D23: A1 | E23: SSB Squat | G23: A2 | H23: Tempo High Bar Squat | J23: A3 | K23: Stiff Bar DL Opp Stance | M23: A4 | N23: Incline Bench Press | P23: A4
B24: A2 | D24: A1 | E24: SSB Squat | G24: A2 | H24: Tempo High Bar Squat | J24: A3 | K24: Stiff Bar DL Opp Stance | M24: A4 | N24: Incline Bench Press | P24: A4
B25: A3 | D25: A1 | E25: High Bar Squat | G25: A2 | H25: Tempo High Bar Squat | J25: A3 | K25: Stiff Bar DL w/ Chains | M25: A4 | N25: Incline Bench Press | P25: A4
B26: A4 | D26: A1 | E26: Competition Squat | G26: A2 | H26: Tempo High Bar Squat | J26: A3 | K26: Reverse Band Comp Deads | M26: A4 | N26: Incline Bench Press w/ Chains | P26: A4
B27: B1 | D27: B1 | E27: 3ct Pause Duffalo | G27: B2 | H27: Tempo Close Grip bench 3ct Pause | J27: B3 | K27: Tempo Stiff leg DL | M27: B4 | N27: Overhead Press | P27: B4
B28: B2 | D28: B1 | E28: 3ct Pause Duffalo | G28: B2 | H28: Tempo Close Grip bench 3ct Pause | J28: B3 | K28: Tempo Stiff leg DL | M28: B4 | N28: Overhead Press | P28: B4
B29: B3 | D29: B1 | E29: 3ct Pause Bench Press | G29: B2 | H29: Tempo Close Grip bench 3ct Pause | J29: B3 | K29: Tempo Stiff leg DL | M29: B4 | N29: Overhead Press | P29: B4
B30: B4 | D30: B1 | E30: 3ct Pause Bench Press | G30: B2 | H30: Tempo Close Grip bench 3ct Pause | J30: B3 | K30: Tempo Stiff leg DL | M30: B4 | N30: Overhead Press | P30: B4
B31: C | D31: C1 | E31: Short Side Plank Clamshell | G31: C2 | H31: Chest Supported Row | J31: C3 | K31: Side Plank | M31: C4 | N31: Pendlay Rows | P31: C4
B32: D | D32: D1 | E32: GHR or Back Extension | G32: D2 | H32: 2-way delt raise w pause | J32: D3 | K32: DB Glute Bridge w 3ct Pause | M32: D4 | N32: Tricep Pushdown w slow eccentric | P32: D4
B33: E | D33: E1 | E33: Slingshot Abduction/Hip Abduction | G33: E2 | H33: Band/Cable Curls Slow eccentric | J33: E3 | K33: Sit ups/Reverse Crunch slow eccentric | M33: E4 | N33: One arm DB row w pause | P33: E4
B34: F | D34: F1 | E34: Band Pullapart/Rear Delt | G34: F2 | H34: DB Flys slow eccentric | J34: F3 | K34: Goblet Reverse Lunge | M34: F4 | N34: DB Curls | P34: F4
B36: Phase 3 | D36: Day | E36: 1 | G36: Day | H36: 2 | J36: Day | K36: 3 | M36: Day | N36: 4 | P36: Day | Q36: 5
D37: Code | E37: Exercise Choice | G37: Code | H37: Exercise Choice | J37: Code | K37: Exercise Choice | M37: Code | N37: Exercise Choice | P37: Code | Q37: Exercise Choice
B38: A1 | D38: A1 | E38: Competition Squat | G38: A2 | H38: High Bar 3ct Paused Squat | J38: A3 | K38: Competition Deadlift | M38: A4 | P38: A4
B39: A2 | D39: A1 | E39: SSB Squats w/ Chains | G39: A2 | H39: High Bar 3ct Paused Squat | J39: A3 | K39: DL w/ Chains | M39: A4 | P39: A4
B40: A3 | D40: A1 | E40: Reverse Bands Squat | G40: A2 | H40: High Bar 3ct Paused Squat | J40: A3 | K40: Competition Deadlift | M40: A4 | P40: A4
B41: A4 | D41: A1 | E41: Competition Squat | G41: A2 | H41: High Bar 3ct Paused Squat | J41: A3 | K41: DL w/ Chains | M41: A4 | P41: A4
B42: B1 | D42: B1 | E42: 3ct Pause Duffalo | G42: B2 | H42: 3ct Spotto Press | J42: B3 | K42: Deficit Deadlift | M42: B4 | P42: B4
B43: B2 | D43: B1 | E43: Duffalo w/ Chains | G43: B2 | H43: 3ct Spotto Press | J43: B3 | K43: Deficit Deadlift | M43: B4 | P43: B4
B44: B3 | D44: B1 | E44: 3ct SlingShot Bench or Reverse Bands | G44: B2 | H44: 3ct Spotto Press | J44: B3 | K44: Deficit Deadlift | M44: B4 | P44: B4
B45: B4 | D45: B1 | E45: 3ct Pause Bench Press | G45: B2 | H45: 3ct Spotto Press | J45: B3 | K45: Deficit Deadlift | M45: B4 | P45: B4
B46: C | D46: C1 | E46: SB Body Saw | G46: C2 | H46: 1 Arm Deadstop KB Row 3ct Pause | J46: C3 | K46: 3ct Wide Grip Feet Up Bench | M46: C4 | P46: C4
B47: D | D47: D1 | E47: DB Glute Bridge w 3ct Pause | G47: D2 | H47: DB Floor Press w Pause | J47: D3 | K47: KB Goblet Squat | M47: D4 | P47: D4
...

Sheet Instructions
A7: - In the tab to the right, input your maximum weights for each of the lifts listed, as well as your projected end date for the program
A8: - The formulas provided will project approximately 90% of those lifts in order to increase submaximal strength
A9: - Any projected weights in each of the phase tabs are only estimates, feel free to adjust on feel, particularly on supplemental lifts
A10: - You should not be failing lifts or giving maximum total effort unless specified
A11: - Anytime a set and rep range is labeled with 2 different numbers (e.g. 5/3 and 3/2), the first group of sets and reps is to be used with the lowest range weight, with the second group of sets and reps are being used to build up to the highest range weight
A12: - Anytime you see an asterisk ( * ) on a rep range, do as many reps as possible
A13: - After you perform this lift, adjust training max in the calculator tab
A14: - Please use the PDF you received as your training log to record the weights you actually use

Sheet Max Calculator
C7: Weight | D7: Reps
B8: Squat | C8: 350 | D8: 1 | E8: =MROUND(((C8*36)/(37-D8))*0.9,5) -> 315
B9: Bench | C9: 250 | D9: 1 | E9: =MROUND(((C9*36)/(37-D9))*0.9,5) -> 225
B10: Deadlift | C10: 450 | D10: 1 | E10: =MROUND(((C10*36)/(37-D10))*0.9,5) -> 405
B12: End Date | E12: 43078

Sheet Exercise Selection
B2: A | C2: B | D2: C | E2: D | F2: E | G2: F
B4: Beltless High Bar Squat | C4: 3ct Pause Close Grip Bench | D4: Slow Eccentric DB or Cable Side Bench | E4: GHR or Back Extension | F4: Slingshot Abduction/Hip Abduction | G4: Band Pullapart/Rear Delt
B5: Beltless Low Bar Squat | C5: 3ct Pause DB Bench | D5: DB 1 Arm Row w Pause | E5: Rear Delt Raise | F5: Band/Cable Curls Slow eccentric | G5: DB Neutral Deadstop Pushups
B6: Dumbbell Squat | C6: Overhead Press | D6: Plank | E6: Band/Cable Row | F6: Sit ups/Reverse Crunch slow eccentric | G6: Reverse Lunge
B7: Front Squat | C7: DB Romanian DL | D7: Chest Supported Row | E7: Side Delt Raise | F7: Tricep Extensions | G7: Bicep Curls
B8: Beltless Stiff Bar DL (opp stance) | C8: Overhand Romanian DL | D8: Side Plank | E8: 2-way delt raise w pause | F8: One arm DB row w pause | G8: DB Flys slow eccentric
B9: Beltless Stiff Bar Deficit DL | C9: DB Incline Press | D9: Pendlay Rows | E9: DB Glute Bridge w 3ct Pause | F9: Hip Circle Side steps | G9: Goblet Reverse Lunge
B10: Beltless DL | C10: Incline Bench Press | D10: SB Body Saw | E10: Tricep Pushdown w slow eccentric | F10: DB Hammer Curls Slow eccentric | G10: DB Curls
B11: Wide Grip Feet Up Bench | C11: 3ct Pause Bench Press | D11: 1 Arm Deadstop KB Row 3ct Pause | E11: DB Floor Press w Pause | F11: Hanging Leg raise | G11: Band/Cable Triceps
B12: Wide Grip Bench | C12: Competition Bench Press | D12: 3ct Wide Grip Feet Up Bench | E12: KB Goblet Squat | F12: Seated Leg curls slow eccentric | G12: Paused Pulldowns
B13: Close Grip Feet Up Bench | C13: Tempo Close Grip bench 3ct Pause | D13: SB Pike | E13: DB Overhead Press | F13: suit case holds | G13: DB Batwing Holds
B14: Close Grip Bench | C14: Tempo Stiff leg DL | D14: Chin up | E14: Meadow Row Slow eccentric | F14: underhand pulldowns | G14: DB Deadstop triceps
... B16: Tempo High Bar Squat | C16: 3ct Spotto Press | D16: Close Grip 3ct Pause Feet Up Bench | E16: DB incline press | F16: Band/Cable Triceps 3ct Pause | G16: Cable/TRX Holds
B17: Stiff Bar Deficit DL | C17: Deficit Deadlift | D17: Band/Cable Face Pulls | E17: One arm DB Row w Pause | F17: Hanging Knee raise
B18: Stiff Bar DL w/ Chains | C18: Low Bar 3ct Pause Squat | D18: Chest Supported Row | E18: DB bench 5ct eccentric | F18: Seated Bicep Curls Slow Eccentric
B19: Incline Bench Press | C19: Double Pause Squat | D19: Spotto Press | E19: Band/TRX holds
B20: Incline Bench Press w/ Chains | C20: Block Pulls | D20: KB Belly Breath Press Out
B21: High Bar 3ct Paused Squat | C21: 3ct Pause Wide Grip Bench Feet Up | D21: Wide Grip Bench
B22: Deadlift | C22: 1ct Pause Squat | D22: Close Grip Bench
B23: High Bar Speed Squat | C23: 3ct Pause Deadlift | D23: Short Side Plank Clamshell
B24: Bench Press 3ct Pause | C24: 3ct Pause Duffalo
B25: Low Bar w/ Chains | C25: 1ct Pause Bench
B26: Low Bar 3ct Pause Squat | C26: Duffalo w/ Chains
B27: Competition Bench Press | C27: 3ct SlingShot Bench or Reverse Bands
B28: Beltless SSB | C28: Bench w/ Chains
B29: Beltless Stiff Bar Opposite Stance DL | C29: 3ct Pause Neutral DB Press
B30: Reverse Band Comp Deads | C30: DB Belly Swing
B31: SSB Squats w/ Chains
B32: Squat Reverse Mini
B33: DL w/ Chains
B34: Bench w/ Chains
B35: Reverse Bands Squat
B36: SlingShot Bench
B37: Speed DL
B38: SSB Squat
B39: Competition Squat
B40: Competition Deadlift
B41: Squat w/ Bands
B42: Bench w/ Bands
... B45: Stiff Bar DL w/ Chains

Sheet PrePeaking Phase
D9: PrePeaking | H9: Day | I9: 1
B13: Week | C13: A | D13: Squat | E13: Sets | F13: Reps | G13: Working Range | I13: Working Weights
B14: ='Max Calculator'!$E$12-140 -> 42938 | C14: A1 | D14: =HLOOKUP($I$9,INDIRECT($D$9),VLOOKUP(C14,'Phase Creator'!$B$8:$C$19,2,FALSE),FALSE) -> Competition Squat | E14: 5 | F14: 3 | G14: 0.82 | H14: 0.87 | I14: =IF(MROUND(IF($D$13="squat",'Max Calculator'!$E$8*G14,IF($D$13="bench",'Max Calculator'!$E$9*G14,IF($D$13="deadlift",'Max Calculator'!$E$10*G14,0))),5)=0," ",MROUND(IF($D$13="squat",'Max Calculator'!$E$8*G14,IF($D$13="bench",'Max Calculator'!$E$9*G14,IF($D$13="deadlift",'Max Calculator'!$E$10*G14,0))),5)) -> 260 | J14: =IF(MROUND(IF($D$13="squat",'Max Calculator'!$E$8*H14,IF($D$13="bench",'Max Calculator'!$E$9*H14,IF($D$13="deadlift",'Max Calculator'!$E$10*H14,0))),5)=0," ",MROUND(IF($D$13="squat",'Max Calculator'!$E$8*H14,IF($D$13="bench",'Max Calculator'!$E$9*H14,IF($D$13="deadlift",'Max Calculator'!$E$10*H14,0))),5)) -> 275
B15: ='Max Calculator'!$E$12-133 -> 42945 | C15: A2 | D15: =HLOOKUP($I$9,INDIRECT($D$9),VLOOKUP(C15,'Phase Creator'!$B$8:$C$19,2,FALSE),FALSE) -> Low Bar w/ Chains | E15: 8 | F15: 2 | G15: 0.55 | H15: 0.65 | I15: =IF(MROUND(IF($D$13="squat",'Max Calculator'!$E$8*G15,IF($D$13="bench",'Max Calculator'!$E$9*G15,IF($D$13="deadlift",'Max Calculator'!$E$10*G15,0))),5)=0," ",MROUND(IF($D$13="squat",'Max Calculator'!$E$8*G15,IF($D$13="bench",'Max Calculator'!$E$9*G15,IF($D$13="deadlift",'Max Calculator'!$E$10*G15,0))),5)) -> 175 | J15: =IF(MROUND(IF($D$13="squat",'Max Calculator'!$E$8*H15,IF($D$13="bench",'Max Calculator'!$E$9*H15,IF($D$13="deadlift",'Max Calculator'!$E$10*H15,0))),5)=0," ",MROUND(IF($D$13="squat",'Max Calculator'!$E$8*H15,IF($D$13="bench",'Max Calculator'!$E$9*H15,IF($D$13="deadlift",'Max Calculator'!$E$10*H15,0))),5)) -> 205
B16: ='Max Calculator'!$E$12-42 -> 43036 | C16: A3 | D16: =HLOOKUP($I$9,INDIRECT($D$9),VLOOKUP(C16,'Phase Creator'!$B$8:$C$19,2,FALSE),FALSE) -> Low Bar w/ Chains | E16: 5/3 | F16: 3/2 | G16: 0.65 | H16: 0.8 | I16: =IF(MROUND(IF($D$13="squat",'Max Calculator'!$E$8*G16,IF($D$13="bench",'Max Calculator'!$E$9*G16,IF($D$13="deadlift",'Max Calculator'!$E$10*G16,0))),5)=0," ",MROUND(IF($D$13="squat",'Max Calculator'!$E$8*G16,IF($D$13="bench",'Max Calculator'!$E$9*G16,IF($D$13="deadlift",'Max Calculator'!$E$10*G16,0))),5)) -> 205 | J16: =IF(MROUND(IF($D$13="squat",'Max Calculator'!$E$8*H16,IF($D$13="bench",'Max Calculator'!$E$9*H16,IF($D$13="deadlift",'Max Calculator'!$E$10*H16,0))),5)=0," ",MROUND(IF($D$13="squat",'Max Calculator'!$E$8*H16,IF($D$13="bench",'Max Calculator'!$E$9*H16,IF($D$13="deadlift",'Max Calculator'!$E$10*H16,0))),5)) -> 250
B17: ='Max Calculator'!$E$12-35 -> 43043 | C17: A4 | D17: =HLOOKUP($I$9,INDIRECT($D$9),VLOOKUP(C17,'Phase Creator'!$B$8:$C$19,2,FALSE),FALSE) -> Competition Squat | E17: 1 | F17: * | H17: 0.93 | I17: =IF(MROUND(IF($D$13="squat",'Max Calculator'!$E$8*G17,IF($D$13="bench",'Max Calculator'!$E$9*G17,IF($D$13="deadlift",'Max Calculator'!$E$10*G17,0))),5)=0," ",MROUND(IF($D$13="squat",'Max Calculator'!$E$8*G17,IF($D$13="bench",'Max Calculator'!$E$9*G17,IF($D$13="deadlift",'Max Calculator'!$E$10*G17,0))),5)) | J17: =IF(MROUND(IF($D$13="squat",'Max Calculator'!$E$8*H17,IF($D$13="bench",'Max Calculator'!$E$9*H17,IF($D$13="deadlift",'Max Calculator'!$E$10*H17,0))),5)=0," ",MROUND(IF($D$13="squat",'Max Calculator'!$E$8*H17,IF($D$13="bench",'Max Calculator'!$E$9*H17,IF($D$13="deadlift",'Max Calculator'!$E$10*H17,0))),5)) -> 295
B19: Week | C19: B | D19: Squat | E19: Sets | F19: Reps | G19: Working Range | I19: Working Weights
B20: ='Max Calculator'!$E$12-140 -> 42938 | C20: B1 | D20: =HLOOKUP($I$9,INDIRECT($D$9),VLOOKUP(C20,'Phase Creator'!$B$8:$C$19,2,FALSE),FALSE) -> Low Bar 3ct Pause Squat | E20: 3 | F20: 6 | H20: 0.55 | I20: =IF(MROUND(IF($D$19="squat",'Max Calculator'!$E$8*G20,IF($D$19="bench",'Max Calculator'!$E$9*G20,IF($D$19="deadlift",'Max Calculator'!$E$10*G20,0))),5)=0," ",MROUND(IF($D$19="squat",'Max Calculator'!$E$8*G20,IF($D$19="bench",'Max Calculator'!$E$9*G20,IF($D$19="deadlift",'Max Calculator'!$E$10*G20,0))),5)) | J20: =IF(MROUND(IF($D$19="squat",'Max Calculator'!$E$8*H20,IF($D$19="bench",'Max Calculator'!$E$9*H20,IF($D$19="deadlift",'Max Calculator'!$E$10*H20,0))),5)=0," ",MROUND(IF($D$19="squat",'Max Calculator'!$E$8*H20,IF($D$19="bench",'Max Calculator'!$E$9*H20,IF($D$19="deadlift",'Max Calculator'!$E$10*H20,0))),5)) -> 175
B21: ='Max Calculator'!$E$12-133 -> 42945 | C21: B2 | D21: =HLOOKUP($I$9,INDIRECT($D$9),VLOOKUP(C21,'Phase Creator'!$B$8:$C$19,2,FALSE),FALSE) -> Low Bar 3ct Pause Squat | E21: 2 | F21: 8 | H21: 0.5 | I21: =IF(MROUND(IF($D$19="squat",'Max Calculator'!$E$8*G21,IF($D$19="bench",'Max Calculator'!$E$9*G21,IF($D$19="deadlift",'Max Calculator'!$E$10*G21,0))),5)=0," ",MROUND(IF($D$19="squat",'Max Calculator'!$E$8*G21,IF($D$19="bench",'Max Calculator'!$E$9*G21,IF($D$19="deadlift",'Max Calculator'!$E$10*G21,0))),5)) | J21: =IF(MROUND(IF($D$19="squat",'Max Calculator'!$E$8*H21,IF($D$19="bench",'Max Calculator'!$E$9*H21,IF($D$19="deadlift",'Max Calculator'!$E$10*H21,0))),5)=0," ",MROUND(IF($D$19="squat",'Max Calculator'!$E$8*H21,IF($D$19="bench",'Max Calculator'!$E$9*H21,IF($D$19="deadlift",'Max Calculator'!$E$10*H21,0))),5)) -> 160
B22: ='Max Calculator'!$E$12-42 -> 43036 | C22: B3 | D22: =HLOOKUP($I$9,INDIRECT($D$9),VLOOKUP(C22,'Phase Creator'!$B$8:$C$19,2,FALSE),FALSE) -> Low Bar 3ct Pause Squat | E22: 4 | F22: 5 | H22: 0.6 | I22: =IF(MROUND(IF($D$19="squat",'Max Calculator'!$E$8*G22,IF($D$19="bench",'Max Calculator'!$E$9*G22,IF($D$19="deadlift",'Max Calculator'!$E$10*G22,0))),5)=0," ",MROUND(IF($D$19="squat",'Max Calculator'!$E$8*G22,IF($D$19="bench",'Max Calculator'!$E$9*G22,IF($D$19="deadlift",'Max Calculator'!$E$10*G22,0))),5)) | J22: =IF(MROUND(IF($D$19="squat",'Max Calculator'!$E$8*H22,IF($D$19="bench",'Max Calculator'!$E$9*H22,IF($D$19="deadlift",'Max Calculator'!$E$10*H22,0))),5)=0," ",MROUND(IF($D$19="squat",'Max Calculator'!$E$8*H22,IF($D$19="bench",'Max Calculator'!$E$9*H22,IF($D$19="deadlift",'Max Calculator'!$E$10*H22,0))),5)) -> 190
B23: ='Max Calculator'!$E$12-35 -> 43043 | C23: B4 | D23: =HLOOKUP($I$9,INDIRECT($D$9),VLOOKUP(C23,'Phase Creator'!$B$8:$C$19,2,FALSE),FALSE) -> Low Bar 3ct Pause Squat | E23: 2 | F23: 5 | H23: 0.55 | I23: =IF(MROUND(IF($D$19="squat",'Max Calculator'!$E$8*G23,IF($D$19="bench",'Max Calculator'!$E$9*G23,IF($D$19="deadlift",'Max Calculator'!$E$10*G23,0))),5)=0," ",MROUND(IF($D$19="squat",'Max Calculator'!$E$8*G23,IF($D$19="bench",'Max Calculator'!$E$9*G23,IF($D$19="deadlift",'Max Calculator'!$E$10*G23,0))),5)) | J23: =IF(MROUND(IF($D$19="squat",'Max Calculator'!$E$8*H23,IF($D$19="bench",'Max Calculator'!$E$9*H23,IF($D$19="deadlift",'Max Calculator'!$E$10*H23,0))),5)=0," ",MROUND(IF($D$19="squat",'Max Calculator'!$E$8*H23,IF($D$19="bench",'Max Calculator'!$E$9*H23,IF($D$19="deadlift",'Max Calculator'!$E$10*H23,0))),5)) -> 175
B25: Week | C25: C | D25: Exercise | E25: Sets | F25: Reps | G25: Working Range | I25: Working Weights
B26: ='Max Calculator'!$E$12-140 -> 42938 | C26: C | D26: =HLOOKUP($I$9,INDIRECT($D$9),VLOOKUP(C26,'Phase Creator'!$B$8:$C$19,2,FALSE),FALSE) -> SB Pike | E26: 3 | F26: 6 | I26: =IF(MROUND(IF(D25="squat",'Max Calculator'!$E$8*G26,IF(D25="bench",'Max Calculator'!$E$9*G26,IF(D25="deadlift",'Max Calculator'!$E$10*G26,0))),5)=0," ",MROUND(IF(D25="squat",'Max Calculator'!$E$8*G26,IF(D25="bench",'Max Calculator'!$E$9*G26,IF(D25="deadlift",'Max Calculator'!$E$10*G26,0))),5)) | J26: =IF(MROUND(IF(D25="squat",'Max Calculator'!$E$8*H26,IF(D25="bench",'Max Calculator'!$E$9*H26,IF(D25="deadlift",'Max Calculator'!$E$10*H26,0))),5)=0," ",MROUND(IF(D25="squat",'Max Calculator'!$E$8*H26,IF(D25="bench",'Max Calculator'!$E$9*H26,IF(D25="deadlift",'Max Calculator'!$E$10*H26,0))),5))
B27: ='Max Calculator'!$E$12-133 -> 42945 | C27: C | D27: =HLOOKUP($I$9,INDIRECT($D$9),VLOOKUP(C27,'Phase Creator'!$B$8:$C$19,2,FALSE),FALSE) -> SB Pike | E27: 2 | F27: 8 | I27: =IF(MROUND(IF(D25="squat",'Max Calculator'!$E$8*G27,IF(D25="bench",'Max Calculator'!$E$9*G27,IF(D25="deadlift",'Max Calculator'!$E$10*G27,0))),5)=0," ",MROUND(IF(D25="squat",'Max Calculator'!$E$8*G27,IF(D25="bench",'Max Calculator'!$E$9*G27,IF(D25="deadlift",'Max Calculator'!$E$10*G27,0))),5)) | J27: =IF(MROUND(IF(D25="squat",'Max Calculator'!$E$8*H27,IF(D25="bench",'Max Calculator'!$E$9*H27,IF(D25="deadlift",'Max Calculator'!$E$10*H27,0))),5)=0," ",MROUND(IF(D25="squat",'Max Calculator'!$E$8*H27,IF(D25="bench",'Max Calculator'!$E$9*H27,IF(D25="deadlift",'Max Calculator'!$E$10*H27,0))),5))
B28: ='Max Calculator'!$E$12-42 -> 43036 | C28: C | D28: =HLOOKUP($I$9,INDIRECT($D$9),VLOOKUP(C28,'Phase Creator'!$B$8:$C$19,2,FALSE),FALSE) -> SB Pike | E28: 4 | F28: 5 | I28: =IF(MROUND(IF(D25="squat",'Max Calculator'!$E$8*G28,IF(D25="bench",'Max Calculator'!$E$9*G28,IF(D25="deadlift",'Max Calculator'!$E$10*G28,0))),5)=0," ",MROUND(IF(D25="squat",'Max Calculator'!$E$8*G28,IF(D25="bench",'Max Calculator'!$E$9*G28,IF(D25="deadlift",'Max Calculator'!$E$10*G28,0))),5)) | J28: =IF(MROUND(IF(D25="squat",'Max Calculator'!$E$8*H28,IF(D25="bench",'Max Calculator'!$E$9*H28,IF(D25="deadlift",'Max Calculator'!$E$10*H28,0))),5)=0," ",MROUND(IF(D25="squat",'Max Calculator'!$E$8*H28,IF(D25="bench",'Max Calculator'!$E$9*H28,IF(D25="deadlift",'Max Calculator'!$E$10*H28,0))),5))
B29: ='Max Calculator'!$E$12-35 -> 43043 | C29: C | D29: =HLOOKUP($I$9,INDIRECT($D$9),VLOOKUP(C29,'Phase Creator'!$B$8:$C$19,2,FALSE),FALSE) -> SB Pike | E29: 1 | F29: 10 | I29: =IF(MROUND(IF(D25="squat",'Max Calculator'!$E$8*G29,IF(D25="bench",'Max Calculator'!$E$9*G29,IF(D25="deadlift",'Max Calculator'!$E$10*G29,0))),5)=0," ",MROUND(IF(D25="squat",'Max Calculator'!$E$8*G29,IF(D25="bench",'Max Calculator'!$E$9*G29,IF(D25="deadlift",'Max Calculator'!$E$10*G29,0))),5)) | J29: =IF(MROUND(IF(D25="squat",'Max Calculator'!$E$8*H29,IF(D25="bench",'Max Calculator'!$E$9*H29,IF(D25="deadlift",'Max Calculator'!$E$10*H29,0))),5)=0," ",MROUND(IF(D25="squat",'Max Calculator'!$E$8*H29,IF(D25="bench",'Max Calculator'!$E$9*H29,IF(D25="deadlift",'Max Calculator'!$E$10*H29,0))),5))
B31: Week | C31: D | D31: Exercise | E31: Sets | F31: Reps | G31: Working Range | I31: Working Weights
B32: ='Max Calculator'!$E$12-140 -> 42938 | C32: D | D32: =HLOOKUP($I$9,INDIRECT($D$9),VLOOKUP(C32,'Phase Creator'!$B$8:$C$19,2,FALSE),FALSE) -> GHR or Back Extension | E32: 3 | F32: 15 | I32: =IF(MROUND(IF(D31="squat",'Max Calculator'!$E$8*G32,IF(D31="bench",'Max Calculator'!$E$9*G32,IF(D31="deadlift",'Max Calculator'!$E$10*G32,0))),5)=0," ",MROUND(IF(D31="squat",'Max Calculator'!$E$8*G32,IF(D31="bench",'Max Calculator'!$E$9*G32,IF(D31="deadlift",'Max Calculator'!$E$10*G32,0))),5)) | J32: =IF(MROUND(IF(D31="squat",'Max Calculator'!$E$8*H32,IF(D31="bench",'Max Calculator'!$E$9*H32,IF(D31="deadlift",'Max Calculator'!$E$10*H32,0))),5)=0," ",MROUND(IF(D31="squat",'Max Calculator'!$E$8*H32,IF(D31="bench",'Max Calculator'!$E$9*H32,IF(D31="deadlift",'Max Calculator'!$E$10*H32,0))),5))
B33: ='Max Calculator'!$E$12-133 -> 42945 | C33: D | D33: =HLOOKUP($I$9,INDIRECT($D$9),VLOOKUP(C33,'Phase Creator'!$B$8:$C$19,2,FALSE),FALSE) -> GHR or Back Extension | E33: 2 | F33: 20 | I33: =IF(MROUND(IF(D31="squat",'Max Calculator'!$E$8*G33,IF(D31="bench",'Max Calculator'!$E$9*G33,IF(D31="deadlift",'Max Calculator'!$E$10*G33,0))),5)=0," ",MROUND(IF(D31="squat",'Max Calculator'!$E$8*G33,IF(D31="bench",'Max Calculator'!$E$9*G33,IF(D31="deadlift",'Max Calculator'!$E$10*G33,0))),5)) | J33: =IF(MROUND(IF(D31="squat",'Max Calculator'!$E$8*H33,IF(D31="bench",'Max Calculator'!$E$9*H33,IF(D31="deadlift",'Max Calculator'!$E$10*H33,0))),5)=0," ",MROUND(IF(D31="squat",'Max Calculator'!$E$8*H33,IF(D31="bench",'Max Calculator'!$E$9*H33,IF(D31="deadlift",'Max Calculator'!$E$10*H33,0))),5))
B34: ='Max Calculator'!$E$12-42 -> 43036 | C34: D | D34: =HLOOKUP($I$9,INDIRECT($D$9),VLOOKUP(C34,'Phase Creator'!$B$8:$C$19,2,FALSE),FALSE) -> GHR or Back Extension | E34: 4 | F34: 12 | I34: =IF(MROUND(IF(D31="squat",'Max Calculator'!$E$8*G34,IF(D31="bench",'Max Calculator'!$E$9*G34,IF(D31="deadlift",'Max Calculator'!$E$10*G34,0))),5)=0," ",MROUND(IF(D31="squat",'Max Calculator'!$E$8*G34,IF(D31="bench",'Max Calculator'!$E$9*G34,IF(D31="deadlift",'Max Calculator'!$E$10*G34,0))),5)) | J34: =IF(MROUND(IF(D31="squat",'Max Calculator'!$E$8*H34,IF(D31="bench",'Max Calculator'!$E$9*H34,IF(D31="deadlift",'Max Calculator'!$E$10*H34,0))),5)=0," ",MROUND(IF(D31="squat",'Max Calculator'!$E$8*H34,IF(D31="bench",'Max Calculator'!$E$9*H34,IF(D31="deadlift",'Max Calculator'!$E$10*H34,0))),5))
B35: ='Max Calculator'!$E$12-35 -> 43043 | C35: D | D35: =HLOOKUP($I$9,INDIRECT($D$9),VLOOKUP(C35,'Phase Creator'!$B$8:$C$19,2,FALSE),FALSE) -> GHR or Back Extension | E35: 1 | F35: 20 | I35: =IF(MROUND(IF(D31="squat",'Max Calculator'!$E$8*G35,IF(D31="bench",'Max Calculator'!$E$9*G35,IF(D31="deadlift",'Max Calculator'!$E$10*G35,0))),5)=0," ",MROUND(IF(D31="squat",'Max Calculator'!$E$8*G35,IF(D31="bench",'Max Calculator'!$E$9*G35,IF(D31="deadlift",'Max Calculator'!$E$10*G35,0))),5)) | J35: =IF(MROUND(IF(D31="squat",'Max Calculator'!$E$8*H35,IF(D31="bench",'Max Calculator'!$E$9*H35,IF(D31="deadlift",'Max Calculator'!$E$10*H35,0))),5)=0," ",MROUND(IF(D31="squat",'Max Calculator'!$E$8*H35,IF(D31="bench",'Max Calculator'!$E$9*H35,IF(D31="deadlift",'Max Calculator'!$E$10*H35,0))),5))
B37: Week | C37: E | D37: Exercise | E37: Sets | F37: Reps | G37: Working Range | I37: Working Weights
B38: ='Max Calculator'!$E$12-140 -> 42938 | C38: E | D38: =HLOOKUP($I$9,INDIRECT($D$9),VLOOKUP(C38,'Phase Creator'!$B$8:$C$19,2,FALSE),FALSE) -> Slingshot Abduction/Hip Abduction | E38: 3 | F38: 8 | I38: =IF(MROUND(IF(D37="squat",'Max Calculator'!$E$8*G38,IF(D37="bench",'Max Calculator'!$E$9*G38,IF(D37="deadlift",'Max Calculator'!$E$10*G38,0))),5)=0," ",MROUND(IF(D37="squat",'Max Calculator'!$E$8*G38,IF(D37="bench",'Max Calculator'!$E$9*G38,IF(D37="deadlift",'Max Calculator'!$E$10*G38,0))),5)) | J38: =IF(MROUND(IF(D37="squat",'Max Calculator'!$E$8*H38,IF(D37="bench",'Max Calculator'!$E$9*H38,IF(D37="deadlift",'Max Calculator'!$E$10*H38,0))),5)=0," ",MROUND(IF(D37="squat",'Max Calculator'!$E$8*H38,IF(D37="bench",'Max Calculator'!$E$9*H38,IF(D37="deadlift",'Max Calculator'!$E$10*H38,0))),5))
B39: ='Max Calculator'!$E$12-133 -> 42945 | C39: E | D39: =HLOOKUP($I$9,INDIRECT($D$9),VLOOKUP(C39,'Phase Creator'!$B$8:$C$19,2,FALSE),FALSE) -> Slingshot Abduction/Hip Abduction | E39: 2 | F39: 12 | I39: =IF(MROUND(IF(D37="squat",'Max Calculator'!$E$8*G39,IF(D37="bench",'Max Calculator'!$E$9*G39,IF(D37="deadlift",'Max Calculator'!$E$10*G39,0))),5)=0," ",MROUND(IF(D37="squat",'Max Calculator'!$E$8*G39,IF(D37="bench",'Max Calculator'!$E$9*G39,IF(D37="deadlift",'Max Calculator'!$E$10*G39,0))),5)) | J39: =IF(MROUND(IF(D37="squat",'Max Calculator'!$E$8*H39,IF(D37="bench",'Max Calculator'!$E$9*H39,IF(D37="deadlift",'Max Calculator'!$E$10*H39,0))),5)=0," ",MROUND(IF(D37="squat",'Max Calculator'!$E$8*H39,IF(D37="bench",'Max Calculator'!$E$9*H39,IF(D37="deadlift",'Max Calculator'!$E$10*H39,0))),5))
B40: ='Max Calculator'!$E$12-42 -> 43036 | C40: E | D40: =HLOOKUP($I$9,INDIRECT($D$9),VLOOKUP(C40,'Phase Creator'!$B$8:$C$19,2,FALSE),FALSE) -> Slingshot Abduction/Hip Abduction | E40: 4 | F40: 10 | I40: =IF(MROUND(IF(D37="squat",'Max Calculator'!$E$8*G40,IF(D37="bench",'Max Calculator'!$E$9*G40,IF(D37="deadlift",'Max Calculator'!$E$10*G40,0))),5)=0," ",MROUND(IF(D37="squat",'Max Calculator'!$E$8*G40,IF(D37="bench",'Max Calculator'!$E$9*G40,IF(D37="deadlift",'Max Calculator'!$E$10*G40,0))),5)) | J40: =IF(MROUND(IF(D37="squat",'Max Calculator'!$E$8*H40,IF(D37="bench",'Max Calculator'!$E$9*H40,IF(D37="deadlift",'Max Calculator'!$E$10*H40,0))),5)=0," ",MROUND(IF(D37="squat",'Max Calculator'!$E$8*H40,IF(D37="bench",'Max Calculator'!$E$9*H40,IF(D37="deadlift",'Max Calculator'!$E$10*H40,0))),5))
B41: ='Max Calculator'!$E$12-35 -> 43043 | C41: E | D41: =HLOOKUP($I$9,INDIRECT($D$9),VLOOKUP(C41,'Phase Creator'!$B$8:$C$19,2,FALSE),FALSE) -> Slingshot Abduction/Hip Abduction | E41: 1 | F41: 15 | I41: =IF(MROUND(IF(D37="squat",'Max Calculator'!$E$8*G41,IF(D37="bench",'Max Calculator'!$E$9*G41,IF(D37="deadlift",'Max Calculator'!$E$10*G41,0))),5)=0," ",MROUND(IF(D37="squat",'Max Calculator'!$E$8*G41,IF(D37="bench",'Max Calculator'!$E$9*G41,IF(D37="deadlift",'Max Calculator'!$E$10*G41,0))),5)) | J41: =IF(MROUND(IF(D37="squat",'Max Calculator'!$E$8*H41,IF(D37="bench",'Max Calculator'!$E$9*H41,IF(D37="deadlift",'Max Calculator'!$E$10*H41,0))),5)=0," ",MROUND(IF(D37="squat",'Max Calculator'!$E$8*H41,IF(D37="bench",'Max Calculator'!$E$9*H41,IF(D37="deadlift",'Max Calculator'!$E$10*H41,0))),5))
B43: Week | C43: F | D43: Exercise | E43: Sets | F43: Reps | G43: Working Range | I43: Working Weights
B44: ='Max Calculator'!$E$12-140 -> 42938 | C44: F | D44: =HLOOKUP($I$9,INDIRECT($D$9),VLOOKUP(C44,'Phase Creator'!$B$8:$C$19,2,FALSE),FALSE) -> Cable/TRX Holds | E44: 3 | F44: 25 | I44: =IF(MROUND(IF(D43="squat",'Max Calculator'!$E$8*G44,IF(D43="bench",'Max Calculator'!$E$9*G44,IF(D43="deadlift",'Max Calculator'!$E$10*G44,0))),5)=0," ",MROUND(IF(D43="squat",'Max Calculator'!$E$8*G44,IF(D43="bench",'Max Calculator'!$E$9*G44,IF(D43="deadlift",'Max Calculator'!$E$10*G44,0))),5)) | J44: =IF(MROUND(IF(D43="squat",'Max Calculator'!$E$8*H44,IF(D43="bench",'Max Calculator'!$E$9*H44,IF(D43="deadlift",'Max Calculator'!$E$10*H44,0))),5)=0," ",MROUND(IF(D43="squat",'Max Calculator'!$E$8*H44,IF(D43="bench",'Max Calculator'!$E$9*H44,IF(D43="deadlift",'Max Calculator'!$E$10*H44,0))),5))
B45: ='Max Calculator'!$E$12-133 -> 42945 | C45: F | D45: =HLOOKUP($I$9,INDIRECT($D$9),VLOOKUP(C45,'Phase Creator'!$B$8:$C$19,2,FALSE),FALSE) -> Cable/TRX Holds | E45: 2 | F45: 30 | I45: =IF(MROUND(IF(D43="squat",'Max Calculator'!$E$8*G45,IF(D43="bench",'Max Calculator'!$E$9*G45,IF(D43="deadlift",'Max Calculator'!$E$10*G45,0))),5)=0," ",MROUND(IF(D43="squat",'Max Calculator'!$E$8*G45,IF(D43="bench",'Max Calculator'!$E$9*G45,IF(D43="deadlift",'Max Calculator'!$E$10*G45,0))),5)) | J45: =IF(MROUND(IF(D43="squat",'Max Calculator'!$E$8*H45,IF(D43="bench",'Max Calculator'!$E$9*H45,IF(D43="deadlift",'Max Calculator'!$E$10*H45,0))),5)=0," ",MROUND(IF(D43="squat",'Max Calculator'!$E$8*H45,IF(D43="bench",'Max Calculator'!$E$9*H45,IF(D43="deadlift",'Max Calculator'!$E$10*H45,0))),5))
B46: ='Max Calculator'!$E$12-42 -> 43036 | C46: F | D46: =HLOOKUP($I$9,INDIRECT($D$9),VLOOKUP(C46,'Phase Creator'!$B$8:$C$19,2,FALSE),FALSE) -> Cable/TRX Holds | E46: 4 | F46: 20 | I46: =IF(MROUND(IF(D43="squat",'Max Calculator'!$E$8*G46,IF(D43="bench",'Max Calculator'!$E$9*G46,IF(D43="deadlift",'Max Calculator'!$E$10*G46,0))),5)=0," ",MROUND(IF(D43="squat",'Max Calculator'!$E$8*G46,IF(D43="bench",'Max Calculator'!$E$9*G46,IF(D43="deadlift",'Max Calculator'!$E$10*G46,0))),5)) | J46: =IF(MROUND(IF(D43="squat",'Max Calculator'!$E$8*H46,IF(D43="bench",'Max Calculator'!$E$9*H46,IF(D43="deadlift",'Max Calculator'!$E$10*H46,0))),5)=0," ",MROUND(IF(D43="squat",'Max Calculator'!$E$8*H46,IF(D43="bench",'Max Calculator'!$E$9*H46,IF(D43="deadlift",'Max Calculator'!$E$10*H46,0))),5))
B47: ='Max Calculator'!$E$12-35 -> 43043 | C47: F | D47: =HLOOKUP($I$9,INDIRECT($D$9),VLOOKUP(C47,'Phase Creator'!$B$8:$C$19,2,FALSE),FALSE) -> Cable/TRX Holds | E47: 1 | F47: 35 | I47: =IF(MROUND(IF(D43="squat",'Max Calculator'!$E$8*G47,IF(D43="bench",'Max Calculator'!$E$9*G47,IF(D43="deadlift",'Max Calculator'!$E$10*G47,0))),5)=0," ",MROUND(IF(D43="squat",'Max Calculator'!$E$8*G47,IF(D43="bench",'Max Calculator'!$E$9*G47,IF(D43="deadlift",'Max Calculator'!$E$10*G47,0))),5)) | J47: =IF(MROUND(IF(D43="squat",'Max Calculator'!$E$8*H47,IF(D43="bench",'Max Calculator'!$E$9*H47,IF(D43="deadlift",'Max Calculator'!$E$10*H47,0))),5)=0," ",MROUND(IF(D43="squat",'Max Calculator'!$E$8*H47,IF(D43="bench",'Max Calculator'!$E$9*H47,IF(D43="deadlift",'Max Calculator'!$E$10*H47,0))),5))
D56: =D9 -> PrePeaking | H56: Day | I56: 2
B60: Week | C60: A | D60: Bench | E60: Sets | F60: Reps | G60: Working Range | I60: Working Weights
B61: ='Max Calculator'!$E$12-140 -> 42938 | C61: A1 | D61: =HLOOKUP($I$56,INDIRECT($D$9),VLOOKUP(C61,'Phase Creator'!$B$8:$C$19,2,FALSE),FALSE) -> Bench Press 3ct Pause | E61: 5 | F61: 3 | G61: 0.82 | H61: 0.87 | I61: =IF(MROUND(IF(D60="squat",'Max Calculator'!$E$8*G61,IF(D60="bench",'Max Calculator'!$E$9*G61,IF(D60="deadlift",'Max Calculator'!$E$10*G61,0))),5)=0," ",MROUND(IF(D60="squat",'Max Calculator'!$E$8*G61,IF(D60="bench",'Max Calculator'!$E$9*G61,IF(D60="deadlift",'Max Calculator'!$E$10*G61,0))),5)) -> 185 | J61: =IF(MROUND(IF(D60="squat",'Max Calculator'!$E$8*H61,IF(D60="bench",'Max Calculator'!$E$9*H61,IF(D60="deadlift",'Max Calculator'!$E$10*H61,0))),5)=0," ",MROUND(IF(D60="squat",'Max Calculator'!$E$8*H61,IF(D60="bench",'Max Calculator'!$E$9*H61,IF(D60="deadlift",'Max Calculator'!$E$10*H61,0))),5)) -> 195
B62: ='Max Calculator'!$E$12-133 -> 42945 | C62: A2 | D62: =HLOOKUP($I$56,INDIRECT($D$9),VLOOKUP(C62,'Phase Creator'!$B$8:$C$19,2,FALSE),FALSE) -> Bench w/ Chains | E62: 8 | F62: 3 | G62: 0.55 | H62: 0.6 | I62: =IF(MROUND(IF(D60="squat",'Max Calculator'!$E$8*G62,IF(D60="bench",'Max Calculator'!$E$9*G62,IF(D60="deadlift",'Max Calculator'!$E$10*G62,0))),5)=0," ",MROUND(IF(D60="squat",'Max Calculator'!$E$8*G62,IF(D60="bench",'Max Calculator'!$E$9*G62,IF(D60="deadlift",'Max Calculator'!$E$10*G62,0))),5)) -> 125 | J62: =IF(MROUND(IF(D60="squat",'Max Calculator'!$E$8*H62,IF(D60="bench",'Max Calculator'!$E$9*H62,IF(D60="deadlift",'Max Calculator'!$E$10*H62,0))),5)=0," ",MROUND(IF(D60="squat",'Max Calculator'!$E$8*H62,IF(D60="bench",'Max Calculator'!$E$9*H62,IF(D60="deadlift",'Max Calculator'!$E$10*H62,0))),5)) -> 135
B63: ='Max Calculator'!$E$12-42 -> 43036 | C63: A3 | D63: =HLOOKUP($I$56,INDIRECT($D$9),VLOOKUP(C63,'Phase Creator'!$B$8:$C$19,2,FALSE),FALSE) -> Bench w/ Chains | E63: 5/3 | F63: 3/2 | G63: 0.65 | H63: 0.8 | I63: =IF(MROUND(IF(D60="squat",'Max Calculator'!$E$8*G63,IF(D60="bench",'Max Calculator'!$E$9*G63,IF(D60="deadlift",'Max Calculator'!$E$10*G63,0))),5)=0," ",MROUND(IF(D60="squat",'Max Calculator'!$E$8*G63,IF(D60="bench",'Max Calculator'!$E$9*G63,IF(D60="deadlift",'Max Calculator'!$E$10*G63,0))),5)) -> 145 | J63: =IF(MROUND(IF(D60="squat",'Max Calculator'!$E$8*H63,IF(D60="bench",'Max Calculator'!$E$9*H63,IF(D60="deadlift",'Max Calculator'!$E$10*H63,0))),5)=0," ",MROUND(IF(D60="squat",'Max Calculator'!$E$8*H63,IF(D60="bench",'Max Calculator'!$E$9*H63,IF(D60="deadlift",'Max Calculator'!$E$10*H63,0))),5)) -> 180
B64: ='Max Calculator'!$E$12-35 -> 43043 | C64: A4 | D64: =HLOOKUP($I$56,INDIRECT($D$9),VLOOKUP(C64,'Phase Creator'!$B$8:$C$19,2,FALSE),FALSE) -> Competition Bench Press | E64: 1 | F64: * | H64: 0.93 | I64: =IF(MROUND(IF(D60="squat",'Max Calculator'!$E$8*G64,IF(D60="bench",'Max Calculator'!$E$9*G64,IF(D60="deadlift",'Max Calculator'!$E$10*G64,0))),5)=0," ",MROUND(IF(D60="squat",'Max Calculator'!$E$8*G64,IF(D60="bench",'Max Calculator'!$E$9*G64,IF(D60="deadlift",'Max Calculator'!$E$10*G64,0))),5)) | J64: =IF(MROUND(IF(D60="squat",'Max Calculator'!$E$8*H64,IF(D60="bench",'Max Calculator'!$E$9*H64,IF(D60="deadlift",'Max Calculator'!$E$10*H64,0))),5)=0," ",MROUND(IF(D60="squat",'Max Calculator'!$E$8*H64,IF(D60="bench",'Max Calculator'!$E$9*H64,IF(D60="deadlift",'Max Calculator'!$E$10*H64,0))),5)) -> 210
B66: Week | C66: B | D66: Bench | E66: Sets | F66: Reps | G66: Working Range | I66: Working Weights
B67: ='Max Calculator'!$E$12-140 -> 42938 | C67: B1 | D67: =HLOOKUP($I$56,INDIRECT($D$9),VLOOKUP(C67,'Phase Creator'!$B$8:$C$19,2,FALSE),FALSE) -> 3ct Pause Close Grip Bench | E67: 3 | F67: 6 | H67: 0.55 | I67: =IF(MROUND(IF(D66="squat",'Max Calculator'!$E$8*G67,IF(D66="bench",'Max Calculator'!$E$9*G67,IF(D66="deadlift",'Max Calculator'!$E$10*G67,0))),5)=0," ",MROUND(IF(D66="squat",'Max Calculator'!$E$8*G67,IF(D66="bench",'Max Calculator'!$E$9*G67,IF(D66="deadlift",'Max Calculator'!$E$10*G67,0))),5)) | J67: =IF(MROUND(IF(D66="squat",'Max Calculator'!$E$8*H67,IF(D66="bench",'Max Calculator'!$E$9*H67,IF(D66="deadlift",'Max Calculator'!$E$10*H67,0))),5)=0," ",MROUND(IF(D66="squat",'Max Calculator'!$E$8*H67,IF(D66="bench",'Max Calculator'!$E$9*H67,IF(D66="deadlift",'Max Calculator'!$E$10*H67,0))),5)) -> 125
B68: ='Max Calculator'!$E$12-133 -> 42945 | C68: B2 | D68: =HLOOKUP($I$56,INDIRECT($D$9),VLOOKUP(C68,'Phase Creator'!$B$8:$C$19,2,FALSE),FALSE) -> 3ct Pause Close Grip Bench | E68: 2 | F68: 8 | H68: 0.6 | I68: =IF(MROUND(IF(D66="squat",'Max Calculator'!$E$8*G68,IF(D66="bench",'Max Calculator'!$E$9*G68,IF(D66="deadlift",'Max Calculator'!$E$10*G68,0))),5)=0," ",MROUND(IF(D66="squat",'Max Calculator'!$E$8*G68,IF(D66="bench",'Max Calculator'!$E$9*G68,IF(D66="deadlift",'Max Calculator'!$E$10*G68,0))),5)) | J68: =IF(MROUND(IF(D66="squat",'Max Calculator'!$E$8*H68,IF(D66="bench",'Max Calculator'!$E$9*H68,IF(D66="deadlift",'Max Calculator'!$E$10*H68,0))),5)=0," ",MROUND(IF(D66="squat",'Max Calculator'!$E$8*H68,IF(D66="bench",'Max Calculator'!$E$9*H68,IF(D66="deadlift",'Max Calculator'!$E$10*H68,0))),5)) -> 135
...

Sheet Peaking Phase
D9: Peaking | H9: Day | I9: 1
B13: Week | C13: A | D13: Squat | E13: Sets | F13: Reps | G13: Working Range | I13: Working Weights
B14: ='Max Calculator'!$E$12-28 -> 43050 | C14: A1 | D14: =HLOOKUP($I$9,INDIRECT($D$9),VLOOKUP(C14,'Phase Creator'!$B$8:$C$19,2,FALSE),FALSE) -> Squat w/ Bands | E14: 6 | F14: 2 | G14: 0.5 | H14: 0.7 | I14: =IF(MROUND(IF($D$13="squat",'Max Calculator'!$E$8*G14,IF($D$13="bench",'Max Calculator'!$E$9*G14,IF($D$13="deadlift",'Max Calculator'!$E$10*G14,0))),5)=0," ",MROUND(IF($D$13="squat",'Max Calculator'!$E$8*G14,IF($D$13="bench",'Max Calculator'!$E$9*G14,IF($D$13="deadlift",'Max Calculator'!$E$10*G14,0))),5)) -> 160 | J14: =IF(MROUND(IF($D$13="squat",'Max Calculator'!$E$8*H14,IF($D$13="bench",'Max Calculator'!$E$9*H14,IF($D$13="deadlift",'Max Calculator'!$E$10*H14,0))),5)=0," ",MROUND(IF($D$13="squat",'Max Calculator'!$E$8*H14,IF($D$13="bench",'Max Calculator'!$E$9*H14,IF($D$13="deadlift",'Max Calculator'!$E$10*H14,0))),5)) -> 220
B15: ='Max Calculator'!$E$12-21 -> 43057 | C15: A2 | D15: =HLOOKUP($I$9,INDIRECT($D$9),VLOOKUP(C15,'Phase Creator'!$B$8:$C$19,2,FALSE),FALSE) -> Reverse Bands Squat | E15: 1 | F15: 3 | H15: 1 | I15: =IF(MROUND(IF($D$13="squat",'Max Calculator'!$E$8*G15,IF($D$13="bench",'Max Calculator'!$E$9*G15,IF($D$13="deadlift",'Max Calculator'!$E$10*G15,0))),5)=0," ",MROUND(IF($D$13="squat",'Max Calculator'!$E$8*G15,IF($D$13="bench",'Max Calculator'!$E$9*G15,IF($D$13="deadlift",'Max Calculator'!$E$10*G15,0))),5)) | J15: =IF(MROUND(IF($D$13="squat",'Max Calculator'!$E$8*H15,IF($D$13="bench",'Max Calculator'!$E$9*H15,IF($D$13="deadlift",'Max Calculator'!$E$10*H15,0))),5)=0," ",MROUND(IF($D$13="squat",'Max Calculator'!$E$8*H15,IF($D$13="bench",'Max Calculator'!$E$9*H15,IF($D$13="deadlift",'Max Calculator'!$E$10*H15,0))),5)) -> 315
B16: ='Max Calculator'!$E$12-14 -> 43064 | C16: A3 | D16: =HLOOKUP($I$9,INDIRECT($D$9),VLOOKUP(C16,'Phase Creator'!$B$8:$C$19,2,FALSE),FALSE) -> Competition Squat | E16: 1 | F16: 1 | H16: 1 | I16: =IF(MROUND(IF($D$13="squat",'Max Calculator'!$E$8*G16,IF($D$13="bench",'Max Calculator'!$E$9*G16,IF($D$13="deadlift",'Max Calculator'!$E$10*G16,0))),5)=0," ",MROUND(IF($D$13="squat",'Max Calculator'!$E$8*G16,IF($D$13="bench",'Max Calculator'!$E$9*G16,IF($D$13="deadlift",'Max Calculator'!$E$10*G16,0))),5)) | J16: =IF(MROUND(IF($D$13="squat",'Max Calculator'!$E$8*H16,IF($D$13="bench",'Max Calculator'!$E$9*H16,IF($D$13="deadlift",'Max Calculator'!$E$10*H16,0))),5)=0," ",MROUND(IF($D$13="squat",'Max Calculator'!$E$8*H16,IF($D$13="bench",'Max Calculator'!$E$9*H16,IF($D$13="deadlift",'Max Calculator'!$E$10*H16,0))),5)) -> 315
B17: ='Max Calculator'!$E$12-7 -> 43071 | C17: A4 | D17: =HLOOKUP($I$9,INDIRECT($D$9),VLOOKUP(C17,'Phase Creator'!$B$8:$C$19,2,FALSE),FALSE) -> Competition Squat | E17: 1 | F17: 1 | H17: 0.9 | I17: =IF(MROUND(IF($D$13="squat",'Max Calculator'!$E$8*G17,IF($D$13="bench",'Max Calculator'!$E$9*G17,IF($D$13="deadlift",'Max Calculator'!$E$10*G17,0))),5)=0," ",MROUND(IF($D$13="squat",'Max Calculator'!$E$8*G17,IF($D$13="bench",'Max Calculator'!$E$9*G17,IF($D$13="deadlift",'Max Calculator'!$E$10*G17,0))),5)) | J17: =IF(MROUND(IF($D$13="squat",'Max Calculator'!$E$8*H17,IF($D$13="bench",'Max Calculator'!$E$9*H17,IF($D$13="deadlift",'Max Calculator'!$E$10*H17,0))),5)=0," ",MROUND(IF($D$13="squat",'Max Calculator'!$E$8*H17,IF($D$13="bench",'Max Calculator'!$E$9*H17,IF($D$13="deadlift",'Max Calculator'!$E$10*H17,0))),5)) -> 285
B19: Week | C19: B | D19: Squat | E19: Sets | F19: Reps | G19: Working Range | I19: Working Weights
B20: ='Max Calculator'!$E$12-28 -> 43050 | C20: B1 | D20: =HLOOKUP($I$9,INDIRECT($D$9),VLOOKUP(C20,'Phase Creator'!$B$8:$C$19,2,FALSE),FALSE) -> 1ct Pause Squat | E20: 3 | F20: 6 | H20: 0.55 | I20: =IF(MROUND(IF($D$19="squat",'Max Calculator'!$E$8*G20,IF($D$19="bench",'Max Calculator'!$E$9*G20,IF($D$19="deadlift",'Max Calculator'!$E$10*G20,0))),5)=0," ",MROUND(IF($D$19="squat",'Max Calculator'!$E$8*G20,IF($D$19="bench",'Max Calculator'!$E$9*G20,IF($D$19="deadlift",'Max Calculator'!$E$10*G20,0))),5)) | J20: =IF(MROUND(IF($D$19="squat",'Max Calculator'!$E$8*H20,IF($D$19="bench",'Max Calculator'!$E$9*H20,IF($D$19="deadlift",'Max Calculator'!$E$10*H20,0))),5)=0," ",MROUND(IF($D$19="squat",'Max Calculator'!$E$8*H20,IF($D$19="bench",'Max Calculator'!$E$9*H20,IF($D$19="deadlift",'Max Calculator'!$E$10*H20,0))),5)) -> 175
B21: ='Max Calculator'!$E$12-21 -> 43057 | C21: B2 | D21: =HLOOKUP($I$9,INDIRECT($D$9),VLOOKUP(C21,'Phase Creator'!$B$8:$C$19,2,FALSE),FALSE) -> 1ct Pause Squat | E21: 2 | F21: 5 | H21: 0.65 | I21: =IF(MROUND(IF($D$19="squat",'Max Calculator'!$E$8*G21,IF($D$19="bench",'Max Calculator'!$E$9*G21,IF($D$19="deadlift",'Max Calculator'!$E$10*G21,0))),5)=0," ",MROUND(IF($D$19="squat",'Max Calculator'!$E$8*G21,IF($D$19="bench",'Max Calculator'!$E$9*G21,IF($D$19="deadlift",'Max Calculator'!$E$10*G21,0))),5)) | J21: =IF(MROUND(IF($D$19="squat",'Max Calculator'!$E$8*H21,IF($D$19="bench",'Max Calculator'!$E$9*H21,IF($D$19="deadlift",'Max Calculator'!$E$10*H21,0))),5)=0," ",MROUND(IF($D$19="squat",'Max Calculator'!$E$8*H21,IF($D$19="bench",'Max Calculator'!$E$9*H21,IF($D$19="deadlift",'Max Calculator'!$E$10*H21,0))),5)) -> 205
B22: ='Max Calculator'!$E$12-14 -> 43064 | C22: B3 | D22: =HLOOKUP($I$9,INDIRECT($D$9),VLOOKUP(C22,'Phase Creator'!$B$8:$C$19,2,FALSE),FALSE) -> 1ct Pause Squat | E22: 2 | F22: 5 | H22: 0.6 | I22: =IF(MROUND(IF($D$19="squat",'Max Calculator'!$E$8*G22,IF($D$19="bench",'Max Calculator'!$E$9*G22,IF($D$19="deadlift",'Max Calculator'!$E$10*G22,0))),5)=0," ",MROUND(IF($D$19="squat",'Max Calculator'!$E$8*G22,IF($D$19="bench",'Max Calculator'!$E$9*G22,IF($D$19="deadlift",'Max Calculator'!$E$10*G22,0))),5)) | J22: =IF(MROUND(IF($D$19="squat",'Max Calculator'!$E$8*H22,IF($D$19="bench",'Max Calculator'!$E$9*H22,IF($D$19="deadlift",'Max Calculator'!$E$10*H22,0))),5)=0," ",MROUND(IF($D$19="squat",'Max Calculator'!$E$8*H22,IF($D$19="bench",'Max Calculator'!$E$9*H22,IF($D$19="deadlift",'Max Calculator'!$E$10*H22,0))),5)) -> 190
B23: ='Max Calculator'!$E$12-7 -> 43071 | C23: B4 | D23: =HLOOKUP($I$9,INDIRECT($D$9),VLOOKUP(C23,'Phase Creator'!$B$8:$C$19,2,FALSE),FALSE) -> 1ct Pause Squat | E23: 1 | F23: 5 | H23: 0.5 | I23: =IF(MROUND(IF($D$19="squat",'Max Calculator'!$E$8*G23,IF($D$19="bench",'Max Calculator'!$E$9*G23,IF($D$19="deadlift",'Max Calculator'!$E$10*G23,0))),5)=0," ",MROUND(IF($D$19="squat",'Max Calculator'!$E$8*G23,IF($D$19="bench",'Max Calculator'!$E$9*G23,IF($D$19="deadlift",'Max Calculator'!$E$10*G23,0))),5)) | J23: =IF(MROUND(IF($D$19="squat",'Max Calculator'!$E$8*H23,IF($D$19="bench",'Max Calculator'!$E$9*H23,IF($D$19="deadlift",'Max Calculator'!$E$10*H23,0))),5)=0," ",MROUND(IF($D$19="squat",'Max Calculator'!$E$8*H23,IF($D$19="bench",'Max Calculator'!$E$9*H23,IF($D$19="deadlift",'Max Calculator'!$E$10*H23,0))),5)) -> 160
B25: Week | C25: C | D25: Exercise | E25: Sets | F25: Reps | G25: Working Range | I25: Working Weights
B26: ='Max Calculator'!$E$12-28 -> 43050 | C26: C | D26: =HLOOKUP($I$9,INDIRECT($D$9),VLOOKUP(C26,'Phase Creator'!$B$8:$C$19,2,FALSE),FALSE) -> Plank | E26: 3 | F26: 20 | I26: =IF(MROUND(IF(D25="squat",'Max Calculator'!$E$8*G26,IF(D25="bench",'Max Calculator'!$E$9*G26,IF(D25="deadlift",'Max Calculator'!$E$10*G26,0))),5)=0," ",MROUND(IF(D25="squat",'Max Calculator'!$E$8*G26,IF(D25="bench",'Max Calculator'!$E$9*G26,IF(D25="deadlift",'Max Calculator'!$E$10*G26,0))),5)) | J26: =IF(MROUND(IF(D25="squat",'Max Calculator'!$E$8*H26,IF(D25="bench",'Max Calculator'!$E$9*H26,IF(D25="deadlift",'Max Calculator'!$E$10*H26,0))),5)=0," ",MROUND(IF(D25="squat",'Max Calculator'!$E$8*H26,IF(D25="bench",'Max Calculator'!$E$9*H26,IF(D25="deadlift",'Max Calculator'!$E$10*H26,0))),5))
B27: ='Max Calculator'!$E$12-21 -> 43057 | C27: C | D27: =HLOOKUP($I$9,INDIRECT($D$9),VLOOKUP(C27,'Phase Creator'!$B$8:$C$19,2,FALSE),FALSE) -> Plank | E27: 2 | F27: 30 | I27: =IF(MROUND(IF(D25="squat",'Max Calculator'!$E$8*G27,IF(D25="bench",'Max Calculator'!$E$9*G27,IF(D25="deadlift",'Max Calculator'!$E$10*G27,0))),5)=0," ",MROUND(IF(D25="squat",'Max Calculator'!$E$8*G27,IF(D25="bench",'Max Calculator'!$E$9*G27,IF(D25="deadlift",'Max Calculator'!$E$10*G27,0))),5)) | J27: =IF(MROUND(IF(D25="squat",'Max Calculator'!$E$8*H27,IF(D25="bench",'Max Calculator'!$E$9*H27,IF(D25="deadlift",'Max Calculator'!$E$10*H27,0))),5)=0," ",MROUND(IF(D25="squat",'Max Calculator'!$E$8*H27,IF(D25="bench",'Max Calculator'!$E$9*H27,IF(D25="deadlift",'Max Calculator'!$E$10*H27,0))),5))
B28: ='Max Calculator'!$E$12-14 -> 43064 | C28: C | D28: =HLOOKUP($I$9,INDIRECT($D$9),VLOOKUP(C28,'Phase Creator'!$B$8:$C$19,2,FALSE),FALSE) -> Plank | E28: 2 | F28: 30 | I28: =IF(MROUND(IF(D25="squat",'Max Calculator'!$E$8*G28,IF(D25="bench",'Max Calculator'!$E$9*G28,IF(D25="deadlift",'Max Calculator'!$E$10*G28,0))),5)=0," ",MROUND(IF(D25="squat",'Max Calculator'!$E$8*G28,IF(D25="bench",'Max Calculator'!$E$9*G28,IF(D25="deadlift",'Max Calculator'!$E$10*G28,0))),5)) | J28: =IF(MROUND(IF(D25="squat",'Max Calculator'!$E$8*H28,IF(D25="bench",'Max Calculator'!$E$9*H28,IF(D25="deadlift",'Max Calculator'!$E$10*H28,0))),5)=0," ",MROUND(IF(D25="squat",'Max Calculator'!$E$8*H28,IF(D25="bench",'Max Calculator'!$E$9*H28,IF(D25="deadlift",'Max Calculator'!$E$10*H28,0))),5))
B29: ='Max Calculator'!$E$12-7 -> 43071 | C29: C | D29: =HLOOKUP($I$9,INDIRECT($D$9),VLOOKUP(C29,'Phase Creator'!$B$8:$C$19,2,FALSE),FALSE) -> Plank | E29: 1 | F29: 30 | I29: =IF(MROUND(IF(D25="squat",'Max Calculator'!$E$8*G29,IF(D25="bench",'Max Calculator'!$E$9*G29,IF(D25="deadlift",'Max Calculator'!$E$10*G29,0))),5)=0," ",MROUND(IF(D25="squat",'Max Calculator'!$E$8*G29,IF(D25="bench",'Max Calculator'!$E$9*G29,IF(D25="deadlift",'Max Calculator'!$E$10*G29,0))),5)) | J29: =IF(MROUND(IF(D25="squat",'Max Calculator'!$E$8*H29,IF(D25="bench",'Max Calculator'!$E$9*H29,IF(D25="deadlift",'Max Calculator'!$E$10*H29,0))),5)=0," ",MROUND(IF(D25="squat",'Max Calculator'!$E$8*H29,IF(D25="bench",'Max Calculator'!$E$9*H29,IF(D25="deadlift",'Max Calculator'!$E$10*H29,0))),5))
B31: Week | C31: D | D31: Exercise | E31: Sets | F31: Reps | G31: Working Range | I31: Working Weights
B32: ='Max Calculator'!$E$12-28 -> 43050 | C32: D | D32: =HLOOKUP($I$9,INDIRECT($D$9),VLOOKUP(C32,'Phase Creator'!$B$8:$C$19,2,FALSE),FALSE) -> GHR or Back Extension | E32: 3 | F32: 15 | I32: =IF(MROUND(IF(D31="squat",'Max Calculator'!$E$8*G32,IF(D31="bench",'Max Calculator'!$E$9*G32,IF(D31="deadlift",'Max Calculator'!$E$10*G32,0))),5)=0," ",MROUND(IF(D31="squat",'Max Calculator'!$E$8*G32,IF(D31="bench",'Max Calculator'!$E$9*G32,IF(D31="deadlift",'Max Calculator'!$E$10*G32,0))),5)) | J32: =IF(MROUND(IF(D31="squat",'Max Calculator'!$E$8*H32,IF(D31="bench",'Max Calculator'!$E$9*H32,IF(D31="deadlift",'Max Calculator'!$E$10*H32,0))),5)=0," ",MROUND(IF(D31="squat",'Max Calculator'!$E$8*H32,IF(D31="bench",'Max Calculator'!$E$9*H32,IF(D31="deadlift",'Max Calculator'!$E$10*H32,0))),5))
B33: ='Max Calculator'!$E$12-21 -> 43057 | C33: D | D33: =HLOOKUP($I$9,INDIRECT($D$9),VLOOKUP(C33,'Phase Creator'!$B$8:$C$19,2,FALSE),FALSE) -> GHR or Back Extension | E33: 2 | F33: 12 | I33: =IF(MROUND(IF(D31="squat",'Max Calculator'!$E$8*G33,IF(D31="bench",'Max Calculator'!$E$9*G33,IF(D31="deadlift",'Max Calculator'!$E$10*G33,0))),5)=0," ",MROUND(IF(D31="squat",'Max Calculator'!$E$8*G33,IF(D31="bench",'Max Calculator'!$E$9*G33,IF(D31="deadlift",'Max Calculator'!$E$10*G33,0))),5)) | J33: =IF(MROUND(IF(D31="squat",'Max Calculator'!$E$8*H33,IF(D31="bench",'Max Calculator'!$E$9*H33,IF(D31="deadlift",'Max Calculator'!$E$10*H33,0))),5)=0," ",MROUND(IF(D31="squat",'Max Calculator'!$E$8*H33,IF(D31="bench",'Max Calculator'!$E$9*H33,IF(D31="deadlift",'Max Calculator'!$E$10*H33,0))),5))
B34: ='Max Calculator'!$E$12-14 -> 43064 | C34: D | D34: =HLOOKUP($I$9,INDIRECT($D$9),VLOOKUP(C34,'Phase Creator'!$B$8:$C$19,2,FALSE),FALSE) -> GHR or Back Extension | E34: 2 | F34: 8 | I34: =IF(MROUND(IF(D31="squat",'Max Calculator'!$E$8*G34,IF(D31="bench",'Max Calculator'!$E$9*G34,IF(D31="deadlift",'Max Calculator'!$E$10*G34,0))),5)=0," ",MROUND(IF(D31="squat",'Max Calculator'!$E$8*G34,IF(D31="bench",'Max Calculator'!$E$9*G34,IF(D31="deadlift",'Max Calculator'!$E$10*G34,0))),5)) | J34: =IF(MROUND(IF(D31="squat",'Max Calculator'!$E$8*H34,IF(D31="bench",'Max Calculator'!$E$9*H34,IF(D31="deadlift",'Max Calculator'!$E$10*H34,0))),5)=0," ",MROUND(IF(D31="squat",'Max Calculator'!$E$8*H34,IF(D31="bench",'Max Calculator'!$E$9*H34,IF(D31="deadlift",'Max Calculator'!$E$10*H34,0))),5))
B35: ='Max Calculator'!$E$12-7 -> 43071 | C35: D | D35: =HLOOKUP($I$9,INDIRECT($D$9),VLOOKUP(C35,'Phase Creator'!$B$8:$C$19,2,FALSE),FALSE) -> GHR or Back Extension | E35: 1 | F35: 10 | I35: =IF(MROUND(IF(D31="squat",'Max Calculator'!$E$8*G35,IF(D31="bench",'Max Calculator'!$E$9*G35,IF(D31="deadlift",'Max Calculator'!$E$10*G35,0))),5)=0," ",MROUND(IF(D31="squat",'Max Calculator'!$E$8*G35,IF(D31="bench",'Max Calculator'!$E$9*G35,IF(D31="deadlift",'Max Calculator'!$E$10*G35,0))),5)) | J35: =IF(MROUND(IF(D31="squat",'Max Calculator'!$E$8*H35,IF(D31="bench",'Max Calculator'!$E$9*H35,IF(D31="deadlift",'Max Calculator'!$E$10*H35,0))),5)=0," ",MROUND(IF(D31="squat",'Max Calculator'!$E$8*H35,IF(D31="bench",'Max Calculator'!$E$9*H35,IF(D31="deadlift",'Max Calculator'!$E$10*H35,0))),5))
B37: Week | C37: E | D37: Exercise | E37: Sets | F37: Reps | G37: Working Range | I37: Working Weights
B38: ='Max Calculator'!$E$12-28 -> 43050 | C38: E | D38: =HLOOKUP($I$9,INDIRECT($D$9),VLOOKUP(C38,'Phase Creator'!$B$8:$C$19,2,FALSE),FALSE) -> Hip Circle wall squat 3ct Pause | E38: 3 | F38: 8 | I38: =IF(MROUND(IF(D37="squat",'Max Calculator'!$E$8*G38,IF(D37="bench",'Max Calculator'!$E$9*G38,IF(D37="deadlift",'Max Calculator'!$E$10*G38,0))),5)=0," ",MROUND(IF(D37="squat",'Max Calculator'!$E$8*G38,IF(D37="bench",'Max Calculator'!$E$9*G38,IF(D37="deadlift",'Max Calculator'!$E$10*G38,0))),5)) | J38: =IF(MROUND(IF(D37="squat",'Max Calculator'!$E$8*H38,IF(D37="bench",'Max Calculator'!$E$9*H38,IF(D37="deadlift",'Max Calculator'!$E$10*H38,0))),5)=0," ",MROUND(IF(D37="squat",'Max Calculator'!$E$8*H38,IF(D37="bench",'Max Calculator'!$E$9*H38,IF(D37="deadlift",'Max Calculator'!$E$10*H38,0))),5))
B39: ='Max Calculator'!$E$12-21 -> 43057 | C39: E | D39: =HLOOKUP($I$9,INDIRECT($D$9),VLOOKUP(C39,'Phase Creator'!$B$8:$C$19,2,FALSE),FALSE) -> Hip Circle wall squat 3ct Pause | E39: 2 | F39: 10 | I39: =IF(MROUND(IF(D37="squat",'Max Calculator'!$E$8*G39,IF(D37="bench",'Max Calculator'!$E$9*G39,IF(D37="deadlift",'Max Calculator'!$E$10*G39,0))),5)=0," ",MROUND(IF(D37="squat",'Max Calculator'!$E$8*G39,IF(D37="bench",'Max Calculator'!$E$9*G39,IF(D37="deadlift",'Max Calculator'!$E$10*G39,0))),5)) | J39: =IF(MROUND(IF(D37="squat",'Max Calculator'!$E$8*H39,IF(D37="bench",'Max Calculator'!$E$9*H39,IF(D37="deadlift",'Max Calculator'!$E$10*H39,0))),5)=0," ",MROUND(IF(D37="squat",'Max Calculator'!$E$8*H39,IF(D37="bench",'Max Calculator'!$E$9*H39,IF(D37="deadlift",'Max Calculator'!$E$10*H39,0))),5))
B40: ='Max Calculator'!$E$12-14 -> 43064 | C40: E | D40: =HLOOKUP($I$9,INDIRECT($D$9),VLOOKUP(C40,'Phase Creator'!$B$8:$C$19,2,FALSE),FALSE) -> Hip Circle wall squat 3ct Pause | E40: 2 | F40: 8 | I40: =IF(MROUND(IF(D37="squat",'Max Calculator'!$E$8*G40,IF(D37="bench",'Max Calculator'!$E$9*G40,IF(D37="deadlift",'Max Calculator'!$E$10*G40,0))),5)=0," ",MROUND(IF(D37="squat",'Max Calculator'!$E$8*G40,IF(D37="bench",'Max Calculator'!$E$9*G40,IF(D37="deadlift",'Max Calculator'!$E$10*G40,0))),5)) | J40: =IF(MROUND(IF(D37="squat",'Max Calculator'!$E$8*H40,IF(D37="bench",'Max Calculator'!$E$9*H40,IF(D37="deadlift",'Max Calculator'!$E$10*H40,0))),5)=0," ",MROUND(IF(D37="squat",'Max Calculator'!$E$8*H40,IF(D37="bench",'Max Calculator'!$E$9*H40,IF(D37="deadlift",'Max Calculator'!$E$10*H40,0))),5))
B41: ='Max Calculator'!$E$12-7 -> 43071 | C41: E | D41: =HLOOKUP($I$9,INDIRECT($D$9),VLOOKUP(C41,'Phase Creator'!$B$8:$C$19,2,FALSE),FALSE) -> Hip Circle wall squat 3ct Pause | E41: 1 | F41: 12 | I41: =IF(MROUND(IF(D37="squat",'Max Calculator'!$E$8*G41,IF(D37="bench",'Max Calculator'!$E$9*G41,IF(D37="deadlift",'Max Calculator'!$E$10*G41,0))),5)=0," ",MROUND(IF(D37="squat",'Max Calculator'!$E$8*G41,IF(D37="bench",'Max Calculator'!$E$9*G41,IF(D37="deadlift",'Max Calculator'!$E$10*G41,0))),5)) | J41: =IF(MROUND(IF(D37="squat",'Max Calculator'!$E$8*H41,IF(D37="bench",'Max Calculator'!$E$9*H41,IF(D37="deadlift",'Max Calculator'!$E$10*H41,0))),5)=0," ",MROUND(IF(D37="squat",'Max Calculator'!$E$8*H41,IF(D37="bench",'Max Calculator'!$E$9*H41,IF(D37="deadlift",'Max Calculator'!$E$10*H41,0))),5))
B43: Week | C43: F | D43: Exercise | E43: Sets | F43: Reps | G43: Working Range | I43: Working Weights
B44: ='Max Calculator'!$E$12-140 -> 42938 | C44: F | D44: =HLOOKUP($I$9,INDIRECT($D$9),VLOOKUP(C44,'Phase Creator'!$B$8:$C$19,2,FALSE),FALSE) | I44: =IF(MROUND(IF(D43="squat",'Max Calculator'!$E$8*G44,IF(D43="bench",'Max Calculator'!$E$9*G44,IF(D43="deadlift",'Max Calculator'!$E$10*G44,0))),5)=0," ",MROUND(IF(D43="squat",'Max Calculator'!$E$8*G44,IF(D43="bench",'Max Calculator'!$E$9*G44,IF(D43="deadlift",'Max Calculator'!$E$10*G44,0))),5)) | J44: =IF(MROUND(IF(D43="squat",'Max Calculator'!$E$8*H44,IF(D43="bench",'Max Calculator'!$E$9*H44,IF(D43="deadlift",'Max Calculator'!$E$10*H44,0))),5)=0," ",MROUND(IF(D43="squat",'Max Calculator'!$E$8*H44,IF(D43="bench",'Max Calculator'!$E$9*H44,IF(D43="deadlift",'Max Calculator'!$E$10*H44,0))),5))
B45: ='Max Calculator'!$E$12-133 -> 42945 | C45: F | D45: =HLOOKUP($I$9,INDIRECT($D$9),VLOOKUP(C45,'Phase Creator'!$B$8:$C$19,2,FALSE),FALSE) | I45: =IF(MROUND(IF(D43="squat",'Max Calculator'!$E$8*G45,IF(D43="bench",'Max Calculator'!$E$9*G45,IF(D43="deadlift",'Max Calculator'!$E$10*G45,0))),5)=0," ",MROUND(IF(D43="squat",'Max Calculator'!$E$8*G45,IF(D43="bench",'Max Calculator'!$E$9*G45,IF(D43="deadlift",'Max Calculator'!$E$10*G45,0))),5)) | J45: =IF(MROUND(IF(D43="squat",'Max Calculator'!$E$8*H45,IF(D43="bench",'Max Calculator'!$E$9*H45,IF(D43="deadlift",'Max Calculator'!$E$10*H45,0))),5)=0," ",MROUND(IF(D43="squat",'Max Calculator'!$E$8*H45,IF(D43="bench",'Max Calculator'!$E$9*H45,IF(D43="deadlift",'Max Calculator'!$E$10*H45,0))),5))
B46: ='Max Calculator'!$E$12-126 -> 42952 | C46: F | D46: =HLOOKUP($I$9,INDIRECT($D$9),VLOOKUP(C46,'Phase Creator'!$B$8:$C$19,2,FALSE),FALSE) | I46: =IF(MROUND(IF(D43="squat",'Max Calculator'!$E$8*G46,IF(D43="bench",'Max Calculator'!$E$9*G46,IF(D43="deadlift",'Max Calculator'!$E$10*G46,0))),5)=0," ",MROUND(IF(D43="squat",'Max Calculator'!$E$8*G46,IF(D43="bench",'Max Calculator'!$E$9*G46,IF(D43="deadlift",'Max Calculator'!$E$10*G46,0))),5)) | J46: =IF(MROUND(IF(D43="squat",'Max Calculator'!$E$8*H46,IF(D43="bench",'Max Calculator'!$E$9*H46,IF(D43="deadlift",'Max Calculator'!$E$10*H46,0))),5)=0," ",MROUND(IF(D43="squat",'Max Calculator'!$E$8*H46,IF(D43="bench",'Max Calculator'!$E$9*H46,IF(D43="deadlift",'Max Calculator'!$E$10*H46,0))),5))
B47: ='Max Calculator'!$E$12-119 -> 42959 | C47: F | D47: =HLOOKUP($I$9,INDIRECT($D$9),VLOOKUP(C47,'Phase Creator'!$B$8:$C$19,2,FALSE),FALSE) | I47: =IF(MROUND(IF(D43="squat",'Max Calculator'!$E$8*G47,IF(D43="bench",'Max Calculator'!$E$9*G47,IF(D43="deadlift",'Max Calculator'!$E$10*G47,0))),5)=0," ",MROUND(IF(D43="squat",'Max Calculator'!$E$8*G47,IF(D43="bench",'Max Calculator'!$E$9*G47,IF(D43="deadlift",'Max Calculator'!$E$10*G47,0))),5)) | J47: =IF(MROUND(IF(D43="squat",'Max Calculator'!$E$8*H47,IF(D43="bench",'Max Calculator'!$E$9*H47,IF(D43="deadlift",'Max Calculator'!$E$10*H47,0))),5)=0," ",MROUND(IF(D43="squat",'Max Calculator'!$E$8*H47,IF(D43="bench",'Max Calculator'!$E$9*H47,IF(D43="deadlift",'Max Calculator'!$E$10*H47,0))),5))
D56: =D9 -> Peaking | H56: Day | I56: 2
B60: Week | C60: A | D60: Bench | E60: Sets | F60: Reps | G60: Working Range | I60: Working Weights
B61: ='Max Calculator'!$E$12-28 -> 43050 | C61: A1 | D61: =HLOOKUP($I$56,INDIRECT($D$9),VLOOKUP(C61,'Phase Creator'!$B$8:$C$19,2,FALSE),FALSE) -> Bench w/ Bands | E61: 6 | F61: 2 | G61: 0.5 | H61: 0.7 | I61: =IF(MROUND(IF(D60="squat",'Max Calculator'!$E$8*G61,IF(D60="bench",'Max Calculator'!$E$9*G61,IF(D60="deadlift",'Max Calculator'!$E$10*G61,0))),5)=0," ",MROUND(IF(D60="squat",'Max Calculator'!$E$8*G61,IF(D60="bench",'Max Calculator'!$E$9*G61,IF(D60="deadlift",'Max Calculator'!$E$10*G61,0))),5)) -> 115 | J61: =IF(MROUND(IF(D60="squat",'Max Calculator'!$E$8*H61,IF(D60="bench",'Max Calculator'!$E$9*H61,IF(D60="deadlift",'Max Calculator'!$E$10*H61,0))),5)=0," ",MROUND(IF(D60="squat",'Max Calculator'!$E$8*H61,IF(D60="bench",'Max Calculator'!$E$9*H61,IF(D60="deadlift",'Max Calculator'!$E$10*H61,0))),5)) -> 160
B62: ='Max Calculator'!$E$12-21 -> 43057 | C62: A2 | D62: =HLOOKUP($I$56,INDIRECT($D$9),VLOOKUP(C62,'Phase Creator'!$B$8:$C$19,2,FALSE),FALSE) -> SlingShot Bench | E62: 1 | F62: 3 | H62: 1 | I62: =IF(MROUND(IF(D60="squat",'Max Calculator'!$E$8*G62,IF(D60="bench",'Max Calculator'!$E$9*G62,IF(D60="deadlift",'Max Calculator'!$E$10*G62,0))),5)=0," ",MROUND(IF(D60="squat",'Max Calculator'!$E$8*G62,IF(D60="bench",'Max Calculator'!$E$9*G62,IF(D60="deadlift",'Max Calculator'!$E$10*G62,0))),5)) | J62: =IF(MROUND(IF(D60="squat",'Max Calculator'!$E$8*H62,IF(D60="bench",'Max Calculator'!$E$9*H62,IF(D60="deadlift",'Max Calculator'!$E$10*H62,0))),5)=0," ",MROUND(IF(D60="squat",'Max Calculator'!$E$8*H62,IF(D60="bench",'Max Calculator'!$E$9*H62,IF(D60="deadlift",'Max Calculator'!$E$10*H62,0))),5)) -> 225
B63: ='Max Calculator'!$E$12-14 -> 43064 | C63: A3 | D63: =HLOOKUP($I$56,INDIRECT($D$9),VLOOKUP(C63,'Phase Creator'!$B$8:$C$19,2,FALSE),FALSE) -> Competition Bench Press | E63: 1 | F63: 1 | H63: 1 | I63: =IF(MROUND(IF(D60="squat",'Max Calculator'!$E$8*G63,IF(D60="bench",'Max Calculator'!$E$9*G63,IF(D60="deadlift",'Max Calculator'!$E$10*G63,0))),5)=0," ",MROUND(IF(D60="squat",'Max Calculator'!$E$8*G63,IF(D60="bench",'Max Calculator'!$E$9*G63,IF(D60="deadlift",'Max Calculator'!$E$10*G63,0))),5)) | J63: =IF(MROUND(IF(D60="squat",'Max Calculator'!$E$8*H63,IF(D60="bench",'Max Calculator'!$E$9*H63,IF(D60="deadlift",'Max Calculator'!$E$10*H63,0))),5)=0," ",MROUND(IF(D60="squat",'Max Calculator'!$E$8*H63,IF(D60="bench",'Max Calculator'!$E$9*H63,IF(D60="deadlift",'Max Calculator'!$E$10*H63,0))),5)) -> 225
B64: ='Max Calculator'!$E$12-7 -> 43071 | C64: A4 | D64: =HLOOKUP($I$56,INDIRECT($D$9),VLOOKUP(C64,'Phase Creator'!$B$8:$C$19,2,FALSE),FALSE) -> Competition Bench Press | E64: 1 | F64: 1 | H64: 0.9 | I64: =IF(MROUND(IF(D60="squat",'Max Calculator'!$E$8*G64,IF(D60="bench",'Max Calculator'!$E$9*G64,IF(D60="deadlift",'Max Calculator'!$E$10*G64,0))),5)=0," ",MROUND(IF(D60="squat",'Max Calculator'!$E$8*G64,IF(D60="bench",'Max Calculator'!$E$9*G64,IF(D60="deadlift",'Max Calculator'!$E$10*G64,0))),5)) | J64: =IF(MROUND(IF(D60="squat",'Max Calculator'!$E$8*H64,IF(D60="bench",'Max Calculator'!$E$9*H64,IF(D60="deadlift",'Max Calculator'!$E$10*H64,0))),5)=0," ",MROUND(IF(D60="squat",'Max Calculator'!$E$8*H64,IF(D60="bench",'Max Calculator'!$E$9*H64,IF(D60="deadlift",'Max Calculator'!$E$10*H64,0))),5)) -> 205
