Workbook

Sheet Max
A1: WWW.RUTINADEBIBLIOTECAS.COM
A2: Introduce 1RM: | Z2: Made by ChaseT 2008.05.09
A3: Sentadilals | B3: 100 | D3: Sheiko Intermedios Large Load
A4: Press de banca | B4: 100
A5: Peso muerto | B5: 100
H17: Que programa usar
H18: Large load: | J18: Menos de 80kg
H20: Medium load: | J20: Más de 80kg
H22: Small load: | J22: Más de 110kg

Sheet #37
B1: Sheiko
B2: Bloque de preparacion 1 (4 semanas)
A5: semana 1 | M5: squat | R5: bench | W5: deadlift | AC5: semana 2 | AJ5: semana 3 | AQ5: semana 4
A6: dia 1 Lunes | C6: % | D6: reps | E6: sets | F6: peso | M6: 50-59 | N6: 60-69 | O6: 70-79 | P6: 80-89 | Q6: 90+ | R6: 50-59 | S6: 60-69 | T6: 70-79 | U6: 80-89 | V6: 90+ | W6: 50-59 | X6: 60-69 | Y6: 70-79 | Z6: 80-89 | AA6: 90+ | AC6: dia 1 lunes | AE6: % | AF6: reps | AG6: sets | AH6: peso | AJ6: dia 1 lunes | AL6: % | AM6: reps | AN6: sets | AO6: peso | AQ6: dia 1 lunes | AS6: % | AT6: reps | AU6: sets | AV6: peso
A7: 1 | B7: Press de banca | C7: 0.5 | D7: 5 | E7: 1 | F7: =Max!$B$4*C7 -> 50 | I7: =D7*E7 -> 5 | J7: =F7*I7 -> 250 | R7: =I7 -> 5 | S7: =I8 -> 8 | T7: =I9+I10 -> 21 | U7: 0 | V7: 0 | AC7: 1 | AD7: Sentadillas | AE7: 0.5 | AF7: 5 | AG7: 1 | AH7: =Max!$B$3*AE7 -> 50 | AJ7: 1 | AK7: Sentadillas | AL7: 0.5 | AM7: 5 | AN7: 1 | AO7: =Max!$B$3*AL7 -> 50 | AQ7: 1 | AR7: Sentadillas | AS7: 0.5 | AT7: 5 | AU7: 1 | AV7: =Max!$B$3*AS7 -> 50
C8: 0.6 | D8: 4 | E8: 2 | F8: =Max!$B$4*C8 -> 60 | I8: =D8*E8 -> 8 | J8: =F8*I8 -> 480 | AE8: 0.6 | AF8: 4 | AG8: 2 | AH8: =Max!$B$3*AE8 -> 60 | AL8: 0.6 | AM8: 4 | AN8: 2 | AO8: =Max!$B$3*AL8 -> 60 | AS8: 0.6 | AT8: 4 | AU8: 1 | AV8: =Max!$B$3*AS8 -> 60
C9: 0.7 | D9: 3 | E9: 2 | F9: =Max!$B$4*C9 -> 70 | I9: =D9*E9 -> 6 | J9: =F9*I9 -> 420 | AE9: 0.7 | AF9: 3 | AG9: 2 | AH9: =Max!$B$3*AE9 -> 70 | AL9: 0.7 | AM9: 3 | AN9: 2 | AO9: =Max!$B$3*AL9 -> 70 | AS9: 0.7 | AT9: 3 | AU9: 2 | AV9: =Max!$B$3*AS9 -> 70
C10: 0.75 | D10: 3 | E10: 5 | F10: =Max!$B$4*C10 -> 75 | I10: =D10*E10 -> 15 | J10: =F10*I10 -> 1125 | AE10: 0.8 | AF10: 2 | AG10: 5 | AH10: =Max!$B$3*AE10 -> 80 | AL10: 0.8 | AM10: 3 | AN10: 5 | AO10: =Max!$B$3*AL10 -> 80 | AS10: 0.8 | AT10: 3 | AU10: 2 | AV10: =Max!$B$3*AS10 -> 80
A11: 2 | B11: Sentadilla | C11: 0.5 | D11: 5 | E11: 1 | F11: =Max!$B$3*C11 -> 50 | G11: =D11*E11 -> 5 | H11: =F11*G11 -> 250 | M11: =G11 -> 5 | N11: =G12 -> 10 | O11: =G13 -> 25 | P11: 0 | Q11: 0 | AC11: 2 | AD11: Press de banca | AE11: 0.5 | AF11: 5 | AG11: 1 | AH11: =Max!$B$4*AE11 -> 50 | AJ11: 2 | AK11: Press de banca | AL11: 0.5 | AM11: 5 | AN11: 1 | AO11: =Max!$B$4*AL11 -> 50 | AS11: 0.85 | AT11: 2 | AU11: 3 | AV11: =Max!$B$3*AS11 -> 85
C12: 0.6 | D12: 5 | E12: 2 | F12: =Max!$B$3*C12 -> 60 | G12: =D12*E12 -> 10 | H12: =F12*G12 -> 600 | AE12: 0.6 | AF12: 4 | AG12: 1 | AH12: =Max!$B$4*AE12 -> 60 | AL12: 0.6 | AM12: 4 | AN12: 1 | AO12: =Max!$B$4*AL12 -> 60 | AQ12: 2 | AR12: Press de banca | AS12: 0.5 | AT12: 5 | AU12: 1 | AV12: =Max!$B$4*AS12 -> 50
C13: 0.7 | D13: 5 | E13: 5 | F13: =Max!$B$3*C13 -> 70 | G13: =D13*E13 -> 25 | H13: =F13*G13 -> 1750 | AE13: 0.7 | AF13: 3 | AG13: 2 | AH13: =Max!$B$4*AE13 -> 70 | AL13: 0.7 | AM13: 3 | AN13: 2 | AO13: =Max!$B$4*AL13 -> 70 | AS13: 0.6 | AT13: 4 | AU13: 1 | AV13: =Max!$B$4*AS13 -> 60
A14: 4 | B14: Press de banca | C14: 0.5 | D14: 6 | E14: 1 | F14: =Max!$B$4*C14 -> 50 | I14: =D14*E14 -> 6 | J14: =F14*I14 -> 300 | R14: =I14 -> 6 | S14: =I15 -> 12 | T14: =I16 -> 24 | U14: 0 | V14: 0 | AE14: 0.8 | AF14: 2 | AG14: 6 | AH14: =Max!$B$4*AE14 -> 80 | AL14: 0.8 | AM14: 3 | AN14: 5 | AO14: =Max!$B$4*AL14 -> 80 | AS14: 0.7 | AT14: 3 | AU14: 2 | AV14: =Max!$B$4*AS14 -> 70
C15: 0.6 | D15: 6 | E15: 2 | F15: =Max!$B$4*C15 -> 60 | I15: =D15*E15 -> 12 | J15: =F15*I15 -> 720 | AC15: 3 | AD15: Flys con mancuernas | AF15: 10 | AG15: 5 | AJ15: 3 | AK15: Flys con mancuernas | AM15: 10 | AN15: 5 | AS15: 0.8 | AT15: 3 | AU15: 5 | AV15: =Max!$B$4*AS15 -> 80
C16: 0.65 | D16: 6 | E16: 4 | F16: =Max!$B$4*C16 -> 65 | I16: =D16*E16 -> 24 | J16: =F16*I16 -> 1560 | AC16: 4 | AD16: Flexiones lastradas | AF16: 10 | AG16: 5 | AJ16: 4 | AK16: Flexiones lastradas | AM16: 10 | AN16: 5 | AQ16: 3 | AR16: Flys con mancuernas | AT16: 10 | AU16: 5
A17: 3 | B17: Flys con mancuerna | D17: 10 | E17: 5 | AC17: 5 | AD17: Sentadillas | AE17: 0.55 | AF17: 3 | AG17: 1 | AH17: =Max!$B$3*AE17 -> 55 | AJ17: 5 | AK17: Sentadillas | AL17: 0.5 | AM17: 5 | AN17: 1 | AO17: =Max!$B$3*AL17 -> 50 | AQ17: 4 | AR17: Fondos | AT17: 8 | AU17: 5
A18: 5 | B18: Buenos dias | D18: 5 | E18: 5 | AE18: 0.65 | AF18: 3 | AG18: 1 | AH18: =Max!$B$3*AE18 -> 65 | AL18: 0.6 | AM18: 5 | AN18: 1 | AO18: =Max!$B$3*AL18 -> 60 | AQ18: 5 | AR18: Sentadillas | AS18: 0.5 | AT18: 5 | AU18: 1 | AV18: =Max!$B$3*AS18 -> 50
AE19: 0.75 | AF19: 3 | AG19: 4 | AH19: =Max!$B$3*AE19 -> 75 | AL19: 0.7 | AM19: 5 | AN19: 5 | AO19: =Max!$B$3*AL19 -> 70 | AS19: 0.6 | AT19: 4 | AU19: 1 | AV19: =Max!$B$3*AS19 -> 60
A20: dia 3 miercoles | C20: % | D20: reps | E20: sets | F20: weight | AC20: 6 | AD20: Buenos dias | AF20: 5 | AG20: 5 | AJ20: 6 | AK20: Abs | AM20: 10 | AN20: 3 | AS20: 0.7 | AT20: 3 | AU20: 2 | AV20: =Max!$B$3*AS20 -> 70
A21: 1 | B21: Peso muerto | C21: 0.5 | D21: 5 | E21: 1 | F21: =Max!$B$5*C21 -> 50 | K21: =D21*E21 -> 5 | L21: =F21*K21 -> 250 | W21: =K21 -> 5 | X21: =K22 -> 10 | Y21: =K23+K24 -> 20 | Z21: 0 | AA21: 0 | AS21: 0.8 | AT21: 2 | AU21: 4 | AV21: =Max!$B$3*AS21 -> 80
C22: 0.6 | D22: 5 | E22: 2 | F22: =Max!$B$5*C22 -> 60 | K22: =D22*E22 -> 10 | L22: =F22*K22 -> 600 | AC22: dia 3 miercoles | AE22: % | AF22: reps | AG22: sets | AH22: weight | AJ22: dia 3 miercoles | AL22: % | AM22: reps | AN22: sets | AO22: weight | AQ22: 6 | AR22: Buenos dias | AT22: 5 | AU22: 5
C23: 0.7 | D23: 4 | E23: 2 | F23: =Max!$B$5*C23 -> 70 | K23: =D23*E23 -> 8 | L23: =F23*K23 -> 560 | AC23: 1 | AD23: Peso muerto a las rodillas | AE23: 0.5 | AF23: 4 | AG23: 1 | AH23: =Max!$B$5*AE23 -> 50 | AJ23: 1 | AK23: Peso muerto a las rodillas | AL23: 0.5 | AM23: 4 | AN23: 1 | AO23: =Max!$B$5*AL23 -> 50
C24: 0.75 | D24: 3 | E24: 4 | F24: =Max!$B$5*C24 -> 75 | K24: =D24*E24 -> 12 | L24: =F24*K24 -> 900 | AE24: 0.6 | AF24: 4 | AG24: 2 | AH24: =Max!$B$5*AE24 -> 60 | AL24: 0.6 | AM24: 4 | AN24: 1 | AO24: =Max!$B$5*AL24 -> 60 | AQ24: dia 3 miercoles | AS24: % | AT24: reps | AU24: sets | AV24: weight
A25: 2 | B25: Press de banca inclinado | D25: 4 | E25: 6 | AE25: 0.7 | AF25: 4 | AG25: 4 | AH25: =Max!$B$5*AE25 -> 70 | AL25: 0.7 | AM25: 4 | AN25: 2 | AO25: =Max!$B$5*AL25 -> 70 | AQ25: 1 | AR25: Press de banca | AS25: 0.5 | AT25: 5 | AU25: 1 | AV25: =Max!$B$4*AS25 -> 50
A26: 3 | B26: Fondos | D26: 5 | E26: 5 | AC26: 2 | AD26: Press de banca | AE26: 0.5 | AF26: 5 | AG26: 1 | AH26: =Max!$B$4*AE26 -> 50 | AL26: 0.75 | AM26: 4 | AN26: 4 | AO26: =Max!$B$5*AL26 -> 75 | AS26: 0.6 | AT26: 4 | AU26: 1 | AV26: =Max!$B$4*AS26 -> 60
A27: 4 | B27: Peso muerto en cajas | C27: 0.5 | D27: 5 | E27: 1 | F27: =Max!$B$5*C27 -> 50 | K27: =D27*E27 -> 5 | L27: =F27*K27 -> 250 | W27: =K27 -> 5 | X27: =K28 -> 10 | Y27: =K29 -> 8 | Z27: =K30 -> 12 | AA27: 0 | AE27: 0.6 | AF27: 5 | AG27: 2 | AH27: =Max!$B$4*AE27 -> 60 | AJ27: 2 | AK27: Press de banca | AL27: 0.5 | AM27: 6 | AN27: 1 | AO27: =Max!$B$4*AL27 -> 50 | AS27: 0.7 | AT27: 3 | AU27: 2 | AV27: =Max!$B$4*AS27 -> 70
C28: 0.6 | D28: 5 | E28: 2 | F28: =Max!$B$5*C28 -> 60 | K28: =D28*E28 -> 10 | L28: =F28*K28 -> 600 | AE28: 0.7 | AF28: 4 | AG28: 5 | AH28: =Max!$B$4*AE28 -> 70 | AL28: 0.6 | AM28: 5 | AN28: 1 | AO28: =Max!$B$4*AL28 -> 60 | AS28: 0.8 | AT28: 3 | AU28: 2 | AV28: =Max!$B$4*AS28 -> 80
C29: 0.7 | D29: 4 | E29: 2 | F29: =Max!$B$5*C29 -> 70 | K29: =D29*E29 -> 8 | L29: =F29*K29 -> 560 | AC29: 3 | AD29: Flys con mancuernas | AF29: 10 | AG29: 5 | AL29: 0.7 | AM29: 4 | AN29: 2 | AO29: =Max!$B$4*AL29 -> 70 | AS29: 0.85 | AT29: 2 | AU29: 3 | AV29: =Max!$B$4*AS29 -> 85
C30: 0.8 | D30: 3 | E30: 4 | F30: =Max!$B$5*C30 -> 80 | K30: =D30*E30 -> 12 | L30: =F30*K30 -> 960 | AC30: 4 | AD30: Peso muerto | AE30: 0.5 | AF30: 4 | AG30: 1 | AH30: =Max!$B$5*AE30 -> 50 | AL30: 0.75 | AM30: 3 | AN30: 2 | AO30: =Max!$B$4*AL30 -> 75 | AQ30: 2 | AR30: Peso muerto | AS30: 0.5 | AT30: 4 | AU30: 1 | AV30: =Max!$B$5*AS30 -> 50
A31: 5 | B31: Zancadas | D31: 5 | E31: 5 | AE31: 0.6 | AF31: 4 | AG31: 1 | AH31: =Max!$B$5*AE31 -> 60 | AL31: 0.8 | AM31: 2 | AN31: 2 | AO31: =Max!$B$4*AL31 -> 80 | AS31: 0.6 | AT31: 4 | AU31: 1 | AV31: =Max!$B$5*AS31 -> 60
A32: 6 | B32: Abs | D32: 10 | E32: 3 | AE32: 0.7 | AF32: 3 | AG32: 2 | AH32: =Max!$B$5*AE32 -> 70 | AL32: 0.75 | AM32: 3 | AN32: 2 | AO32: =Max!$B$4*AL32 -> 75 | AS32: 0.7 | AT32: 3 | AU32: 2 | AV32: =Max!$B$5*AS32 -> 70
AE33: 0.75 | AF33: 3 | AG33: 5 | AH33: =Max!$B$5*AE33 -> 75 | AL33: 0.7 | AM33: 4 | AN33: 1 | AO33: =Max!$B$4*AL33 -> 70 | AS33: 0.8 | AT33: 3 | AU33: 2 | AV33: =Max!$B$5*AS33 -> 80
A34: dia 5 viernes | C34: % | D34: reps | E34: sets | F34: weight | AC34: 5 | AD34: Zancadas | AF34: 5 | AG34: 5 | AL34: 0.65 | AM34: 5 | AN34: 1 | AO34: =Max!$B$4*AL34 -> 65 | AS34: 0.85 | AT34: 2 | AU34: 3 | AV34: =Max!$B$5*AS34 -> 85
A35: 1 | B35: Press de banca | C35: 0.5 | D35: 7 | E35: 1 | F35: =Max!$B$4*C35 -> 50 | I35: =D35*E35 -> 7 | J35: =F35*I35 -> 350 | R35: =I35+I36+I44+I45 -> 31 | S35: =I37+I38+I42+I43 -> 19 | T35: =I39+I40+I41 -> 16 | U35: 0 | V35: 0 | AL35: 0.6 | AM35: 6 | AN35: 1 | AO35: =Max!$B$4*AL35 -> 60 | AQ35: 3 | AR35: Press de banca | AS35: 0.55 | AT35: 5 | AU35: 1 | AV35: =Max!$B$4*AS35 -> 55
C36: 0.55 | D36: 6 | E36: 1 | F36: =Max!$B$4*C36 -> 55 | I36: =D36*E36 -> 6 | J36: =F36*I36 -> 330 | AC36: dia 5 viernes | AE36: % | AF36: reps | AG36: sets | AH36: weight | AL36: 0.55 | AM36: 7 | AN36: 1 | AO36: =Max!$B$4*AL36 -> 55 | AS36: 0.65 | AT36: 5 | AU36: 1 | AV36: =Max!$B$4*AS36 -> 65
C37: 0.6 | D37: 5 | E37: 1 | F37: =Max!$B$4*C37 -> 60 | I37: =D37*E37 -> 5 | J37: =F37*I37 -> 300 | AC37: 1 | AD37: Sentadillas | AE37: 0.5 | AF37: 4 | AG37: 1 | AH37: =Max!$B$3*AE37 -> 50 | AL37: 0.5 | AM37: 8 | AN37: 1 | AO37: =Max!$B$4*AL37 -> 50 | AS37: 0.75 | AT37: 4 | AU37: 4 | AV37: =Max!$B$4*AS37 -> 75
C38: 0.65 | D38: 4 | E38: 1 | F38: =Max!$B$4*C38 -> 65 | I38: =D38*E38 -> 4 | J38: =F38*I38 -> 260 | AE38: 0.6 | AF38: 4 | AG38: 1 | AH38: =Max!$B$3*AE38 -> 60 | AJ38: 3 | AK38: Flys con mancuernas | AM38: 10 | AN38: 5 | AQ38: 4 | AR38: Flys con mancuernas | AT38: 10 | AU38: 5
C39: 0.7 | D39: 3 | E39: 2 | F39: =Max!$B$4*C39 -> 70 | I39: =D39*E39 -> 6 | J39: =F39*I39 -> 420 | AE39: 0.7 | AF39: 3 | AG39: 2 | AH39: =Max!$B$3*AE39 -> 70 | AJ39: 4 | AK39: Peso muerto en cajas | AL39: 0.6 | AM39: 5 | AN39: 1 | AO39: =Max!$B$5*AL39 -> 60 | AQ39: 5 | AR39: Zancadas | AT39: 5 | AU39: 5
C40: 0.75 | D40: 2 | E40: 2 | F40: =Max!$B$4*C40 -> 75 | I40: =D40*E40 -> 4 | J40: =F40*I40 -> 300 | AE40: 0.75 | AF40: 3 | AG40: 6 | AH40: =Max!$B$3*AE40 -> 75 | AL40: 0.7 | AM40: 5 | AN40: 2 | AO40: =Max!$B$5*AL40 -> 70
C41: 0.7 | D41: 3 | E41: 2 | F41: =Max!$B$4*C41 -> 70 | I41: =D41*E41 -> 6 | J41: =F41*I41 -> 420 | AC41: 2 | AD41: Press de banca | AE41: 0.5 | AF41: 6 | AG41: 1 | AH41: =Max!$B$4*AE41 -> 50 | AL41: 0.8 | AM41: 4 | AN41: 4 | AO41: =Max!$B$5*AL41 -> 80 | AQ41: dia 5 viernes | AS41: % | AT41: reps | AU41: sets | AV41: weight
C42: 0.65 | D42: 4 | E42: 1 | F42: =Max!$B$4*C42 -> 65 | I42: =D42*E42 -> 4 | J42: =F42*I42 -> 260 | AE42: 0.6 | AF42: 5 | AG42: 1 | AH42: =Max!$B$4*AE42 -> 60 | AJ42: 5 | AK42: Zancadas | AM42: 5 | AN42: 5 | AQ42: 1 | AR42: Sentadillas | AS42: 0.5 | AT42: 5 | AU42: 1 | AV42: =Max!$B$3*AS42 -> 50
...

Sheet #30
B1: Sheiko
B2: Bloque preparacion 2 (4 Semanas)
A5: semana 1 | M5: squat | R5: bench | W5: deadlift | AC5: semana 2 | AJ5: semana 3 | AQ5: semana 4
A6: dia 1 lunes | C6: % | D6: reps | E6: sets | F6: peso | M6: 50-59 | N6: 60-69 | O6: 70-79 | P6: 80-89 | Q6: 90+ | R6: 50-59 | S6: 60-69 | T6: 70-79 | U6: 80-89 | V6: 90+ | W6: 50-59 | X6: 60-69 | Y6: 70-79 | Z6: 80-89 | AA6: 90+ | AC6: dia 1 lunes | AE6: % | AF6: reps | AG6: sets | AH6: peso | AJ6: dia 1 lunes | AL6: % | AM6: reps | AN6: sets | AO6: peso | AQ6: dia 1 lunes | AS6: % | AT6: reps | AU6: sets | AV6: peso
A7: 1 | B7: Press de banca | C7: 0.5 | D7: 5 | E7: 1 | F7: =Max!$B$4*C7 -> 50 | I7: =D7*E7 -> 5 | J7: =F7*I7 -> 250 | R7: =I7 -> 5 | S7: =I8 -> 4 | T7: =I9 -> 3 | U7: =I10 -> 15 | AC7: 1 | AD7: Sentadillas | AE7: 0.5 | AF7: 5 | AG7: 1 | AH7: =Max!$B$3*AE7 -> 50 | AJ7: 1 | AK7: Sentadillas | AL7: 0.5 | AM7: 5 | AN7: 1 | AO7: =Max!$B$3*AL7 -> 50 | AQ7: 1 | AR7: Sentadillas | AS7: 0.5 | AT7: 5 | AU7: 1 | AV7: =Max!$B$3*AS7 -> 50
C8: 0.6 | D8: 4 | E8: 1 | F8: =Max!$B$4*C8 -> 60 | I8: =D8*E8 -> 4 | J8: =F8*I8 -> 240 | AE8: 0.6 | AF8: 4 | AG8: 2 | AH8: =Max!$B$3*AE8 -> 60 | AL8: 0.6 | AM8: 4 | AN8: 2 | AO8: =Max!$B$3*AL8 -> 60 | AS8: 0.6 | AT8: 4 | AU8: 1 | AV8: =Max!$B$3*AS8 -> 60
C9: 0.7 | D9: 3 | E9: 1 | F9: =Max!$B$4*C9 -> 70 | I9: =D9*E9 -> 3 | J9: =F9*I9 -> 210 | AE9: 0.7 | AF9: 3 | AG9: 2 | AH9: =Max!$B$3*AE9 -> 70 | AL9: 0.7 | AM9: 3 | AN9: 2 | AO9: =Max!$B$3*AL9 -> 70 | AS9: 0.7 | AT9: 3 | AU9: 2 | AV9: =Max!$B$3*AS9 -> 70
C10: 0.8 | D10: 3 | E10: 5 | F10: =Max!$B$4*C10 -> 80 | I10: =D10*E10 -> 15 | J10: =F10*I10 -> 1200 | AE10: 0.8 | AF10: 2 | AG10: 2 | AH10: =Max!$B$3*AE10 -> 80 | AL10: 0.8 | AM10: 3 | AN10: 5 | AO10: =Max!$B$3*AL10 -> 80 | AS10: 0.8 | AT10: 3 | AU10: 2 | AV10: =Max!$B$3*AS10 -> 80
A11: 2 | B11: Sentadillas | C11: 0.5 | D11: 5 | E11: 1 | F11: =Max!$B$3*C11 -> 50 | G11: =D11*E11 -> 5 | H11: =F11*G11 -> 250 | M11: =G11 -> 5 | N11: =G12 -> 4 | O11: =G13 -> 6 | P11: =G14 -> 15 | AE11: 0.9 | AF11: 1 | AG11: 3 | AH11: =Max!$B$3*AE11 -> 90 | AJ11: 2 | AK11: Press de banca | AL11: 0.5 | AM11: 5 | AN11: 1 | AO11: =Max!$B$4*AL11 -> 50 | AS11: 0.85 | AT11: 2 | AU11: 2 | AV11: =Max!$B$3*AS11 -> 85
C12: 0.6 | D12: 4 | E12: 1 | F12: =Max!$B$3*C12 -> 60 | G12: =D12*E12 -> 4 | H12: =F12*G12 -> 240 | AC12: 2 | AD12: Press de banca | AE12: 0.5 | AF12: 5 | AG12: 1 | AH12: =Max!$B$4*AE12 -> 50 | AL12: 0.6 | AM12: 4 | AN12: 1 | AO12: =Max!$B$4*AL12 -> 60 | AS12: 0.9 | AT12: 1 | AU12: 2 | AV12: =Max!$B$3*AS12 -> 90
C13: 0.7 | D13: 3 | E13: 2 | F13: =Max!$B$3*C13 -> 70 | G13: =D13*E13 -> 6 | H13: =F13*G13 -> 420 | AE13: 0.6 | AF13: 4 | AG13: 1 | AH13: =Max!$B$4*AE13 -> 60 | AL13: 0.7 | AM13: 3 | AN13: 1 | AO13: =Max!$B$4*AL13 -> 70 | AQ13: 2 | AR13: Press de banca | AS13: 0.5 | AT13: 5 | AU13: 1 | AV13: =Max!$B$4*AS13 -> 50
C14: 0.8 | D14: 3 | E14: 5 | F14: =Max!$B$3*C14 -> 80 | G14: =D14*E14 -> 15 | H14: =F14*G14 -> 1200 | AE14: 0.7 | AF14: 3 | AG14: 1 | AH14: =Max!$B$4*AE14 -> 70 | AL14: 0.8 | AM14: 3 | AN14: 2 | AO14: =Max!$B$4*AL14 -> 80 | AS14: 0.6 | AT14: 4 | AU14: 1 | AV14: =Max!$B$4*AS14 -> 60
A15: 3 | B15: Press de banca estrecho | C15: 0.5 | D15: 3 | E15: 1 | F15: =Max!$B$4*C15 -> 50 | I15: =D15*E15 -> 3 | J15: =F15*I15 -> 150 | R15: =I15 -> 3 | S15: =I16 -> 3 | T15: =I17 -> 12 | AE15: 0.8 | AF15: 3 | AG15: 5 | AH15: =Max!$B$4*AE15 -> 80 | AL15: 0.85 | AM15: 2 | AN15: 3 | AO15: =Max!$B$4*AL15 -> 85 | AS15: 0.7 | AT15: 3 | AU15: 1 | AV15: =Max!$B$4*AS15 -> 70
C16: 0.6 | D16: 3 | E16: 1 | F16: =Max!$B$4*C16 -> 60 | I16: =D16*E16 -> 3 | J16: =F16*I16 -> 180 | AC16: 3 | AD16: Flys con mancuernas | AF16: 10 | AG16: 5 | AL16: 0.8 | AM16: 3 | AN16: 2 | AO16: =Max!$B$4*AL16 -> 80 | AS16: 0.8 | AT16: 2 | AU16: 5 | AV16: =Max!$B$4*AS16 -> 80
C17: 0.7 | D17: 3 | E17: 4 | F17: =Max!$B$4*C17 -> 70 | I17: =D17*E17 -> 12 | J17: =F17*I17 -> 840 | AC17: 4 | AD17: Flexiones | AF17: 10 | AG17: 5 | AJ17: 3 | AK17: Sentadillas | AL17: 0.5 | AM17: 6 | AN17: 1 | AO17: =Max!$B$3*AL17 -> 50 | AQ17: 3 | AR17: Flys con mancuernas | AT17: 10 | AU17: 5
A18: 4 | B18: Flys con mancuernas | D18: 10 | E18: 5 | AC18: 5 | AD18: Sentadilals | AE18: 0.5 | AF18: 5 | AG18: 1 | AH18: =Max!$B$3*AE18 -> 50 | AL18: 0.6 | AM18: 6 | AN18: 1 | AO18: =Max!$B$3*AL18 -> 60 | AQ18: 4 | AR18: Fondos | AT18: 8 | AU18: 5
A19: 5 | B19: Sentadillas | C19: 0.55 | D19: 5 | E19: 1 | F19: =Max!$B$3*C19 -> 55 | G19: =D19*E19 -> 5 | H19: =F19*G19 -> 275 | M19: =G19 -> 5 | N19: =G20 -> 4 | O19: =G21 -> 15 | AE19: 0.6 | AF19: 4 | AG19: 1 | AH19: =Max!$B$3*AE19 -> 60 | AL19: 0.65 | AM19: 6 | AN19: 4 | AO19: =Max!$B$3*AL19 -> 65 | AQ19: 5 | AR19: Sentadillas | AS19: 0.5 | AT19: 5 | AU19: 1 | AV19: =Max!$B$3*AS19 -> 50
C20: 0.65 | D20: 4 | E20: 1 | F20: =Max!$B$3*C20 -> 65 | G20: =D20*E20 -> 4 | H20: =F20*G20 -> 260 | AE20: 0.7 | AF20: 3 | AG20: 2 | AH20: =Max!$B$3*AE20 -> 70 | AJ20: 4 | AK20: Flys con mancuerna | AM20: 10 | AN20: 5 | AS20: 0.6 | AT20: 4 | AU20: 1 | AV20: =Max!$B$3*AS20 -> 60
C21: 0.75 | D21: 3 | E21: 5 | F21: =Max!$B$3*C21 -> 75 | G21: =D21*E21 -> 15 | H21: =F21*G21 -> 1125 | AE21: 0.8 | AF21: 2 | AG21: 4 | AH21: =Max!$B$3*AE21 -> 80 | AJ21: 5 | AK21: Buenos dias | AM21: 5 | AN21: 5 | AS21: 0.7 | AT21: 3 | AU21: 2 | AV21: =Max!$B$3*AS21 -> 70
A22: 6 | B22: Buenos dias | D22: 5 | E22: 5 | AC22: 6 | AD22: Buenos dias | AF22: 5 | AG22: 5 | AS22: 0.8 | AT22: 2 | AU22: 4 | AV22: =Max!$B$3*AS22 -> 80
AQ23: 6 | AR23: Buenos dias | AT23: 5 | AU23: 5
A24: dia 3 miercoles | C24: % | D24: reps | E24: sets | F24: weight | AC24: dia 3 miercoles | AE24: % | AF24: reps | AG24: sets | AH24: weight | AJ24: dia 3 miercoles | AL24: % | AM24: reps | AN24: sets | AO24: weight
A25: 1 | B25: Peso muerto | C25: 0.5 | D25: 4 | E25: 1 | F25: =Max!$B$5*C25 -> 50 | K25: =D25*E25 -> 4 | L25: =F25*K25 -> 200 | W25: =K25 -> 4 | X25: =K26 -> 8 | Y25: =K27 -> 6 | Z25: =K28 -> 15 | AC25: 1 | AD25: Peso muerto hasta rodillas | AE25: 0.5 | AF25: 4 | AG25: 1 | AH25: =Max!$B$5*AE25 -> 50 | AJ25: 1 | AK25: Peso muerto | AL25: 0.5 | AM25: 4 | AN25: 1 | AO25: =Max!$B$5*AL25 -> 50 | AQ25: dia 3 miercoles | AS25: % | AT25: reps | AU25: sets | AV25: weight
C26: 0.6 | D26: 4 | E26: 2 | F26: =Max!$B$5*C26 -> 60 | K26: =D26*E26 -> 8 | L26: =F26*K26 -> 480 | AE26: 0.6 | AF26: 4 | AG26: 2 | AH26: =Max!$B$5*AE26 -> 60 | AL26: 0.6 | AM26: 4 | AN26: 1 | AO26: =Max!$B$5*AL26 -> 60 | AQ26: 1 | AR26: Press de banca | AS26: 0.55 | AT26: 5 | AU26: 1 | AV26: =Max!$B$4*AS26 -> 55
C27: 0.7 | D27: 3 | E27: 2 | F27: =Max!$B$5*C27 -> 70 | K27: =D27*E27 -> 6 | L27: =F27*K27 -> 420 | AE27: 0.7 | AF27: 3 | AG27: 2 | AH27: =Max!$B$5*AE27 -> 70 | AL27: 0.7 | AM27: 3 | AN27: 2 | AO27: =Max!$B$5*AL27 -> 70 | AS27: 0.65 | AT27: 4 | AU27: 1 | AV27: =Max!$B$4*AS27 -> 65
C28: 0.8 | D28: 3 | E28: 5 | F28: =Max!$B$5*C28 -> 80 | K28: =D28*E28 -> 15 | L28: =F28*K28 -> 1200 | AE28: 0.75 | AF28: 3 | AG28: 4 | AH28: =Max!$B$5*AE28 -> 75 | AL28: 0.8 | AM28: 3 | AN28: 3 | AO28: =Max!$B$5*AL28 -> 80 | AS28: 0.75 | AT28: 3 | AU28: 1 | AV28: =Max!$B$4*AS28 -> 75
A29: 2 | B29: Press de banca | C29: 0.5 | D29: 5 | E29: 1 | F29: =Max!$B$4*C29 -> 50 | I29: =D29*E29 -> 5 | J29: =F29*I29 -> 250 | R29: =I29+I37 -> 14 | S29: =I30+I36 -> 11 | T29: =I31+I35 -> 8 | U29: =I32+I33+I34 -> 13 | V29: 0 | AC29: 2 | AD29: Press de banca | AE29: 0.55 | AF29: 5 | AG29: 1 | AH29: =Max!$B$4*AE29 -> 55 | AL29: 0.85 | AM29: 2 | AN29: 3 | AO29: =Max!$B$5*AL29 -> 85 | AS29: 0.85 | AT29: 2 | AU29: 4 | AV29: =Max!$B$4*AS29 -> 85
C30: 0.6 | D30: 4 | E30: 1 | F30: =Max!$B$4*C30 -> 60 | I30: =D30*E30 -> 4 | J30: =F30*I30 -> 240 | AE30: 0.65 | AF30: 4 | AG30: 1 | AH30: =Max!$B$4*AE30 -> 65 | AJ30: 2 | AK30: Press de banca | AL30: 0.5 | AM30: 5 | AN30: 1 | AO30: =Max!$B$4*AL30 -> 50 | AQ30: 2 | AR30: Peso muerto | AS30: 0.5 | AT30: 4 | AU30: 1 | AV30: =Max!$B$5*AS30 -> 50
C31: 0.7 | D31: 3 | E31: 1 | F31: =Max!$B$4*C31 -> 70 | I31: =D31*E31 -> 3 | J31: =F31*I31 -> 210 | AE31: 0.75 | AF31: 3 | AG31: 1 | AH31: =Max!$B$4*AE31 -> 75 | AL31: 0.6 | AM31: 4 | AN31: 1 | AO31: =Max!$B$4*AL31 -> 60 | AS31: 0.6 | AT31: 4 | AU31: 1 | AV31: =Max!$B$5*AS31 -> 60
C32: 0.8 | D32: 3 | E32: 2 | F32: =Max!$B$4*C32 -> 80 | I32: =D32*E32 -> 6 | J32: =F32*I32 -> 480 | AE32: 0.8 | AF32: 2 | AG32: 2 | AH32: =Max!$B$4*AE32 -> 80 | AL32: 0.7 | AM32: 3 | AN32: 1 | AO32: =Max!$B$4*AL32 -> 70 | AS32: 0.7 | AT32: 3 | AU32: 2 | AV32: =Max!$B$5*AS32 -> 70
C33: 0.85 | D33: 2 | E33: 2 | F33: =Max!$B$4*C33 -> 85 | I33: =D33*E33 -> 4 | J33: =F33*I33 -> 340 | AE33: 0.85 | AF33: 1 | AG33: 2 | AH33: =Max!$B$4*AE33 -> 85 | AL33: 0.8 | AM33: 2 | AN33: 5 | AO33: =Max!$B$4*AL33 -> 80 | AS33: 0.8 | AT33: 3 | AU33: 2 | AV33: =Max!$B$5*AS33 -> 80
C34: 0.8 | D34: 3 | E34: 1 | F34: =Max!$B$4*C34 -> 80 | I34: =D34*E34 -> 3 | J34: =F34*I34 -> 240 | AE34: 0.75 | AF34: 3 | AG34: 1 | AH34: =Max!$B$4*AE34 -> 75 | AJ34: 3 | AK34: Flys con mancuernas | AM34: 10 | AN34: 5 | AS34: 0.85 | AT34: 2 | AU34: 3 | AV34: =Max!$B$5*AS34 -> 85
C35: 0.7 | D35: 5 | E35: 1 | F35: =Max!$B$4*C35 -> 70 | I35: =D35*E35 -> 5 | J35: =F35*I35 -> 350 | AE35: 0.65 | AF35: 5 | AG35: 1 | AH35: =Max!$B$4*AE35 -> 65 | AJ35: 4 | AK35: Peso muerto en cajas | AL35: 0.65 | AM35: 5 | AN35: 1 | AO35: =Max!$B$5*AL35 -> 65 | AQ35: 3 | AR35: Press de banca | AS35: 0.5 | AT35: 3 | AU35: 1 | AV35: =Max!$B$4*AS35 -> 50
C36: 0.6 | D36: 7 | E36: 1 | F36: =Max!$B$4*C36 -> 60 | I36: =D36*E36 -> 7 | J36: =F36*I36 -> 420 | AE36: 0.55 | AF36: 7 | AG36: 1 | AH36: =Max!$B$4*AE36 -> 55 | AL36: 0.75 | AM36: 5 | AN36: 2 | AO36: =Max!$B$5*AL36 -> 75 | AS36: 0.6 | AT36: 3 | AU36: 1 | AV36: =Max!$B$4*AS36 -> 60
C37: 0.5 | D37: 9 | E37: 1 | F37: =Max!$B$4*C37 -> 50 | I37: =D37*E37 -> 9 | J37: =F37*I37 -> 450 | AC37: 3 | AD37: Flys con mancuernas | AF37: 10 | AG37: 5 | AL37: 0.85 | AM37: 4 | AN37: 4 | AO37: =Max!$B$5*AL37 -> 85 | AS37: 0.7 | AT37: 3 | AU37: 1 | AV37: =Max!$B$4*AS37 -> 70
A38: 3 | B38: Flys con mancuerna | D38: 4 | E38: 6 | AC38: 4 | AD38: Peso muerto | AE38: 0.5 | AF38: 4 | AG38: 1 | AH38: =Max!$B$5*AE38 -> 50 | AJ38: 5 | AK38: Zancadas | AM38: 5 | AN38: 5 | AS38: 0.8 | AT38: 2 | AU38: 3 | AV38: =Max!$B$4*AS38 -> 80
A39: 4 | B39: Peso muerto en cajas | C39: 0.6 | D39: 5 | E39: 1 | F39: =Max!$B$5*C39 -> 60 | K39: =D39*E39 -> 5 | L39: =F39*K39 -> 300 | X39: =K39 -> 5 | Y39: =K40 -> 8 | Z39: =K41 -> 9 | AA39: =K42 -> 8 | AE39: 0.6 | AF39: 4 | AG39: 1 | AH39: =Max!$B$5*AE39 -> 60 | AJ39: 6 | AK39: Abs | AM39: 10 | AN39: 3 | AQ39: 4 | AR39: Flys con mancuernas | AT39: 10 | AU39: 5
C40: 0.7 | D40: 4 | E40: 2 | F40: =Max!$B$5*C40 -> 70 | K40: =D40*E40 -> 8 | L40: =F40*K40 -> 560 | AE40: 0.7 | AF40: 3 | AG40: 2 | AH40: =Max!$B$5*AE40 -> 70 | AQ40: 5 | AR40: Zancadas | AT40: 5 | AU40: 5
C41: 0.8 | D41: 3 | E41: 3 | F41: =Max!$B$5*C41 -> 80 | K41: =D41*E41 -> 9 | L41: =F41*K41 -> 720 | AE41: 0.8 | AF41: 3 | AG41: 5 | AH41: =Max!$B$5*AE41 -> 80 | AJ41: dia 5 viernes | AL41: % | AM41: reps | AN41: sets | AO41: weight
C42: 0.9 | D42: 2 | E42: 4 | F42: =Max!$B$5*C42 -> 90 | K42: =D42*E42 -> 8 | L42: =F42*K42 -> 720 | AC42: 5 | AD42: Zancadas | AF42: 5 | AG42: 5 | AJ42: 1 | AK42: Press de banca | AL42: 0.5 | AM42: 5 | AN42: 1 | AO42: =Max!$B$4*AL42 -> 50 | AQ42: dia 5 viernes | AS42: % | AT42: reps | AU42: sets | AV42: weight
...

Sheet #32
B1: Sheiko
B2: Bloque competicion/peaking (4 Semanas)
A5: semana 1 | M5: squat | R5: bench | W5: deadlift | AC5: semana 2 | AJ5: semana 3 | AQ5: semana 4
A6: dia 1 lunes | C6: % | D6: reps | E6: sets | F6: peso | M6: 50-59 | N6: 60-69 | O6: 70-79 | P6: 80-89 | Q6: 90+ | R6: 50-59 | S6: 60-69 | T6: 70-79 | U6: 80-89 | V6: 90+ | W6: 50-59 | X6: 60-69 | Y6: 70-79 | Z6: 80-89 | AA6: 90+ | AC6: dia 1 unes | AE6: % | AF6: reps | AG6: sets | AH6: peso | AJ6: dia 1 lunes | AL6: % | AM6: reps | AN6: sets | AO6: peso | AQ6: dia 1 lunes | AS6: % | AT6: reps | AU6: sets | AV6: peso
A7: 1 | B7: Sentadillas | C7: 0.5 | D7: 3 | E7: 1 | F7: =Max!$B$3*C7 -> 50 | G7: =D7*E7 -> 3 | H7: =G7*F7 -> 150 | M7: =G7 -> 3 | N7: =G8 -> 3 | O7: =G9+G10 -> 12 | AC7: 1 | AD7: Sentadilla | AE7: 0.5 | AF7: 3 | AG7: 1 | AH7: =Max!$B$3*AE7 -> 50 | AJ7: 1 | AK7: Sentadillas | AL7: 0.5 | AM7: 3 | AN7: 1 | AO7: =Max!$B$3*AL7 -> 50 | AQ7: 1 | AR7: Press de banca | AS7: 0.5 | AT7: 3 | AU7: 1 | AV7: =Max!$B$4*AS7 -> 50
C8: 0.6 | D8: 3 | E8: 1 | F8: =Max!$B$3*C8 -> 60 | G8: =D8*E8 -> 3 | H8: =G8*F8 -> 180 | AE8: 0.6 | AF8: 3 | AG8: 2 | AH8: =Max!$B$3*AE8 -> 60 | AL8: 0.6 | AM8: 3 | AN8: 1 | AO8: =Max!$B$3*AL8 -> 60 | AS8: 0.6 | AT8: 3 | AU8: 2 | AV8: =Max!$B$4*AS8 -> 60
C9: 0.7 | D9: 3 | E9: 2 | F9: =Max!$B$3*C9 -> 70 | G9: =D9*E9 -> 6 | H9: =G9*F9 -> 420 | AE9: 0.7 | AF9: 3 | AG9: 2 | AH9: =Max!$B$3*AE9 -> 70 | AL9: 0.7 | AM9: 3 | AN9: 2 | AO9: =Max!$B$3*AL9 -> 70 | AS9: 0.7 | AT9: 2 | AU9: 2 | AV9: =Max!$B$4*AS9 -> 70
C10: 0.75 | D10: 2 | E10: 3 | F10: =Max!$B$3*C10 -> 75 | G10: =D10*E10 -> 6 | H10: =G10*F10 -> 450 | AE10: 0.8 | AF10: 2 | AG10: 4 | AH10: =Max!$B$3*AE10 -> 80 | AL10: 0.8 | AM10: 2 | AN10: 5 | AO10: =Max!$B$3*AL10 -> 80 | AS10: 0.75 | AT10: 1 | AU10: 4 | AV10: =Max!$B$4*AS10 -> 75
A11: 2 | B11: Press de banca | C11: 0.5 | D11: 3 | E11: 1 | F11: =Max!$B$4*C11 -> 50 | I11: =D11*E11 -> 3 | J11: =I11*F11 -> 150 | R11: =I11 -> 3 | S11: =I12 -> 3 | T11: =I13+I14 -> 12 | AC11: 2 | AD11: Press de banca | AE11: 0.5 | AF11: 3 | AG11: 1 | AH11: =Max!$B$4*AE11 -> 50 | AJ11: 2 | AK11: Press de banca | AL11: 0.5 | AM11: 3 | AN11: 1 | AO11: =Max!$B$4*AL11 -> 50 | AQ11: 1 | AR11: Peso muerto | AS11: 0.5 | AT11: 3 | AU11: 1 | AV11: =Max!$B$5*AS11 -> 50
C12: 0.6 | D12: 3 | E12: 1 | F12: =Max!$B$4*C12 -> 60 | I12: =D12*E12 -> 3 | J12: =I12*F12 -> 180 | AE12: 0.6 | AF12: 3 | AG12: 1 | AH12: =Max!$B$4*AE12 -> 60 | AL12: 0.6 | AM12: 3 | AN12: 1 | AO12: =Max!$B$4*AL12 -> 60 | AS12: 0.6 | AT12: 2 | AU12: 2 | AV12: =Max!$B$5*AS12 -> 60
C13: 0.7 | D13: 3 | E13: 2 | F13: =Max!$B$4*C13 -> 70 | I13: =D13*E13 -> 6 | J13: =I13*F13 -> 420 | AE13: 0.7 | AF13: 3 | AG13: 2 | AH13: =Max!$B$4*AE13 -> 70 | AL13: 0.7 | AM13: 3 | AN13: 2 | AO13: =Max!$B$4*AL13 -> 70 | AS13: 0.7 | AT13: 2 | AU13: 4 | AV13: =Max!$B$5*AS13 -> 70
C14: 0.75 | D14: 2 | E14: 3 | F14: =Max!$B$4*C14 -> 75 | I14: =D14*E14 -> 6 | J14: =I14*F14 -> 450 | AE14: 0.8 | AF14: 3 | AG14: 5 | AH14: =Max!$B$4*AE14 -> 80 | AL14: 0.8 | AM14: 2 | AN14: 3 | AO14: =Max!$B$4*AL14 -> 80 | AQ14: 3 | AR14: Abs | AT14: 8 | AU14: 2
A15: 3 | B15: Abs | D15: 10 | E15: 3 | AC15: 3 | AD15: Flys con mancuerna | AF15: 8 | AG15: 4 | AL15: 0.85 | AM15: 1 | AN15: 3 | AO15: =Max!$B$4*AL15 -> 85
AC16: 4 | AD16: Sentadilla | AE16: 0.55 | AF16: 3 | AG16: 1 | AH16: =Max!$B$3*AE16 -> 55 | AJ16: 3 | AK16: Flys con mancuernas | AM16: 8 | AN16: 4 | AQ16: dia 3 miercoles | AS16: % | AT16: reps | AU16: sets | AV16: weight
A17: dia 3 miercoles | C17: % | D17: reps | E17: sets | F17: weight | AE17: 0.65 | AF17: 3 | AG17: 2 | AH17: =Max!$B$3*AE17 -> 65 | AJ17: 4 | AK17: Abs | AM17: 4 | AN17: 5 | AQ17: 1 | AR17: Sentadillas | AS17: 0.5 | AT17: 3 | AU17: 1 | AV17: =Max!$B$3*AS17 -> 50
A18: 1 | B18: Sentadillas | C18: 0.5 | D18: 3 | E18: 1 | F18: =Max!$B$3*C18 -> 50 | G18: =D18*E18 -> 3 | H18: =G18*F18 -> 150 | M18: =G18 -> 3 | N18: =G19 -> 6 | O18: =G20 -> 4 | P18: =G21 -> 2 | Q18: =G22+G23 -> 3 | AE18: 0.75 | AF18: 3 | AG18: 4 | AH18: =Max!$B$3*AE18 -> 75 | AS18: 0.6 | AT18: 3 | AU18: 2 | AV18: =Max!$B$3*AS18 -> 60
C19: 0.6 | D19: 3 | E19: 2 | F19: =Max!$B$3*C19 -> 60 | G19: =D19*E19 -> 6 | H19: =G19*F19 -> 360 | AJ19: dia 3 miercoles | AL19: % | AM19: reps | AN19: sets | AO19: weight | AS19: 0.7 | AT19: 2 | AU19: 3 | AV19: =Max!$B$3*AS19 -> 70
C20: 0.7 | D20: 2 | E20: 2 | F20: =Max!$B$3*C20 -> 70 | G20: =D20*E20 -> 4 | H20: =G20*F20 -> 280 | AC20: dia 3 miercoles | AE20: % | AF20: reps | AG20: sets | AH20: weight | AJ20: 1 | AK20: Press de banca | AL20: 0.5 | AM20: 3 | AN20: 1 | AO20: =Max!$B$4*AL20 -> 50 | AQ20: 2 | AR20: Press de banca | AS20: 0.5 | AT20: 3 | AU20: 1 | AV20: =Max!$B$4*AS20 -> 50
C21: 0.8 | D21: 2 | E21: 1 | F21: =Max!$B$3*C21 -> 80 | G21: =D21*E21 -> 2 | H21: =G21*F21 -> 160 | AC21: 1 | AD21: Peso muerto hasta rodillas | AE21: 0.5 | AF21: 3 | AG21: 1 | AH21: =Max!$B$5*AE21 -> 50 | AL21: 0.6 | AM21: 3 | AN21: 1 | AO21: =Max!$B$4*AL21 -> 60 | AS21: 0.6 | AT21: 3 | AU21: 2 | AV21: =Max!$B$4*AS21 -> 60
C22: 0.9 | D22: 1 | E22: 1 | F22: =Max!$B$3*C22 -> 90 | G22: =D22*E22 -> 1 | H22: =G22*F22 -> 90 | AE22: 0.6 | AF22: 2 | AG22: 2 | AH22: =Max!$B$5*AE22 -> 60 | AL22: 0.7 | AM22: 3 | AN22: 2 | AO22: =Max!$B$4*AL22 -> 70 | AS22: 0.7 | AT22: 2 | AU22: 3 | AV22: =Max!$B$4*AS22 -> 70
C23: 100%-105% | D23: 1 | E23: 2-3 | F23: =Max!$B$3*MID(C23,1,1)&"-"&Max!$B$3*MID(C23,6,7) -> 100-105 | G23: =2 -> 2 | H23: =Max!B3*2*1 -> 200 | AE23: 0.65 | AF23: 2 | AG23: 2 | AH23: =Max!$B$5*AE23 -> 65 | AL23: 0.8 | AM23: 2 | AN23: 5 | AO23: =Max!$B$4*AL23 -> 80
A24: 2 | B24: Press de banca | C24: 0.5 | D24: 3 | E24: 1 | F24: =Max!$B$4*C24 -> 50 | I24: =D24*E24 -> 3 | J24: =I24*F24 -> 150 | R24: =I24 -> 3 | S24: =I25 -> 3 | T24: =I26 -> 4 | U24: =I27 -> 2 | V24: =I28+I29 -> 3 | AE24: 0.7 | AF24: 1 | AG24: 3 | AH24: =Max!$B$5*AE24 -> 70 | AJ24: 2 | AK24: Flys con mancuernas | AM24: 8 | AN24: 4 | AQ24: Dia 5, 6 o 7
C25: 0.6 | D25: 3 | E25: 1 | F25: =Max!$B$4*C25 -> 60 | I25: =D25*E25 -> 3 | J25: =I25*F25 -> 180 | AC25: 2 | AD25: Press de banca | AE25: 0.5 | AF25: 3 | AG25: 1 | AH25: =Max!$B$4*AE25 -> 50 | AJ25: 3 | AK25: Peso muerto | AL25: 0.5 | AM25: 3 | AN25: 1 | AO25: =Max!$B$5*AL25 -> 50 | AR25: Competicion
C26: 0.7 | D26: 2 | E26: 2 | F26: =Max!$B$4*C26 -> 70 | I26: =D26*E26 -> 4 | J26: =I26*F26 -> 280 | AE26: 0.6 | AF26: 3 | AG26: 1 | AH26: =Max!$B$4*AE26 -> 60 | AL26: 0.6 | AM26: 3 | AN26: 2 | AO26: =Max!$B$5*AL26 -> 60
C27: 0.8 | D27: 2 | E27: 1 | F27: =Max!$B$4*C27 -> 80 | I27: =D27*E27 -> 2 | J27: =I27*F27 -> 160 | AE27: 0.7 | AF27: 3 | AG27: 2 | AH27: =Max!$B$4*AE27 -> 70 | AL27: 0.7 | AM27: 3 | AN27: 2 | AO27: =Max!$B$5*AL27 -> 70
C28: 0.9 | D28: 1 | E28: 1 | F28: =Max!$B$4*C28 -> 90 | I28: =D28*E28 -> 1 | J28: =I28*F28 -> 90 | AE28: 0.8 | AF28: 3 | AG28: 2 | AH28: =Max!$B$4*AE28 -> 80 | AL28: 0.75 | AM28: 2 | AN28: 5 | AO28: =Max!$B$5*AL28 -> 75
C29: 100%-105% | D29: 1 | E29: 2-3 | F29: =Max!$B$4*MID(C29,1,1)&"-"&Max!$B$4*MID(C29,6,7) -> 100-105 | I29: =2 -> 2 | J29: =2*1*Max!B4 -> 200 | AE29: 0.85 | AF29: 2 | AG29: 3 | AH29: =Max!$B$4*AE29 -> 85 | AJ29: 4 | AK29: Buenos dias | AM29: 5 | AN29: 4
A30: 3 | B30: peso muerto | C30: 0.5 | D30: 3 | E30: 1 | F30: =Max!$B$5*C30 -> 50 | K30: =D30*E30 -> 3 | L30: =K30*F30 -> 150 | W30: =K30 -> 3 | X30: =K31 -> 2 | Y30: =K32 -> 4 | Z30: =K33 -> 1 | AA30: =K34+K35 -> 3 | AC30: 3 | AD30: Flys con mancuernas | AF30: 10 | AG30: 5
C31: 0.6 | D31: 2 | E31: 1 | F31: =Max!$B$5*C31 -> 60 | K31: =D31*E31 -> 2 | L31: =K31*F31 -> 120 | AC31: 4 | AD31: Peso muerto | AE31: 0.5 | AF31: 3 | AG31: 1 | AH31: =Max!$B$5*AE31 -> 50 | AJ31: dia 5 viernes | AL31: % | AM31: reps | AN31: sets | AO31: weight
C32: 0.7 | D32: 2 | E32: 2 | F32: =Max!$B$5*C32 -> 70 | K32: =D32*E32 -> 4 | L32: =K32*F32 -> 280 | AE32: 0.6 | AF32: 3 | AG32: 1 | AH32: =Max!$B$5*AE32 -> 60 | AJ32: 1 | AK32: Sentadillas | AL32: 0.5 | AM32: 3 | AN32: 1 | AO32: =Max!$B$3*AL32 -> 50
C33: 0.8 | D33: 1 | E33: 1 | F33: =Max!$B$5*C33 -> 80 | K33: =D33*E33 -> 1 | L33: =K33*F33 -> 80 | AE33: 0.7 | AF33: 3 | AG33: 2 | AH33: =Max!$B$5*AE33 -> 70 | AL33: 0.6 | AM33: 3 | AN33: 2 | AO33: =Max!$B$3*AL33 -> 60
C34: 0.9 | D34: 1 | E34: 1 | F34: =Max!$B$5*C34 -> 90 | K34: =D34*E34 -> 1 | L34: =K34*F34 -> 90 | AE34: 0.8 | AF34: 3 | AG34: 5 | AH34: =Max!$B$5*AE34 -> 80 | AL34: 0.7 | AM34: 2 | AN34: 2 | AO34: =Max!$B$3*AL34 -> 70
C35: 100%-105% | D35: 1 | E35: 2-3 | F35: =Max!$B$5*MID(C35,1,1)&"-"&Max!$B$5*MID(C35,6,7) -> 100-105 | K35: =2 -> 2 | L35: =2*1*Max!B5 -> 200 | AC35: 5 | AD35: Abs | AF35: 10 | AG35: 3 | AL35: 0.75 | AM35: 2 | AN35: 3 | AO35: =Max!$B$3*AL35 -> 75
AJ36: 2 | AK36: Press de banca | AL36: 0.5 | AM36: 3 | AN36: 1 | AO36: =Max!$B$4*AL36 -> 50
A37: dia 5 viernes | C37: % | D37: reps | E37: sets | F37: weight | AC37: dia 5 viernes | AE37: % | AF37: reps | AG37: sets | AH37: weight | AL37: 0.6 | AM37: 3 | AN37: 1 | AO37: =Max!$B$4*AL37 -> 60
A38: 1 | B38: sentadilla | C38: 0.5 | D38: 3 | E38: 1 | F38: =Max!$B$3*C38 -> 50 | G38: =D38*E38 -> 3 | H38: =G38*F38 -> 150 | M38: =G38 -> 3 | N38: =G39 -> 6 | O38: =G40+G41 -> 14 | AC38: 1 | AD38: Press de banca | AE38: 0.5 | AF38: 3 | AG38: 1 | AH38: =Max!$B$4*AE38 -> 50 | AL38: 0.7 | AM38: 3 | AN38: 2 | AO38: =Max!$B$4*AL38 -> 70
C39: 0.6 | D39: 3 | E39: 2 | F39: =Max!$B$3*C39 -> 60 | G39: =D39*E39 -> 6 | H39: =G39*F39 -> 360 | AE39: 0.6 | AF39: 3 | AG39: 1 | AH39: =Max!$B$4*AE39 -> 60 | AL39: 0.75 | AM39: 2 | AN39: 4 | AO39: =Max!$B$4*AL39 -> 75
C40: 0.7 | D40: 3 | E40: 2 | F40: =Max!$B$3*C40 -> 70 | G40: =D40*E40 -> 6 | H40: =G40*F40 -> 420 | AE40: 0.7 | AF40: 3 | AG40: 2 | AH40: =Max!$B$4*AE40 -> 70 | AJ40: 3 | AK40: Abs | AM40: 8 | AN40: 3
C41: 0.75 | D41: 2 | E41: 4 | F41: =Max!$B$3*C41 -> 75 | G41: =D41*E41 -> 8 | H41: =G41*F41 -> 600 | AE41: 0.8 | AF41: 3 | AG41: 5 | AH41: =Max!$B$4*AE41 -> 80
A42: 2 | B42: Press de banca | C42: 0.55 | D42: 3 | E42: 1 | F42: =Max!$B$4*C42 -> 55 | I42: =D42*E42 -> 3 | J42: =I42*F42 -> 165 | R42: =I42 -> 3 | S42: =I43 -> 6 | T42: =I44 -> 18 | AC42: 2 | AD42: Sentadillas | AE42: 0.5 | AF42: 3 | AG42: 1 | AH42: =Max!$B$3*AE42 -> 50
...

Sheet Volume Calcs
A1: Volume Calculations
B3: Overall summary | U3: These graphs show the type of loading | AN3: These graphs show the focus of the loading
U25: Squat | AA25: Bench | AG25: Deadlift
A26: #37 | B26: Squat | C26: Bench | D26: Dead | E26: NL | G26: Squat | H26: Bench | I26: Dead | K26: Avg Wt. | M26: Squat | N26: Bench | O26: Dead | U26: % | V26: Week 1 | W26: Week 2 | X26: Week 3 | Y26: Week 4 | Z26: Month | AA26: % | AB26: Week 1 | AC26: Week 2 | AD26: Week 3 | AE26: Week 4 | AF26: Month | AG26: % | AH26: Week 1 | AI26: Week 2 | AJ26: Week 3 | AK26: Week 4 | AL26: Month | AN26: % of Lifts | AO26: Week 1 | AP26: Week 2 | AQ26: Week 3 | AR26: Week 4 | AS26: Month
A27: 1 | B27: ='#37'!G54 -> 74 | C27: ='#37'!I54 -> 142 | D27: ='#37'!K54 -> 70 | E27: =SUM(B27:D27) -> 286 | G27: ='#37'!H54 -> 4875 | H27: ='#37'!J54 -> 8795 | I27: ='#37'!L54 -> 4680 | J27: =SUM(G27:I27) -> 18350 | K27: =J27/E27 -> 64.160839 | M27: =G27/B27/Max!B3 -> 0.65878378 | N27: =H27/C27/Max!B$4 -> 0.6193662 | O27: =I27/D27/Max!B$5 -> 0.66857143 | U27: 50-59 | V27: ='#37'!$M$54 -> 10 | W27: ='#37'!$M$107 -> 15 | X27: ='#37'!$M$163 -> 15 | Y27: ='#37'!$M$213 -> 15 | Z27: ='#37'!$M$216 -> 55 | AA27: 50-59 | AB27: ='#37'!$R$54 -> 42 | AC27: ='#37'!$R$107 -> 23 | AD27: ='#37'!$R$163 -> 37 | AE27: ='#37'!$R$213 -> 20 | AF27: ='#37'!$R$216 -> 122 | AG27: 50-59 | AH27: ='#37'!$W$54 -> 10 | AI27: ='#37'!$W$107 -> 8 | AJ27: ='#37'!$W$163 -> 4 | AK27: ='#37'!$W$213 -> 4 | AL27: ='#37'!$W$216 -> 26 | AN27: Squat | AO27: =V32/(V32+AB32+AH32) -> 0.25874126 | AP27: =W32/(W32+AC32+AI32) -> 0.35361217 | AQ27: =X32/(X32+AD32+AJ32) -> 0.32634731 | AR27: =Y32/(Y32+AE32+AK32) -> 0.36563877 | AS27: =Z32/(Z32+AF32+AL32) -> 0.32342342
A28: 2 | B28: ='#37'!G107 -> 93 | C28: ='#37'!I107 -> 113 | D28: ='#37'!K107 -> 57 | E28: =SUM(B28:D28) -> 263 | G28: ='#37'!H107 -> 6380 | H28: ='#37'!J107 -> 7410 | I28: ='#37'!L107 -> 3785 | J28: =SUM(G28:I28) -> 17575 | K28: =J28/E28 -> 66.825095 | M28: =G28/B28/Max!B3 -> 0.68602151 | N28: =H28/C28/Max!B$4 -> 0.65575221 | O28: =I28/D28/Max!B$5 -> 0.66403509 | U28: 60-69 | V28: ='#37'!$N$54 -> 18 | W28: ='#37'!$N$107 -> 18 | X28: ='#37'!$N$163 -> 18 | Y28: ='#37'!$N$213 -> 12 | Z28: ='#37'!$N$216 -> 66 | AA28: 60-69 | AB28: ='#37'!$S$54 -> 39 | AC28: ='#37'!$S$107 -> 25 | AD28: ='#37'!$S$163 -> 60 | AE28: ='#37'!$S$213 -> 18 | AF28: ='#37'!$S$216 -> 142 | AG28: 60-69 | AH28: ='#37'!$X$54 -> 20 | AI28: ='#37'!$X$107 -> 12 | AJ28: ='#37'!$X$163 -> 9 | AK28: ='#37'!$X$213 -> 4 | AL28: ='#37'!$X$216 -> 45 | AN28: Bench | AO28: =AB32/(V32+AB32+AH32) -> 0.4965035 | AP28: =AC32/(W32+AC32+AI32) -> 0.42965779 | AQ28: =AD32/(X32+AD32+AJ32) -> 0.48502994 | AR28: =AE32/(Y32+AE32+AK32) -> 0.51982379 | AS28: =AF32/(Z32+AF32+AL32) -> 0.48198198
A29: 3 | B29: ='#37'!G163 -> 109 | C29: ='#37'!I163 -> 162 | D29: ='#37'!K163 -> 63 | E29: =SUM(B29:D29) -> 334 | G29: ='#37'!H163 -> 7400 | H29: ='#37'!J163 -> 10530 | I29: ='#37'!L163 -> 4480 | J29: =SUM(G29:I29) -> 22410 | K29: =J29/E29 -> 67.095808 | M29: =G29/B29/Max!B3 -> 0.67889908 | N29: =H29/C29/Max!B$4 -> 0.65 | O29: =I29/D29/Max!B$5 -> 0.71111111 | U29: 70-79 | V29: ='#37'!$O$54 -> 46 | W29: ='#37'!$O$107 -> 50 | X29: ='#37'!$O$163 -> 61 | Y29: ='#37'!$O$213 -> 18 | Z29: ='#37'!$O$216 -> 175 | AA29: 70-79 | AB29: ='#37'!$T$54 -> 61 | AC29: ='#37'!$T$107 -> 49 | AD29: ='#37'!$T$163 -> 36 | AE29: ='#37'!$T$213 -> 53 | AF29: ='#37'!$T$216 -> 199 | AG29: 70-79 | AH29: ='#37'!$Y$54 -> 28 | AI29: ='#37'!$Y$107 -> 37 | AJ29: ='#37'!$Y$163 -> 34 | AK29: ='#37'!$Y$213 -> 6 | AL29: ='#37'!$Y$216 -> 105 | AN29: Deadlift | AO29: =AH32/(AH32+AB32+V32) -> 0.24475524 | AP29: =AI32/(AI32+AC32+W32) -> 0.21673004 | AQ29: =AJ32/(AJ32+AD32+X32) -> 0.18862275 | AR29: =AK32/(AK32+AE32+Y32) -> 0.11453744 | AS29: =AL32/(AL32+AF32+Z32) -> 0.19459459
A30: 4 | B30: ='#37'!G213 -> 83 | C30: ='#37'!I213 -> 118 | D30: ='#37'!K213 -> 26 | E30: =SUM(B30:D30) -> 227 | G30: ='#37'!H213 -> 5800 | H30: ='#37'!J213 -> 8110 | I30: ='#37'!L213 -> 1850 | J30: =SUM(G30:I30) -> 15760 | K30: =J30/E30 -> 69.427313 | M30: =G30/B30/Max!B3 -> 0.69879518 | N30: =H30/C30/Max!B$4 -> 0.68728814 | O30: =I30/D30/Max!B$5 -> 0.71153846 | P30: =J31/E31 -> 66.752252 | U30: 80-89 | V30: ='#37'!$P$54 -> 0 | W30: ='#37'!$P$107 -> 10 | X30: ='#37'!$P$163 -> 15 | Y30: ='#37'!$P$213 -> 38 | Z30: ='#37'!$P$216 -> 63 | AA30: 80-89 | AB30: ='#37'!$U$54 -> 0 | AC30: ='#37'!$U$107 -> 16 | AD30: ='#37'!$U$163 -> 29 | AE30: ='#37'!$U$213 -> 27 | AF30: ='#37'!$U$216 -> 72 | AG30: 80-89 | AH30: ='#37'!$Z$54 -> 12 | AI30: ='#37'!$Z$107 -> 0 | AJ30: ='#37'!$Z$163 -> 16 | AK30: ='#37'!$Z$213 -> 12 | AL30: ='#37'!$Z$216 -> 40
A31: Total | B31: ='#37'!G216 -> 359 | C31: ='#37'!I216 -> 535 | D31: ='#37'!K216 -> 216 | E31: =SUM(B31:D31) -> 1110 | G31: =SUM(G26:G30) -> 24455 | H31: =SUM(H26:H30) -> 34845 | I31: =SUM(I26:I30) -> 14795 | J31: =SUM(J26:J30) -> 74095 | M31: =G31/B31/Max!B3 -> 0.68119777 | N31: =H31/C31/Max!B$4 -> 0.65130841 | O31: =I31/D31/Max!B$5 -> 0.6849537 | U31: 90+ | V31: ='#37'!$Q$54 -> 0 | W31: ='#37'!$Q$107 -> 0 | X31: ='#37'!$Q$163 -> 0 | Y31: ='#37'!$Q$213 -> 0 | Z31: ='#37'!$Q$216 -> 0 | AA31: 90+ | AB31: ='#37'!$V$54 -> 0 | AC31: ='#37'!$V$107 -> 0 | AD31: ='#37'!$V$163 -> 0 | AE31: ='#37'!$V$213 -> 0 | AF31: ='#37'!$V$216 -> 0 | AG31: 90+ | AH31: ='#37'!$AA$54 -> 0 | AI31: ='#37'!$AA$107 -> 0 | AJ31: ='#37'!$AA$163 -> 0 | AK31: ='#37'!$AA$213 -> 0 | AL31: ='#37'!$AA$216 -> 0
U32: NL | V32: =SUM(V27:V31) -> 74 | W32: =SUM(W27:W31) -> 93 | X32: =SUM(X27:X31) -> 109 | Y32: =SUM(Y27:Y31) -> 83 | Z32: =SUM(Z27:Z31) -> 359 | AA32: NL | AB32: =SUM(AB27:AB31) -> 142 | AC32: =SUM(AC27:AC31) -> 113 | AD32: =SUM(AD27:AD31) -> 162 | AE32: =SUM(AE27:AE31) -> 118 | AF32: =SUM(AF27:AF31) -> 535 | AG32: NL | AH32: =SUM(AH27:AH31) -> 70 | AI32: =SUM(AI27:AI31) -> 57 | AJ32: =SUM(AJ27:AJ31) -> 63 | AK32: =SUM(AK27:AK31) -> 26 | AL32: =SUM(AL27:AL31) -> 216
U33: Avg. Int. | V33: =M27 -> 0.65878378 | W33: =M28 -> 0.68602151 | X33: =M29 -> 0.67889908 | Y33: =M30 -> 0.69879518 | Z33: =M31 -> 0.68119777 | AA33: Avg. Int. | AB33: =N27 -> 0.6193662 | AC33: =N28 -> 0.65575221 | AD33: =N29 -> 0.65 | AE33: =N30 -> 0.68728814 | AF33: =N31 -> 0.65130841 | AG33: Avg. Int. | AH33: =O27 -> 0.66857143 | AI33: =O28 -> 0.66403509 | AJ33: =O29 -> 0.71111111 | AK33: =O30 -> 0.71153846 | AL33: =O31 -> 0.6849537
U57: Squat | AA57: Bench | AG57: Deadlift
A58: #30 | B58: Squat | C58: Bench | D58: Dead | E58: NL | G58: Squat | H58: Bench | I58: Dead | K58: Avg Wt. | M58: Squat | N58: Bench | O58: Dead | U58: % | V58: Week 1 | W58: Week 2 | X58: Week 3 | Y58: Week 4 | Z58: Month | AA58: % | AB58: Week 1 | AC58: Week 2 | AD58: Week 3 | AE58: Week 4 | AF58: Month | AG58: % | AH58: Week 1 | AI58: Week 2 | AJ58: Week 3 | AK58: Week 4 | AL58: Month | AN58: % of Lifts | AO58: Week 1 | AP58: Week 2 | AQ58: Week 3 | AR58: Week 4 | AS58: Month
A59: 1 | B59: ='#30'!G62 -> 119 | C59: ='#30'!I62 -> 113 | D59: ='#30'!K62 -> 63 | E59: =SUM(B59:D59) -> 295 | G59: ='#30'!H62 -> 8090 | H59: ='#30'!J62 -> 7550 | I59: ='#30'!L62 -> 4600 | J59: =SUM(G59:I59) -> 20240 | K59: =J59/E59 -> 68.610169 | M59: =G59/B59/Max!B3 -> 0.67983193 | N59: =H59/C59/Max!B4 -> 0.66814159 | O59: =I59/D59/Max!B5 -> 0.73015873 | U59: 50-59 | V59: ='#30'!$M$62 -> 20 | W59: ='#30'!$M$117 -> 15 | X59: ='#30'!$M$171 -> 16 | Y59: ='#30'!$M$222 -> 15 | Z59: ='#30'!$M$225 -> 66 | AA59: 50-59 | AB59: ='#30'!$R$62 -> 27 | AC59: ='#30'!$R$117 -> 21 | AD59: ='#30'!$R$171 -> 21 | AE59: ='#30'!$R$222 -> 17 | AF59: ='#30'!$R$225 -> 86 | AG59: 50-59 | AH59: ='#30'!$W$62 -> 4 | AI59: ='#30'!$W$117 -> 8 | AJ59: ='#30'!$W$171 -> 4 | AK59: ='#30'!$W$222 -> 4 | AL59: ='#30'!$W$225 -> 20 | AN59: Squat | AO59: =V64/(V64+AB64+AH64) -> 0.40338983 | AP59: =W64/(W64+AC64+AI64) -> 0.37168142 | AQ59: =X64/(X64+AD64+AJ64) -> 0.38129496 | AR59: =Y64/(Y64+AE64+AK64) -> 0.43684211 | AS59: =Z64/(Z64+AF64+AL64) -> 0.39635996
A60: 2 | B60: ='#30'!G117 -> 84 | C60: ='#30'!I117 -> 83 | D60: ='#30'!K117 -> 59 | E60: =SUM(B60:D60) -> 226 | G60: ='#30'!H117 -> 5590 | H60: ='#30'!J117 -> 5690 | I60: ='#30'!L117 -> 4060 | J60: =SUM(G60:I60) -> 15340 | K60: =J60/E60 -> 67.876106 | M60: =G60/B60/Max!B3 -> 0.66547619 | N60: =H60/C60/Max!B4 -> 0.68554217 | O60: =I60/D60/Max!B5 -> 0.68813559 | U60: 60-69 | V60: ='#30'!$N$62 -> 26 | W60: ='#30'!$N$117 -> 17 | X60: ='#30'!$N$171 -> 18 | Y60: ='#30'!$N$222 -> 12 | Z60: ='#30'!$N$225 -> 73 | AA60: 60-69 | AB60: ='#30'!$S$62 -> 22 | AC60: ='#30'!$S$117 -> 17 | AD60: ='#30'!$S$171 -> 18 | AE60: ='#30'!$S$222 -> 15 | AF60: ='#30'!$S$225 -> 72 | AG60: 60-69 | AH60: ='#30'!$X$62 -> 13 | AI60: ='#30'!$X$117 -> 12 | AJ60: ='#30'!$X$171 -> 9 | AK60: ='#30'!$X$222 -> 4 | AL60: ='#30'!$X$225 -> 38 | AN60: Bench | AO60: =AB64/(V64+AB64+AH64) -> 0.38305085 | AP60: =AC64/(W64+AC64+AI64) -> 0.36725664 | AQ60: =AD64/(X64+AD64+AJ64) -> 0.4028777 | AR60: =AE64/(Y64+AE64+AK64) -> 0.42631579 | AS60: =AF64/(Z64+AF64+AL64) -> 0.39332659
A61: 3 | B61: ='#30'!G171 -> 106 | C61: ='#30'!I171 -> 112 | D61: ='#30'!K171 -> 60 | E61: =SUM(B61:D61) -> 278 | G61: ='#30'!H171 -> 7190 | H61: ='#30'!J171 -> 7670 | I61: ='#30'!L171 -> 4525 | J61: =SUM(G61:I61) -> 19385 | K61: =J61/E61 -> 69.730216 | M61: =G61/B61/Max!B3 -> 0.67830189 | N61: =H61/C61/Max!B4 -> 0.68482143 | O61: =I61/D61/Max!B5 -> 0.75416667 | U61: 70-79 | V61: ='#30'!$O$62 -> 43 | W61: ='#30'!$O$117 -> 37 | X61: ='#30'!$O$171 -> 36 | Y61: ='#30'!$O$222 -> 18 | Z61: ='#30'!$O$225 -> 134 | AA61: 70-79 | AB61: ='#30'!$T$62 -> 26 | AC61: ='#30'!$T$117 -> 24 | AD61: ='#30'!$T$171 -> 33 | AE61: ='#30'!$T$222 -> 25 | AF61: ='#30'!$T$225 -> 108 | AG61: 70-79 | AH61: ='#30'!$Y$62 -> 14 | AI61: ='#30'!$Y$117 -> 24 | AJ61: ='#30'!$Y$171 -> 16 | AK61: ='#30'!$Y$222 -> 6 | AL61: ='#30'!$Y$225 -> 60 | AN61: Deadlift | AO61: =AH64/(AH64+AB64+V64) -> 0.21355932 | AP61: =AI64/(AI64+AC64+W64) -> 0.26106195 | AQ61: =AJ64/(AJ64+AD64+X64) -> 0.21582734 | AR61: =AK64/(AK64+AE64+Y64) -> 0.13684211 | AS61: =AL64/(AL64+AF64+Z64) -> 0.21031345
A62: 4 | B62: ='#30'!G222 -> 83 | C62: ='#30'!I222 -> 81 | D62: ='#30'!K222 -> 26 | E62: =SUM(B62:D62) -> 190 | G62: ='#30'!H222 -> 5810 | H62: ='#30'!J222 -> 5640 | I62: ='#30'!L222 -> 1850 | J62: =SUM(G62:I62) -> 13300 | K62: =J62/E62 -> 70 | M62: =G62/B62/Max!B3 -> 0.7 | N62: =H62/C62/Max!B4 -> 0.6962963 | O62: =I62/D62/Max!B5 -> 0.71153846 | U62: 80-89 | V62: ='#30'!$P$62 -> 30 | W62: ='#30'!$P$117 -> 12 | X62: ='#30'!$P$171 -> 36 | Y62: ='#30'!$P$222 -> 36 | Z62: ='#30'!$P$225 -> 114 | AA62: 80-89 | AB62: ='#30'!$U$62 -> 38 | AC62: ='#30'!$U$117 -> 21 | AD62: ='#30'!$U$171 -> 40 | AE62: ='#30'!$U$222 -> 24 | AF62: ='#30'!$U$225 -> 123 | AG62: 80-89 | AH62: ='#30'!$Z$62 -> 24 | AI62: ='#30'!$Z$117 -> 15 | AJ62: ='#30'!$Z$171 -> 31 | AK62: ='#30'!$Z$222 -> 12 | AL62: ='#30'!$Z$225 -> 82
A63: Total | B63: ='#30'!G225 -> 392 | C63: ='#30'!I225 -> 389 | D63: ='#30'!K225 -> 208 | E63: =SUM(B63:D63) -> 989 | G63: =SUM(G58:G62) -> 26680 | H63: =SUM(H58:H62) -> 26550 | I63: =SUM(I58:I62) -> 15035 | J63: =SUM(J58:J62) -> 68265 | K63: =J63/E63 -> 69.024267 | M63: =G63/B63/Max!B3 -> 0.68061224 | N63: =H63/C63/Max!B4 -> 0.68251928 | O63: =I63/D63/Max!B5 -> 0.72283654 | U63: 90+ | V63: 0 | W63: ='#30'!$Q$117 -> 3 | X63: 0 | Y63: ='#30'!$Q$222 -> 2 | Z63: ='#30'!$Q$225 -> 5 | AA63: 90+ | AB63: 0 | AC63: 0 | AD63: 0 | AE63: 0 | AF63: ='#30'!$V$225 -> 0 | AG63: 90+ | AH63: ='#30'!$AA$62 -> 8 | AI63: 0 | AJ63: 0 | AK63: 0 | AL63: ='#30'!$AA$225 -> 8
U64: NL | V64: =SUM(V59:V63) -> 119 | W64: =SUM(W59:W63) -> 84 | X64: =SUM(X59:X63) -> 106 | Y64: =SUM(Y59:Y63) -> 83 | Z64: =SUM(Z59:Z63) -> 392 | AA64: NL | AB64: =SUM(AB59:AB63) -> 113 | AC64: =SUM(AC59:AC63) -> 83 | AD64: =SUM(AD59:AD63) -> 112 | AE64: =SUM(AE59:AE63) -> 81 | AF64: =SUM(AF59:AF63) -> 389 | AG64: NL | AH64: =SUM(AH59:AH63) -> 63 | AI64: =SUM(AI59:AI63) -> 59 | AJ64: =SUM(AJ59:AJ63) -> 60 | AK64: =SUM(AK59:AK63) -> 26 | AL64: =SUM(AL59:AL63) -> 208
U88: Squat | AA88: Bench | AG88: Deadlift
A89: #32 | B89: Squat | C89: Bench | D89: Dead | E89: NL | G89: Squat | H89: Bench | I89: Dead | K89: Avg Wt. | M89: Squat | N89: Bench | O89: Dead | U89: % | V89: Week 1 | W89: Week 2 | X89: Week 3 | Y89: Week 4 | Z89: Month | AA89: % | AB89: Week 1 | AC89: Week 2 | AD89: Week 3 | AE89: Week 4 | AF89: Month | AG89: % | AH89: Week 1 | AI89: Week 2 | AJ89: Week 3 | AK89: Week 4 | AL89: Month | AN89: % of Lifts | AO89: Week 1 | AP89: Week 2 | AQ89: Week 3 | AR89: Week 4 | AS89: Month
A90: 1 | B90: ='#32'!G48 -> 59 | C90: ='#32'!I48 -> 60 | D90: ='#32'!K48 -> 13 | E90: =SUM(B90:D90) -> 132 | G90: ='#32'!H48 -> 3970 | H90: ='#32'!J48 -> 4165 | I90: ='#32'!L48 -> 920 | J90: =SUM(G90:I90) -> 9055 | K90: =J90/E90 -> 68.598485 | M90: =G90/B90/Max!B3 -> 0.67288136 | N90: =H90/C90/Max!B4 -> 0.69416667 | O90: =I90/D90/Max!B5 -> 0.70769231 | U90: 50-59 | V90: ='#32'!$M$48 -> 9 | W90: ='#32'!$M$95 -> 9 | X90: ='#32'!$M$132 -> 6 | Y90: ='#32'!$M$154 -> 3 | Z90: ='#32'!$M$156 -> 27 | AA90: 50-59 | AB90: ='#32'!$R$48 -> 9 | AC90: ='#32'!$R$95 -> 13 | AD90: ='#32'!$R$132 -> 9 | AE90: ='#32'!$R$154 -> 6 | AF90: ='#32'!$R$156 -> 37 | AG90: 50-59 | AH90: ='#32'!$W$48 -> 3 | AI90: ='#32'!$W$95 -> 6 | AJ90: ='#32'!$W$132 -> 3 | AK90: ='#32'!$W$154 -> 3 | AL90: ='#32'!$W$156 -> 15 | AN90: Squat | AO90: =V95/(V95+AB95+AH95) -> 0.4469697 | AP90: =W95/(W95+AC95+AI95) -> 0.35 | AQ90: =X95/(X95+AD95+AJ95) -> 0.31782946 | AR90: =Y95/(Y95+AE95+AK95) -> 0.24193548 | AS90: =Z95/(Z95+AF95+AL95) -> 0.35359116
A91: 2 | B91: ='#32'!G95 -> 77 | C91: ='#32'!I95 -> 102 | D91: ='#32'!K95 -> 41 | E91: =SUM(B91:D91) -> 220 | G91: ='#32'!H95 -> 5395 | H91: ='#32'!J95 -> 7200 | I91: ='#32'!L95 -> 2810 | J91: =SUM(G91:I91) -> 15405 | K91: =J91/E91 -> 70.022727 | M91: =G91/B91/Max!B3 -> 0.70064935 | N91: =H91/C91/Max!B4 -> 0.70588235 | O91: =I91/D91/Max!B5 -> 0.68536585 | U91: 60-69 | V91: ='#32'!$N$48 -> 15 | W91: ='#32'!$N$95 -> 18 | X91: ='#32'!$N$132 -> 9 | Y91: ='#32'!$N$154 -> 6 | Z91: ='#32'!$N$156 -> 48 | AA91: 60-69 | AB91: ='#32'!$S$48 -> 12 | AC91: ='#32'!$S$95 -> 13 | AD91: ='#32'!$S$132 -> 9 | AE91: ='#32'!$S$154 -> 12 | AF91: ='#32'!$S$156 -> 46 | AG91: 60-69 | AH91: ='#32'!$X$48 -> 2 | AI91: ='#32'!$X$95 -> 11 | AJ91: ='#32'!$X$132 -> 6 | AK91: ='#32'!$X$154 -> 4 | AL91: ='#32'!$X$156 -> 23 | AN91: Bench | AO91: =AB95/(V95+AB95+AH95) -> 0.45454545 | AP91: =AC95/(W95+AC95+AI95) -> 0.46363636 | AQ91: =AD95/(X95+AD95+AJ95) -> 0.48837209 | AR91: =AE95/(Y95+AE95+AK95) -> 0.51612903 | AS91: =AF95/(Z95+AF95+AL95) -> 0.4732965
A92: 3 | B92: ='#32'!G132 -> 41 | C92: ='#32'!I132 -> 63 | D92: ='#32'!K132 -> 25 | E92: =SUM(B92:D92) -> 129 | G92: ='#32'!H132 -> 2790 | H92: ='#32'!J132 -> 4385 | I92: ='#32'!L132 -> 1680 | J92: =SUM(G92:I92) -> 8855 | K92: =J92/E92 -> 68.643411 | M92: =G92/B92/Max!B3 -> 0.6804878 | N92: =H92/C92/Max!B4 -> 0.69603175 | O92: =I92/D92/Max!B5 -> 0.672 | U92: 70-79 | V92: ='#32'!$O$48 -> 30 | W92: ='#32'!$O$95 -> 24 | X92: ='#32'!$O$132 -> 16 | Y92: ='#32'!$O$154 -> 6 | Z92: ='#32'!$O$156 -> 76 | AA92: 70-79 | AB92: ='#32'!$T$48 -> 34 | AC92: ='#32'!$T$95 -> 34 | AD92: ='#32'!$T$132 -> 26 | AE92: ='#32'!$T$154 -> 14 | AF92: ='#32'!$T$156 -> 108 | AG92: 70-79 | AH92: ='#32'!$Y$48 -> 4 | AI92: ='#32'!$Y$95 -> 9 | AJ92: ='#32'!$Y$132 -> 16 | AK92: ='#32'!$Y$154 -> 8 | AL92: ='#32'!$Y$156 -> 37 | AN92: Deadlift | AO92: =AH95/(AH95+AB95+V95) -> 0.098484848 | AP92: =AI95/(AI95+AC95+W95) -> 0.18636364 | AQ92: =AJ95/(AJ95+AD95+X95) -> 0.19379845 | AR92: =AK95/(AK95+AE95+Y95) -> 0.24193548 | AS92: =AL95/(AL95+AF95+Z95) -> 0.17311234
A93: 4 | B93: ='#32'!G154 -> 15 | C93: ='#32'!I154 -> 32 | D93: ='#32'!K154 -> 15 | E93: =SUM(B93:D93) -> 62 | G93: ='#32'!H154 -> 930 | H93: ='#32'!J154 -> 2020 | I93: ='#32'!L154 -> 950 | J93: =SUM(G93:I93) -> 3900 | K93: =J93/E93 -> 62.903226 | M93: =G93/B93/Max!B3 -> 0.62 | N93: =H93/C93/Max!B4 -> 0.63125 | O93: =I93/D93/Max!B5 -> 0.63333333 | U93: 80-89 | V93: ='#32'!$P$48 -> 2 | W93: ='#32'!$P$95 -> 26 | X93: ='#32'!$P$132 -> 10 | Y93: 0 | Z93: ='#32'!$P$156 -> 38 | AA93: 80-89 | AB93: ='#32'!$U$48 -> 2 | AC93: ='#32'!$U$95 -> 42 | AD93: ='#32'!$U$132 -> 19 | AE93: 0 | AF93: ='#32'!$U$156 -> 63 | AG93: 80-89 | AH93: ='#32'!$Z$48 -> 1 | AI93: ='#32'!$Z$95 -> 15 | AJ93: 0 | AK93: 0 | AL93: ='#32'!$Z$156 -> 16
A94: Total | B94: ='#32'!G156 -> 192 | C94: ='#32'!I156 -> 257 | D94: ='#32'!K156 -> 94 | E94: =SUM(B94:D94) -> 543 | G94: =SUM(G89:G93) -> 13085 | H94: =SUM(H89:H93) -> 17770 | I94: =SUM(I89:I93) -> 6360 | J94: =SUM(J89:J93) -> 37215 | K94: =J94/E94 -> 68.535912 | M94: =G94/B94/Max!B3 -> 0.68151042 | N94: =H94/C94/Max!B4 -> 0.69143969 | O94: =I94/D94/Max!B5 -> 0.67659574 | U94: 90+ | V94: ='#32'!$Q$48 -> 3 | W94: 0 | X94: 0 | Y94: 0 | Z94: ='#32'!$Q$156 -> 3 | AA94: 90+ | AB94: ='#32'!$V$48 -> 3 | AC94: 0 | AD94: 0 | AE94: 0 | AF94: ='#32'!$V$156 -> 3 | AG94: 90+ | AH94: ='#32'!$AA$48 -> 3 | AI94: 0 | AJ94: 0 | AK94: 0 | AL94: ='#32'!$AA$156 -> 3
U95: NL | V95: =SUM(V90:V94) -> 59 | W95: =SUM(W90:W94) -> 77 | X95: =SUM(X90:X94) -> 41 | Y95: =SUM(Y90:Y94) -> 15 | Z95: =SUM(Z90:Z94) -> 192 | AA95: NL | AB95: =SUM(AB90:AB94) -> 60 | AC95: =SUM(AC90:AC94) -> 102 | AD95: =SUM(AD90:AD94) -> 63 | AE95: =SUM(AE90:AE94) -> 32 | AF95: =SUM(AF90:AF94) -> 257 | AG95: NL | AH95: =SUM(AH90:AH94) -> 13 | AI95: =SUM(AI90:AI94) -> 41 | AJ95: =SUM(AJ90:AJ94) -> 25 | AK95: =SUM(AK90:AK94) -> 15 | AL95: =SUM(AL90:AL94) -> 94
U96: Avg. Int. | V96: =M90 -> 0.67288136 | W96: =M91 -> 0.70064935 | X96: =M92 -> 0.6804878 | Y96: =M93 -> 0.62 | Z96: =M94 -> 0.68151042 | AA96: Avg. Int. | AB96: =N90 -> 0.69416667 | AC96: =N91 -> 0.70588235 | AD96: =N92 -> 0.69603175 | AE96: =N93 -> 0.63125 | AF96: =N94 -> 0.69143969 | AG96: Avg. Int. | AH96: =O90 -> 0.70769231 | AI96: =O91 -> 0.68536585 | AJ96: =O92 -> 0.672 | AK96: =O93 -> 0.63333333 | AL96: =O94 -> 0.67659574
