Workbook

Sheet 1RM
E1: Made by ChaseT 2008.05.09
C2: Kilos
B3: Peso corporal | C3: =IF('1RM'!C2="Kilos", 105,IF('1RM'!C2="Pounds",(105*2.20462))) -> 105 | D3: INTRODUCE 1RM (Se conservador y no estimes al alza):
B4: Sentadilla | C4: =IF('1RM'!C2="Kilos", D4,IF('1RM'!C2="Pounds",(D4*2.20462))) -> 100 | D4: 100
B5: Press de banca | C5: =IF('1RM'!C2="Kilos", D5,IF('1RM'!C2="Pounds",(D5*2.20462))) -> 100 | D5: 100
B6: Peso muerto | C6: =IF('1RM'!C2="Kilos", D6,IF('1RM'!C2="Pounds",(D6*2.20462))) -> 100 | D6: 100
B7: Total | C7: =SUM(C4:C6) -> 300 | D7: =SUM(D4:D6) -> 300
B13: WWW.BIBLIOTECADERUTINAS.COM

Sheet Graficos
A1: Volume Calculations
C6: These graphs show you volume vs intensity | U6: These graphs show the type of loading | AT6: These graphs show the focus of the loading
B10: Adaptation
G28: Poundage | U28: Sentadilla | AC28: Press de banca | AK28: Peso muerto
A29: 4 Dia Prep | B29: Sentadilla | C29: Press de banca | D29: Dead | E29: NL | G29: Sentadilla | H29: Press de banca | I29: Dead | K29: Avg Wt. | L29: Avg % | M29: Sentadilla | N29: Press de banca | O29: Dead | U29: % | V29: Semana 1 | W29: Semana 2 | X29: Semana 3 | Y29: Semana 4 | Z29: Month | AC29: % | AD29: Semana 1 | AE29: Semana 2 | AF29: Semana 3 | AG29: Semana 4 | AH29: Month | AK29: % | AL29: Semana 1 | AM29: Semana 2 | AN29: Semana 3 | AO29: Semana 4 | AP29: Month | AT29: % of Lifts | AU29: Semana 1 | AV29: Semana 2 | AW29: Semana 3 | AX29: Semana 4 | AY29: Month
A30: Wk1 | B30: ='[1]4 Dia Prep (1)'!G64 -> #REF! | C30: ='[1]4 Dia Prep (1)'!I64 -> #REF! | D30: ='[1]4 Dia Prep (1)'!K64 -> #REF! | E30: =SUM(B30:D30) -> #REF! | G30: ='Ciclo 1'!H64 -> 3010 | H30: ='Ciclo 1'!J64 -> 7140 | I30: ='Ciclo 1'!L64 -> 4080 | J30: =SUM(G30:I30) -> 14230 | K30: =J30/E30 -> #REF! | L30: =K30/SUM('1RM'!$C$4:$C$6) -> #REF! | M30: =G30/B30/'1RM'!C4 -> #REF! | N30: =H30/C30/'1RM'!C5 -> #REF! | O30: =I30/D30/'1RM'!C6 -> #REF! | U30: 50-59 | V30: ='Ciclo 1'!$M$64 -> 6 | W30: ='Ciclo 1'!$M$117 -> 5 | X30: ='Ciclo 1'!$M$185 -> 8 | Y30: ='Ciclo 1'!$M$254 -> 8 | Z30: =SUM(V30:Y30) -> 27 | AC30: 50-59 | AD30: ='Ciclo 1'!$R$64 -> 15 | AE30: ='Ciclo 1'!$R$117 -> 12 | AF30: ='Ciclo 1'!$R$185 -> 21 | AG30: ='Ciclo 1'!$R$254 -> 19 | AH30: =SUM(AD30:AG30) -> 67 | AK30: 50-59 | AL30: ='Ciclo 1'!$W$64 -> 12 | AM30: ='Ciclo 1'!$W$117 -> 6 | AN30: ='Ciclo 1'!$W$185 -> 9 | AO30: ='Ciclo 1'!$W$254 -> 9 | AP30: =SUM(AL30:AO30) -> 36 | AT30: Sentadilla | AU30: =V35/(V35+AD35+AL35) -> 0.16666667 | AV30: =W35/(W35+AE35+AM35) -> 0.19230769 | AW30: =X35/(X35+AF35+AN35) -> 0.19047619 | AX30: =Y35/(Y35+AG35+AO35) -> 0.19047619 | AY30: =Z35/(Z35+AH35+AP35) -> 0.18493151
A31: Wk2 | B31: ='Ciclo 1'!G117 -> 59 | C31: ='Ciclo 1'!I117 -> 108 | D31: ='Ciclo 1'!K117 -> 32 | E31: =SUM(B31:D31) -> 199 | G31: ='Ciclo 1'!H117 -> 3605 | H31: ='Ciclo 1'!J117 -> 7380 | I31: ='Ciclo 1'!L117 -> 2125 | J31: =SUM(G31:I31) -> 13110 | K31: =J31/E31 -> 65.879397 | L31: =K31/SUM('1RM'!$C$4:$C$6) -> 0.21959799 | M31: =G31/B31/'1RM'!C4 -> 0.61101695 | N31: =H31/C31/'1RM'!C5 -> 0.68333333 | O31: =I31/D31/'1RM'!C6 -> 0.6640625 | U31: 60-69 | V31: ='Ciclo 1'!$N$64 -> 0 | W31: ='Ciclo 1'!$N$117 -> 0 | X31: ='Ciclo 1'!$N$185 -> 0 | Y31: ='Ciclo 1'!$N$254 -> 0 | Z31: =SUM(V31:Y31) -> 0 | AC31: 60-69 | AD31: ='Ciclo 1'!$S$64 -> 3 | AE31: ='Ciclo 1'!$S$117 -> 3 | AF31: ='Ciclo 1'!$S$185 -> 0 | AG31: ='Ciclo 1'!$S$254 -> 3 | AH31: =SUM(AD31:AG31) -> 9 | AK31: 60-69 | AL31: ='Ciclo 1'!$X$64 -> 0 | AM31: ='Ciclo 1'!$X$117 -> 0 | AN31: ='Ciclo 1'!$X$185 -> 4 | AO31: ='Ciclo 1'!$X$254 -> 3 | AP31: =SUM(AL31:AO31) -> 7 | AT31: Press de banca | AU31: =AD35/(V35+AD35+AL35) -> 0.5 | AV31: =AE35/(W35+AE35+AM35) -> 0.57692308 | AW31: =AF35/(X35+AF35+AN35) -> 0.5 | AX31: =AG35/(Y35+AG35+AO35) -> 0.52380952 | AY31: =AH35/(Z35+AH35+AP35) -> 0.52054795
A32: Wk3 | B32: ='Ciclo 1'!G185 -> 71 | C32: ='Ciclo 1'!I185 -> 139 | D32: ='Ciclo 1'!K185 -> 75 | E32: =SUM(B32:D32) -> 285 | G32: ='Ciclo 1'!H185 -> 4695 | H32: ='Ciclo 1'!J185 -> 9265 | I32: ='Ciclo 1'!L185 -> 5220 | J32: =SUM(G32:I32) -> 19180 | K32: =J32/E32 -> 67.298246 | L32: =K32/SUM('1RM'!$C$4:$C$6) -> 0.22432749 | M32: =G32/B32/'1RM'!C4 -> 0.66126761 | N32: =H32/C32/'1RM'!C5 -> 0.66654676 | O32: =I32/D32/'1RM'!C6 -> 0.696 | U32: 70-79 | V32: ='Ciclo 1'!$O$64 -> 0 | W32: ='Ciclo 1'!$O$117 -> 0 | X32: ='Ciclo 1'!$O$185 -> 0 | Y32: ='Ciclo 1'!$O$254 -> 0 | Z32: =SUM(V32:Y32) -> 0 | AC32: 70-79 | AD32: ='Ciclo 1'!$T$64 -> 0 | AE32: ='Ciclo 1'!$T$117 -> 0 | AF32: ='Ciclo 1'!$T$185 -> 0 | AG32: ='Ciclo 1'!$T$254 -> 0 | AH32: =SUM(AD32:AG32) -> 0 | AK32: 70-79 | AL32: ='Ciclo 1'!$Y$64 -> 0 | AM32: ='Ciclo 1'!$Y$117 -> 0 | AN32: ='Ciclo 1'!$Y$185 -> 0 | AO32: ='Ciclo 1'!$Y$254 -> 0 | AP32: =SUM(AL32:AO32) -> 0 | AT32: Peso muerto | AU32: =AL35/(AL35+AD35+V35) -> 0.33333333 | AV32: =AM35/(AM35+AE35+W35) -> 0.23076923 | AW32: =AN35/(AN35+AF35+X35) -> 0.30952381 | AX32: =AO35/(AO35+AG35+Y35) -> 0.28571429 | AY32: =AP35/(AP35+AH35+Z35) -> 0.29452055
A33: Wk4 | B33: ='Ciclo 1'!G254 -> 74 | C33: ='Ciclo 1'!I254 -> 135 | D33: ='Ciclo 1'!K254 -> 65 | E33: =SUM(B33:D33) -> 274 | G33: ='Ciclo 1'!H254 -> 4850 | H33: ='Ciclo 1'!J254 -> 9425 | I33: ='Ciclo 1'!L254 -> 4530 | J33: =SUM(G33:I33) -> 18805 | K33: =J33/E33 -> 68.631387 | L33: =K33/SUM('1RM'!$C$4:$C$6) -> 0.22877129 | M33: =G33/B33/'1RM'!C4 -> 0.65540541 | N33: =H33/C33/'1RM'!C5 -> 0.69814815 | O33: =I33/D33/'1RM'!C6 -> 0.69692308 | U33: 80-89 | V33: ='Ciclo 1'!$P$64 -> 0 | W33: ='Ciclo 1'!$P$117 -> 0 | X33: ='Ciclo 1'!$P$185 -> 0 | Y33: ='Ciclo 1'!$P$254 -> 0 | Z33: =SUM(V33:Y33) -> 0 | AC33: 80-89 | AD33: ='Ciclo 1'!$U$64 -> 0 | AE33: ='Ciclo 1'!$U$117 -> 0 | AF33: ='Ciclo 1'!$U$185 -> 0 | AG33: ='Ciclo 1'!$U$254 -> 0 | AH33: =SUM(AD33:AG33) -> 0 | AK33: 80-89 | AL33: ='Ciclo 1'!$Z$64 -> 0 | AM33: ='Ciclo 1'!$Z$117 -> 0 | AN33: ='Ciclo 1'!$Z$185 -> 0 | AO33: ='Ciclo 1'!$Z$254 -> 0 | AP33: =SUM(AL33:AO33) -> 0
A34: Total | B34: =SUM(B30:B33) -> #REF! | C34: =SUM(C30:C33) -> #REF! | D34: =SUM(D30:D33) -> #REF! | E34: =SUM(E30:E33) -> #REF! | G34: =SUM(G30:G33) -> 16160 | H34: =SUM(H30:H33) -> 33210 | I34: =SUM(I30:I33) -> 15955 | J34: =SUM(J30:J33) -> 65325 | K34: =J34/E34 -> #REF! | L34: =K34/SUM('1RM'!$C$4:$C$6) -> #REF! | M34: =G34/B34/'1RM'!C4 -> #REF! | N34: =H34/C34/'1RM'!C5 -> #REF! | O34: =I34/D34/'1RM'!C6 -> #REF! | U34: 90+ | V34: ='Ciclo 1'!$Q$64 -> 0 | W34: ='Ciclo 1'!$Q$117 -> 0 | X34: ='Ciclo 1'!$Q$185 -> 0 | Y34: ='Ciclo 1'!$Q$254 -> 0 | Z34: =SUM(V34:Y34) -> 0 | AC34: 90+ | AD34: ='Ciclo 1'!$V$64 -> 0 | AE34: ='Ciclo 1'!$V$117 -> 0 | AF34: ='Ciclo 1'!$V$185 -> 0 | AG34: ='Ciclo 1'!$V$254 -> 0 | AH34: =SUM(AD34:AG34) -> 0 | AK34: 90+ | AL34: ='Ciclo 1'!$AA$64 -> 0 | AM34: ='Ciclo 1'!$AA$117 -> 0 | AN34: ='Ciclo 1'!$AA$185 -> 0 | AO34: ='Ciclo 1'!$AA$254 -> 0 | AP34: =SUM(AL34:AO34) -> 0
U35: NL | V35: =SUM(V30:V34) -> 6 | W35: =SUM(W30:W34) -> 5 | X35: =SUM(X30:X34) -> 8 | Y35: =SUM(Y30:Y34) -> 8 | Z35: =SUM(V35:Y35) -> 27 | AC35: NL | AD35: =SUM(AD30:AD34) -> 18 | AE35: =SUM(AE30:AE34) -> 15 | AF35: =SUM(AF30:AF34) -> 21 | AG35: =SUM(AG30:AG34) -> 22 | AH35: =SUM(AD35:AG35) -> 76 | AK35: NL | AL35: =SUM(AL30:AL34) -> 12 | AM35: =SUM(AM30:AM34) -> 6 | AN35: =SUM(AN30:AN34) -> 13 | AO35: =SUM(AO30:AO34) -> 12 | AP35: =SUM(AL35:AO35) -> 43
U36: Avg. Int. | V36: =M30 -> #REF! | W36: =M31 -> 0.61101695 | X36: =M32 -> 0.66126761 | Y36: =M33 -> 0.65540541 | Z36: =M34 -> #REF! | AC36: Avg. Int. | AD36: =N30 -> #REF! | AE36: =N31 -> 0.68333333 | AF36: =N32 -> 0.66654676 | AG36: =N33 -> 0.69814815 | AH36: =N34 -> #REF! | AK36: Avg. Int. | AL36: =O30 -> #REF! | AM36: =O31 -> 0.6640625 | AN36: =O32 -> 0.696 | AO36: =O33 -> 0.69692308 | AP36: =O34 -> #REF!
B40: Accumulation
G58: Poundage | U58: Sentadilla | AC58: Press de banca | AK58: Peso muerto
A59: 4 Dia Prep2 | B59: Sentadilla | C59: Press de banca | D59: Dead | E59: NL | G59: Sentadilla | H59: Press de banca | I59: Dead | K59: Avg Wt. | L59: Avg % | M59: Sentadilla | N59: Press de banca | O59: Dead | U59: % | V59: Semana 1 | W59: Semana 2 | X59: Semana 3 | Y59: Semana 4 | Z59: Semana 5 | AA59: Semana 6 | AB59: Cycle | AC59: % | AD59: Semana 1 | AE59: Semana 2 | AF59: Semana 3 | AG59: Semana 4 | AH59: Semana 5 | AI59: Semana 6 | AJ59: Cycle | AK59: % | AL59: Semana 1 | AM59: Semana 2 | AN59: Semana 3 | AO59: Semana 4 | AP59: Semana 5 | AQ59: Semana 6 | AR59: Cycle | AT59: % of Lifts | AU59: Semana 1 | AV59: Semana 2 | AW59: Semana 3 | AX59: Semana 4 | AY59: Semana 5 | AZ59: Semana 6 | BA59: Cycle
A60: Wk1 | B60: ='Ciclo 2'!G66 -> 81 | C60: ='Ciclo 2'!I66 -> 127 | D60: ='Ciclo 2'!K66 -> 59 | E60: =SUM(B60:D60) -> 267 | G60: ='Ciclo 2'!H66 -> 5580 | H60: ='Ciclo 2'!J66 -> 8940 | I60: ='Ciclo 2'!L66 -> 4415 | J60: =SUM(G60:I60) -> 18935 | K60: =J60/E60 -> 70.917603 | L60: =K60/SUM('1RM'!$C$4:$C$6) -> 0.23639201 | M60: =G60/B60/'1RM'!C4 -> 0.68888889 | N60: =H60/C60/'1RM'!C5 -> 0.70393701 | O60: =I60/D60/'1RM'!C6 -> 0.74830508 | U60: 50-59 | V60: ='Ciclo 2'!$M$66 -> 10 | W60: ='Ciclo 2'!$M$124 -> 13 | X60: ='Ciclo 2'!$M$186 -> 14 | Y60: ='Ciclo 2'!$M$247 -> 10 | Z60: ='Ciclo 2'!$M$319 -> 14 | AA60: ='Ciclo 2'!$M$383 -> 15 | AB60: =SUM(V60:AA60) -> 76 | AC60: 50-59 | AD60: ='Ciclo 2'!$R$66 -> 17 | AE60: ='Ciclo 2'!$R$124 -> 18 | AF60: ='Ciclo 2'!$R$186 -> 21 | AG60: ='Ciclo 2'!$R$247 -> 16 | AH60: ='Ciclo 2'!$R$319 -> 35 | AI60: ='Ciclo 2'!$R$383 -> 19 | AJ60: =SUM(AD60:AI60) -> 126 | AK60: 50-59 | AL60: ='Ciclo 2'!$W$66 -> 3 | AM60: ='Ciclo 2'!$W$124 -> 9 | AN60: ='Ciclo 2'!$W$186 -> 6 | AO60: ='Ciclo 2'!$W$247 -> 9 | AP60: ='Ciclo 2'!$W$319 -> 14 | AQ60: ='Ciclo 2'!$W$383 -> 13 | AR60: =SUM(AL60:AQ60) -> 54 | AT60: Sentadilla | AU60: =V65/(V65+AD65+AL65) -> 0.30337079 | AV60: =W65/(W65+AE65+AM65) -> 0.31799163 | AW60: =X65/(X65+AF65+AN65) -> 0.38782051 | AX60: =Y65/(Y65+AG65+AO65) -> 0.30396476 | AY60: =Z65/(Z65+AH65+AP65) -> 0.32590529 | AZ60: =AA65/(AA65+AI65+AQ65) -> 0.27762803 | BA60: =AB65/(AB65+AJ65+AR65) -> 0.31943662
A61: Wk2 | B61: ='Ciclo 2'!G124 -> 76 | C61: ='Ciclo 2'!I124 -> 115 | D61: ='Ciclo 2'!K124 -> 48 | E61: =SUM(B61:D61) -> 239 | G61: ='Ciclo 2'!H124 -> 5480 | H61: ='Ciclo 2'!J124 -> 8325 | I61: ='Ciclo 2'!L124 -> 3170 | J61: =SUM(G61:I61) -> 16975 | K61: =J61/E61 -> 71.025105 | L61: =K61/SUM('1RM'!$C$4:$C$6) -> 0.23675035 | M61: =G61/B61/'1RM'!C4 -> 0.72105263 | N61: =H61/C61/'1RM'!C5 -> 0.72391304 | O61: =I61/D61/'1RM'!C6 -> 0.66041667 | U61: 60-69 | V61: ='Ciclo 2'!$N$66 -> 9 | W61: ='Ciclo 2'!$N$124 -> 11 | X61: ='Ciclo 2'!$N$186 -> 13 | Y61: ='Ciclo 2'!$N$247 -> 8 | Z61: ='Ciclo 2'!$N$319 -> 13 | AA61: ='Ciclo 2'!$N$383 -> 13 | AB61: =SUM(V61:AA61) -> 67 | AC61: 60-69 | AD61: ='Ciclo 2'!$S$66 -> 18 | AE61: ='Ciclo 2'!$S$124 -> 15 | AF61: ='Ciclo 2'!$S$186 -> 19 | AG61: ='Ciclo 2'!$S$247 -> 14 | AH61: ='Ciclo 2'!$S$319 -> 28 | AI61: ='Ciclo 2'!$S$383 -> 17 | AJ61: =SUM(AD61:AI61) -> 111 | AK61: 60-69 | AL61: ='Ciclo 2'!$X$66 -> 9 | AM61: ='Ciclo 2'!$X$124 -> 9 | AN61: ='Ciclo 2'!$X$186 -> 7 | AO61: ='Ciclo 2'!$X$247 -> 12 | AP61: ='Ciclo 2'!$X$319 -> 14 | AQ61: ='Ciclo 2'!$X$383 -> 19 | AR61: =SUM(AL61:AQ61) -> 70 | AT61: Press de banca | AU61: =AD65/(V65+AD65+AL65) -> 0.47565543 | AV61: =AE65/(W65+AE65+AM65) -> 0.48117155 | AW61: =AF65/(X65+AF65+AN65) -> 0.43269231 | AX61: =AG65/(Y65+AG65+AO65) -> 0.45374449 | AY61: =AH65/(Z65+AH65+AP65) -> 0.42339833 | AZ61: =AI65/(AA65+AI65+AQ65) -> 0.47978437 | BA61: =AJ65/(AB65+AJ65+AR65) -> 0.45633803
A62: Wk3 | B62: ='Ciclo 2'!G186 -> 121 | C62: ='Ciclo 2'!I186 -> 135 | D62: ='Ciclo 2'!K186 -> 59 | E62: =SUM(B62:D62) -> 315 | G62: ='Ciclo 2'!H186 -> 8260 | H62: ='Ciclo 2'!J186 -> 9335 | I62: ='Ciclo 2'!L186 -> 4130 | J62: =SUM(G62:I62) -> 21725 | K62: =J62/E62 -> 68.968254 | L62: =K62/SUM('1RM'!$C$4:$C$6) -> 0.22989418 | M62: =G62/B62/'1RM'!C4 -> 0.68264463 | N62: =H62/C62/'1RM'!C5 -> 0.69148148 | O62: =I62/D62/'1RM'!C6 -> 0.7 | U62: 70-79 | V62: ='Ciclo 2'!$O$66 -> 42 | W62: ='Ciclo 2'!$O$124 -> 9 | X62: ='Ciclo 2'!$O$186 -> 74 | Y62: ='Ciclo 2'!$O$247 -> 6 | Z62: ='Ciclo 2'!$O$319 -> 90 | AA62: ='Ciclo 2'!$O$383 -> 30 | AB62: =SUM(V62:AA62) -> 251 | AC62: 70-79 | AD62: ='Ciclo 2'!$T$66 -> 52 | AE62: ='Ciclo 2'!$T$124 -> 25 | AF62: ='Ciclo 2'!$T$186 -> 57 | AG62: ='Ciclo 2'!$T$247 -> 12 | AH62: ='Ciclo 2'!$T$319 -> 36 | AI62: ='Ciclo 2'!$T$383 -> 117 | AJ62: =SUM(AD62:AI62) -> 299 | AK62: 70-79 | AL62: ='Ciclo 2'!$Y$66 -> 14 | AM62: ='Ciclo 2'!$Y$124 -> 30 | AN62: ='Ciclo 2'!$Y$186 -> 27 | AO62: ='Ciclo 2'!$Y$247 -> 17 | AP62: ='Ciclo 2'!$Y$319 -> 50 | AQ62: ='Ciclo 2'!$Y$383 -> 33 | AR62: =SUM(AL62:AQ62) -> 171 | AT62: Peso muerto | AU62: =AL65/(AL65+AD65+V65) -> 0.22097378 | AV62: =AM65/(AM65+AE65+W65) -> 0.20083682 | AW62: =AN65/(AN65+AF65+X65) -> 0.17948718 | AX62: =AO65/(AO65+AG65+Y65) -> 0.24229075 | AY62: =AP65/(AP65+AH65+Z65) -> 0.25069638 | AZ62: =AQ65/(AQ65+AI65+AA65) -> 0.2425876 | BA62: =AR65/(AR65+AJ65+AB65) -> 0.22422535
A63: Wk4 | B63: ='Ciclo 2'!G247 -> 69 | C63: ='Ciclo 2'!I247 -> 103 | D63: ='Ciclo 2'!K247 -> 63 | E63: =SUM(B63:D63) -> 235 | G63: ='Ciclo 2'!H247 -> 5000 | H63: ='Ciclo 2'!J247 -> 7620 | I63: ='Ciclo 2'!L247 -> 4350 | J63: =SUM(G63:I63) -> 16970 | K63: =J63/E63 -> 72.212766 | L63: =K63/SUM('1RM'!$C$4:$C$6) -> 0.24070922 | M63: =G63/B63/'1RM'!C4 -> 0.72463768 | N63: =H63/C63/'1RM'!C5 -> 0.73980583 | O63: =I63/D63/'1RM'!C6 -> 0.69047619 | U63: 80-89 | V63: ='Ciclo 2'!$P$66 -> 20 | W63: ='Ciclo 2'!$P$124 -> 43 | X63: ='Ciclo 2'!$P$186 -> 20 | Y63: ='Ciclo 2'!$P$247 -> 45 | Z63: ='Ciclo 2'!$P$319 -> 0 | AA63: ='Ciclo 2'!$P$383 -> 45 | AB63: =SUM(V63:AA63) -> 173 | AC63: 80-89 | AD63: ='Ciclo 2'!$U$66 -> 40 | AE63: ='Ciclo 2'!$U$124 -> 51 | AF63: ='Ciclo 2'!$U$186 -> 38 | AG63: ='Ciclo 2'!$U$247 -> 54 | AH63: ='Ciclo 2'!$U$319 -> 53 | AI63: ='Ciclo 2'!$U$383 -> 25 | AJ63: =SUM(AD63:AI63) -> 261 | AK63: 80-89 | AL63: ='Ciclo 2'!$Z$66 -> 33 | AM63: ='Ciclo 2'!$Z$124 -> 0 | AN63: ='Ciclo 2'!$Z$186 -> 16 | AO63: ='Ciclo 2'!$Z$247 -> 17 | AP63: ='Ciclo 2'!$Z$319 -> 12 | AQ63: ='Ciclo 2'!$Z$383 -> 25 | AR63: =SUM(AL63:AQ63) -> 103
A64: Wk5 | B64: ='Ciclo 2'!G319 -> 117 | C64: ='Ciclo 2'!I319 -> 152 | D64: ='Ciclo 2'!K319 -> 90 | E64: =SUM(B64:D64) -> 359 | G64: ='Ciclo 2'!H319 -> 7920 | H64: ='Ciclo 2'!J319 -> 10290 | I64: ='Ciclo 2'!L319 -> 6225 | J64: =SUM(G64:I64) -> 24435 | K64: =J64/E64 -> 68.064067 | L64: =K64/SUM('1RM'!$C$4:$C$6) -> 0.22688022 | M64: =G64/B64/'1RM'!C4 -> 0.67692308 | N64: =H64/C64/'1RM'!C5 -> 0.67697368 | O64: =I64/D64/'1RM'!C6 -> 0.69166667 | U64: 90+ | V64: ='Ciclo 2'!$Q$66 -> 0 | W64: ='Ciclo 2'!$Q$124 -> 0 | X64: ='Ciclo 2'!$Q$186 -> 0 | Y64: ='Ciclo 2'!$Q$247 -> 0 | Z64: ='Ciclo 2'!$Q$319 -> 0 | AA64: ='Ciclo 2'!$Q$383 -> 0 | AB64: =SUM(V64:AA64) -> 0 | AC64: 90+ | AD64: ='Ciclo 2'!$V$66 -> 0 | AE64: ='Ciclo 2'!$V$124 -> 6 | AF64: ='Ciclo 2'!$V$186 -> 0 | AG64: ='Ciclo 2'!$V$247 -> 7 | AH64: ='Ciclo 2'!$V$319 -> 0 | AI64: ='Ciclo 2'!$V$383 -> 0 | AJ64: =SUM(AD64:AI64) -> 13 | AK64: 90+ | AL64: ='Ciclo 2'!$AA$66 -> 0 | AM64: ='Ciclo 2'!$AA$124 -> 0 | AN64: ='Ciclo 2'!$AA$186 -> 0 | AO64: ='Ciclo 2'!$AA$247 -> 0 | AP64: ='Ciclo 2'!$AA$319 -> 0 | AQ64: ='Ciclo 2'!$AA$383 -> 0 | AR64: =SUM(AL64:AQ64) -> 0
A65: Wk6 | B65: ='Ciclo 2'!G383 -> 69 | C65: ='Ciclo 2'!I383 -> 103 | D65: ='Ciclo 2'!K383 -> 63 | E65: =SUM(B65:D65) -> 235 | G65: ='Ciclo 2'!H383 -> 5000 | H65: ='Ciclo 2'!J383 -> 7620 | I65: ='Ciclo 2'!L383 -> 4350 | J65: =SUM(G65:I65) -> 16970 | K65: =J65/E65 -> 72.212766 | L65: =K65/SUM('1RM'!$C$4:$C$6) -> 0.24070922 | M65: =G65/B65/'1RM'!C4 -> 0.72463768 | N65: =H65/C65/'1RM'!C5 -> 0.73980583 | O65: =I65/D65/'1RM'!C6 -> 0.69047619 | U65: NL | V65: =SUM(V60:V64) -> 81 | W65: =SUM(W60:W64) -> 76 | X65: =SUM(X60:X64) -> 121 | Y65: =SUM(Y60:Y64) -> 69 | Z65: =SUM(Z60:Z64) -> 117 | AA65: =SUM(AA60:AA64) -> 103 | AB65: =SUM(AB60:AB64) -> 567 | AC65: NL | AD65: =SUM(AD60:AD64) -> 127 | AE65: =SUM(AE60:AE64) -> 115 | AF65: =SUM(AF60:AF64) -> 135 | AG65: =SUM(AG60:AG64) -> 103 | AH65: =SUM(AH60:AH64) -> 152 | AI65: =SUM(AI60:AI64) -> 178 | AJ65: =SUM(AJ60:AJ64) -> 810 | AK65: NL | AL65: =SUM(AL60:AL64) -> 59 | AM65: =SUM(AM60:AM64) -> 48 | AN65: =SUM(AN60:AN64) -> 56 | AO65: =SUM(AO60:AO64) -> 55 | AP65: =SUM(AP60:AP64) -> 90 | AQ65: =SUM(AQ60:AQ64) -> 90 | AR65: =SUM(AL65:AQ65) -> 398
A66: Total | B66: ='Ciclo 2'!G386 -> 533 | C66: ='Ciclo 2'!I386 -> 735 | D66: ='Ciclo 2'!K386 -> 382 | E66: =SUM(E60:E65) -> 1650 | G66: =SUM(G60:G65) -> 37240 | H66: =SUM(H60:H65) -> 52130 | I66: =SUM(I60:I65) -> 26640 | J66: =SUM(J60:J65) -> 116010 | K66: =J66/E66 -> 70.309091 | L66: =K66/SUM('1RM'!$C$4:$C$6) -> 0.23436364 | M66: =G66/B66/'1RM'!C4 -> 0.69868668 | N66: =H66/C66/'1RM'!C5 -> 0.7092517 | O66: =I66/D66/'1RM'!C6 -> 0.6973822 | U66: Avg. Int. | V66: =M60 -> 0.68888889 | W66: =M61 -> 0.72105263 | X66: =M62 -> 0.68264463 | Y66: =M63 -> 0.72463768 | Z66: =M64 -> 0.67692308 | AA66: =M65 -> 0.72463768 | AB66: =M66 -> 0.69868668 | AC66: Avg. Int. | AD66: =N60 -> 0.70393701 | AE66: =N61 -> 0.72391304 | AF66: =N62 -> 0.69148148 | AG66: =N63 -> 0.73980583 | AH66: =N64 -> 0.67697368 | AI66: =N65 -> 0.73980583 | AJ66: =N66 -> 0.7092517 | AK66: Avg. Int. | AL66: =O60 -> 0.74830508 | AM66: =O61 -> 0.66041667 | AN66: =O62 -> 0.7 | AO66: =O63 -> 0.69047619 | AP66: =O64 -> 0.69166667 | AQ66: =O65 -> 0.69047619 | AR66: =O66 -> 0.6973822
B70: Transmutation
G88: Poundage | U88: Sentadilla | AC88: Press de banca | AK88: Peso muerto
A89: 4 Dia Prep3 | B89: Sentadilla | C89: Press de banca | D89: Dead | E89: NL | G89: Sentadilla | H89: Press de banca | I89: Dead | K89: Avg Wt. | L89: Avg % | M89: Sentadilla | N89: Press de banca | O89: Dead | U89: % | V89: Semana 1 | W89: Semana 2 | X89: Semana 3 | Y89: Semana 4 | Z89: Semana 5 | AA89: Cycle | AC89: % | AD89: Semana 1 | AE89: Semana 2 | AF89: Semana 3 | AG89: Semana 4 | AH89: Semana 5 | AI89: Cycle | AK89: % | AL89: Semana 1 | AM89: Semana 2 | AN89: Semana 3 | AO89: Semana 4 | AP89: Semana 5 | AQ89: Cycle | AT89: % of Lifts | AU89: Semana 1 | AV89: Semana 2 | AW89: Semana 3 | AX89: Semana 4 | AY89: Semana 5 | AZ89: Cycle
A90: Wk1 | B90: ='Ciclo 3'!G58 -> 67 | C90: ='Ciclo 3'!I58 -> 74 | D90: ='Ciclo 3'!K58 -> 35 | E90: =SUM(B90:D90) -> 176 | G90: ='Ciclo 3'!H58 -> 4670 | H90: ='Ciclo 3'!J58 -> 5070 | I90: ='Ciclo 3'!L58 -> 2610 | J90: =SUM(G90:I90) -> 12350 | K90: =J90/E90 -> 70.170455 | L90: =K90/SUM('1RM'!$C$4:$C$6) -> 0.23390152 | M90: =G90/B90/'1RM'!C4 -> 0.69701493 | N90: =H90/C90/'1RM'!C5 -> 0.68513514 | O90: =I90/D90/'1RM'!C6 -> 0.74571429 | U90: 50-59 | V90: ='Ciclo 3'!$M$58 -> 13 | W90: ='Ciclo 3'!$M$122 -> 15 | X90: ='Ciclo 3'!$M$187 -> 10 | Y90: ='Ciclo 3'!$M$253 -> 10 | Z90: ='Ciclo 3'!$M$314 -> 13 | AA90: =SUM(V90:Z90) -> 61 | AC90: 50-59 | AD90: ='Ciclo 3'!$R$58 -> 15 | AE90: ='Ciclo 3'!$R$122 -> 20 | AF90: ='Ciclo 3'!$R$187 -> 28 | AG90: ='Ciclo 3'!$R$253 -> 19 | AH90: ='Ciclo 3'!$R$314 -> 24 | AI90: =SUM(AD90:AH90) -> 106 | AK90: 50-59 | AL90: ='Ciclo 3'!$W$58 -> 3 | AM90: ='Ciclo 3'!$W$122 -> 8 | AN90: ='Ciclo 3'!$W$187 -> 11 | AO90: ='Ciclo 3'!$W$253 -> 7 | AP90: ='Ciclo 3'!$W$314 -> 9 | AQ90: =SUM(AL90:AP90) -> 38 | AT90: Sentadilla | AU90: =V95/(V95+AD95+AL95) -> 0.38068182 | AV90: =W95/(W95+AE95+AM95) -> 0.31226766 | AW90: =X95/(X95+AF95+AN95) -> 0.3006135 | AX90: =Y95/(Y95+AG95+AO95) -> 0.2972973 | AY90: =Z95/(Z95+AH95+AP95) -> 0.28143713 | AZ90: =AA95/(AA95+AI95+AQ95) -> 0.30791789
A91: Wk2 | B91: ='Ciclo 3'!G122 -> 84 | C91: ='Ciclo 3'!I122 -> 121 | D91: ='Ciclo 3'!K122 -> 64 | E91: =SUM(B91:D91) -> 269 | G91: ='Ciclo 3'!H122 -> 5755 | H91: ='Ciclo 3'!J122 -> 8235 | I91: ='Ciclo 3'!L122 -> 4585 | J91: =SUM(G91:I91) -> 18575 | K91: =J91/E91 -> 69.052045 | L91: =K91/SUM('1RM'!$C$4:$C$6) -> 0.23017348 | M91: =G91/B91/'1RM'!C4 -> 0.68511905 | N91: =H91/C91/'1RM'!C5 -> 0.68057851 | O91: =I91/D91/'1RM'!C6 -> 0.71640625 | U91: 60-69 | V91: ='Ciclo 3'!$N$58 -> 11 | W91: ='Ciclo 3'!$N$122 -> 13 | X91: ='Ciclo 3'!$N$187 -> 60 | Y91: ='Ciclo 3'!$N$253 -> 9 | Z91: ='Ciclo 3'!$N$314 -> 11 | AA91: =SUM(V91:Z91) -> 104 | AC91: 60-69 | AD91: ='Ciclo 3'!$S$58 -> 12 | AE91: ='Ciclo 3'!$S$122 -> 17 | AF91: ='Ciclo 3'!$S$187 -> 27 | AG91: ='Ciclo 3'!$S$253 -> 18 | AH91: ='Ciclo 3'!$S$314 -> 22 | AI91: =SUM(AD91:AH91) -> 96 | AK91: 60-69 | AL91: ='Ciclo 3'!$X$58 -> 6 | AM91: ='Ciclo 3'!$X$122 -> 11 | AN91: ='Ciclo 3'!$X$187 -> 11 | AO91: ='Ciclo 3'!$X$253 -> 10 | AP91: ='Ciclo 3'!$X$314 -> 12 | AQ91: =SUM(AL91:AP91) -> 50 | AT91: Press de banca | AU91: =AD95/(V95+AD95+AL95) -> 0.42045455 | AV91: =AE95/(W95+AE95+AM95) -> 0.44981413 | AW91: =AF95/(X95+AF95+AN95) -> 0.5 | AX91: =AG95/(Y95+AG95+AO95) -> 0.49420849 | AY91: =AH95/(Z95+AH95+AP95) -> 0.50299401 | AZ91: =AI95/(AA95+AI95+AQ95) -> 0.47947214
A92: Wk3 | B92: ='Ciclo 3'!G187 -> 98 | C92: ='Ciclo 3'!I187 -> 163 | D92: ='Ciclo 3'!K187 -> 65 | E92: =SUM(B92:D92) -> 326 | G92: ='Ciclo 3'!H187 -> 6565 | H92: ='Ciclo 3'!J187 -> 11340 | I92: ='Ciclo 3'!L187 -> 4320 | J92: =SUM(G92:I92) -> 22225 | K92: =J92/E92 -> 68.174847 | L92: =K92/SUM('1RM'!$C$4:$C$6) -> 0.22724949 | M92: =G92/B92/'1RM'!C4 -> 0.66989796 | N92: =H92/C92/'1RM'!C5 -> 0.69570552 | O92: =I92/D92/'1RM'!C6 -> 0.66461538 | U92: 70-79 | V92: ='Ciclo 3'!$O$58 -> 25 | W92: ='Ciclo 3'!$O$122 -> 34 | X92: ='Ciclo 3'!$O$187 -> 3 | Y92: ='Ciclo 3'!$O$253 -> 42 | Z92: ='Ciclo 3'!$O$314 -> 30 | AA92: =SUM(V92:Z92) -> 134 | AC92: 70-79 | AD92: ='Ciclo 3'!$T$58 -> 25 | AE92: ='Ciclo 3'!$T$122 -> 77 | AF92: ='Ciclo 3'!$T$187 -> 34 | AG92: ='Ciclo 3'!$T$253 -> 61 | AH92: ='Ciclo 3'!$T$314 -> 102 | AI92: =SUM(AD92:AH92) -> 299 | AK92: 70-79 | AL92: ='Ciclo 3'!$Y$58 -> 14 | AM92: ='Ciclo 3'!$Y$122 -> 22 | AN92: ='Ciclo 3'!$Y$187 -> 43 | AO92: ='Ciclo 3'!$Y$253 -> 9 | AP92: ='Ciclo 3'!$Y$314 -> 29 | AQ92: =SUM(AL92:AP92) -> 117 | AT92: Peso muerto | AU92: =AL95/(AL95+AD95+V95) -> 0.19886364 | AV92: =AM95/(AM95+AE95+W95) -> 0.23791822 | AW92: =AN95/(AN95+AF95+X95) -> 0.1993865 | AX92: =AO95/(AO95+AG95+Y95) -> 0.20849421 | AY92: =AP95/(AP95+AH95+Z95) -> 0.21556886 | AZ92: =AQ95/(AQ95+AI95+AA95) -> 0.21260997
A93: Wk4 | B93: ='Ciclo 3'!G253 -> 77 | C93: ='Ciclo 3'!I253 -> 128 | D93: ='Ciclo 3'!K253 -> 54 | E93: =SUM(B93:D93) -> 259 | G93: ='Ciclo 3'!H253 -> 5280 | H93: ='Ciclo 3'!J253 -> 9005 | I93: ='Ciclo 3'!L253 -> 3970 | J93: =SUM(G93:I93) -> 18255 | K93: =J93/E93 -> 70.482625 | L93: =K93/SUM('1RM'!$C$4:$C$6) -> 0.23494208 | M93: =G93/B93/'1RM'!C4 -> 0.68571429 | N93: =H93/C93/'1RM'!C5 -> 0.70351562 | O93: =I93/D93/'1RM'!C6 -> 0.73518519 | U93: 80-89 | V93: ='Ciclo 3'!$P$58 -> 18 | W93: ='Ciclo 3'!$P$122 -> 17 | X93: ='Ciclo 3'!$P$187 -> 25 | Y93: ='Ciclo 3'!$P$253 -> 16 | Z93: ='Ciclo 3'!$P$314 -> 40 | AA93: =SUM(V93:Z93) -> 116 | AC93: 80-89 | AD93: ='Ciclo 3'!$U$58 -> 22 | AE93: ='Ciclo 3'!$U$122 -> 2 | AF93: ='Ciclo 3'!$U$187 -> 74 | AG93: ='Ciclo 3'!$U$253 -> 24 | AH93: ='Ciclo 3'!$U$314 -> 20 | AI93: =SUM(AD93:AH93) -> 142 | AK93: 80-89 | AL93: ='Ciclo 3'!$Z$58 -> 6 | AM93: ='Ciclo 3'!$Z$122 -> 18 | AN93: ='Ciclo 3'!$Z$187 -> 0 | AO93: ='Ciclo 3'!$Z$253 -> 22 | AP93: ='Ciclo 3'!$Z$314 -> 15 | AQ93: =SUM(AL93:AP93) -> 61
A94: Wk5 | B94: ='Ciclo 3'!G314 -> 94 | C94: ='Ciclo 3'!I314 -> 168 | D94: ='Ciclo 3'!K314 -> 72 | E94: =SUM(B94:D94) -> 334 | G94: ='Ciclo 3'!H314 -> 6760 | H94: ='Ciclo 3'!J314 -> 11300 | I94: ='Ciclo 3'!L314 -> 5225 | J94: =SUM(G94:I94) -> 23285 | K94: =J94/E94 -> 69.715569 | L94: =K94/SUM('1RM'!$C$4:$C$6) -> 0.23238523 | M94: =G94/B94/'1RM'!C4 -> 0.71914894 | N94: =H94/C94/'1RM'!C5 -> 0.67261905 | O94: =I94/D94/'1RM'!C6 -> 0.72569444 | U94: 90+ | V94: ='Ciclo 3'!$Q$58 -> 0 | W94: ='Ciclo 3'!$Q$122 -> 5 | X94: ='Ciclo 3'!$Q$187 -> 0 | Y94: ='Ciclo 3'!$Q$253 -> 0 | Z94: ='Ciclo 3'!$Q$314 -> 0 | AA94: =SUM(V94:Z94) -> 5 | AC94: 90+ | AD94: ='Ciclo 3'!$V$58 -> 0 | AE94: ='Ciclo 3'!$V$122 -> 5 | AF94: ='Ciclo 3'!$V$187 -> 0 | AG94: ='Ciclo 3'!$V$253 -> 6 | AH94: ='Ciclo 3'!$V$314 -> 0 | AI94: =SUM(AD94:AH94) -> 11 | AK94: 90+ | AL94: ='Ciclo 3'!$AA$58 -> 6 | AM94: ='Ciclo 3'!$AA$122 -> 5 | AN94: ='Ciclo 3'!$AA$187 -> 0 | AO94: ='Ciclo 3'!$AA$253 -> 6 | AP94: ='Ciclo 3'!$AA$314 -> 7 | AQ94: =SUM(AL94:AP94) -> 24
A95: Total | B95: =SUM(B90:B94) -> 420 | C95: =SUM(C90:C94) -> 654 | D95: =SUM(D90:D94) -> 290 | E95: =SUM(E90:E94) -> 1364 | G95: =SUM(G90:G94) -> 29030 | H95: =SUM(H90:H94) -> 44950 | I95: =SUM(I90:I94) -> 20710 | J95: =SUM(J90:J94) -> 94690 | K95: =J95/E95 -> 69.420821 | L95: =K95/SUM('1RM'!$C$4:$C$6) -> 0.23140274 | M95: =G95/B95/'1RM'!C4 -> 0.69119048 | N95: =H95/C95/'1RM'!C5 -> 0.68730887 | O95: =I95/D95/'1RM'!C6 -> 0.71413793 | U95: NL | V95: =SUM(V90:V94) -> 67 | W95: =SUM(W90:W94) -> 84 | X95: =SUM(X90:X94) -> 98 | Y95: =SUM(Y90:Y94) -> 77 | Z95: =SUM(Z90:Z94) -> 94 | AA95: =SUM(V95:Z95) -> 420 | AC95: NL | AD95: =SUM(AD90:AD94) -> 74 | AE95: =SUM(AE90:AE94) -> 121 | AF95: =SUM(AF90:AF94) -> 163 | AG95: =SUM(AG90:AG94) -> 128 | AH95: =SUM(AH90:AH94) -> 168 | AI95: =SUM(AD95:AH95) -> 654 | AK95: NL | AL95: =SUM(AL90:AL94) -> 35 | AM95: =SUM(AM90:AM94) -> 64 | AN95: =SUM(AN90:AN94) -> 65 | AO95: =SUM(AO90:AO94) -> 54 | AP95: =SUM(AP90:AP94) -> 72 | AQ95: =SUM(AL95:AP95) -> 290
U96: Avg. Int. | V96: =M90 -> 0.69701493 | W96: =M91 -> 0.68511905 | X96: =M92 -> 0.66989796 | Y96: =M93 -> 0.68571429 | Z96: =M94 -> 0.71914894 | AA96: =M95 -> 0.69119048 | AC96: Avg. Int. | AD96: =N90 -> 0.68513514 | AE96: =N91 -> 0.68057851 | AF96: =N92 -> 0.69570552 | AG96: =N93 -> 0.70351562 | AH96: =N94 -> 0.67261905 | AI96: =N95 -> 0.68730887 | AK96: Avg. Int. | AL96: =O90 -> 0.74571429 | AM96: =O91 -> 0.71640625 | AN96: =O92 -> 0.66461538 | AO96: =O93 -> 0.73518519 | AP96: =O94 -> 0.72569444 | AQ96: =O95 -> 0.71413793
B100: Realization
G118: Poundage | U118: Sentadilla | AC118: Press de banca | AK118: Peso muerto
A119: 4 Dia Comp | B119: Sentadilla | C119: Press de banca | D119: Dead | E119: NL | G119: Sentadilla | H119: Press de banca | I119: Dead | K119: Avg Wt. | L119: Avg % | M119: Sentadilla | N119: Press de banca | O119: Dead | U119: % | V119: Semana 1 | W119: Semana 2 | X119: Semana 3 | Y119: Semana 4 | Z119: Semana 5 | AA119: Month | AC119: % | AD119: Semana 1 | AE119: Semana 2 | AF119: Semana 3 | AG119: Semana 4 | AH119: Semana 5 | AI119: Month | AK119: % | AL119: Semana 1 | AM119: Semana 2 | AN119: Semana 3 | AO119: Semana 4 | AP119: Semana 5 | AQ119: Month | AT119: % of Lifts | AU119: Semana 1 | AV119: Semana 2 | AW119: Semana 3 | AX119: Semana 4 | AY119: Semana 5 | AZ119: Month
A120: Wk1 | B120: ='Ciclo 4'!G62 -> 40 | C120: ='Ciclo 4'!I62 -> 85 | D120: ='Ciclo 4'!K62 -> 38 | E120: =SUM(B120:D120) -> 163 | G120: ='Ciclo 4'!H62 -> 2775 | H120: ='Ciclo 4'!J62 -> 5960 | I120: ='Ciclo 4'!L62 -> 2685 | J120: =SUM(G120:I120) -> 11420 | K120: =J120/E120 -> 70.06135 | L120: =K120/SUM('1RM'!$C$4:$C$6) -> 0.23353783 | M120: =G120/B120/'1RM'!C4 -> 0.69375 | N120: =H120/C120/'1RM'!C5 -> 0.70117647 | O120: =I120/D120/'1RM'!C6 -> 0.70657895 | U120: 50-59 | V120: ='Ciclo 4'!$M$62 -> 8 | W120: ='Ciclo 4'!$M$117 -> 6 | X120: ='Ciclo 4'!$M$169 -> 6 | Y120: ='Ciclo 4'!$M$208 -> 6 | Z120: ='Ciclo 4'!$M$230 -> 3 | AA120: =SUM(V120:Z120) -> 29 | AC120: 50-59 | AD120: ='Ciclo 4'!$R$62 -> 18 | AE120: ='Ciclo 4'!$R$117 -> 9 | AF120: ='Ciclo 4'!$R$169 -> 9 | AG120: ='Ciclo 4'!$R$208 -> 9 | AH120: ='Ciclo 4'!$R$230 -> 6 | AI120: =SUM(AD120:AH120) -> 51 | AK120: 50-59 | AL120: ='Ciclo 4'!$W$62 -> 6 | AM120: ='Ciclo 4'!$W$117 -> 6 | AN120: ='Ciclo 4'!$W$169 -> 9 | AO120: ='Ciclo 4'!$W$208 -> 2 | AP120: ='Ciclo 4'!$W$230 -> 3 | AQ120: =SUM(AL120:AP120) -> 26 | AT120: Sentadilla | AU120: =V125/(V125+AD125+AL125) -> 0.24539877 | AV120: =W125/(W125+AE125+AM125) -> 0.28301887 | AW120: =X125/(X125+AF125+AN125) -> 0.23134328 | AX120: =Y125/(Y125+AG125+AO125) -> 0.35714286 | AY120: =Z125/(Z125+AH125+AP125) -> 0.17777778 | AZ120: =AA125/(AA125+AI125+AQ125) -> 0.2612782
A121: Wk2 | B121: ='Ciclo 4'!G117 -> 30 | C121: ='Ciclo 4'!I117 -> 47 | D121: ='Ciclo 4'!K117 -> 29 | E121: =SUM(B121:D121) -> 106 | G121: ='Ciclo 4'!H117 -> 2065 | H121: ='Ciclo 4'!J117 -> 3205 | I121: ='Ciclo 4'!L117 -> 1995 | J121: =SUM(G121:I121) -> 7265 | K121: =J121/E121 -> 68.537736 | L121: =K121/SUM('1RM'!$C$4:$C$6) -> 0.22845912 | M121: =G121/B121/'1RM'!C4 -> 0.68833333 | N121: =H121/C121/'1RM'!C5 -> 0.68191489 | O121: =I121/D121/'1RM'!C6 -> 0.68793103 | U121: 60-69 | V121: ='Ciclo 4'!$N$62 -> 7 | W121: ='Ciclo 4'!$N$117 -> 6 | X121: ='Ciclo 4'!$N$169 -> 6 | Y121: ='Ciclo 4'!$N$208 -> 6 | Z121: ='Ciclo 4'!$N$230 -> 2 | AA121: =SUM(V121:Z121) -> 27 | AC121: 60-69 | AD121: ='Ciclo 4'!$S$62 -> 15 | AE121: ='Ciclo 4'!$S$117 -> 9 | AF121: ='Ciclo 4'!$S$169 -> 9 | AG121: ='Ciclo 4'!$S$208 -> 9 | AH121: ='Ciclo 4'!$S$230 -> 6 | AI121: =SUM(AD121:AH121) -> 48 | AK121: 60-69 | AL121: ='Ciclo 4'!$X$62 -> 9 | AM121: ='Ciclo 4'!$X$117 -> 6 | AN121: ='Ciclo 4'!$X$169 -> 9 | AO121: ='Ciclo 4'!$X$208 -> 2 | AP121: ='Ciclo 4'!$X$230 -> 3 | AQ121: =SUM(AL121:AP121) -> 29 | AT121: Press de banca | AU121: =AD125/(V125+AD125+AL125) -> 0.52147239 | AV121: =AE125/(W125+AE125+AM125) -> 0.44339623 | AW121: =AF125/(X125+AF125+AN125) -> 0.41791045 | AX121: =AG125/(Y125+AG125+AO125) -> 0.52380952 | AY121: =AH125/(Z125+AH125+AP125) -> 0.55555556 | AZ121: =AI125/(AA125+AI125+AQ125) -> 0.48308271
A122: Wk3 | B122: ='Ciclo 4'!G169 -> 31 | C122: ='Ciclo 4'!I169 -> 56 | D122: ='Ciclo 4'!K169 -> 47 | E122: =SUM(B122:D122) -> 134 | G122: ='Ciclo 4'!H169 -> 2180 | H122: ='Ciclo 4'!J169 -> 3955 | I122: ='Ciclo 4'!L169 -> 3265 | J122: =SUM(G122:I122) -> 9400 | K122: =J122/E122 -> 70.149254 | L122: =K122/SUM('1RM'!$C$4:$C$6) -> 0.23383085 | M122: =G122/B122/'1RM'!C4 -> 0.70322581 | N122: =H122/C122/'1RM'!C5 -> 0.70625 | O122: =I122/D122/'1RM'!C6 -> 0.69468085 | U122: 70-79 | V122: ='Ciclo 4'!$O$62 -> 6 | W122: ='Ciclo 4'!$O$117 -> 12 | X122: ='Ciclo 4'!$O$169 -> 7 | Y122: ='Ciclo 4'!$O$208 -> 10 | Z122: ='Ciclo 4'!$O$230 -> 3 | AA122: =SUM(V122:Z122) -> 38 | AC122: 70-79 | AD122: ='Ciclo 4'!$T$62 -> 12 | AE122: ='Ciclo 4'!$T$117 -> 23 | AF122: ='Ciclo 4'!$T$169 -> 9 | AG122: ='Ciclo 4'!$T$208 -> 15 | AH122: ='Ciclo 4'!$T$230 -> 13 | AI122: =SUM(AD122:AH122) -> 72 | AK122: 70-79 | AL122: ='Ciclo 4'!$Y$62 -> 10 | AM122: ='Ciclo 4'!$Y$117 -> 11 | AN122: ='Ciclo 4'!$Y$169 -> 15 | AO122: ='Ciclo 4'!$Y$208 -> 6 | AP122: ='Ciclo 4'!$Y$230 -> 6 | AQ122: =SUM(AL122:AP122) -> 48 | AT122: Peso muerto | AU122: =AL125/(AL125+AD125+V125) -> 0.23312883 | AV122: =AM125/(AM125+AE125+W125) -> 0.27358491 | AW122: =AN125/(AN125+AF125+X125) -> 0.35074627 | AX122: =AO125/(AO125+AG125+Y125) -> 0.11904762 | AY122: =AP125/(AP125+AH125+Z125) -> 0.26666667 | AZ122: =AQ125/(AQ125+AI125+AA125) -> 0.2556391
A123: Wk4 | B123: ='Ciclo 4'!G208 -> 30 | C123: ='Ciclo 4'!I208 -> 44 | D123: ='Ciclo 4'!K208 -> 10 | E123: =SUM(B123:D123) -> 84 | G123: ='Ciclo 4'!H208 -> 2015 | H123: ='Ciclo 4'!J208 -> 2965 | I123: ='Ciclo 4'!L208 -> 640 | J123: =SUM(G123:I123) -> 5620 | K123: =J123/E123 -> 66.904762 | L123: =K123/SUM('1RM'!$C$4:$C$6) -> 0.22301587 | M123: =G123/B123/'1RM'!C4 -> 0.67166667 | N123: =H123/C123/'1RM'!C5 -> 0.67386364 | O123: =I123/D123/'1RM'!C6 -> 0.64 | U123: 80-89 | V123: ='Ciclo 4'!$P$62 -> 19 | W123: ='Ciclo 4'!$P$117 -> 2 | X123: ='Ciclo 4'!$P$169 -> 12 | Y123: ='Ciclo 4'!$P$208 -> 8 | Z123: ='Ciclo 4'!$P$230 -> 0 | AA123: =SUM(V123:Z123) -> 41 | AC123: 80-89 | AD123: ='Ciclo 4'!$U$62 -> 40 | AE123: ='Ciclo 4'!$U$117 -> 2 | AF123: ='Ciclo 4'!$U$169 -> 29 | AG123: ='Ciclo 4'!$U$208 -> 11 | AH123: ='Ciclo 4'!$U$230 -> 0 | AI123: =SUM(AD123:AH123) -> 82 | AK123: 80-89 | AL123: ='Ciclo 4'!$Z$62 -> 10 | AM123: ='Ciclo 4'!$Z$117 -> 2 | AN123: ='Ciclo 4'!$Z$169 -> 14 | AO123: ='Ciclo 4'!$Z$208 -> 0 | AP123: ='Ciclo 4'!$Z$230 -> 0 | AQ123: =SUM(AL123:AP123) -> 26
A124: Wk5 | B124: ='Ciclo 4'!G230 -> 8 | C124: ='Ciclo 4'!I230 -> 25 | D124: ='Ciclo 4'!K230 -> 12 | E124: =SUM(B124:D124) -> 45 | G124: ='Ciclo 4'!H230 -> 480 | H124: ='Ciclo 4'!J230 -> 1585 | I124: ='Ciclo 4'!L230 -> 750 | J124: =SUM(G124:I124) -> 2815 | K124: =J124/E124 -> 62.555556 | L124: =K124/SUM('1RM'!$C$4:$C$6) -> 0.20851852 | M124: =G124/B124/'1RM'!C4 -> 0.6 | N124: =H124/C124/'1RM'!C5 -> 0.634 | O124: =I124/D124/'1RM'!C6 -> 0.625 | U124: 90+ | V124: ='Ciclo 4'!$Q$62 -> 0 | W124: ='Ciclo 4'!$Q$117 -> 4 | X124: ='Ciclo 4'!$Q$169 -> 0 | Y124: ='Ciclo 4'!$Q$208 -> 0 | Z124: ='Ciclo 4'!$Q$230 -> 0 | AA124: =SUM(V124:Z124) -> 4 | AC124: 90+ | AD124: ='Ciclo 4'!$V$62 -> 0 | AE124: ='Ciclo 4'!$V$117 -> 4 | AF124: ='Ciclo 4'!$V$169 -> 0 | AG124: ='Ciclo 4'!$V$208 -> 0 | AH124: ='Ciclo 4'!$V$230 -> 0 | AI124: =SUM(AD124:AH124) -> 4 | AK124: 90+ | AL124: ='Ciclo 4'!$AA$62 -> 3 | AM124: ='Ciclo 4'!$AA$117 -> 4 | AN124: ='Ciclo 4'!$AA$169 -> 0 | AO124: ='Ciclo 4'!$AA$208 -> 0 | AP124: ='Ciclo 4'!$AA$230 -> 0 | AQ124: =SUM(AL124:AP124) -> 7
...

Sheet Ciclo 1
B1: Sheiko | C1: WWW.BIBLIOTECADERUTINAS.COM
B2: Preparatory Period for Class 1 & CMS
B5: Semana 1 | M5: Sentadilla | R5: Press de banca | W5: Peso muerto
B6: Dia 1 | C6: % | D6: reps | E6: Series | F6: peso | M6: 50-59 | N6: 60-69 | O6: 70-79 | P6: 80-89 | Q6: 90+ | R6: 50-59 | S6: 60-69 | T6: 70-79 | U6: 80-89 | V6: 90+ | W6: 50-59 | X6: 60-69 | Y6: 70-79 | Z6: 80-89 | AA6: 90+
A7: 1 | B7: Sentadilla frontal | C7: 0.3 | D7: 4 | E7: 1 | F7: ='1RM'!$C$4*C7 -> 30 | G7: =D7*E7 -> 4 | H7: =F7*G7 -> 120 | M7: =IF(ISNUMBER(SEARCH("Sentadilla",$B7)),IF($C7>=0.5,IF($C7<0.6,$D7*$E7," ")," ")," ") | N7: =IF(ISNUMBER(SEARCH("Sentadilla",$B7)),IF($C7>=0.6,IF($C7<0.7,$D7*$E7," ")," ")," ") | O7: =IF(ISNUMBER(SEARCH("Sentadilla",$B7)),IF($C7>=0.7,IF($C7<0.8,$D7*$E7," ")," ")," ") | P7: =IF(ISNUMBER(SEARCH("Sentadilla",$B7)),IF($C7>=0.8,IF($C7<0.9,$D7*$E7," ")," ")," ") | Q7: =IF(ISNUMBER(SEARCH("Sentadilla",$B7)),IF($C7>=0.9,$D7*$E7," ")," ") | R7: =IF(ISNUMBER(SEARCH("Press de banca",$B7)),IF($C7>=0.5,IF($C7<0.6,$D7*$E7," ")," ")," ") | S7: =IF(ISNUMBER(SEARCH("Press de banca",$B7)),IF($C7>=0.6,IF($C7<0.7,$D7*$E7," ")," ")," ") | T7: =IF(ISNUMBER(SEARCH("Press de banca",$B7)),IF($C7>=0.7,IF($C7<0.8,$D7*$E7," ")," ")," ") | U7: =IF(ISNUMBER(SEARCH("Press de banca",$B7)),IF($C7>=0.8,IF($C7<0.9,$D7*$E7," ")," ")," ") | V7: =IF(ISNUMBER(SEARCH("Press de banca",$B7)),IF($C7>=0.9,$D7*$E7," ")," ")
C8: 0.4 | D8: 4 | E8: 1 | F8: ='1RM'!$C$4*C8 -> 40 | G8: =D8*E8 -> 4 | H8: =F8*G8 -> 160 | M8: =IF(ISNUMBER(SEARCH("Sentadilla",$B8)),IF($C8>=0.5,IF($C8<0.6,$D8*$E8," ")," ")," ") | N8: =IF(ISNUMBER(SEARCH("Sentadilla",$B8)),IF($C8>=0.6,IF($C8<0.7,$D8*$E8," ")," ")," ") | O8: =IF(ISNUMBER(SEARCH("Sentadilla",$B8)),IF($C8>=0.7,IF($C8<0.8,$D8*$E8," ")," ")," ") | P8: =IF(ISNUMBER(SEARCH("Sentadilla",$B8)),IF($C8>=0.8,IF($C8<0.9,$D8*$E8," ")," ")," ") | Q8: =IF(ISNUMBER(SEARCH("Sentadilla",$B8)),IF($C8>=0.9,$D8*$E8," ")," ") | R8: =IF(ISNUMBER(SEARCH("Press de banca",$B8)),IF($C8>=0.5,IF($C8<0.6,$D8*$E8," ")," ")," ") | S8: =IF(ISNUMBER(SEARCH("Press de banca",$B8)),IF($C8>=0.6,IF($C8<0.7,$D8*$E8," ")," ")," ") | T8: =IF(ISNUMBER(SEARCH("Press de banca",$B8)),IF($C8>=0.7,IF($C8<0.8,$D8*$E8," ")," ")," ") | U8: =IF(ISNUMBER(SEARCH("Press de banca",$B8)),IF($C8>=0.8,IF($C8<0.9,$D8*$E8," ")," ")," ") | V8: =IF(ISNUMBER(SEARCH("Press de banca",$B8)),IF($C8>=0.9,$D8*$E8," ")," ")
C9: 0.5 | D9: 4 | E9: 3 | F9: ='1RM'!$C$4*C9 -> 50 | G9: =D9*E9 -> 12 | H9: =F9*G9 -> 600 | M9: =IF(ISNUMBER(SEARCH("Sentadilla",$B9)),IF($C9>=0.5,IF($C9<0.6,$D9*$E9," ")," ")," ") | N9: =IF(ISNUMBER(SEARCH("Sentadilla",$B9)),IF($C9>=0.6,IF($C9<0.7,$D9*$E9," ")," ")," ") | O9: =IF(ISNUMBER(SEARCH("Sentadilla",$B9)),IF($C9>=0.7,IF($C9<0.8,$D9*$E9," ")," ")," ") | P9: =IF(ISNUMBER(SEARCH("Sentadilla",$B9)),IF($C9>=0.8,IF($C9<0.9,$D9*$E9," ")," ")," ") | Q9: =IF(ISNUMBER(SEARCH("Sentadilla",$B9)),IF($C9>=0.9,$D9*$E9," ")," ") | R9: =IF(ISNUMBER(SEARCH("Press de banca",$B9)),IF($C9>=0.5,IF($C9<0.6,$D9*$E9," ")," ")," ") | S9: =IF(ISNUMBER(SEARCH("Press de banca",$B9)),IF($C9>=0.6,IF($C9<0.7,$D9*$E9," ")," ")," ") | T9: =IF(ISNUMBER(SEARCH("Press de banca",$B9)),IF($C9>=0.7,IF($C9<0.8,$D9*$E9," ")," ")," ") | U9: =IF(ISNUMBER(SEARCH("Press de banca",$B9)),IF($C9>=0.8,IF($C9<0.9,$D9*$E9," ")," ")," ") | V9: =IF(ISNUMBER(SEARCH("Press de banca",$B9)),IF($C9>=0.9,$D9*$E9," ")," ")
A10: 2 | B10: Press de banca | C10: 0.5 | D10: 5 | E10: 1 | F10: ='1RM'!$C$5*C10 -> 50 | I10: =D10*E10 -> 5 | J10: =F10*I10 -> 250 | M10: =IF(ISNUMBER(SEARCH("Sentadilla",$B10)),IF($C10>=0.5,IF($C10<0.6,$D10*$E10," ")," ")," ") | N10: =IF(ISNUMBER(SEARCH("Sentadilla",$B10)),IF($C10>=0.6,IF($C10<0.7,$D10*$E10," ")," ")," ") | O10: =IF(ISNUMBER(SEARCH("Sentadilla",$B10)),IF($C10>=0.7,IF($C10<0.8,$D10*$E10," ")," ")," ") | P10: =IF(ISNUMBER(SEARCH("Sentadilla",$B10)),IF($C10>=0.8,IF($C10<0.9,$D10*$E10," ")," ")," ") | Q10: =IF(ISNUMBER(SEARCH("Sentadilla",$B10)),IF($C10>=0.9,$D10*$E10," ")," ") | R10: =IF(ISNUMBER(SEARCH("Press de banca",$B10)),IF($C10>=0.5,IF($C10<0.6,$D10*$E10," ")," ")," ") -> 5 | S10: =IF(ISNUMBER(SEARCH("Press de banca",$B10)),IF($C10>=0.6,IF($C10<0.7,$D10*$E10," ")," ")," ") | T10: =IF(ISNUMBER(SEARCH("Press de banca",$B10)),IF($C10>=0.7,IF($C10<0.8,$D10*$E10," ")," ")," ") | U10: =IF(ISNUMBER(SEARCH("Press de banca",$B10)),IF($C10>=0.8,IF($C10<0.9,$D10*$E10," ")," ")," ") | V10: =IF(ISNUMBER(SEARCH("Press de banca",$B10)),IF($C10>=0.9,$D10*$E10," ")," ")
C11: 0.6 | D11: 4 | E11: 1 | F11: ='1RM'!$C$5*C11 -> 60 | I11: =D11*E11 -> 4 | J11: =F11*I11 -> 240 | M11: =IF(ISNUMBER(SEARCH("Sentadilla",$B11)),IF($C11>=0.5,IF($C11<0.6,$D11*$E11," ")," ")," ") | N11: =IF(ISNUMBER(SEARCH("Sentadilla",$B11)),IF($C11>=0.6,IF($C11<0.7,$D11*$E11," ")," ")," ") | O11: =IF(ISNUMBER(SEARCH("Sentadilla",$B11)),IF($C11>=0.7,IF($C11<0.8,$D11*$E11," ")," ")," ") | P11: =IF(ISNUMBER(SEARCH("Sentadilla",$B11)),IF($C11>=0.8,IF($C11<0.9,$D11*$E11," ")," ")," ") | Q11: =IF(ISNUMBER(SEARCH("Sentadilla",$B11)),IF($C11>=0.9,$D11*$E11," ")," ") | R11: =IF(ISNUMBER(SEARCH("Press de banca",$B11)),IF($C11>=0.5,IF($C11<0.6,$D11*$E11," ")," ")," ") | S11: =IF(ISNUMBER(SEARCH("Press de banca",$B11)),IF($C11>=0.6,IF($C11<0.7,$D11*$E11," ")," ")," ") | T11: =IF(ISNUMBER(SEARCH("Press de banca",$B11)),IF($C11>=0.7,IF($C11<0.8,$D11*$E11," ")," ")," ") | U11: =IF(ISNUMBER(SEARCH("Press de banca",$B11)),IF($C11>=0.8,IF($C11<0.9,$D11*$E11," ")," ")," ") | V11: =IF(ISNUMBER(SEARCH("Press de banca",$B11)),IF($C11>=0.9,$D11*$E11," ")," ")
C12: 0.7 | D12: 3 | E12: 1 | F12: ='1RM'!$C$5*C12 -> 70 | I12: =D12*E12 -> 3 | J12: =F12*I12 -> 210 | M12: =IF(ISNUMBER(SEARCH("Sentadilla",$B12)),IF($C12>=0.5,IF($C12<0.6,$D12*$E12," ")," ")," ") | N12: =IF(ISNUMBER(SEARCH("Sentadilla",$B12)),IF($C12>=0.6,IF($C12<0.7,$D12*$E12," ")," ")," ") | O12: =IF(ISNUMBER(SEARCH("Sentadilla",$B12)),IF($C12>=0.7,IF($C12<0.8,$D12*$E12," ")," ")," ") | P12: =IF(ISNUMBER(SEARCH("Sentadilla",$B12)),IF($C12>=0.8,IF($C12<0.9,$D12*$E12," ")," ")," ") | Q12: =IF(ISNUMBER(SEARCH("Sentadilla",$B12)),IF($C12>=0.9,$D12*$E12," ")," ") | R12: =IF(ISNUMBER(SEARCH("Press de banca",$B12)),IF($C12>=0.5,IF($C12<0.6,$D12*$E12," ")," ")," ") | S12: =IF(ISNUMBER(SEARCH("Press de banca",$B12)),IF($C12>=0.6,IF($C12<0.7,$D12*$E12," ")," ")," ") | T12: =IF(ISNUMBER(SEARCH("Press de banca",$B12)),IF($C12>=0.7,IF($C12<0.8,$D12*$E12," ")," ")," ") | U12: =IF(ISNUMBER(SEARCH("Press de banca",$B12)),IF($C12>=0.8,IF($C12<0.9,$D12*$E12," ")," ")," ") | V12: =IF(ISNUMBER(SEARCH("Press de banca",$B12)),IF($C12>=0.9,$D12*$E12," ")," ")
C13: 0.75 | D13: 2 | E13: 4 | F13: ='1RM'!$C$5*C13 -> 75 | I13: =D13*E13 -> 8 | J13: =F13*I13 -> 600 | M13: =IF(ISNUMBER(SEARCH("Sentadilla",$B13)),IF($C13>=0.5,IF($C13<0.6,$D13*$E13," ")," ")," ") | N13: =IF(ISNUMBER(SEARCH("Sentadilla",$B13)),IF($C13>=0.6,IF($C13<0.7,$D13*$E13," ")," ")," ") | O13: =IF(ISNUMBER(SEARCH("Sentadilla",$B13)),IF($C13>=0.7,IF($C13<0.8,$D13*$E13," ")," ")," ") | P13: =IF(ISNUMBER(SEARCH("Sentadilla",$B13)),IF($C13>=0.8,IF($C13<0.9,$D13*$E13," ")," ")," ") | Q13: =IF(ISNUMBER(SEARCH("Sentadilla",$B13)),IF($C13>=0.9,$D13*$E13," ")," ") | R13: =IF(ISNUMBER(SEARCH("Press de banca",$B13)),IF($C13>=0.5,IF($C13<0.6,$D13*$E13," ")," ")," ") | S13: =IF(ISNUMBER(SEARCH("Press de banca",$B13)),IF($C13>=0.6,IF($C13<0.7,$D13*$E13," ")," ")," ") | T13: =IF(ISNUMBER(SEARCH("Press de banca",$B13)),IF($C13>=0.7,IF($C13<0.8,$D13*$E13," ")," ")," ") | U13: =IF(ISNUMBER(SEARCH("Press de banca",$B13)),IF($C13>=0.8,IF($C13<0.9,$D13*$E13," ")," ")," ") | V13: =IF(ISNUMBER(SEARCH("Press de banca",$B13)),IF($C13>=0.9,$D13*$E13," ")," ")
A14: 3 | B14: Sentadilla | C14: 0.55 | D14: 3 | E14: 1 | F14: ='1RM'!$C$4*C14 -> 55 | G14: =D14*E14 -> 3 | H14: =F14*G14 -> 165 | M14: =IF(ISNUMBER(SEARCH("Sentadilla",$B14)),IF($C14>=0.5,IF($C14<0.6,$D14*$E14," ")," ")," ") -> 3 | N14: =IF(ISNUMBER(SEARCH("Sentadilla",$B14)),IF($C14>=0.6,IF($C14<0.7,$D14*$E14," ")," ")," ") | O14: =IF(ISNUMBER(SEARCH("Sentadilla",$B14)),IF($C14>=0.7,IF($C14<0.8,$D14*$E14," ")," ")," ") | P14: =IF(ISNUMBER(SEARCH("Sentadilla",$B14)),IF($C14>=0.8,IF($C14<0.9,$D14*$E14," ")," ")," ") | Q14: =IF(ISNUMBER(SEARCH("Sentadilla",$B14)),IF($C14>=0.9,$D14*$E14," ")," ") | R14: =IF(ISNUMBER(SEARCH("Press de banca",$B14)),IF($C14>=0.5,IF($C14<0.6,$D14*$E14," ")," ")," ") | S14: =IF(ISNUMBER(SEARCH("Press de banca",$B14)),IF($C14>=0.6,IF($C14<0.7,$D14*$E14," ")," ")," ") | T14: =IF(ISNUMBER(SEARCH("Press de banca",$B14)),IF($C14>=0.7,IF($C14<0.8,$D14*$E14," ")," ")," ") | U14: =IF(ISNUMBER(SEARCH("Press de banca",$B14)),IF($C14>=0.8,IF($C14<0.9,$D14*$E14," ")," ")," ") | V14: =IF(ISNUMBER(SEARCH("Press de banca",$B14)),IF($C14>=0.9,$D14*$E14," ")," ")
C15: 0.65 | D15: 3 | E15: 1 | F15: ='1RM'!$C$4*C15 -> 65 | G15: =D15*E15 -> 3 | H15: =F15*G15 -> 195 | M15: =IF(ISNUMBER(SEARCH("Sentadilla",$B15)),IF($C15>=0.5,IF($C15<0.6,$D15*$E15," ")," ")," ") | N15: =IF(ISNUMBER(SEARCH("Sentadilla",$B15)),IF($C15>=0.6,IF($C15<0.7,$D15*$E15," ")," ")," ") | O15: =IF(ISNUMBER(SEARCH("Sentadilla",$B15)),IF($C15>=0.7,IF($C15<0.8,$D15*$E15," ")," ")," ") | P15: =IF(ISNUMBER(SEARCH("Sentadilla",$B15)),IF($C15>=0.8,IF($C15<0.9,$D15*$E15," ")," ")," ") | Q15: =IF(ISNUMBER(SEARCH("Sentadilla",$B15)),IF($C15>=0.9,$D15*$E15," ")," ") | R15: =IF(ISNUMBER(SEARCH("Press de banca",$B15)),IF($C15>=0.5,IF($C15<0.6,$D15*$E15," ")," ")," ") | S15: =IF(ISNUMBER(SEARCH("Press de banca",$B15)),IF($C15>=0.6,IF($C15<0.7,$D15*$E15," ")," ")," ") | T15: =IF(ISNUMBER(SEARCH("Press de banca",$B15)),IF($C15>=0.7,IF($C15<0.8,$D15*$E15," ")," ")," ") | U15: =IF(ISNUMBER(SEARCH("Press de banca",$B15)),IF($C15>=0.8,IF($C15<0.9,$D15*$E15," ")," ")," ") | V15: =IF(ISNUMBER(SEARCH("Press de banca",$B15)),IF($C15>=0.9,$D15*$E15," ")," ")
C16: 0.75 | D16: 2 | E16: 4 | F16: ='1RM'!$C$4*C16 -> 75 | G16: =D16*E16 -> 8 | H16: =F16*G16 -> 600 | M16: =IF(ISNUMBER(SEARCH("Sentadilla",$B16)),IF($C16>=0.5,IF($C16<0.6,$D16*$E16," ")," ")," ") | N16: =IF(ISNUMBER(SEARCH("Sentadilla",$B16)),IF($C16>=0.6,IF($C16<0.7,$D16*$E16," ")," ")," ") | O16: =IF(ISNUMBER(SEARCH("Sentadilla",$B16)),IF($C16>=0.7,IF($C16<0.8,$D16*$E16," ")," ")," ") | P16: =IF(ISNUMBER(SEARCH("Sentadilla",$B16)),IF($C16>=0.8,IF($C16<0.9,$D16*$E16," ")," ")," ") | Q16: =IF(ISNUMBER(SEARCH("Sentadilla",$B16)),IF($C16>=0.9,$D16*$E16," ")," ") | R16: =IF(ISNUMBER(SEARCH("Press de banca",$B16)),IF($C16>=0.5,IF($C16<0.6,$D16*$E16," ")," ")," ") | S16: =IF(ISNUMBER(SEARCH("Press de banca",$B16)),IF($C16>=0.6,IF($C16<0.7,$D16*$E16," ")," ")," ") | T16: =IF(ISNUMBER(SEARCH("Press de banca",$B16)),IF($C16>=0.7,IF($C16<0.8,$D16*$E16," ")," ")," ") | U16: =IF(ISNUMBER(SEARCH("Press de banca",$B16)),IF($C16>=0.8,IF($C16<0.9,$D16*$E16," ")," ")," ") | V16: =IF(ISNUMBER(SEARCH("Press de banca",$B16)),IF($C16>=0.9,$D16*$E16," ")," ")
A17: 4 | B17: Press de banca inclinado | D17: 10 | E17: 5
A18: 5 | B18: Abs | D18: 10 | E18: 3
B20: Dia 3 | C20: % | D20: reps | E20: Series | F20: peso
A21: 1 | B21: Peso muerto hasta las rodillas | C21: 0.5 | D21: 3 | E21: 1 | F21: ='1RM'!$C$6*C21 -> 50 | K21: =D21*E21 -> 3 | L21: =F21*K21 -> 150 | R21: =IF(ISNUMBER(SEARCH("Press de banca",$B21)),IF($C21>=0.5,IF($C21<0.6,$D21*$E21," ")," ")," ") | S21: =IF(ISNUMBER(SEARCH("Press de banca",$B21)),IF($C21>=0.6,IF($C21<0.7,$D21*$E21," ")," ")," ") | T21: =IF(ISNUMBER(SEARCH("Press de banca",$B21)),IF($C21>=0.7,IF($C21<0.8,$D21*$E21," ")," ")," ") | U21: =IF(ISNUMBER(SEARCH("Press de banca",$B21)),IF($C21>=0.8,IF($C21<0.9,$D21*$E21," ")," ")," ") | V21: =IF(ISNUMBER(SEARCH("Press de banca",$B21)),IF($C21>=0.9,$D21*$E21," ")," ") | W21: =IF(ISNUMBER(SEARCH("Peso muerto",$B21)),IF($C21>=0.5,IF($C21<0.6,$D21*$E21," ")," ")," ") -> 3 | X21: =IF(ISNUMBER(SEARCH("Peso muerto",$B21)),IF($C21>=0.6,IF($C21<0.7,$D21*$E21," ")," ")," ") | Y21: =IF(ISNUMBER(SEARCH("Peso muerto",$B21)),IF($C21>=0.7,IF($C21<0.8,$D21*$E21," ")," ")," ") | Z21: =IF(ISNUMBER(SEARCH("Peso muerto",$B21)),IF($C21>=0.8,IF($C21<0.9,$D21*$E21," ")," ")," ") | AA21: =IF(ISNUMBER(SEARCH("Peso muerto",$B21)),IF($C21>=0.9,$D21*$E21," ")," ")
C22: 0.6 | D22: 3 | E22: 1 | F22: ='1RM'!$C$6*C22 -> 60 | K22: =D22*E22 -> 3 | L22: =F22*K22 -> 180 | R22: =IF(ISNUMBER(SEARCH("Press de banca",$B22)),IF($C22>=0.5,IF($C22<0.6,$D22*$E22," ")," ")," ") | S22: =IF(ISNUMBER(SEARCH("Press de banca",$B22)),IF($C22>=0.6,IF($C22<0.7,$D22*$E22," ")," ")," ") | T22: =IF(ISNUMBER(SEARCH("Press de banca",$B22)),IF($C22>=0.7,IF($C22<0.8,$D22*$E22," ")," ")," ") | U22: =IF(ISNUMBER(SEARCH("Press de banca",$B22)),IF($C22>=0.8,IF($C22<0.9,$D22*$E22," ")," ")," ") | V22: =IF(ISNUMBER(SEARCH("Press de banca",$B22)),IF($C22>=0.9,$D22*$E22," ")," ") | W22: =IF(ISNUMBER(SEARCH("Peso muerto",$B22)),IF($C22>=0.5,IF($C22<0.6,$D22*$E22," ")," ")," ") | X22: =IF(ISNUMBER(SEARCH("Peso muerto",$B22)),IF($C22>=0.6,IF($C22<0.7,$D22*$E22," ")," ")," ") | Y22: =IF(ISNUMBER(SEARCH("Peso muerto",$B22)),IF($C22>=0.7,IF($C22<0.8,$D22*$E22," ")," ")," ") | Z22: =IF(ISNUMBER(SEARCH("Peso muerto",$B22)),IF($C22>=0.8,IF($C22<0.9,$D22*$E22," ")," ")," ") | AA22: =IF(ISNUMBER(SEARCH("Peso muerto",$B22)),IF($C22>=0.9,$D22*$E22," ")," ")
C23: 0.7 | D23: 3 | E23: 4 | F23: ='1RM'!$C$6*C23 -> 70 | K23: =D23*E23 -> 12 | L23: =F23*K23 -> 840 | R23: =IF(ISNUMBER(SEARCH("Press de banca",$B23)),IF($C23>=0.5,IF($C23<0.6,$D23*$E23," ")," ")," ") | S23: =IF(ISNUMBER(SEARCH("Press de banca",$B23)),IF($C23>=0.6,IF($C23<0.7,$D23*$E23," ")," ")," ") | T23: =IF(ISNUMBER(SEARCH("Press de banca",$B23)),IF($C23>=0.7,IF($C23<0.8,$D23*$E23," ")," ")," ") | U23: =IF(ISNUMBER(SEARCH("Press de banca",$B23)),IF($C23>=0.8,IF($C23<0.9,$D23*$E23," ")," ")," ") | V23: =IF(ISNUMBER(SEARCH("Press de banca",$B23)),IF($C23>=0.9,$D23*$E23," ")," ") | W23: =IF(ISNUMBER(SEARCH("Peso muerto",$B23)),IF($C23>=0.5,IF($C23<0.6,$D23*$E23," ")," ")," ") | X23: =IF(ISNUMBER(SEARCH("Peso muerto",$B23)),IF($C23>=0.6,IF($C23<0.7,$D23*$E23," ")," ")," ") | Y23: =IF(ISNUMBER(SEARCH("Peso muerto",$B23)),IF($C23>=0.7,IF($C23<0.8,$D23*$E23," ")," ")," ") | Z23: =IF(ISNUMBER(SEARCH("Peso muerto",$B23)),IF($C23>=0.8,IF($C23<0.9,$D23*$E23," ")," ")," ") | AA23: =IF(ISNUMBER(SEARCH("Peso muerto",$B23)),IF($C23>=0.9,$D23*$E23," ")," ")
A24: 2 | B24: Press de banca | C24: 0.5 | D24: 5 | E24: 1 | F24: ='1RM'!$C$5*C24 -> 50 | I24: =D24*E24 -> 5 | J24: =F24*I24 -> 250 | R24: =IF(ISNUMBER(SEARCH("Press de banca",$B24)),IF($C24>=0.5,IF($C24<0.6,$D24*$E24," ")," ")," ") -> 5 | S24: =IF(ISNUMBER(SEARCH("Press de banca",$B24)),IF($C24>=0.6,IF($C24<0.7,$D24*$E24," ")," ")," ") | T24: =IF(ISNUMBER(SEARCH("Press de banca",$B24)),IF($C24>=0.7,IF($C24<0.8,$D24*$E24," ")," ")," ") | U24: =IF(ISNUMBER(SEARCH("Press de banca",$B24)),IF($C24>=0.8,IF($C24<0.9,$D24*$E24," ")," ")," ") | V24: =IF(ISNUMBER(SEARCH("Press de banca",$B24)),IF($C24>=0.9,$D24*$E24," ")," ") | W24: =IF(ISNUMBER(SEARCH("Peso muerto",$B24)),IF($C24>=0.5,IF($C24<0.6,$D24*$E24," ")," ")," ") | X24: =IF(ISNUMBER(SEARCH("Peso muerto",$B24)),IF($C24>=0.6,IF($C24<0.7,$D24*$E24," ")," ")," ") | Y24: =IF(ISNUMBER(SEARCH("Peso muerto",$B24)),IF($C24>=0.7,IF($C24<0.8,$D24*$E24," ")," ")," ") | Z24: =IF(ISNUMBER(SEARCH("Peso muerto",$B24)),IF($C24>=0.8,IF($C24<0.9,$D24*$E24," ")," ")," ") | AA24: =IF(ISNUMBER(SEARCH("Peso muerto",$B24)),IF($C24>=0.9,$D24*$E24," ")," ")
C25: 0.6 | D25: 5 | E25: 1 | F25: ='1RM'!$C$5*C25 -> 60 | I25: =D25*E25 -> 5 | J25: =F25*I25 -> 300 | R25: =IF(ISNUMBER(SEARCH("Press de banca",$B25)),IF($C25>=0.5,IF($C25<0.6,$D25*$E25," ")," ")," ") | S25: =IF(ISNUMBER(SEARCH("Press de banca",$B25)),IF($C25>=0.6,IF($C25<0.7,$D25*$E25," ")," ")," ") | T25: =IF(ISNUMBER(SEARCH("Press de banca",$B25)),IF($C25>=0.7,IF($C25<0.8,$D25*$E25," ")," ")," ") | U25: =IF(ISNUMBER(SEARCH("Press de banca",$B25)),IF($C25>=0.8,IF($C25<0.9,$D25*$E25," ")," ")," ") | V25: =IF(ISNUMBER(SEARCH("Press de banca",$B25)),IF($C25>=0.9,$D25*$E25," ")," ") | W25: =IF(ISNUMBER(SEARCH("Peso muerto",$B25)),IF($C25>=0.5,IF($C25<0.6,$D25*$E25," ")," ")," ") | X25: =IF(ISNUMBER(SEARCH("Peso muerto",$B25)),IF($C25>=0.6,IF($C25<0.7,$D25*$E25," ")," ")," ") | Y25: =IF(ISNUMBER(SEARCH("Peso muerto",$B25)),IF($C25>=0.7,IF($C25<0.8,$D25*$E25," ")," ")," ") | Z25: =IF(ISNUMBER(SEARCH("Peso muerto",$B25)),IF($C25>=0.8,IF($C25<0.9,$D25*$E25," ")," ")," ") | AA25: =IF(ISNUMBER(SEARCH("Peso muerto",$B25)),IF($C25>=0.9,$D25*$E25," ")," ")
C26: 0.7 | D26: 3 | E26: 1 | F26: ='1RM'!$C$5*C26 -> 70 | I26: =D26*E26 -> 3 | J26: =F26*I26 -> 210 | R26: =IF(ISNUMBER(SEARCH("Press de banca",$B26)),IF($C26>=0.5,IF($C26<0.6,$D26*$E26," ")," ")," ") | S26: =IF(ISNUMBER(SEARCH("Press de banca",$B26)),IF($C26>=0.6,IF($C26<0.7,$D26*$E26," ")," ")," ") | T26: =IF(ISNUMBER(SEARCH("Press de banca",$B26)),IF($C26>=0.7,IF($C26<0.8,$D26*$E26," ")," ")," ") | U26: =IF(ISNUMBER(SEARCH("Press de banca",$B26)),IF($C26>=0.8,IF($C26<0.9,$D26*$E26," ")," ")," ") | V26: =IF(ISNUMBER(SEARCH("Press de banca",$B26)),IF($C26>=0.9,$D26*$E26," ")," ") | W26: =IF(ISNUMBER(SEARCH("Peso muerto",$B26)),IF($C26>=0.5,IF($C26<0.6,$D26*$E26," ")," ")," ") | X26: =IF(ISNUMBER(SEARCH("Peso muerto",$B26)),IF($C26>=0.6,IF($C26<0.7,$D26*$E26," ")," ")," ") | Y26: =IF(ISNUMBER(SEARCH("Peso muerto",$B26)),IF($C26>=0.7,IF($C26<0.8,$D26*$E26," ")," ")," ") | Z26: =IF(ISNUMBER(SEARCH("Peso muerto",$B26)),IF($C26>=0.8,IF($C26<0.9,$D26*$E26," ")," ")," ") | AA26: =IF(ISNUMBER(SEARCH("Peso muerto",$B26)),IF($C26>=0.9,$D26*$E26," ")," ")
C27: 0.7 | D27: 5 | E27: 1 | F27: ='1RM'!$C$5*C27 -> 70 | I27: =D27*E27 -> 5 | J27: =F27*I27 -> 350 | R27: =IF(ISNUMBER(SEARCH("Press de banca",$B27)),IF($C27>=0.5,IF($C27<0.6,$D27*$E27," ")," ")," ") | S27: =IF(ISNUMBER(SEARCH("Press de banca",$B27)),IF($C27>=0.6,IF($C27<0.7,$D27*$E27," ")," ")," ") | T27: =IF(ISNUMBER(SEARCH("Press de banca",$B27)),IF($C27>=0.7,IF($C27<0.8,$D27*$E27," ")," ")," ") | U27: =IF(ISNUMBER(SEARCH("Press de banca",$B27)),IF($C27>=0.8,IF($C27<0.9,$D27*$E27," ")," ")," ") | V27: =IF(ISNUMBER(SEARCH("Press de banca",$B27)),IF($C27>=0.9,$D27*$E27," ")," ") | W27: =IF(ISNUMBER(SEARCH("Peso muerto",$B27)),IF($C27>=0.5,IF($C27<0.6,$D27*$E27," ")," ")," ") | X27: =IF(ISNUMBER(SEARCH("Peso muerto",$B27)),IF($C27>=0.6,IF($C27<0.7,$D27*$E27," ")," ")," ") | Y27: =IF(ISNUMBER(SEARCH("Peso muerto",$B27)),IF($C27>=0.7,IF($C27<0.8,$D27*$E27," ")," ")," ") | Z27: =IF(ISNUMBER(SEARCH("Peso muerto",$B27)),IF($C27>=0.8,IF($C27<0.9,$D27*$E27," ")," ")," ") | AA27: =IF(ISNUMBER(SEARCH("Peso muerto",$B27)),IF($C27>=0.9,$D27*$E27," ")," ")
C28: 0.7 | D28: 7 | E28: 1 | F28: ='1RM'!$C$5*C28 -> 70 | I28: =D28*E28 -> 7 | J28: =F28*I28 -> 490 | R28: =IF(ISNUMBER(SEARCH("Press de banca",$B28)),IF($C28>=0.5,IF($C28<0.6,$D28*$E28," ")," ")," ") | S28: =IF(ISNUMBER(SEARCH("Press de banca",$B28)),IF($C28>=0.6,IF($C28<0.7,$D28*$E28," ")," ")," ") | T28: =IF(ISNUMBER(SEARCH("Press de banca",$B28)),IF($C28>=0.7,IF($C28<0.8,$D28*$E28," ")," ")," ") | U28: =IF(ISNUMBER(SEARCH("Press de banca",$B28)),IF($C28>=0.8,IF($C28<0.9,$D28*$E28," ")," ")," ") | V28: =IF(ISNUMBER(SEARCH("Press de banca",$B28)),IF($C28>=0.9,$D28*$E28," ")," ") | W28: =IF(ISNUMBER(SEARCH("Peso muerto",$B28)),IF($C28>=0.5,IF($C28<0.6,$D28*$E28," ")," ")," ") | X28: =IF(ISNUMBER(SEARCH("Peso muerto",$B28)),IF($C28>=0.6,IF($C28<0.7,$D28*$E28," ")," ")," ") | Y28: =IF(ISNUMBER(SEARCH("Peso muerto",$B28)),IF($C28>=0.7,IF($C28<0.8,$D28*$E28," ")," ")," ") | Z28: =IF(ISNUMBER(SEARCH("Peso muerto",$B28)),IF($C28>=0.8,IF($C28<0.9,$D28*$E28," ")," ")," ") | AA28: =IF(ISNUMBER(SEARCH("Peso muerto",$B28)),IF($C28>=0.9,$D28*$E28," ")," ")
C29: 0.7 | D29: 4 | E29: 1 | F29: ='1RM'!$C$5*C29 -> 70 | I29: =D29*E29 -> 4 | J29: =F29*I29 -> 280 | R29: =IF(ISNUMBER(SEARCH("Press de banca",$B29)),IF($C29>=0.5,IF($C29<0.6,$D29*$E29," ")," ")," ") | S29: =IF(ISNUMBER(SEARCH("Press de banca",$B29)),IF($C29>=0.6,IF($C29<0.7,$D29*$E29," ")," ")," ") | T29: =IF(ISNUMBER(SEARCH("Press de banca",$B29)),IF($C29>=0.7,IF($C29<0.8,$D29*$E29," ")," ")," ") | U29: =IF(ISNUMBER(SEARCH("Press de banca",$B29)),IF($C29>=0.8,IF($C29<0.9,$D29*$E29," ")," ")," ") | V29: =IF(ISNUMBER(SEARCH("Press de banca",$B29)),IF($C29>=0.9,$D29*$E29," ")," ") | W29: =IF(ISNUMBER(SEARCH("Peso muerto",$B29)),IF($C29>=0.5,IF($C29<0.6,$D29*$E29," ")," ")," ") | X29: =IF(ISNUMBER(SEARCH("Peso muerto",$B29)),IF($C29>=0.6,IF($C29<0.7,$D29*$E29," ")," ")," ") | Y29: =IF(ISNUMBER(SEARCH("Peso muerto",$B29)),IF($C29>=0.7,IF($C29<0.8,$D29*$E29," ")," ")," ") | Z29: =IF(ISNUMBER(SEARCH("Peso muerto",$B29)),IF($C29>=0.8,IF($C29<0.9,$D29*$E29," ")," ")," ") | AA29: =IF(ISNUMBER(SEARCH("Peso muerto",$B29)),IF($C29>=0.9,$D29*$E29," ")," ")
C30: 0.7 | D30: 6 | E30: 1 | F30: ='1RM'!$C$5*C30 -> 70 | I30: =D30*E30 -> 6 | J30: =F30*I30 -> 420 | R30: =IF(ISNUMBER(SEARCH("Press de banca",$B30)),IF($C30>=0.5,IF($C30<0.6,$D30*$E30," ")," ")," ") | S30: =IF(ISNUMBER(SEARCH("Press de banca",$B30)),IF($C30>=0.6,IF($C30<0.7,$D30*$E30," ")," ")," ") | T30: =IF(ISNUMBER(SEARCH("Press de banca",$B30)),IF($C30>=0.7,IF($C30<0.8,$D30*$E30," ")," ")," ") | U30: =IF(ISNUMBER(SEARCH("Press de banca",$B30)),IF($C30>=0.8,IF($C30<0.9,$D30*$E30," ")," ")," ") | V30: =IF(ISNUMBER(SEARCH("Press de banca",$B30)),IF($C30>=0.9,$D30*$E30," ")," ") | W30: =IF(ISNUMBER(SEARCH("Peso muerto",$B30)),IF($C30>=0.5,IF($C30<0.6,$D30*$E30," ")," ")," ") | X30: =IF(ISNUMBER(SEARCH("Peso muerto",$B30)),IF($C30>=0.6,IF($C30<0.7,$D30*$E30," ")," ")," ") | Y30: =IF(ISNUMBER(SEARCH("Peso muerto",$B30)),IF($C30>=0.7,IF($C30<0.8,$D30*$E30," ")," ")," ") | Z30: =IF(ISNUMBER(SEARCH("Peso muerto",$B30)),IF($C30>=0.8,IF($C30<0.9,$D30*$E30," ")," ")," ") | AA30: =IF(ISNUMBER(SEARCH("Peso muerto",$B30)),IF($C30>=0.9,$D30*$E30," ")," ")
C31: 0.7 | D31: 8 | E31: 1 | F31: ='1RM'!$C$5*C31 -> 70 | I31: =D31*E31 -> 8 | J31: =F31*I31 -> 560 | R31: =IF(ISNUMBER(SEARCH("Press de banca",$B31)),IF($C31>=0.5,IF($C31<0.6,$D31*$E31," ")," ")," ") | S31: =IF(ISNUMBER(SEARCH("Press de banca",$B31)),IF($C31>=0.6,IF($C31<0.7,$D31*$E31," ")," ")," ") | T31: =IF(ISNUMBER(SEARCH("Press de banca",$B31)),IF($C31>=0.7,IF($C31<0.8,$D31*$E31," ")," ")," ") | U31: =IF(ISNUMBER(SEARCH("Press de banca",$B31)),IF($C31>=0.8,IF($C31<0.9,$D31*$E31," ")," ")," ") | V31: =IF(ISNUMBER(SEARCH("Press de banca",$B31)),IF($C31>=0.9,$D31*$E31," ")," ") | W31: =IF(ISNUMBER(SEARCH("Peso muerto",$B31)),IF($C31>=0.5,IF($C31<0.6,$D31*$E31," ")," ")," ") | X31: =IF(ISNUMBER(SEARCH("Peso muerto",$B31)),IF($C31>=0.6,IF($C31<0.7,$D31*$E31," ")," ")," ") | Y31: =IF(ISNUMBER(SEARCH("Peso muerto",$B31)),IF($C31>=0.7,IF($C31<0.8,$D31*$E31," ")," ")," ") | Z31: =IF(ISNUMBER(SEARCH("Peso muerto",$B31)),IF($C31>=0.8,IF($C31<0.9,$D31*$E31," ")," ")," ") | AA31: =IF(ISNUMBER(SEARCH("Peso muerto",$B31)),IF($C31>=0.9,$D31*$E31," ")," ")
A32: 3 | B32: Peso muerto con pausa | C32: 0.55 | D32: 3 | E32: 1 | F32: ='1RM'!$C$6*C32 -> 55 | K32: =D32*E32 -> 3 | L32: =F32*K32 -> 165 | R32: =IF(ISNUMBER(SEARCH("Press de banca",$B32)),IF($C32>=0.5,IF($C32<0.6,$D32*$E32," ")," ")," ") | S32: =IF(ISNUMBER(SEARCH("Press de banca",$B32)),IF($C32>=0.6,IF($C32<0.7,$D32*$E32," ")," ")," ") | T32: =IF(ISNUMBER(SEARCH("Press de banca",$B32)),IF($C32>=0.7,IF($C32<0.8,$D32*$E32," ")," ")," ") | U32: =IF(ISNUMBER(SEARCH("Press de banca",$B32)),IF($C32>=0.8,IF($C32<0.9,$D32*$E32," ")," ")," ") | V32: =IF(ISNUMBER(SEARCH("Press de banca",$B32)),IF($C32>=0.9,$D32*$E32," ")," ") | W32: =IF(ISNUMBER(SEARCH("Peso muerto",$B32)),IF($C32>=0.5,IF($C32<0.6,$D32*$E32," ")," ")," ") -> 3 | X32: =IF(ISNUMBER(SEARCH("Peso muerto",$B32)),IF($C32>=0.6,IF($C32<0.7,$D32*$E32," ")," ")," ") | Y32: =IF(ISNUMBER(SEARCH("Peso muerto",$B32)),IF($C32>=0.7,IF($C32<0.8,$D32*$E32," ")," ")," ") | Z32: =IF(ISNUMBER(SEARCH("Peso muerto",$B32)),IF($C32>=0.8,IF($C32<0.9,$D32*$E32," ")," ")," ") | AA32: =IF(ISNUMBER(SEARCH("Peso muerto",$B32)),IF($C32>=0.9,$D32*$E32," ")," ")
C33: 0.65 | D33: 3 | E33: 1 | F33: ='1RM'!$C$6*C33 -> 65 | K33: =D33*E33 -> 3 | L33: =F33*K33 -> 195 | R33: =IF(ISNUMBER(SEARCH("Press de banca",$B33)),IF($C33>=0.5,IF($C33<0.6,$D33*$E33," ")," ")," ") | S33: =IF(ISNUMBER(SEARCH("Press de banca",$B33)),IF($C33>=0.6,IF($C33<0.7,$D33*$E33," ")," ")," ") | T33: =IF(ISNUMBER(SEARCH("Press de banca",$B33)),IF($C33>=0.7,IF($C33<0.8,$D33*$E33," ")," ")," ") | U33: =IF(ISNUMBER(SEARCH("Press de banca",$B33)),IF($C33>=0.8,IF($C33<0.9,$D33*$E33," ")," ")," ") | V33: =IF(ISNUMBER(SEARCH("Press de banca",$B33)),IF($C33>=0.9,$D33*$E33," ")," ") | W33: =IF(ISNUMBER(SEARCH("Peso muerto",$B33)),IF($C33>=0.5,IF($C33<0.6,$D33*$E33," ")," ")," ") | X33: =IF(ISNUMBER(SEARCH("Peso muerto",$B33)),IF($C33>=0.6,IF($C33<0.7,$D33*$E33," ")," ")," ") | Y33: =IF(ISNUMBER(SEARCH("Peso muerto",$B33)),IF($C33>=0.7,IF($C33<0.8,$D33*$E33," ")," ")," ") | Z33: =IF(ISNUMBER(SEARCH("Peso muerto",$B33)),IF($C33>=0.8,IF($C33<0.9,$D33*$E33," ")," ")," ") | AA33: =IF(ISNUMBER(SEARCH("Peso muerto",$B33)),IF($C33>=0.9,$D33*$E33," ")," ")
C34: 0.75 | D34: 2 | E34: 4 | F34: ='1RM'!$C$6*C34 -> 75 | K34: =D34*E34 -> 8 | L34: =F34*K34 -> 600 | R34: =IF(ISNUMBER(SEARCH("Press de banca",$B34)),IF($C34>=0.5,IF($C34<0.6,$D34*$E34," ")," ")," ") | S34: =IF(ISNUMBER(SEARCH("Press de banca",$B34)),IF($C34>=0.6,IF($C34<0.7,$D34*$E34," ")," ")," ") | T34: =IF(ISNUMBER(SEARCH("Press de banca",$B34)),IF($C34>=0.7,IF($C34<0.8,$D34*$E34," ")," ")," ") | U34: =IF(ISNUMBER(SEARCH("Press de banca",$B34)),IF($C34>=0.8,IF($C34<0.9,$D34*$E34," ")," ")," ") | V34: =IF(ISNUMBER(SEARCH("Press de banca",$B34)),IF($C34>=0.9,$D34*$E34," ")," ") | W34: =IF(ISNUMBER(SEARCH("Peso muerto",$B34)),IF($C34>=0.5,IF($C34<0.6,$D34*$E34," ")," ")," ") | X34: =IF(ISNUMBER(SEARCH("Peso muerto",$B34)),IF($C34>=0.6,IF($C34<0.7,$D34*$E34," ")," ")," ") | Y34: =IF(ISNUMBER(SEARCH("Peso muerto",$B34)),IF($C34>=0.7,IF($C34<0.8,$D34*$E34," ")," ")," ") | Z34: =IF(ISNUMBER(SEARCH("Peso muerto",$B34)),IF($C34>=0.8,IF($C34<0.9,$D34*$E34," ")," ")," ") | AA34: =IF(ISNUMBER(SEARCH("Peso muerto",$B34)),IF($C34>=0.9,$D34*$E34," ")," ")
A35: 4 | B35: Dominadas | D35: 10 | E35: 5
A36: 5 | B36: Buenos dias | D36: 5 | E36: 5
B38: Dia 5 | C38: % | D38: reps | E38: Series | F38: peso
A39: 1 | B39: Press de banca | C39: 0.5 | D39: 5 | E39: 1 | F39: ='1RM'!$C$5*C39 -> 50 | I39: =D39*E39 -> 5 | J39: =F39*I39 -> 250 | M39: =IF(ISNUMBER(SEARCH("Sentadilla",$B39)),IF($C39>=0.5,IF($C39<0.6,$D39*$E39," ")," ")," ") | N39: =IF(ISNUMBER(SEARCH("Sentadilla",$B39)),IF($C39>=0.6,IF($C39<0.7,$D39*$E39," ")," ")," ") | O39: =IF(ISNUMBER(SEARCH("Sentadilla",$B39)),IF($C39>=0.7,IF($C39<0.8,$D39*$E39," ")," ")," ") | P39: =IF(ISNUMBER(SEARCH("Sentadilla",$B39)),IF($C39>=0.8,IF($C39<0.9,$D39*$E39," ")," ")," ") | Q39: =IF(ISNUMBER(SEARCH("Sentadilla",$B39)),IF($C39>=0.9,$D39*$E39," ")," ") | R39: =IF(ISNUMBER(SEARCH("Press de banca",$B39)),IF($C39>=0.5,IF($C39<0.6,$D39*$E39," ")," ")," ") -> 5 | S39: =IF(ISNUMBER(SEARCH("Press de banca",$B39)),IF($C39>=0.6,IF($C39<0.7,$D39*$E39," ")," ")," ") | T39: =IF(ISNUMBER(SEARCH("Press de banca",$B39)),IF($C39>=0.7,IF($C39<0.8,$D39*$E39," ")," ")," ") | U39: =IF(ISNUMBER(SEARCH("Press de banca",$B39)),IF($C39>=0.8,IF($C39<0.9,$D39*$E39," ")," ")," ") | V39: =IF(ISNUMBER(SEARCH("Press de banca",$B39)),IF($C39>=0.9,$D39*$E39," ")," ")
