Workbook

Sheet Max
A1: WWW.BIBLIOTECADERUTINAS.COM
A2: iNTRODUCIR 1RM | Z2: Made by ChaseT 2008.05.09
A3: SENTADILLA | B3: 100 | D3: Sheiko Advanced Small Load
A4: PRESS DE BANCA | B4: 100
A5: PESO MUERTO | B5: 100
E13: Download the spreadsheet in order to edit it.
E15: Get the official Sheiko mobile app for more.
E17: Exclusive /PLG/ content brought to you by trappy-chan ;3
A19: How to run the program: | H19: Which program to run?
A20: Not competing: Run any amount of Prep cycles, then test new maxes. Restart. | H20: Large load: | J20: Light to Medium bodyweight (men) Light to Heavy bodyweight (women)
A22: Competing: Run any amount of Prep cycles plus the Comp cycle. Adjust the program length so that the last week of the Comp cycle ends at the competition. | H22: Medium load: | J22: Medium to Heavy bodyweight (men) Heavy to Superheavy bodyweight (women)
H24: Small load: | J24: Heavy to Superheavy bodyweight (men)
A25: Inflating/Deloading: If you feel the weights are too light or heavy, adjust your maxes so that you achieve a good moderate difficulty that's heavy but allows you to perform every set with perfect technique. Keep in mind some workouts are intentionally lighter/easier than others.
A29: Adjusting maxes: If you get a new PR during the program, you can adjust your maxes to the new value. However, if the competition is in less than 30 days, it is recommended to keep the old maxes instead.
B33: \/ Click on the sheets below \/

Sheet Prep 1
B1: Sheiko
B2: Prep period 1 (4 weeks)
A5: week 1 | M5: squat | R5: bench | W5: deadlift | AC5: week 2 | AJ5: week 3 | AQ5: week 4
A6: 1 day (Monday) | C6: % | D6: reps | E6: sets | F6: weight | M6: 50-59 | N6: 60-69 | O6: 70-79 | P6: 80-89 | Q6: 90+ | R6: 50-59 | S6: 60-69 | T6: 70-79 | U6: 80-89 | V6: 90+ | W6: 50-59 | X6: 60-69 | Y6: 70-79 | Z6: 80-89 | AA6: 90+ | AC6: 1 day (Monday) | AE6: % | AF6: reps | AG6: sets | AH6: weight | AJ6: 1 day (Monday) | AL6: % | AM6: reps | AN6: sets | AO6: weight | AQ6: 1 day (Monday) | AS6: % | AT6: reps | AU6: sets | AV6: weight
A7: 1 | B7: Squat | C7: 0.5 | D7: 5 | E7: 1 | F7: =Max!$B$3*C7 -> 50 | I7: =D7*E7 -> 5 | J7: =F7*I7 -> 250 | R7: =I7 -> 5 | S7: =I8 -> 4 | T7: =I9+I10 -> 11 | U7: 0 | V7: 0 | AC7: 1 | AD7: Bench press | AE7: 0.5 | AF7: 5 | AG7: 1 | AH7: =Max!$B$4*AE7 -> 50 | AJ7: 1 | AK7: Squat | AL7: 0.5 | AM7: 5 | AN7: 1 | AO7: =Max!$B$3*AL7 -> 50 | AQ7: 1 | AR7: Squat | AS7: 0.5 | AT7: 5 | AU7: 1 | AV7: =Max!$B$3*AS7 -> 50
C8: 0.6 | D8: 4 | E8: 1 | F8: =Max!$B$3*C8 -> 60 | I8: =D8*E8 -> 4 | J8: =F8*I8 -> 240 | AE8: 0.6 | AF8: 4 | AG8: 1 | AH8: =Max!$B$4*AE8 -> 60 | AL8: 0.6 | AM8: 4 | AN8: 1 | AO8: =Max!$B$3*AL8 -> 60 | AS8: 0.6 | AT8: 4 | AU8: 1 | AV8: =Max!$B$3*AS8 -> 60
C9: 0.7 | D9: 3 | E9: 1 | F9: =Max!$B$3*C9 -> 70 | I9: =D9*E9 -> 3 | J9: =F9*I9 -> 210 | AE9: 0.7 | AF9: 3 | AG9: 1 | AH9: =Max!$B$4*AE9 -> 70 | AL9: 0.7 | AM9: 3 | AN9: 1 | AO9: =Max!$B$3*AL9 -> 70 | AS9: 0.7 | AT9: 3 | AU9: 1 | AV9: =Max!$B$3*AS9 -> 70
C10: 0.75 | D10: 2 | E10: 4 | F10: =Max!$B$3*C10 -> 75 | I10: =D10*E10 -> 8 | J10: =F10*I10 -> 600 | AE10: 0.8 | AF10: 2 | AG10: 4 | AH10: =Max!$B$4*AE10 -> 80 | AL10: 0.8 | AM10: 2 | AN10: 5 | AO10: =Max!$B$3*AL10 -> 80 | AS10: 0.8 | AT10: 3 | AU10: 4 | AV10: =Max!$B$3*AS10 -> 80
A11: 2 | B11: Bench press | C11: 0.5 | D11: 5 | E11: 1 | F11: =Max!$B$4*C11 -> 50 | G11: =D11*E11 -> 5 | H11: =F11*G11 -> 250 | M11: =G11 -> 5 | N11: =G12 -> 4 | O11: =G13 -> 3 | P11: 0 | Q11: 0 | AC11: 2 | AD11: Squat | AE11: 0.5 | AF11: 5 | AG11: 1 | AH11: =Max!$B$3*AE11 -> 50 | AJ11: 2 | AK11: Bench press | AL11: 0.55 | AM11: 5 | AN11: 1 | AO11: =Max!$B$4*AL11 -> 55 | AQ11: 2 | AR11: Bench press | AS11: 0.5 | AT11: 5 | AU11: 1 | AV11: =Max!$B$4*AS11 -> 50
C12: 0.6 | D12: 4 | E12: 1 | F12: =Max!$B$4*C12 -> 60 | G12: =D12*E12 -> 4 | H12: =F12*G12 -> 240 | AE12: 0.6 | AF12: 4 | AG12: 1 | AH12: =Max!$B$3*AE12 -> 60 | AL12: 0.65 | AM12: 4 | AN12: 1 | AO12: =Max!$B$4*AL12 -> 65 | AS12: 0.6 | AT12: 4 | AU12: 1 | AV12: =Max!$B$4*AS12 -> 60
C13: 0.7 | D13: 3 | E13: 1 | F13: =Max!$B$4*C13 -> 70 | G13: =D13*E13 -> 3 | H13: =F13*G13 -> 210 | AE13: 0.7 | AF13: 3 | AG13: 1 | AH13: =Max!$B$3*AE13 -> 70 | AL13: 0.75 | AM13: 3 | AN13: 1 | AO13: =Max!$B$4*AL13 -> 75 | AS13: 0.7 | AT13: 3 | AU13: 1 | AV13: =Max!$B$4*AS13 -> 70
C14: 0.75 | D14: 3 | E14: 4 | F14: =Max!$B$4*C14 -> 75 | I14: =D14*E14 -> 12 | J14: =F14*I14 -> 900 | R14: =I14 -> 12 | S14: =I15+I16 -> 80 | T14: 0 | U14: 0 | V14: 0 | AE14: 0.75 | AF14: 3 | AG14: 4 | AH14: =Max!$B$3*AE14 -> 75 | AL14: 0.85 | AM14: 2 | AN14: 4 | AO14: =Max!$B$4*AL14 -> 85 | AS14: 0.8 | AT14: 3 | AU14: 5 | AV14: =Max!$B$4*AS14 -> 80
A15: 3 | B15: Chest muscles | C15: 0.65 | D15: 8 | E15: 5 | I15: =D15*E15 -> 40 | J15: =F15*I15 -> 0 | AC15: 3 | AD15: Bench press | AE15: 0.55 | AF15: 3 | AG15: 1 | AH15: =Max!$B$4*AE15 -> 55 | AJ15: 3 | AK15: Chest muscles | AL15: 0.65 | AM15: 8 | AN15: 5 | AQ15: 3 | AR15: Chest muscles | AS15: 0.65 | AT15: 8 | AU15: 5
A16: 4 | B16: Lat Mucles | C16: 0.65 | D16: 8 | E16: 5 | I16: =D16*E16 -> 40 | J16: =F16*I16 -> 0 | AE16: 0.65 | AF16: 3 | AG16: 1 | AH16: =Max!$B$4*AE16 -> 65 | AJ16: 4 | AK16: Dips | AL16: 0.75 | AM16: 5 | AN16: 5 | AQ16: 4 | AR16: Good morning (standing) | AS16: 0.75 | AT16: 5 | AU16: 5
A17: 5 | B17: Good morning (sitting) | C17: 0.6 | D17: 10 | E17: 3 | AE17: 0.75 | AF17: 3 | AG17: 4 | AH17: =Max!$B$4*AE17 -> 75 | AJ17: 5 | AK17: Good morning (sitting) | AL17: 0.75 | AM17: 5 | AN17: 5
AC18: 4 | AD18: Chest muscles | AE18: 0.7 | AF18: 6 | AG18: 5
A19: 3 day (Wednesday) | C19: % | D19: reps | E19: sets | F19: weight | AC19: 5 | AD19: Back Extensions | AE19: 0.65 | AF19: 8 | AG19: 4 | AJ19: 3 day (Wednesday) | AL19: % | AM19: reps | AN19: sets | AO19: weight | AQ19: 3 day (Wednesday) | AS19: % | AT19: reps | AU19: sets | AV19: weight
A20: 1 | B20: Deadlift (Pause below knees) | C20: 0.5 | D20: 3 | E20: 1 | F20: =Max!$B$5*C20 -> 50 | AJ20: 1 | AK20: Deficit deadlift | AL20: 0.5 | AM20: 3 | AN20: 1 | AO20: =Max!$B$5*AL20 -> 50 | AQ20: 1 | AR20: Bench press | AS20: 0.5 | AT20: 5 | AU20: 1 | AV20: =Max!$B$4*AS20 -> 50
C21: 0.6 | D21: 3 | E21: 1 | F21: =Max!$B$5*C21 -> 60 | K21: =D18*E18 -> 0 | L21: =F18*K21 -> 0 | W21: =K21 -> 0 | X21: =K22 -> #VALUE! | Y21: =K23+K24 -> 6 | Z21: 0 | AA21: 0 | AC21: 3 day (Wednesday) | AE21: % | AF21: reps | AG21: sets | AH21: weight | AL21: 0.6 | AM21: 3 | AN21: 1 | AO21: =Max!$B$5*AL21 -> 60 | AS21: 0.6 | AT21: 4 | AU21: 1 | AV21: =Max!$B$4*AS21 -> 60
C22: 0.7 | D22: 2 | E22: 1 | F22: =Max!$B$5*C22 -> 70 | K22: =D19*E19 -> #VALUE! | L22: =F19*K22 -> #VALUE! | AC22: 1 | AD22: Bench press | AE22: 0.5 | AF22: 5 | AG22: 1 | AH22: =Max!$B$4*AE22 -> 50 | AL22: 0.65 | AM22: 3 | AN22: 1 | AO22: =Max!$B$5*AL22 -> 65 | AS22: 0.7 | AT22: 3 | AU22: 1 | AV22: =Max!$B$4*AS22 -> 70
C23: 0.75 | D23: 2 | E23: 4 | F23: =Max!$B$5*C23 -> 75 | K23: =D20*E20 -> 3 | L23: =F20*K23 -> 150 | AE23: 0.6 | AF23: 4 | AG23: 1 | AH23: =Max!$B$4*AE23 -> 60 | AL23: 0.7 | AM23: 2 | AN23: 4 | AO23: =Max!$B$5*AL23 -> 70 | AS23: 0.8 | AT23: 3 | AU23: 1 | AV23: =Max!$B$4*AS23 -> 80
A24: 2 | B24: Bench press | C24: 0.5 | D24: 5 | E24: 1 | F24: =Max!$B$4*C24 -> 50 | K24: =D21*E21 -> 3 | L24: =F21*K24 -> 180 | AE24: 0.7 | AF24: 3 | AG24: 1 | AH24: =Max!$B$4*AE24 -> 70 | AJ24: 2 | AK24: Bench press | AL24: 0.5 | AM24: 3 | AN24: 1 | AO24: =Max!$B$4*AL24 -> 50 | AS24: 0.85 | AT24: 2 | AU24: 1 | AV24: =Max!$B$4*AS24 -> 85
C25: 0.6 | D25: 4 | E25: 1 | F25: =Max!$B$4*C25 -> 60 | AE25: 0.8 | AF25: 2 | AG25: 5 | AH25: =Max!$B$4*AE25 -> 80 | AL25: 0.6 | AM25: 3 | AN25: 1 | AO25: =Max!$B$4*AL25 -> 60 | AS25: 0.9 | AT25: 1 | AU25: 2 | AV25: =Max!$B$4*AS25 -> 90
C26: 0.7 | D26: 3 | E26: 1 | F26: =Max!$B$4*C26 -> 70 | AC26: 1 | AD26: Deadlift up to knees | AE26: 0.5 | AF26: 3 | AG26: 1 | AH26: =Max!$B$5*AE26 -> 50 | AL26: 0.7 | AM26: 3 | AN26: 1 | AO26: =Max!$B$4*AL26 -> 70 | AS26: 0.75 | AT26: 4 | AU26: 1 | AV26: =Max!$B$4*AS26 -> 75
C27: 0.8 | D27: 2 | E27: 4 | F27: =Max!$B$4*C27 -> 80 | AE27: 0.6 | AF27: 3 | AG27: 1 | AH27: =Max!$B$5*AE27 -> 60 | AL27: 0.8 | AM27: 2 | AN27: 4 | AO27: =Max!$B$4*AL27 -> 80 | AQ27: 2 | AR27: Deadlift up to knees | AS27: 0.5 | AT27: 3 | AU27: 1 | AV27: =Max!$B$5*AS27 -> 50
A28: 3 | B28: Triceps | C28: 0.7 | D28: 6 | E28: 5 | K28: =D25*E25 -> 4 | L28: =F25*K28 -> 240 | W28: 0 | X28: =K28 -> 4 | Y28: =K29 -> 3 | Z28: =K30 -> 8 | AA28: 0 | AE28: 0.7 | AF28: 3 | AG28: 1 | AH28: =Max!$B$5*AE28 -> 70 | AJ28: 3 | AK28: Deadlift from boxes | AL28: 0.6 | AM28: 4 | AN28: 1 | AO28: =Max!$B$5*AL28 -> 60 | AS28: 0.6 | AT28: 3 | AU28: 1 | AV28: =Max!$B$5*AS28 -> 60
A29: 4 | B29: Leg Ext. + Leg Press (Superset) | C29: 0.7 | D29: 6 | E29: 5 | K29: =D26*E26 -> 3 | L29: =F26*K29 -> 210 | AE29: 0.75 | AF29: 2 | AG29: 4 | AH29: =Max!$B$5*AE29 -> 75 | AL29: 0.7 | AM29: 4 | AN29: 1 | AO29: =Max!$B$5*AL29 -> 70 | AS29: 0.7 | AT29: 3 | AU29: 1 | AV29: =Max!$B$5*AS29 -> 70
A30: 5 | B30: Back Extensions | C30: 0.65 | D30: 8 | E30: 4 | K30: =D27*E27 -> 8 | L30: =F27*K30 -> 640 | AC30: 3 | AD30: Dips | AE30: 0.75 | AF30: 5 | AG30: 5 | AL30: 0.8 | AM30: 4 | AN30: 4 | AO30: =Max!$B$5*AL30 -> 80 | AS30: 0.75 | AT30: 2 | AU30: 2 | AV30: =Max!$B$5*AS30 -> 75
AC31: 4 | AD31: Lat Muscles | AE31: 0.7 | AF31: 6 | AG31: 5 | AJ31: 4 | AK31: Triceps | AL31: 0.7 | AM31: 6 | AN31: 5 | AS31: 0.8 | AT31: 1 | AU31: 3 | AV31: =Max!$B$5*AS31 -> 80
A32: 5 day (Friday) | C32: % | D32: reps | E32: sets | F32: weight | AC32: 5 | AD32: Abs | AE32: 0.65 | AF32: 8 | AG32: 4 | AJ32: 5 | AK32: Abs | AL32: 0.6 | AM32: 10 | AN32: 4 | AQ32: 3 | AR32: Lat Muscles | AS32: 0.65 | AT32: 8 | AU32: 5
A33: 1 | B33: Squat | C33: 0.5 | D33: 4 | E33: 1 | F33: =Max!$B$3*C33 -> 50 | AQ33: 4 | AR33: Good morning (standing) | AS33: 0.75 | AT33: 5 | AU33: 4
C34: 0.6 | D34: 4 | E34: 1 | F34: =Max!$B$3*C34 -> 60 | AC34: 5 day (Friday) | AE34: % | AF34: reps | AG34: sets | AH34: weight | AJ34: 5 day (Friday) | AL34: % | AM34: reps | AN34: sets | AO34: weight
C35: 0.7 | D35: 4 | E35: 4 | F35: =Max!$B$3*C35 -> 70 | I35: =D33*E33 -> 4 | J35: =F33*I35 -> 200 | R35: =I35+I36+I44+I45 -> #VALUE! | S35: =I37+I38+I42+I43 -> 79 | T35: =I39+I40+I41 -> #REF! | U35: 0 | V35: 0 | AC35: 1 | AD35: Squat | AE35: 0.5 | AF35: 4 | AG35: 1 | AH35: =Max!$B$3*AE35 -> 50 | AJ35: 1 | AK35: Squat | AL35: 0.55 | AM35: 5 | AN35: 1 | AO35: =Max!$B$3*AL35 -> 55 | AQ35: 5 day (Friday) | AS35: % | AT35: reps | AU35: sets | AV35: weight
A36: 2 | B36: Bench press | C36: 0.5 | D36: 3 | E36: 1 | F36: =Max!$B$4*C36 -> 50 | I36: =D34*E34 -> 4 | J36: =F34*I36 -> 240 | AE36: 0.6 | AF36: 3 | AG36: 1 | AH36: =Max!$B$3*AE36 -> 60 | AL36: 0.65 | AM36: 4 | AN36: 1 | AO36: =Max!$B$3*AL36 -> 65 | AQ36: 1 | AR36: Bench press | AS36: 0.5 | AT36: 5 | AU36: 1 | AV36: =Max!$B$4*AS36 -> 50
C37: 0.6 | D37: 3 | E37: 1 | F37: =Max!$B$4*C37 -> 60 | I37: =D35*E35 -> 16 | J37: =F35*I37 -> 1120 | AE37: 0.7 | AF37: 3 | AG37: 1 | AH37: =Max!$B$3*AE37 -> 70 | AL37: 0.75 | AM37: 3 | AN37: 1 | AO37: =Max!$B$3*AL37 -> 75 | AS37: 0.6 | AT37: 4 | AU37: 1 | AV37: =Max!$B$4*AS37 -> 60
C38: 0.7 | D38: 3 | E38: 1 | F38: =Max!$B$4*C38 -> 70 | I38: =D36*E36 -> 3 | J38: =F36*I38 -> 150 | AE38: 0.8 | AF38: 2 | AG38: 4 | AH38: =Max!$B$3*AE38 -> 80 | AL38: 0.85 | AM38: 2 | AN38: 4 | AO38: =Max!$B$3*AL38 -> 85 | AS38: 0.7 | AT38: 3 | AU38: 1 | AV38: =Max!$B$4*AS38 -> 70
C39: 0.75 | D39: 3 | E39: 5 | F39: =Max!$B$4*C39 -> 75 | I39: =#REF!*#REF! -> #REF! | J39: =#REF!*I39 -> #REF! | AC39: 2 | AD39: Bench press | AE39: 0.5 | AF39: 5 | AG39: 1 | AH39: =Max!$B$4*AE39 -> 50 | AJ39: 2 | AK39: Bench press | AL39: 0.5 | AM39: 5 | AN39: 1 | AO39: =Max!$B$4*AL39 -> 50 | AS39: 0.8 | AT39: 2 | AU39: 4 | AV39: =Max!$B$4*AS39 -> 80
A40: 3 | B40: Lat muscles | C40: 0.7 | D40: 6 | E40: 5 | I40: =#REF!*#REF! -> #REF! | J40: =#REF!*I40 -> #REF! | AE40: 0.6 | AF40: 4 | AG40: 1 | AH40: =Max!$B$4*AE40 -> 60 | AL40: 0.6 | AM40: 5 | AN40: 1 | AO40: =Max!$B$4*AL40 -> 60 | AQ40: 2 | AR40: Squat | AS40: 0.5 | AT40: 5 | AU40: 1 | AV40: =Max!$B$3*AS40 -> 50
A41: 4 | B41: Abs | C41: 0.6 | D41: 10 | E41: 3 | I41: =#REF!*#REF! -> #REF! | J41: =#REF!*I41 -> #REF! | AE41: 0.7 | AF41: 3 | AG41: 1 | AH41: =Max!$B$4*AE41 -> 70 | AL41: 0.7 | AM41: 5 | AN41: 5 | AO41: =Max!$B$4*AL41 -> 70 | AS41: 0.6 | AT41: 4 | AU41: 1 | AV41: =Max!$B$3*AS41 -> 60
I42: =D40*E40 -> 30 | J42: =F40*I42 -> 0 | AE42: 0.8 | AF42: 2 | AG42: 2 | AH42: =Max!$B$4*AE42 -> 80 | AJ42: 3 | AK42: Squat | AL42: 0.5 | AM42: 3 | AN42: 1 | AO42: =Max!$B$3*AL42 -> 50 | AS42: 0.7 | AT42: 3 | AU42: 1 | AV42: =Max!$B$3*AS42 -> 70
...

Sheet Prep 2
B1: Sheiko
B2: Prep period 2 (4 weeks)
A5: week 1 | M5: squat | R5: bench | W5: deadlift | AD5: week 2 | AK5: week 3 | AR5: week 4
A6: 1 day (Monday) | C6: % | D6: reps | E6: sets | F6: weight | M6: 50-59 | N6: 60-69 | O6: 70-79 | P6: 80-89 | Q6: 90+ | R6: 50-59 | S6: 60-69 | T6: 70-79 | U6: 80-89 | V6: 90+ | W6: 50-59 | X6: 60-69 | Y6: 70-79 | Z6: 80-89 | AA6: 90+ | AD6: 1 day (Monday) | AF6: % | AG6: reps | AH6: sets | AI6: weight | AK6: 1 day (Monday) | AM6: % | AN6: reps | AO6: sets | AP6: weight | AR6: 1 day (Monday) | AT6: % | AU6: reps | AV6: sets | AW6: weight
A7: 1 | B7: Squat | C7: 0.5 | D7: 5 | E7: 1 | F7: =Max!$B$3*C7 -> 50 | I7: =D7*E7 -> 5 | J7: =F7*I7 -> 250 | R7: =I7 -> 5 | S7: =I8 -> 5 | T7: =I9 -> 3 | U7: =I10 -> 7 | V7: 0 | AD7: 1 | AE7: Bench press | AF7: 0.55 | AG7: 5 | AH7: 1 | AI7: =Max!$B$4*AF7 -> 55 | AK7: 1 | AL7: Squat | AM7: 0.5 | AN7: 5 | AO7: 1 | AP7: =Max!$B$3*AM7 -> 50 | AR7: 1 | AS7: Squat | AT7: 0.5 | AU7: 5 | AV7: 1 | AW7: =Max!$B$3*AT7 -> 50
C8: 0.6 | D8: 5 | E8: 1 | F8: =Max!$B$3*C8 -> 60 | I8: =D8*E8 -> 5 | J8: =F8*I8 -> 300 | AF8: 0.65 | AG8: 4 | AH8: 1 | AI8: =Max!$B$4*AF8 -> 65 | AM8: 0.6 | AN8: 4 | AO8: 1 | AP8: =Max!$B$3*AM8 -> 60 | AT8: 0.6 | AU8: 4 | AV8: 1 | AW8: =Max!$B$3*AT8 -> 60
C9: 0.7 | D9: 3 | E9: 1 | F9: =Max!$B$3*C9 -> 70 | I9: =D9*E9 -> 3 | J9: =F9*I9 -> 210 | AF9: 0.75 | AG9: 3 | AH9: 1 | AI9: =Max!$B$4*AF9 -> 75 | AM9: 0.7 | AN9: 3 | AO9: 1 | AP9: =Max!$B$3*AM9 -> 70 | AT9: 0.7 | AU9: 3 | AV9: 1 | AW9: =Max!$B$3*AT9 -> 70
C10: 0.7 | D10: 7 | E10: 1 | F10: =Max!$B$3*C10 -> 70 | I10: =D10*E10 -> 7 | J10: =F10*I10 -> 490 | AF10: 0.85 | AG10: 2 | AH10: 4 | AI10: =Max!$B$4*AF10 -> 85 | AM10: 0.8 | AN10: 2 | AO10: 5 | AP10: =Max!$B$3*AM10 -> 80 | AT10: 0.8 | AU10: 2 | AV10: 1 | AW10: =Max!$B$3*AT10 -> 80
C11: 0.7 | D11: 4 | E11: 1 | F11: =Max!$B$3*C11 -> 70 | G11: =D11*E11 -> 4 | H11: =F11*G11 -> 280 | M11: =G11 -> 4 | N11: =G12 -> 8 | O11: =G13 -> 27 | AD11: 2 | AE11: Squat | AF11: 0.5 | AG11: 5 | AH11: 1 | AI11: =Max!$B$3*AF11 -> 50 | AK11: 2 | AL11: Bench press | AM11: 0.55 | AN11: 5 | AO11: 1 | AP11: =Max!$B$4*AM11 -> 55 | AT11: 0.9 | AU11: 1 | AV11: 1 | AW11: =Max!$B$3*AT11 -> 90
C12: 0.7 | D12: 8 | E12: 1 | F12: =Max!$B$3*C12 -> 70 | G12: =D12*E12 -> 8 | H12: =F12*G12 -> 560 | AF12: 0.6 | AG12: 4 | AH12: 1 | AI12: =Max!$B$3*AF12 -> 60 | AM12: 0.65 | AN12: 4 | AO12: 1 | AP12: =Max!$B$4*AM12 -> 65 | AT12: 0.95 | AU12: 1 | AV12: 1 | AW12: =Max!$B$3*AT12 -> 95
C13: 0.7 | D13: 2 | E13: 1 | F13: =Max!$B$3*C13 -> 70 | G13: 27 | H13: =F13*G13 -> 1890 | AF13: 0.7 | AG13: 3 | AH13: 1 | AI13: =Max!$B$3*AF13 -> 70 | AM13: 0.75 | AN13: 3 | AO13: 1 | AP13: =Max!$B$4*AM13 -> 75 | AT13: 1 | AU13: 1 | AV13: 1 | AW13: =Max!$B$3*AT13 -> 100
C14: 0.7 | D14: 5 | E14: 1 | F14: =Max!$B$3*C14 -> 70 | I14: =D14*E14 -> 5 | J14: =F14*I14 -> 350 | R14: =I14 -> 5 | S14: =I15 -> 5 | T14: =I16 -> 4 | U14: 0 | V14: 0 | AF14: 0.8 | AG14: 2 | AH14: 4 | AI14: =Max!$B$3*AF14 -> 80 | AM14: 0.85 | AN14: 2 | AO14: 4 | AP14: =Max!$B$4*AM14 -> 85 | AT14: 1.05 | AU14: 1 | AV14: 1 | AW14: =Max!$B$3*AT14 -> 105
A15: 2 | B15: Bench press | C15: 0.5 | D15: 5 | E15: 1 | F15: =Max!$B$4*C15 -> 50 | I15: =D15*E15 -> 5 | J15: =F15*I15 -> 250 | AD15: 3 | AE15: Bench press | AF15: 0.5 | AG15: 3 | AH15: 1 | AI15: =Max!$B$4*AF15 -> 50 | AK15: 3 | AL15: Chest muscles | AM15: 0.65 | AN15: 8 | AO15: 5 | AR15: 2 | AS15: Bench press | AT15: 0.5 | AU15: 5 | AV15: 1 | AW15: =Max!$B$4*AT15 -> 50
C16: 0.6 | D16: 4 | E16: 1 | F16: =Max!$B$4*C16 -> 60 | I16: =D16*E16 -> 4 | J16: =F16*I16 -> 240 | AF16: 0.6 | AG16: 3 | AH16: 1 | AI16: =Max!$B$4*AF16 -> 60 | AK16: 4 | AL16: Barbell curls | AM16: 0.7 | AN16: 6 | AO16: 5 | AT16: 0.6 | AU16: 4 | AV16: 1 | AW16: =Max!$B$4*AT16 -> 60
C17: 0.7 | D17: 3 | E17: 1 | F17: =Max!$B$4*C17 -> 70 | AF17: 0.7 | AG17: 3 | AH17: 1 | AI17: =Max!$B$4*AF17 -> 70 | AK17: 5 | AL17: Abs | AM17: 0.75 | AN17: 5 | AO17: 5 | AT17: 0.7 | AU17: 3 | AV17: 1 | AW17: =Max!$B$4*AT17 -> 70
C18: 0.8 | D18: 2 | E18: 5 | F18: =Max!$B$4*C18 -> 80 | AF18: 0.8 | AG18: 2 | AH18: 4 | AI18: =Max!$B$4*AF18 -> 80 | AT18: 0.75 | AU18: 2 | AV18: 3 | AW18: =Max!$B$4*AT18 -> 75
A19: 3 | B19: Chest muscles | C19: 0.65 | D19: 8 | E19: 5 | AD19: 4 | AE19: Chest muscles | AF19: 0.65 | AG19: 8 | AH19: 5 | AK19: 3 day (Wednesday) | AM19: % | AN19: reps | AO19: sets | AP19: weight | AR19: 3 | AS19: Chest muscles | AT19: 0.6 | AU19: 10 | AV19: 5
A20: 4 | B20: Triceps | C20: 0.7 | D20: 6 | E20: 5 | AD20: 5 | AE20: Good morning (standing) | AF20: 0.75 | AG20: 5 | AH20: 5 | AK20: 1 | AL20: Deadlift up to knees | AM20: 0.5 | AN20: 3 | AO20: 1 | AP20: =Max!$B$5*AM20 -> 50 | AR20: 4 | AS20: Back extensions | AT20: 0.65 | AU20: 8 | AV20: 4
A21: 5 | B21: Abs | C21: 0.65 | D21: 8 | E21: 4 | AM21: 0.6 | AN21: 3 | AO21: 1 | AP21: =Max!$B$5*AM21 -> 60
K22: =D23*E23 -> #VALUE! | L22: =F23*K22 -> #VALUE! | W22: =K22 -> #VALUE! | X22: =K23 -> 3 | Y22: =K24 -> 3 | Z22: =K25 -> 3 | AD22: 3 day (Wednesday) | AF22: % | AG22: reps | AH22: sets | AI22: weight | AM22: 0.7 | AN22: 3 | AO22: 1 | AP22: =Max!$B$5*AM22 -> 70 | AR22: 3 day (Wednesday) | AT22: % | AU22: reps | AV22: sets | AW22: weight
A23: 3 day (Wednesday) | C23: % | D23: reps | E23: sets | F23: weight | K23: =D24*E24 -> 3 | L23: =F24*K23 -> 150 | AD23: 1 | AE23: Deficit deadlift | AF23: 0.5 | AG23: 3 | AH23: 1 | AI23: =Max!$B$5*AF23 -> 50 | AM23: 0.75 | AN23: 2 | AO23: 4 | AP23: =Max!$B$5*AM23 -> 75 | AR23: 1 | AS23: Bench press | AT23: 0.5 | AU23: 5 | AV23: 1 | AW23: =Max!$B$4*AT23 -> 50
A24: 1 | B24: Deadlift | C24: 0.5 | D24: 3 | E24: 1 | F24: =Max!$B$5*C24 -> 50 | K24: =D25*E25 -> 3 | L24: =F25*K24 -> 180 | AF24: 0.6 | AG24: 3 | AH24: 1 | AI24: =Max!$B$5*AF24 -> 60 | AK24: 2 | AL24: Bench press | AM24: 0.5 | AN24: 5 | AO24: 1 | AP24: =Max!$B$4*AM24 -> 50 | AT24: 0.6 | AU24: 4 | AV24: 1 | AW24: =Max!$B$4*AT24 -> 60
C25: 0.6 | D25: 3 | E25: 1 | F25: =Max!$B$5*C25 -> 60 | K25: =D26*E26 -> 3 | L25: =F26*K25 -> 210 | AF25: 0.7 | AG25: 2 | AH25: 4 | AI25: =Max!$B$5*AF25 -> 70 | AM25: 0.6 | AN25: 4 | AO25: 1 | AP25: =Max!$B$4*AM25 -> 60 | AT25: 0.7 | AU25: 3 | AV25: 1 | AW25: =Max!$B$4*AT25 -> 70
C26: 0.7 | D26: 3 | E26: 1 | F26: =Max!$B$5*C26 -> 70 | I26: =D27*E27 -> 6 | J26: =F27*I26 -> 480 | R26: =I26 -> 6 | S26: =I27 -> 6 | T26: =I28 -> 5 | U26: =I30+I31+I29 -> #REF! | AD26: 2 | AE26: Bench press | AF26: 0.5 | AG26: 4 | AH26: 1 | AI26: =Max!$B$4*AF26 -> 50 | AM26: 0.7 | AN26: 3 | AO26: 1 | AP26: =Max!$B$4*AM26 -> 70 | AT26: 0.8 | AU26: 2 | AV26: 1 | AW26: =Max!$B$4*AT26 -> 80
C27: 0.8 | D27: 3 | E27: 2 | F27: =Max!$B$5*C27 -> 80 | I27: =D28*E28 -> 6 | J27: =F28*I27 -> 510 | AF27: 0.6 | AG27: 4 | AH27: 1 | AI27: =Max!$B$4*AF27 -> 60 | AM27: 0.8 | AN27: 2 | AO27: 4 | AP27: =Max!$B$4*AM27 -> 80 | AT27: 0.9 | AU27: 1 | AV27: 1 | AW27: =Max!$B$4*AT27 -> 90
C28: 0.85 | D28: 2 | E28: 3 | F28: =Max!$B$5*C28 -> 85 | I28: =D29*E29 -> 5 | J28: =F29*I28 -> 250 | AF28: 0.7 | AG28: 4 | AH28: 1 | AI28: =Max!$B$4*AF28 -> 70 | AK28: 3 | AL28: Deadlift from boxes | AM28: 0.6 | AN28: 3 | AO28: 1 | AP28: =Max!$B$5*AM28 -> 60 | AT28: 0.95 | AU28: 1 | AV28: 1 | AW28: =Max!$B$4*AT28 -> 95
A29: 2 | B29: Bench press | C29: 0.5 | D29: 5 | E29: 1 | F29: =Max!$B$4*C29 -> 50 | I29: =D30*E30 -> 4 | J29: =F30*I29 -> 240 | AF29: 0.75 | AG29: 4 | AH29: 4 | AI29: =Max!$B$4*AF29 -> 75 | AM29: 0.7 | AN29: 3 | AO29: 1 | AP29: =Max!$B$5*AM29 -> 70 | AT29: 1 | AU29: 1 | AV29: 1 | AW29: =Max!$B$4*AT29 -> 100
C30: 0.6 | D30: 4 | E30: 1 | F30: =Max!$B$4*C30 -> 60 | I30: =D31*E31 -> 3 | J30: =F31*I30 -> 210 | AD30: 3 | AE30: Deadlift from boxes | AF30: 0.7 | AG30: 3 | AH30: 1 | AI30: =Max!$B$5*AF30:AF31 -> 70 | AM30: 0.8 | AN30: 3 | AO30: 2 | AP30: =Max!$B$5*AM30 -> 80 | AT30: 1.05 | AU30: 1 | AV30: 1 | AW30: =Max!$B$4*AT30 -> 105
C31: 0.7 | D31: 3 | E31: 1 | F31: =Max!$B$4*C31 -> 70 | I31: =#REF!*#REF! -> #REF! | J31: =#REF!*I31 -> #REF! | AF31: 0.8 | AG31: 3 | AH31: 2 | AI31: =Max!$B$5*AF30:AF31 -> 80 | AM31: 0.85 | AN31: 2 | AO31: 3 | AP31: =Max!$B$5*AM31 -> 85 | AR31: 2 | AS31: Deadlift | AT31: 0.5 | AU31: 5 | AV31: 1 | AW31: =Max!$B$5*AT31 -> 50
C32: 0.8 | D32: 3 | E32: 5 | F32: =Max!$B$4*C32 -> 80 | K32: =D32*E32 -> 15 | L32: =F32*K32 -> 1200 | X32: =K32 -> 15 | Y32: =K33 -> 30 | Z32: =K34 -> 25 | AA32: =K35 -> 25 | AF32: 0.9 | AG32: 2 | AH32: 2 | AI32: =Max!$B$5*AF31:AF32 -> 90 | AK32: 4 | AL32: Triceps | AM32: 0.7 | AN32: 6 | AO32: 5 | AT32: 0.6 | AU32: 4 | AV32: 1 | AW32: =Max!$B$5*AT32 -> 60
A33: 3 | B33: Lat muscles | C33: 0.7 | D33: 6 | E33: 5 | K33: =D32:D33*E32:E33 -> 30 | L33: =F32:F33*K33 -> 0 | AF33: 0.95 | AG33: 1 | AH33: 3 | AI33: =Max!$B$5*AF32:AF33 -> 95 | AK33: 5 | AL33: Back extensions | AM33: 0.65 | AN33: 8 | AO33: 4 | AT33: 0.7 | AU33: 3 | AV33: 1 | AW33: =Max!$B$5*AT33 -> 70
A34: 4 | B34: Dips | C34: 0.75 | D34: 5 | E34: 5 | K34: =D33:D34*E33:E34 -> 25 | L34: =F33:F34*K34 -> 0 | AD34: 4 | AE34: Triceps | AF34: 0.7 | AG34: 6 | AH34: 5 | AT34: 0.8 | AU34: 2 | AV34: 1 | AW34: =Max!$B$5*AT34 -> 80
A35: 5 | B35: Good morning (standing) | C35: 0.75 | D35: 5 | E35: 5 | K35: =D34:D35*E34:E35 -> 25 | L35: =F34:F35*K35 -> 0 | AD35: 5 | AE35: Abs | AF35: 0.6 | AG35: 10 | AH35: 4 | AK35: 5 day (Friday) | AM35: % | AN35: reps | AO35: sets | AP35: weight | AT35: 0.9 | AU35: 1 | AV35: 1 | AW35: =Max!$B$5*AT35 -> 90
AK36: 1 | AL36: Squat | AM36: 0.5 | AN36: 5 | AO36: 1 | AP36: =Max!$B$3*AM36 -> 50 | AT36: 0.95 | AU36: 1 | AV36: 1 | AW36: =Max!$B$5*AT36 -> 95
A37: 5 day (Friday) | C37: % | D37: reps | E37: sets | F37: weight | AD37: 5 day (Friday) | AF37: % | AG37: reps | AH37: sets | AI37: weight | AM37: 0.6 | AN37: 4 | AO37: 1 | AP37: =Max!$B$3*AM37 -> 60 | AT37: 1 | AU37: 1 | AV37: 1 | AW37: =Max!$B$5*AT37 -> 100
A38: 1 | B38: Bench press | C38: 0.55 | D38: 5 | E38: 1 | F38: =Max!$B$4*C38 -> 55 | AD38: 1 | AE38: Squat | AF38: 0.55 | AG38: 5 | AH38: 1 | AI38: =Max!$B$3*AF38 -> 55 | AM38: 0.7 | AN38: 3 | AO38: 1 | AP38: =Max!$B$3*AM38 -> 70 | AT38: 1.05 | AU38: 1 | AV38: 1 | AW38: =Max!$B$5*AT38 -> 105
C39: 0.65 | D39: 4 | E39: 1 | F39: =Max!$B$4*C39 -> 65 | AF39: 0.65 | AG39: 4 | AH39: 1 | AI39: =Max!$B$3*AF39 -> 65 | AM39: 0.75 | AN39: 2 | AO39: 4 | AP39: =Max!$B$3*AM39 -> 75 | AR39: 3 | AS39: Dips | AT39: 0.8 | AU39: 4 | AV39: 5
C40: 0.75 | D40: 3 | E40: 1 | F40: =Max!$B$4*C40 -> 75 | G40: =D39*E39 -> 4 | H40: =F39*G40 -> 260 | M40: =G40 -> 4 | N40: =G41 -> 3 | O40: =G42 -> 8 | P40: =G43 -> 5 | AF40: 0.75 | AG40: 3 | AH40: 1 | AI40: =Max!$B$3*AF40 -> 75 | AK40: 2 | AL40: Bench press | AM40: 0.5 | AN40: 5 | AO40: 1 | AP40: =Max!$B$4*AM40 -> 50 | AR40: 4 | AS40: Lat muscles | AT40: 0.65 | AU40: 8 | AV40: 4
C41: 0.85 | D41: 2 | E41: 4 | F41: =Max!$B$4*C41 -> 85 | G41: =D40*E40 -> 3 | H41: =F40*G41 -> 225 | AF41: 0.85 | AG41: 2 | AH41: 4 | AI41: =Max!$B$3*AF41 -> 85 | AM41: 0.6 | AN41: 4 | AO41: 1 | AP41: =Max!$B$4*AM41 -> 60
A42: 2 | B42: Squat | C42: 0.5 | D42: 5 | E42: 1 | F42: =Max!$B$3*C42 -> 50 | G42: =D41*E41 -> 8 | H42: =F41*G42 -> 680 | AD42: 2 | AE42: Bench press | AF42: 0.5 | AG42: 5 | AH42: 1 | AI42: =Max!$B$4*AF42 -> 50 | AM42: 0.7 | AN42: 3 | AO42: 1 | AP42: =Max!$B$4*AM42 -> 70 | AR42: 5 day (Friday) | AT42: % | AU42: reps | AV42: sets | AW42: weight
...

Sheet Prep 3
B1: Sheiko
B2: Prep period 3 (4 weeks)
A5: week 1 | M5: squat | R5: bench | W5: deadlift | AD5: week 2 | AK5: week 3 | AR5: week 4
A6: 1 day (Monday) | C6: % | D6: reps | E6: sets | F6: weight | M6: 50-59 | N6: 60-69 | O6: 70-79 | P6: 80-89 | Q6: 90+ | R6: 50-59 | S6: 60-69 | T6: 70-79 | U6: 80-89 | V6: 90+ | W6: 50-59 | X6: 60-69 | Y6: 70-79 | Z6: 80-89 | AA6: 90+ | AD6: 1 day (Monday) | AF6: % | AG6: reps | AH6: sets | AI6: weight | AK6: 1 day (Monday) | AM6: % | AN6: reps | AO6: sets | AP6: weight | AR6: 1 day (Monday) | AT6: % | AU6: reps | AV6: sets | AW6: weight
A7: 1 | B7: Squat | C7: 0.55 | D7: 5 | E7: 1 | F7: =Max!$B$3*C7 -> 55 | I7: =D7*E7 -> 5 | J7: =F7*I7 -> 275 | R7: =I7 -> 5 | S7: =I8 -> 4 | T7: =I9 -> 3 | U7: =I10 -> 6 | V7: 0 | AD7: 3 | AE7: Squat | AF7: 0.5 | AG7: 5 | AH7: 1 | AI7: =Max!$B$3*AF7 -> 50 | AK7: 1 | AL7: Squat | AM7: 0.5 | AN7: 5 | AO7: 1 | AP7: =Max!$B$3*AM7 -> 50 | AR7: 1 | AS7: Bench press | AT7: 0.5 | AU7: 5 | AV7: 1 | AW7: =Max!$B$4*AT7 -> 50
C8: 0.65 | D8: 4 | E8: 1 | F8: =Max!$B$3*C8 -> 65 | I8: =D8*E8 -> 4 | J8: =F8*I8 -> 260 | AF8: 0.6 | AG8: 4 | AH8: 1 | AI8: =Max!$B$3*AF8 -> 60 | AM8: 0.6 | AN8: 4 | AO8: 1 | AP8: =Max!$B$3*AM8 -> 60 | AT8: 0.6 | AU8: 4 | AV8: 1 | AW8: =Max!$B$4*AT8 -> 60
C9: 0.75 | D9: 3 | E9: 1 | F9: =Max!$B$3*C9 -> 75 | I9: =D9*E9 -> 3 | J9: =F9*I9 -> 225 | AF9: 0.7 | AG9: 3 | AH9: 1 | AI9: =Max!$B$3*AF9 -> 70 | AM9: 0.7 | AN9: 3 | AO9: 1 | AP9: =Max!$B$3*AM9 -> 70 | AT9: 0.7 | AU9: 3 | AV9: 1 | AW9: =Max!$B$4*AT9 -> 70
C10: 0.85 | D10: 2 | E10: 3 | F10: =Max!$B$3*C10 -> 85 | I10: =D10*E10 -> 6 | J10: =F10*I10 -> 510 | AF10: 0.8 | AG10: 3 | AH10: 4 | AI10: =Max!$B$3*AF10 -> 80 | AM10: 0.8 | AN10: 3 | AO10: 2 | AP10: =Max!$B$3*AM10 -> 80 | AT10: 0.8 | AU10: 3 | AV10: 4 | AW10: =Max!$B$4*AT10 -> 80
A11: 2 | B11: Bench press | C11: 0.5 | D11: 5 | E11: 1 | F11: =Max!$B$4*C11 -> 50 | G11: =D11*E11 -> 5 | H11: =F11*G11 -> 250 | M11: =G11 -> 5 | N11: =G12 -> 4 | O11: =G13 -> 27 | AD11: 2 | AE11: Bench press | AF11: 0.5 | AG11: 5 | AH11: 1 | AI11: =Max!$B$4*AF11 -> 50 | AM11: 0.85 | AN11: 2 | AO11: 2 | AP11: =Max!$B$3*AM11 -> 85 | AR11: 2 | AS11: Squat | AT11: 0.5 | AU11: 5 | AV11: 1 | AW11: =Max!$B$3*AT11 -> 50
C12: 0.6 | D12: 4 | E12: 1 | F12: =Max!$B$4*C12 -> 60 | G12: =D12*E12 -> 4 | H12: =F12*G12 -> 240 | AF12: 0.6 | AG12: 4 | AH12: 1 | AI12: =Max!$B$4*AF12 -> 60 | AM12: 0.8 | AN12: 3 | AO12: 2 | AP12: =Max!$B$3*AM12 -> 80 | AT12: 0.6 | AU12: 4 | AV12: 1 | AW12: =Max!$B$3*AT12 -> 60
C13: 0.7 | D13: 3 | E13: 1 | F13: =Max!$B$4*C13 -> 70 | G13: 27 | H13: =F13*G13 -> 1890 | AF13: 0.7 | AG13: 3 | AH13: 1 | AI13: =Max!$B$4*AF13 -> 70 | AK13: 2 | AL13: Bench press | AM13: 0.5 | AN13: 5 | AO13: 1 | AP13: =Max!$B$4*AM13 -> 50 | AT13: 0.7 | AU13: 3 | AV13: 1 | AW13: =Max!$B$3*AT13 -> 70
C14: 0.8 | D14: 2 | E14: 4 | F14: =Max!$B$4*C14 -> 80 | I14: =D14*E14 -> 8 | J14: =F14*I14 -> 640 | R14: =I14 -> 8 | S14: =I15 -> 3 | T14: =I16 -> 3 | U14: 0 | V14: 0 | AF14: 0.8 | AG14: 3 | AH14: 5 | AI14: =Max!$B$4*AF14 -> 80 | AM14: 0.6 | AN14: 4 | AO14: 1 | AP14: =Max!$B$4*AM14 -> 60 | AT14: 0.8 | AU14: 2 | AV14: 4 | AW14: =Max!$B$3*AT14 -> 80
A15: 3 | B15: Squat | C15: 0.5 | D15: 3 | E15: 1 | F15: =Max!$B$3*C15 -> 50 | I15: =D15*E15 -> 3 | J15: =F15*I15 -> 150 | AD15: 3 | AE15: Chest muscles | AF15: 0.65 | AG15: 8 | AH15: 4 | AM15: 0.7 | AN15: 3 | AO15: 1 | AP15: =Max!$B$4*AM15 -> 70 | AR15: 3 | AS15: Bench press | AT15: 0.5 | AU15: 4 | AV15: 1 | AW15: =Max!$B$4*AT15 -> 50
C16: 0.6 | D16: 3 | E16: 1 | F16: =Max!$B$3*C16 -> 60 | I16: =D16*E16 -> 3 | J16: =F16*I16 -> 180 | AD16: 4 | AE16: Barbell curls | AF16: 0.65 | AG16: 8 | AH16: 5 | AM16: 0.8 | AN16: 3 | AO16: 5 | AP16: =Max!$B$4*AM16 -> 80 | AT16: 0.6 | AU16: 4 | AV16: 1 | AW16: =Max!$B$4*AT16 -> 60
C17: 0.7 | D17: 3 | E17: 1 | F17: =Max!$B$3*C17 -> 70 | AD17: 5 | AE17: Good morning (standing) | AF17: 0.75 | AG17: 5 | AH17: 5 | AK17: 3 | AL17: Chest muscles | AM17: 0.65 | AN17: 8 | AO17: 4 | AT17: 0.7 | AU17: 4 | AV17: 4 | AW17: =Max!$B$4*AT17 -> 70
C18: 0.8 | D18: 2 | E18: 4 | F18: =Max!$B$3*C18 -> 80 | AK18: 4 | AL18: Triceps | AM18: 0.7 | AN18: 6 | AO18: 5 | AR18: 4 | AS18: Chest muscles | AT18: 0.7 | AU18: 6 | AV18: 4
A19: 4 | B19: Chest muscles | C19: 0.7 | D19: 6 | E19: 4 | AD19: 3 day (Wednesday) | AF19: % | AG19: reps | AH19: sets | AI19: weight | AK19: 5 | AL19: Abs | AM19: 0.6 | AN19: 10 | AO19: 3 | AR19: 5 | AS19: Good morning (sitting) | AT19: 0.75 | AU19: 5 | AV19: 5
A20: 5 | B20: Good morning (standing) | C20: 0.75 | D20: 5 | E20: 5 | AD20: 1 | AE20: Bench press | AF20: 0.5 | AG20: 5 | AH20: 1 | AI20: =Max!$B$4*AF20 -> 50
AF21: 0.6 | AG21: 4 | AH21: 1 | AI21: =Max!$B$4*AF21 -> 60 | AK21: 3 day (Wednesday) | AM21: % | AN21: reps | AO21: sets | AP21: weight | AR21: 3 day (Wednesday) | AT21: % | AU21: reps | AV21: sets | AW21: weight
A22: 3 day (Wednesday) | C22: % | D22: reps | E22: sets | F22: weight | K22: =D23*E23 -> 6 | L22: =F23*K22 -> 300 | W22: =K22 -> 6 | X22: =K23 -> 5 | Y22: =K24 -> 4 | Z22: =K25 -> 3 | AF22: 0.7 | AG22: 3 | AH22: 1 | AI22: =Max!$B$4*AF22 -> 70 | AK22: 1 | AL22: Deadlift | AM22: 0.55 | AN22: 3 | AO22: 1 | AP22: =Max!$B$5*AM22 -> 55 | AR22: 1 | AS22: Deficit deadlift | AT22: 0.5 | AU22: 3 | AV22: 1 | AW22: =Max!$B$5*AT22 -> 50
A23: 1 | B23: Bench press | C23: 0.5 | D23: 6 | E23: 1 | F23: =Max!$B$4*C23 -> 50 | K23: =D24*E24 -> 5 | L23: =F24*K23 -> 300 | AF23: 0.8 | AG23: 3 | AH23: 2 | AI23: =Max!$B$4*AF23 -> 80 | AM23: 0.65 | AN23: 3 | AO23: 1 | AP23: =Max!$B$5*AM23 -> 65 | AT23: 0.6 | AU23: 3 | AV23: 1 | AW23: =Max!$B$5*AT23 -> 60
C24: 0.6 | D24: 5 | E24: 1 | F24: =Max!$B$4*C24 -> 60 | K24: =D25*E25 -> 4 | L24: =F25*K24 -> 280 | AF24: 0.85 | AG24: 2 | AH24: 2 | AI24: =Max!$B$4*AF24 -> 85 | AM24: 0.75 | AN24: 3 | AO24: 1 | AP24: =Max!$B$5*AM24 -> 75 | AT24: 0.65 | AU24: 3 | AV24: 2 | AW24: =Max!$B$5*AT24 -> 65
C25: 0.7 | D25: 4 | E25: 1 | F25: =Max!$B$4*C25 -> 70 | K25: =D26*E26 -> 3 | L25: =F26*K25 -> 225 | AF25: 0.8 | AG25: 3 | AH25: 1 | AI25: =Max!$B$4*AF25 -> 80 | AM25: 0.85 | AN25: 2 | AO25: 4 | AP25: =Max!$B$5*AM25 -> 85 | AT25: 0.7 | AU25: 2 | AV25: 3 | AW25: =Max!$B$5*AT25 -> 70
C26: 0.75 | D26: 3 | E26: 1 | F26: =Max!$B$4*C26 -> 75 | I26: =D27*E27 -> 4 | J26: =F27*I26 -> 320 | R26: =I26 -> 4 | S26: =I27 -> 2 | T26: =I28 -> 3 | U26: =I30+I31+I29 -> #REF! | AF26: 0.7 | AG26: 5 | AH26: 1 | AI26: =Max!$B$4*AF26 -> 70 | AK26: 2 | AL26: Bench press | AM26: 0.5 | AN26: 5 | AO26: 1 | AP26: =Max!$B$4*AM26 -> 50 | AR26: 2 | AS26: Bench press | AT26: 0.5 | AU26: 5 | AV26: 1 | AW26: =Max!$B$4*AT26 -> 50
C27: 0.8 | D27: 2 | E27: 2 | F27: =Max!$B$4*C27 -> 80 | I27: =D28*E28 -> 2 | J27: =F28*I27 -> 170 | AF27: 0.6 | AG27: 7 | AH27: 1 | AI27: =Max!$B$4*AF27 -> 60 | AM27: 0.6 | AN27: 4 | AO27: 1 | AP27: =Max!$B$4*AM27 -> 60 | AT27: 0.6 | AU27: 4 | AV27: 1 | AW27: =Max!$B$4*AT27 -> 60
C28: 0.85 | D28: 1 | E28: 2 | F28: =Max!$B$4*C28 -> 85 | I28: =D29*E29 -> 3 | J28: =F29*I28 -> 225 | AF28: 0.5 | AG28: 9 | AH28: 1 | AI28: =Max!$B$4*AF28 -> 50 | AM28: 0.7 | AN28: 3 | AO28: 1 | AP28: =Max!$B$4*AM28 -> 70 | AT28: 0.7 | AU28: 3 | AV28: 1 | AW28: =Max!$B$4*AT28 -> 70
C29: 0.75 | D29: 3 | E29: 1 | F29: =Max!$B$4*C29 -> 75 | I29: =D30*E30 -> 5 | J29: =F30*I29 -> 325 | AD29: 2 | AE29: Deadlift | AF29: 0.5 | AG29: 4 | AH29: 1 | AI29: =Max!$B$5*AF29 -> 50 | AM29: 0.8 | AN29: 3 | AO29: 2 | AP29: =Max!$B$4*AM29 -> 80 | AT29: 0.75 | AU29: 2 | AV29: 4 | AW29: =Max!$B$4*AT29 -> 75
C30: 0.65 | D30: 5 | E30: 1 | F30: =Max!$B$4*C30 -> 65 | I30: =D31*E31 -> 7 | J30: =F31*I30 -> 385 | AF30: 0.6 | AG30: 4 | AH30: 1 | AI30: =Max!$B$5*AF30 -> 60 | AM30: 0.85 | AN30: 2 | AO30: 3 | AP30: =Max!$B$4*AM30 -> 85 | AR30: 3 | AS30: Deadlift from boxes | AT30: 0.7 | AU30: 3 | AV30: 1 | AW30: =Max!$B$5*AT30 -> 70
C31: 0.55 | D31: 7 | E31: 1 | F31: =Max!$B$4*C31 -> 55 | I31: =#REF!*#REF! -> #REF! | J31: =#REF!*I31 -> #REF! | AF31: 0.7 | AG31: 4 | AH31: 1 | AI31: =Max!$B$5*AF31 -> 70 | AM31: 0.8 | AN31: 3 | AO31: 2 | AP31: =Max!$B$4*AM31 -> 80 | AT31: 0.8 | AU31: 3 | AV31: 1 | AW31: =Max!$B$5*AT31 -> 80
A32: 2 | B32: Deadlift from boxes | C32: 0.65 | D32: 3 | E32: 1 | F32: =Max!$B$5*C32 -> 65 | K32: =D32*E32 -> 3 | L32: =F32*K32 -> 195 | X32: =K32 -> 3 | Y32: =K33 -> 3 | Z32: =K34 -> 6 | AA32: =K35 -> 6 | AF32: 0.8 | AG32: 4 | AH32: 4 | AI32: =Max!$B$5*AF32 -> 80 | AK32: 3 | AL32: Deadlift from boxes | AM32: 0.65 | AN32: 3 | AO32: 1 | AP32: =Max!$B$5*AM32 -> 65 | AT32: 0.9 | AU32: 2 | AV32: 2 | AW32: =Max!$B$5*AT32 -> 90
C33: 0.75 | D33: 3 | E33: 1 | F33: =Max!$B$5*C33 -> 75 | K33: =D33*E33 -> 3 | L33: =F33*K33 -> 225 | AD33: 3 | AE33: Triceps | AF33: 0.7 | AG33: 6 | AH33: 5 | AM33: 0.75 | AN33: 3 | AO33: 1 | AP33: =Max!$B$5*AM33 -> 75 | AT33: 0.95 | AU33: 1 | AV33: 3 | AW33: =Max!$B$5*AT33 -> 95
C34: 0.85 | D34: 3 | E34: 2 | F34: =Max!$B$5*C34 -> 85 | K34: =D34*E34 -> 6 | L34: =F34*K34 -> 510 | AD34: 4 | AE34: Lat muscles | AF34: 0.7 | AG34: 6 | AH34: 5 | AM34: 0.85 | AN34: 2 | AO34: 2 | AP34: =Max!$B$5*AM34 -> 85 | AR34: 4 | AS34: Triceps | AT34: 0.7 | AU34: 6 | AV34: 5
C35: 0.9 | D35: 2 | E35: 3 | F35: =Max!$B$5*C35 -> 90 | K35: =D35*E35 -> 6 | L35: =F35*K35 -> 540 | AD35: 5 | AE35: Abs | AF35: 0.6 | AG35: 10 | AH35: 4 | AM35: 0.95 | AN35: 1 | AO35: 3 | AP35: =Max!$B$5*AM35 -> 95 | AR35: 5 | AS35: Good morning (sitting) | AT35: 0.75 | AU35: 5 | AV35: 4
A36: 3 | B36: Triceps | C36: 0.7 | D36: 6 | E36: 5 | AK36: 4 | AL36: Lat muscles | AM36: 0.7 | AN36: 6 | AO36: 5
A37: 4 | B37: Lat muscles | C37: 0.7 | D37: 6 | E37: 5 | AD37: 5 day (Friday) | AF37: % | AG37: reps | AH37: sets | AI37: weight | AK37: 5 | AL37: Good morning (standing) | AM37: 0.75 | AN37: 5 | AO37: 5 | AR37: 5 day (Friday) | AT37: % | AU37: reps | AV37: sets | AW37: weight
A38: 5 | B38: Abs | C38: 0.65 | D38: 8 | E38: 4 | AD38: 1 | AE38: Squat | AF38: 0.5 | AG38: 5 | AH38: 1 | AI38: =Max!$B$3*AF38 -> 50 | AR38: 1 | AS38: Squat | AT38: 0.5 | AU38: 5 | AV38: 1 | AW38: =Max!$B$3*AT38 -> 50
AF39: 0.6 | AG39: 5 | AH39: 1 | AI39: =Max!$B$3*AF39 -> 60 | AK39: 5 day (Friday) | AM39: % | AN39: reps | AO39: sets | AP39: weight | AT39: 0.6 | AU39: 4 | AV39: 1 | AW39: =Max!$B$3*AT39 -> 60
A40: 5 day (Friday) | C40: % | D40: reps | E40: sets | F40: weight | G40: =D40*E40 -> #VALUE! | H40: =F40*G40 -> #VALUE! | M40: =G40 -> #VALUE! | N40: =G41 -> 5 | O40: =G42 -> 4 | P40: =G43 -> 3 | AF40: 0.65 | AG40: 3 | AH40: 1 | AI40: =Max!$B$3*AF40 -> 65 | AK40: 1 | AL40: Squat | AM40: 0.5 | AN40: 5 | AO40: 1 | AP40: =Max!$B$3*AM40 -> 50 | AT40: 0.7 | AU40: 3 | AV40: 1 | AW40: =Max!$B$3*AT40 -> 70
A41: 2 | B41: Squat | C41: 0.5 | D41: 5 | E41: 1 | F41: =Max!$B$3*C41 -> 50 | G41: =D41*E41 -> 5 | H41: =F41*G41 -> 250 | AF41: 0.65 | AG41: 7 | AH41: 1 | AI41: =Max!$B$3*AF41 -> 65 | AM41: 0.6 | AN41: 5 | AO41: 1 | AP41: =Max!$B$3*AM41 -> 60 | AT41: 0.8 | AU41: 2 | AV41: 5 | AW41: =Max!$B$3*AT41 -> 80
C42: 0.6 | D42: 4 | E42: 1 | F42: =Max!$B$3*C42 -> 60 | G42: =D42*E42 -> 4 | H42: =F42*G42 -> 240 | AF42: 0.65 | AG42: 4 | AH42: 1 | AI42: =Max!$B$3*AF42 -> 65 | AM42: 0.7 | AN42: 3 | AO42: 1 | AP42: =Max!$B$3*AM42 -> 70 | AR42: 2 | AS42: Bench press | AT42: 0.5 | AU42: 6 | AV42: 1 | AW42: =Max!$B$4*AT42 -> 50
...

Sheet Comp
B1: Sheiko
B2: Comp period (5 weeks)
A5: week 1 | M5: squat | R5: bench | W5: deadlift | AC5: week 2 | AJ5: week 3 | AQ5: week 4 | AX5: week 5
A6: 1 day (Monday) | C6: % | D6: reps | E6: sets | F6: weight | M6: 50-59 | N6: 60-69 | O6: 70-79 | P6: 80-89 | Q6: 90+ | R6: 50-59 | S6: 60-69 | T6: 70-79 | U6: 80-89 | V6: 90+ | W6: 50-59 | X6: 60-69 | Y6: 70-79 | Z6: 80-89 | AA6: 90+ | AC6: 1 day (Monday) | AE6: % | AF6: reps | AG6: sets | AH6: weight | AJ6: 1 day (Monday) | AL6: % | AM6: reps | AN6: sets | AO6: weight | AQ6: 1 day (Monday) | AS6: % | AT6: reps | AU6: sets | AV6: weight | AX6: 1 day (Monday) | AZ6: % | BA6: reps | BB6: sets | BC6: weight
A7: 1 | B7: Bench press | C7: 0.55 | D7: 5 | E7: 1 | F7: =Max!$B$4*C7 -> 55 | G7: =D7*E7 -> 5 | H7: =G7*F7 -> 275 | M7: =G7 -> 5 | N7: =G8 -> 4 | O7: =G9+G10 -> 9 | P7: 0 | Q7: 0 | R7: =I11 -> 5 | S7: =I12 -> 4 | T7: =I13+I14 -> 15 | U7: 0 | V7: 0 | AC7: 1 | AD7: Squat | AE7: 0.5 | AF7: 3 | AG7: 1 | AH7: =Max!$B$3*AE7 -> 50 | AJ7: 1 | AK7: Squat | AL7: 0.55 | AM7: 3 | AN7: 1 | AO7: =Max!$B$3*AL7 -> 55 | AQ7: 1 | AR7: Squat | AS7: 0.5 | AT7: 3 | AU7: 1 | AV7: =Max!$B$3*AS7 -> 50 | AX7: 1 | AY7: Bench press | AZ7: 0.5 | BA7: 3 | BB7: 1 | BC7: =Max!$B$4*AZ7 -> 50
C8: 0.65 | D8: 4 | E8: 1 | F8: =Max!$B$4*C8 -> 65 | G8: =D8*E8 -> 4 | H8: =G8*F8 -> 260 | AE8: 0.6 | AF8: 3 | AG8: 1 | AH8: =Max!$B$3*AE8 -> 60 | AL8: 0.65 | AM8: 3 | AN8: 1 | AO8: =Max!$B$3*AL8 -> 65 | AS8: 0.6 | AT8: 3 | AU8: 1 | AV8: =Max!$B$3*AS8 -> 60 | AZ8: 0.6 | BA8: 3 | BB8: 1 | BC8: =Max!$B$4*AZ8 -> 60
C9: 0.75 | D9: 3 | E9: 1 | F9: =Max!$B$4*C9 -> 75 | G9: =D9*E9 -> 3 | H9: =G9*F9 -> 225 | AE9: 0.7 | AF9: 3 | AG9: 1 | AH9: =Max!$B$3*AE9 -> 70 | AL9: 0.75 | AM9: 2 | AN9: 2 | AO9: =Max!$B$3*AL9 -> 75 | AS9: 0.7 | AT9: 3 | AU9: 1 | AV9: =Max!$B$3*AS9 -> 70 | AZ9: 0.7 | BA9: 2 | BB9: 2 | BC9: =Max!$B$4*AZ9 -> 70
C10: 0.85 | D10: 2 | E10: 3 | F10: =Max!$B$4*C10 -> 85 | G10: =D10*E10 -> 6 | H10: =G10*F10 -> 510 | AE10: 0.75 | AF10: 2 | AG10: 3 | AH10: =Max!$B$3*AE10 -> 75 | AL10: 0.85 | AM10: 1 | AN10: 4 | AO10: =Max!$B$3*AL10 -> 85 | AS10: 0.8 | AT10: 2 | AU10: 4 | AV10: =Max!$B$3*AS10 -> 80 | AZ10: 0.75 | BA10: 1 | BB10: 3 | BC10: =Max!$B$4*AZ10 -> 75
A11: 2 | B11: Squat | C11: 0.5 | D11: 5 | E11: 1 | F11: =Max!$B$3*C11 -> 50 | I11: =D11*E11 -> 5 | J11: =I11*F11 -> 250 | AC11: 2 | AD11: Bench press | AE11: 0.5 | AF11: 3 | AG11: 1 | AH11: =Max!$B$4*AE11 -> 50 | AJ11: 2 | AK11: Bench press | AL11: 0.5 | AM11: 3 | AN11: 1 | AO11: =Max!$B$4*AL11 -> 50 | AQ11: 2 | AR11: Bench press | AS11: 0.5 | AT11: 3 | AU11: 1 | AV11: =Max!$B$4*AS11 -> 50 | AX11: 2 | AY11: Deadlift | AZ11: 0.5 | BA11: 3 | BB11: 1 | BC11: =Max!$B$5*AZ11 -> 50
C12: 0.6 | D12: 4 | E12: 1 | F12: =Max!$B$3*C12 -> 60 | I12: =D12*E12 -> 4 | J12: =I12*F12 -> 240 | AE12: 0.6 | AF12: 3 | AG12: 1 | AH12: =Max!$B$4*AE12 -> 60 | AL12: 0.6 | AM12: 3 | AN12: 1 | AO12: =Max!$B$4*AL12 -> 60 | AS12: 0.6 | AT12: 3 | AU12: 1 | AV12: =Max!$B$4*AS12 -> 60 | AZ12: 0.6 | BA12: 3 | BB12: 1 | BC12: =Max!$B$5*AZ12 -> 60
C13: 0.7 | D13: 3 | E13: 1 | F13: =Max!$B$3*C13 -> 70 | I13: =D13*E13 -> 3 | J13: =I13*F13 -> 210 | AE13: 0.7 | AF13: 3 | AG13: 1 | AH13: =Max!$B$4*AE13 -> 70 | AL13: 0.7 | AM13: 3 | AN13: 1 | AO13: =Max!$B$4*AL13 -> 70 | AS13: 0.7 | AT13: 3 | AU13: 1 | AV13: =Max!$B$4*AS13 -> 70 | AZ13: 0.7 | BA13: 2 | BB13: 3 | BC13: =Max!$B$5*AZ13 -> 70
C14: 0.8 | D14: 3 | E14: 4 | F14: =Max!$B$3*C14 -> 80 | I14: =D14*E14 -> 12 | J14: =I14*F14 -> 960 | AE14: 0.75 | AF14: 2 | AG14: 3 | AH14: =Max!$B$4*AE14 -> 75 | AL14: 0.8 | AM14: 3 | AN14: 4 | AO14: =Max!$B$4*AL14 -> 80 | AS14: 0.8 | AT14: 2 | AU14: 2 | AV14: =Max!$B$4*AS14 -> 80 | AX14: 4 | AY14: Abs | AZ14: 0.65 | BA14: 8 | BB14: 3
A15: 3 | B15: Bench press | C15: 0.5 | D15: 5 | E15: 1 | F15: =Max!$B$4*C15 -> 50 | AC15: 3 | AD15: Chest muscles | AE15: 0.7 | AF15: 6 | AG15: 4 | AJ15: 3 | AK15: Chest muscles | AL15: 0.7 | AM15: 6 | AN15: 4 | AS15: 0.85 | AT15: 1 | AU15: 3 | AV15: =Max!$B$4*AS15 -> 85
C16: 0.6 | D16: 4 | E16: 1 | F16: =Max!$B$4*C16 -> 60 | AC16: 4 | AD16: Back Extensions | AE16: 0.65 | AF16: 8 | AG16: 3 | AJ16: 4 | AK16: Back Extensions | AL16: 0.65 | AM16: 8 | AN16: 4 | AQ16: 3 | AR16: Chest muscles | AS16: 0.6 | AT16: 6 | AU16: 4 | AX16: 3 day (Wednesday) | AZ16: % | BA16: reps | BB16: sets | BC16: weight
C17: 0.7 | D17: 3 | E17: 1 | F17: =Max!$B$4*C17 -> 70 | AQ17: 4 | AR17: Good morning (sitting) | AS17: 0.8 | AT17: 4 | AU17: 4 | AX17: 1 | AY17: Squat | AZ17: 0.5 | BA17: 3 | BB17: 1 | BC17: =Max!$B$3*AZ17 -> 50
C18: 0.8 | D18: 2 | E18: 4 | F18: =Max!$B$4*C18 -> 80 | G18: =D24*E24 -> 3 | H18: =G18*F24 -> 180 | M18: =G18 -> 3 | N18: =G19 -> 8 | O18: =G20 -> 5 | P18: =G21 -> 4 | Q18: =G22+G23+G24 -> 17 | AC18: 3 day (Wednesday) | AE18: % | AF18: reps | AG18: sets | AH18: weight | AJ18: 3 day (Wednesday) | AL18: % | AM18: reps | AN18: sets | AO18: weight | AZ18: 0.6 | BA18: 2 | BB18: 1 | BC18: =Max!$B$3*AZ18 -> 60
A19: 4 | B19: Chest muscles | C19: 0.65 | D19: 8 | E19: 4 | G19: =D25*E25 -> 8 | H19: =G19*F25 -> 560 | AC19: 1 | AD19: Bench press | AE19: 0.5 | AF19: 3 | AG19: 1 | AH19: =Max!$B$4*AE19 -> 50 | AJ19: 1 | AK19: Deadlift up to knees | AL19: 0.5 | AM19: 3 | AN19: 1 | AO19: =Max!$B$5*AL19 -> 50 | AQ19: 3 day (Wednesday) | AS19: % | AT19: reps | AU19: sets | AV19: weight | AZ19: 0.7 | BA19: 1 | BB19: 3 | BC19: =Max!$B$3*AZ19 -> 70
A20: 5 | B20: Back Extensions | C20: 0.65 | D20: 8 | E20: 4 | G20: =D26*E26 -> 5 | H20: =G20*F26 -> 250 | AE20: 0.6 | AF20: 3 | AG20: 1 | AH20: =Max!$B$4*AE20 -> 60 | AL20: 0.6 | AM20: 3 | AN20: 1 | AO20: =Max!$B$5*AL20 -> 60 | AQ20: 1 | AR20: Bench press | AS20: 0.5 | AT20: 3 | AU20: 1 | AV20: =Max!$B$4*AS20 -> 50 | AX20: 2 | AY20: Bench press | AZ20: 0.5 | BA20: 3 | BB20: 1 | BC20: =Max!$B$4*AZ20 -> 50
G21: =D27*E27 -> 4 | H21: =G21*F27 -> 240 | AE21: 0.7 | AF21: 3 | AG21: 1 | AH21: =Max!$B$4*AE21 -> 70 | AL21: 0.7 | AM21: 3 | AN21: 1 | AO21: =Max!$B$5*AL21 -> 70 | AS21: 0.6 | AT21: 3 | AU21: 1 | AV21: =Max!$B$4*AS21 -> 60 | AZ21: 0.6 | BA21: 3 | BB21: 1 | BC21: =Max!$B$4*AZ21 -> 60
A22: 3 day (Wednesday) | C22: % | D22: reps | E22: sets | F22: weight | G22: =D28*E28 -> 3 | H22: =G22*F28 -> 210 | AE22: 0.8 | AF22: 2 | AG22: 1 | AH22: =Max!$B$4*AE22 -> 80 | AL22: 0.75 | AM22: 2 | AN22: 3 | AO22: =Max!$B$5*AL22 -> 75 | AS22: 0.7 | AT22: 3 | AU22: 1 | AV22: =Max!$B$4*AS22 -> 70 | AZ22: 0.7 | BA22: 2 | BB22: 3 | BC22: =Max!$B$4*AZ22 -> 70
A23: 1 | B23: Deficit deadlift | C23: 0.5 | D23: 3 | E23: 1 | F23: =Max!$B$5*C23 -> 50 | G23: =D29*E29 -> 12 | H23: =G23*F29 -> 960 | AE23: 0.9 | AF23: 1 | AG23: 1 | AH23: =Max!$B$4*AE23 -> 90 | AJ23: 2 | AK23: Bench press | AL23: 0.5 | AM23: 3 | AN23: 1 | AO23: =Max!$B$4*AL23 -> 50 | AS23: 0.8 | AT23: 2 | AU23: 2 | AV23: =Max!$B$4*AS23 -> 80
C24: 0.6 | D24: 3 | E24: 1 | F24: =Max!$B$5*C24 -> 60 | G24: 2 | H24: =Max!B3*2*1 -> 200 | AE24: 0.95 | AF24: 1 | AG24: 1 | AH24: =Max!$B$4*AE24 -> 95 | AL24: 0.6 | AM24: 3 | AN24: 1 | AO24: =Max!$B$4*AL24 -> 60 | AQ24: 2 | AR24: Deadlift | AS24: 0.5 | AT24: 2 | AU24: 1 | AV24: =Max!$B$5*AS24 -> 50 | AX24: 5-6-7 day
C25: 0.7 | D25: 2 | E25: 4 | F25: =Max!$B$5*C25 -> 70 | I25: =D31*E31 -> 3 | J25: =I25*F31 -> 210 | R25: =I25 -> 3 | S25: =I26 -> 4 | T25: =I27 -> 3 | U25: =I28 -> 32 | V25: =I29+I30 -> 22 | AE25: 1 | AF25: 1 | AG25: 1 | AH25: =Max!$B$4*AE25 -> 100 | AL25: 0.7 | AM25: 3 | AN25: 1 | AO25: =Max!$B$4*AL25 -> 70 | AS25: 0.6 | AT25: 2 | AU25: 1 | AV25: =Max!$B$5*AS25 -> 60 | AX25: Competition
A26: 2 | B26: Bench press | C26: 0.5 | D26: 5 | E26: 1 | F26: =Max!$B$4*C26 -> 50 | I26: =D32*E32 -> 4 | J26: =I26*F32 -> 320 | AC26: 2 | AD26: Deadlift | AE26: 0.5 | AF26: 3 | AG26: 1 | AH26: =Max!$B$5*AE26 -> 50 | AL26: 0.8 | AM26: 2 | AN26: 2 | AO26: =Max!$B$4*AL26 -> 80 | AS26: 0.7 | AT26: 2 | AU26: 3 | AV26: =Max!$B$5*AS26 -> 70
C27: 0.6 | D27: 4 | E27: 1 | F27: =Max!$B$4*C27 -> 60 | I27: =D33*E33 -> 3 | J27: =I27*F33 -> 270 | AE27: 0.6 | AF27: 3 | AG27: 1 | AH27: =Max!$B$5*AE27 -> 60 | AL27: 0.85 | AM27: 1 | AN27: 3 | AO27: =Max!$B$4*AL27 -> 85 | AQ27: 3 | AR27: Lat muscles | AS27: 0.7 | AT27: 6 | AU27: 3
C28: 0.7 | D28: 3 | E28: 1 | F28: =Max!$B$4*C28 -> 70 | I28: =D34*E34 -> 32 | J28: =I28*F34 -> 0 | AE28: 0.7 | AF28: 3 | AG28: 1 | AH28: =Max!$B$5*AE28 -> 70 | AJ28: 3 | AK28: Deadlift | AL28: 0.5 | AM28: 3 | AN28: 1 | AO28: =Max!$B$5*AL28 -> 50 | AQ28: 4 | AR28: Abs | AS28: 0.65 | AT28: 8 | AU28: 3
C29: 0.8 | D29: 3 | E29: 4 | F29: =Max!$B$4*C29 -> 80 | I29: =D35*E35 -> 20 | J29: =I29*F35 -> 0 | AE29: 0.8 | AF29: 2 | AG29: 1 | AH29: =Max!$B$5*AE29 -> 80 | AL29: 0.6 | AM29: 3 | AN29: 1 | AO29: =Max!$B$5*AL29 -> 60
A30: 3 | B30: Deadlift from boxes | C30: 0.6 | D30: 3 | E30: 1 | F30: =Max!$B$5*C30 -> 60 | I30: =2 -> 2 | J30: =2*1*Max!B4 -> 200 | AE30: 0.9 | AF30: 1 | AG30: 1 | AH30: =Max!$B$5*AE30 -> 90 | AL30: 0.7 | AM30: 3 | AN30: 1 | AO30: =Max!$B$5*AL30 -> 70 | AQ30: 5 day (Friday) | AS30: % | AT30: reps | AU30: sets | AV30: weight
C31: 0.7 | D31: 3 | E31: 1 | F31: =Max!$B$5*C31 -> 70 | AE31: 0.95 | AF31: 1 | AG31: 1 | AH31: =Max!$B$5*AE31 -> 95 | AL31: 0.8 | AM31: 2 | AN31: 4 | AO31: =Max!$B$5*AL31 -> 80 | AQ31: 1 | AR31: Squat | AS31: 0.5 | AT31: 3 | AU31: 1 | AV31: =Max!$B$3*AS31 -> 50
C32: 0.8 | D32: 2 | E32: 2 | F32: =Max!$B$5*C32 -> 80 | AE32: 1 | AF32: 1 | AG32: 1 | AH32: =Max!$B$5*AE32 -> 100 | AJ32: 4 | AK32: Lat muscles | AL32: 0.7 | AM32: 6 | AN32: 4 | AS32: 0.6 | AT32: 3 | AU32: 1 | AV32: =Max!$B$3*AS32 -> 60
C33: 0.9 | D33: 1 | E33: 3 | F33: =Max!$B$5*C33 -> 90 | I33: =D39*E39 -> 3 | J33: =I33*F39 -> 180 | R33: =I33 -> 3 | S33: =I34 -> 3 | T33: =I35+I36 -> 7 | U33: 0 | V33: 0 | AC33: 3 | AD33: Triceps | AE33: 0.7 | AF33: 6 | AG33: 4 | AJ33: 5 | AK33: Abs | AL33: 0.65 | AM33: 8 | AN33: 3 | AS33: 0.7 | AT33: 2 | AU33: 2 | AV33: =Max!$B$3*AS33 -> 70
A34: 4 | B34: Lat Muscles | C34: 0.65 | D34: 8 | E34: 4 | I34: =D40*E40 -> 3 | J34: =I34*F40 -> 210 | AC34: 4 | AD34: Abs | AE34: 0.65 | AF34: 8 | AG34: 3 | AS34: 0.75 | AT34: 1 | AU34: 3 | AV34: =Max!$B$3*AS34 -> 75
A35: 5 | B35: Dips | C35: 0.8 | D35: 4 | E35: 5 | I35: =D41*E41 -> 4 | J35: =I35*F41 -> 320 | AJ35: 5 day (Friday) | AL35: % | AM35: reps | AN35: sets | AO35: weight | AQ35: 2 | AR35: Bench press | AS35: 0.5 | AT35: 3 | AU35: 1 | AV35: =Max!$B$4*AS35 -> 50
I36: =D42*E42 -> 3 | J36: =I36*F42 -> 255 | AC36: 5 day (Friday) | AE36: % | AF36: reps | AG36: sets | AH36: weight | AJ36: 1 | AK36: Squat | AL36: 0.5 | AM36: 3 | AN36: 1 | AO36: =Max!$B$3*AL36 -> 50 | AS36: 0.6 | AT36: 3 | AU36: 1 | AV36: =Max!$B$4*AS36 -> 60
A37: 5 day (Friday) | C37: % | D37: reps | E37: sets | F37: weight | K37: =D43*E43 -> 3 | L37: =K37*F43 -> 150 | W37: =K37 -> 3 | X37: =K38 -> 3 | Y37: =K39 -> 3 | Z37: =K40 -> 4 | AA37: =K41+K42 -> 8 | AC37: 1 | AD37: Squat | AE37: 0.5 | AF37: 3 | AG37: 1 | AH37: =Max!$B$3*AE37 -> 50 | AL37: 0.6 | AM37: 3 | AN37: 1 | AO37: =Max!$B$3*AL37 -> 60 | AS37: 0.7 | AT37: 3 | AU37: 1 | AV37: =Max!$B$4*AS37 -> 70
A38: 1 | B38: Squat | C38: 0.5 | D38: 3 | E38: 1 | F38: =Max!$B$3*C38 -> 50 | K38: =D44*E44 -> 3 | L38: =K38*F44 -> 180 | AE38: 0.6 | AF38: 3 | AG38: 1 | AH38: =Max!$B$3*AE38 -> 60 | AL38: 0.7 | AM38: 3 | AN38: 1 | AO38: =Max!$B$3*AL38 -> 70 | AS38: 0.75 | AT38: 2 | AU38: 3 | AV38: =Max!$B$4*AS38 -> 75
C39: 0.6 | D39: 3 | E39: 1 | F39: =Max!$B$3*C39 -> 60 | K39: =D45*E45 -> 3 | L39: =K39*F45 -> 210 | AE39: 0.7 | AF39: 3 | AG39: 1 | AH39: =Max!$B$3*AE39 -> 70 | AL39: 0.8 | AM39: 2 | AN39: 4 | AO39: =Max!$B$3*AL39 -> 80 | AQ39: 3 | AR39: Back Extensions | AS39: 0.7 | AT39: 6 | AU39: 3
C40: 0.7 | D40: 3 | E40: 1 | F40: =Max!$B$3*C40 -> 70 | K40: =D46*E46 -> 4 | L40: =K40*F46 -> 320 | AE40: 0.8 | AF40: 2 | AG40: 1 | AH40: =Max!$B$3*AE40 -> 80 | AJ40: 3 | AK40: Bench press | AL40: 0.5 | AM40: 3 | AN40: 1 | AO40: =Max!$B$4*AL40 -> 50
C41: 0.8 | D41: 2 | E41: 2 | F41: =Max!$B$3*C41 -> 80 | K41: =D47*E47 -> 6 | L41: =K41*F47 -> 510 | AE41: 0.9 | AF41: 1 | AG41: 1 | AH41: =Max!$B$3*AE41 -> 90 | AL41: 0.6 | AM41: 3 | AN41: 1 | AO41: =Max!$B$4*AL41 -> 60 | AQ41: 6 day (Saturday) | AS41: % | AT41: reps | AU41: sets | AV41: weight
C42: 0.85 | D42: 1 | E42: 3 | F42: =Max!$B$3*C42 -> 85 | K42: 2 | L42: =Max!B5*K42 -> 200 | AE42: 0.95 | AF42: 1 | AG42: 1 | AH42: =Max!$B$3*AE42 -> 95 | AL42: 0.7 | AM42: 3 | AN42: 1 | AO42: =Max!$B$4*AL42 -> 70 | AR42: Rest
...
