Workbook

Sheet Start Here
Z4: Made by ChaseT 2008.05.09
A18: WWW.BIBLIOTECADERUTINAS.COM
C19: Introduce 1rm
Q20: Sheiko Advanced Medium Load
D21: Sentadillas | F21: 100
D22: Press de banca | F22: 100
D23: Peso muerto | F23: 100
C25: FAQS
D27: Q: | E27: How should I use this training program?
D28: A: | E28: If you've never used a Sheiko program before, first get youself acquainted with this style of training by running through the program once as is. After that you can modify it to fit your specific needs.
R29: Download the spreadsheet in order to edit it.
D32: Q: | E32: How do I modify the program without messing it up? | R32: Get the official Sheiko mobile app for more.
D33: A: | E33: The most convenient way to make this program fit your specific needs is to make exercise substitutions and preserve the overall structure. Your best bet is to make a substitution that serves a similar purpose.
D37: Q: | E37: Can I do the double sessions as one long session instead?
D38: A: | E38: You can. But just be aware that doing so will shift the emphasis towards metabolic stress and decrease the emphasis on technique development. If that is what you need to make progress then go for it.
D42: Q: | E42: Can I run this program with inflated maxes?
D43: A: | E43: Again, you can. If you do hopefully you have good techniqe because higher intensity usually leads to form breakdown. If that happens you'll wind up practicing bad technique with greater frequency and also increase the risk of injury.
D47: Q: | E47: My gym doesn't have chains. What can I do instead?
D48: A: | E48: Get some. They are an extremely valuable training tool. Check your local hardware store or at least get some bands.
D52: Q: | E52: How can I do board presses by myself?
D53: A: | E53: Take a plastic water bottle and slide it under your shirt. Lower the bar to the bottle then press it back up.
D57: Q: | E57: I train equipped. How can I use this program?
D58: A: | E58: There are two ways you can do it: 1) you can use your gear through the whole program. In that case use your equipped maxes above. Warm up without the gear then put it on around 75% or if the Weight can't be moved without gear 2) you can start the training program with your raw maxes and train that way for the first part of the training program. After your skills test switch to equipped maxes and finish the program using gear.
D62: Q: | E62: Can I have Boris train me personally?
D63: A: | E63: Boris Sheiko offers online coaching on his website.

Sheet Prep Cycle I
B2: Preparatory Period I for Class 1 and Above Athletes
B5: WEEK 1 | N5: squat | S5: bench | X5: deadlift
B6: Monday | D6: % | E6: Reps | F6: Sets | G6: Weight | N6: 50-59 | O6: 60-69 | P6: 70-79 | Q6: 80-89 | R6: 90+ | S6: 50-59 | T6: 60-69 | U6: 70-79 | V6: 80-89 | W6: 90+ | X6: 50-59 | Y6: 60-69 | Z6: 70-79 | AA6: 80-89 | AB6: 90+ | AC6: Notes:
B7: 1 | C7: Front squat | D7: 0.3 | E7: 4 | F7: 1 | G7: ='Start Here'!$F$21*D7 -> 30 | H7: =E7*F7 -> 4 | I7: =G7*H7 -> 120 | N7: =IF(ISNUMBER(SEARCH("squat",$C7)),IF($D7>=0.5,IF($D7<0.6,$E7*$F7," ")," ")," ") | O7: =IF(ISNUMBER(SEARCH("squat",$C7)),IF($D7>=0.6,IF($D7<0.7,$E7*$F7," ")," ")," ") | P7: =IF(ISNUMBER(SEARCH("squat",$C7)),IF($D7>=0.7,IF($D7<0.8,$E7*$F7," ")," ")," ") | Q7: =IF(ISNUMBER(SEARCH("squat",$C7)),IF($D7>=0.8,IF($D7<0.9,$E7*$F7," ")," ")," ") | R7: =IF(ISNUMBER(SEARCH("squat",$C7)),IF($D7>=0.9,$E7*$F7," ")," ") | S7: =IF(ISNUMBER(SEARCH("bench",$C7)),IF($D7>=0.5,IF($D7<0.6,$E7*$F7," ")," ")," ") | T7: =IF(ISNUMBER(SEARCH("bench",$C7)),IF($D7>=0.6,IF($D7<0.7,$E7*$F7," ")," ")," ") | U7: =IF(ISNUMBER(SEARCH("bench",$C7)),IF($D7>=0.7,IF($D7<0.8,$E7*$F7," ")," ")," ") | V7: =IF(ISNUMBER(SEARCH("bench",$C7)),IF($D7>=0.8,IF($D7<0.9,$E7*$F7," ")," ")," ") | W7: =IF(ISNUMBER(SEARCH("bench",$C7)),IF($D7>=0.9,$E7*$F7," ")," ")
C8: Front squat | D8: 0.4 | E8: 4 | F8: 1 | G8: ='Start Here'!$F$21*D8 -> 40 | H8: =E8*F8 -> 4 | I8: =G8*H8 -> 160 | N8: =IF(ISNUMBER(SEARCH("squat",$C8)),IF($D8>=0.5,IF($D8<0.6,$E8*$F8," ")," ")," ") | O8: =IF(ISNUMBER(SEARCH("squat",$C8)),IF($D8>=0.6,IF($D8<0.7,$E8*$F8," ")," ")," ") | P8: =IF(ISNUMBER(SEARCH("squat",$C8)),IF($D8>=0.7,IF($D8<0.8,$E8*$F8," ")," ")," ") | Q8: =IF(ISNUMBER(SEARCH("squat",$C8)),IF($D8>=0.8,IF($D8<0.9,$E8*$F8," ")," ")," ") | R8: =IF(ISNUMBER(SEARCH("squat",$C8)),IF($D8>=0.9,$E8*$F8," ")," ") | S8: =IF(ISNUMBER(SEARCH("bench",$C8)),IF($D8>=0.5,IF($D8<0.6,$E8*$F8," ")," ")," ") | T8: =IF(ISNUMBER(SEARCH("bench",$C8)),IF($D8>=0.6,IF($D8<0.7,$E8*$F8," ")," ")," ") | U8: =IF(ISNUMBER(SEARCH("bench",$C8)),IF($D8>=0.7,IF($D8<0.8,$E8*$F8," ")," ")," ") | V8: =IF(ISNUMBER(SEARCH("bench",$C8)),IF($D8>=0.8,IF($D8<0.9,$E8*$F8," ")," ")," ") | W8: =IF(ISNUMBER(SEARCH("bench",$C8)),IF($D8>=0.9,$E8*$F8," ")," ")
C9: Front squat | D9: 0.5 | E9: 4 | F9: 3 | G9: ='Start Here'!$F$21*D9 -> 50 | H9: =E9*F9 -> 12 | I9: =G9*H9 -> 600 | N9: =IF(ISNUMBER(SEARCH("squat",$C9)),IF($D9>=0.5,IF($D9<0.6,$E9*$F9," ")," ")," ") -> 12 | O9: =IF(ISNUMBER(SEARCH("squat",$C9)),IF($D9>=0.6,IF($D9<0.7,$E9*$F9," ")," ")," ") | P9: =IF(ISNUMBER(SEARCH("squat",$C9)),IF($D9>=0.7,IF($D9<0.8,$E9*$F9," ")," ")," ") | Q9: =IF(ISNUMBER(SEARCH("squat",$C9)),IF($D9>=0.8,IF($D9<0.9,$E9*$F9," ")," ")," ") | R9: =IF(ISNUMBER(SEARCH("squat",$C9)),IF($D9>=0.9,$E9*$F9," ")," ") | S9: =IF(ISNUMBER(SEARCH("bench",$C9)),IF($D9>=0.5,IF($D9<0.6,$E9*$F9," ")," ")," ") | T9: =IF(ISNUMBER(SEARCH("bench",$C9)),IF($D9>=0.6,IF($D9<0.7,$E9*$F9," ")," ")," ") | U9: =IF(ISNUMBER(SEARCH("bench",$C9)),IF($D9>=0.7,IF($D9<0.8,$E9*$F9," ")," ")," ") | V9: =IF(ISNUMBER(SEARCH("bench",$C9)),IF($D9>=0.8,IF($D9<0.9,$E9*$F9," ")," ")," ") | W9: =IF(ISNUMBER(SEARCH("bench",$C9)),IF($D9>=0.9,$E9*$F9," ")," ")
B10: 2 | C10: Bench press | D10: 0.5 | E10: 5 | F10: 1 | G10: ='Start Here'!$F$22*D10 -> 50 | J10: =E10*F10 -> 5 | K10: =G10*J10 -> 250 | N10: =IF(ISNUMBER(SEARCH("squat",$C10)),IF($D10>=0.5,IF($D10<0.6,$E10*$F10," ")," ")," ") | O10: =IF(ISNUMBER(SEARCH("squat",$C10)),IF($D10>=0.6,IF($D10<0.7,$E10*$F10," ")," ")," ") | P10: =IF(ISNUMBER(SEARCH("squat",$C10)),IF($D10>=0.7,IF($D10<0.8,$E10*$F10," ")," ")," ") | Q10: =IF(ISNUMBER(SEARCH("squat",$C10)),IF($D10>=0.8,IF($D10<0.9,$E10*$F10," ")," ")," ") | R10: =IF(ISNUMBER(SEARCH("squat",$C10)),IF($D10>=0.9,$E10*$F10," ")," ") | S10: =IF(ISNUMBER(SEARCH("bench",$C10)),IF($D10>=0.5,IF($D10<0.6,$E10*$F10," ")," ")," ") -> 5 | T10: =IF(ISNUMBER(SEARCH("bench",$C10)),IF($D10>=0.6,IF($D10<0.7,$E10*$F10," ")," ")," ") | U10: =IF(ISNUMBER(SEARCH("bench",$C10)),IF($D10>=0.7,IF($D10<0.8,$E10*$F10," ")," ")," ") | V10: =IF(ISNUMBER(SEARCH("bench",$C10)),IF($D10>=0.8,IF($D10<0.9,$E10*$F10," ")," ")," ") | W10: =IF(ISNUMBER(SEARCH("bench",$C10)),IF($D10>=0.9,$E10*$F10," ")," ")
C11: Bench press | D11: 0.6 | E11: 4 | F11: 1 | G11: ='Start Here'!$F$22*D11 -> 60 | J11: =E11*F11 -> 4 | K11: =G11*J11 -> 240 | N11: =IF(ISNUMBER(SEARCH("squat",$C11)),IF($D11>=0.5,IF($D11<0.6,$E11*$F11," ")," ")," ") | O11: =IF(ISNUMBER(SEARCH("squat",$C11)),IF($D11>=0.6,IF($D11<0.7,$E11*$F11," ")," ")," ") | P11: =IF(ISNUMBER(SEARCH("squat",$C11)),IF($D11>=0.7,IF($D11<0.8,$E11*$F11," ")," ")," ") | Q11: =IF(ISNUMBER(SEARCH("squat",$C11)),IF($D11>=0.8,IF($D11<0.9,$E11*$F11," ")," ")," ") | R11: =IF(ISNUMBER(SEARCH("squat",$C11)),IF($D11>=0.9,$E11*$F11," ")," ") | S11: =IF(ISNUMBER(SEARCH("bench",$C11)),IF($D11>=0.5,IF($D11<0.6,$E11*$F11," ")," ")," ") | T11: =IF(ISNUMBER(SEARCH("bench",$C11)),IF($D11>=0.6,IF($D11<0.7,$E11*$F11," ")," ")," ") -> 4 | U11: =IF(ISNUMBER(SEARCH("bench",$C11)),IF($D11>=0.7,IF($D11<0.8,$E11*$F11," ")," ")," ") | V11: =IF(ISNUMBER(SEARCH("bench",$C11)),IF($D11>=0.8,IF($D11<0.9,$E11*$F11," ")," ")," ") | W11: =IF(ISNUMBER(SEARCH("bench",$C11)),IF($D11>=0.9,$E11*$F11," ")," ")
C12: Bench press | D12: 0.7 | E12: 3 | F12: 1 | G12: ='Start Here'!$F$22*D12 -> 70 | J12: =E12*F12 -> 3 | K12: =G12*J12 -> 210 | N12: =IF(ISNUMBER(SEARCH("squat",$C12)),IF($D12>=0.5,IF($D12<0.6,$E12*$F12," ")," ")," ") | O12: =IF(ISNUMBER(SEARCH("squat",$C12)),IF($D12>=0.6,IF($D12<0.7,$E12*$F12," ")," ")," ") | P12: =IF(ISNUMBER(SEARCH("squat",$C12)),IF($D12>=0.7,IF($D12<0.8,$E12*$F12," ")," ")," ") | Q12: =IF(ISNUMBER(SEARCH("squat",$C12)),IF($D12>=0.8,IF($D12<0.9,$E12*$F12," ")," ")," ") | R12: =IF(ISNUMBER(SEARCH("squat",$C12)),IF($D12>=0.9,$E12*$F12," ")," ") | S12: =IF(ISNUMBER(SEARCH("bench",$C12)),IF($D12>=0.5,IF($D12<0.6,$E12*$F12," ")," ")," ") | T12: =IF(ISNUMBER(SEARCH("bench",$C12)),IF($D12>=0.6,IF($D12<0.7,$E12*$F12," ")," ")," ") | U12: =IF(ISNUMBER(SEARCH("bench",$C12)),IF($D12>=0.7,IF($D12<0.8,$E12*$F12," ")," ")," ") -> 3 | V12: =IF(ISNUMBER(SEARCH("bench",$C12)),IF($D12>=0.8,IF($D12<0.9,$E12*$F12," ")," ")," ") | W12: =IF(ISNUMBER(SEARCH("bench",$C12)),IF($D12>=0.9,$E12*$F12," ")," ")
C13: Bench press | D13: 0.75 | E13: 2 | F13: 4 | G13: ='Start Here'!$F$22*D13 -> 75 | J13: =E13*F13 -> 8 | K13: =G13*J13 -> 600 | N13: =IF(ISNUMBER(SEARCH("squat",$C13)),IF($D13>=0.5,IF($D13<0.6,$E13*$F13," ")," ")," ") | O13: =IF(ISNUMBER(SEARCH("squat",$C13)),IF($D13>=0.6,IF($D13<0.7,$E13*$F13," ")," ")," ") | P13: =IF(ISNUMBER(SEARCH("squat",$C13)),IF($D13>=0.7,IF($D13<0.8,$E13*$F13," ")," ")," ") | Q13: =IF(ISNUMBER(SEARCH("squat",$C13)),IF($D13>=0.8,IF($D13<0.9,$E13*$F13," ")," ")," ") | R13: =IF(ISNUMBER(SEARCH("squat",$C13)),IF($D13>=0.9,$E13*$F13," ")," ") | S13: =IF(ISNUMBER(SEARCH("bench",$C13)),IF($D13>=0.5,IF($D13<0.6,$E13*$F13," ")," ")," ") | T13: =IF(ISNUMBER(SEARCH("bench",$C13)),IF($D13>=0.6,IF($D13<0.7,$E13*$F13," ")," ")," ") | U13: =IF(ISNUMBER(SEARCH("bench",$C13)),IF($D13>=0.7,IF($D13<0.8,$E13*$F13," ")," ")," ") -> 8 | V13: =IF(ISNUMBER(SEARCH("bench",$C13)),IF($D13>=0.8,IF($D13<0.9,$E13*$F13," ")," ")," ") | W13: =IF(ISNUMBER(SEARCH("bench",$C13)),IF($D13>=0.9,$E13*$F13," ")," ")
B14: 3 | C14: Squat | D14: 0.55 | E14: 3 | F14: 1 | G14: ='Start Here'!$F$21*D14 -> 55 | H14: =E14*F14 -> 3 | I14: =G14*H14 -> 165 | N14: =IF(ISNUMBER(SEARCH("squat",$C14)),IF($D14>=0.5,IF($D14<0.6,$E14*$F14," ")," ")," ") -> 3 | O14: =IF(ISNUMBER(SEARCH("squat",$C14)),IF($D14>=0.6,IF($D14<0.7,$E14*$F14," ")," ")," ") | P14: =IF(ISNUMBER(SEARCH("squat",$C14)),IF($D14>=0.7,IF($D14<0.8,$E14*$F14," ")," ")," ") | Q14: =IF(ISNUMBER(SEARCH("squat",$C14)),IF($D14>=0.8,IF($D14<0.9,$E14*$F14," ")," ")," ") | R14: =IF(ISNUMBER(SEARCH("squat",$C14)),IF($D14>=0.9,$E14*$F14," ")," ") | S14: =IF(ISNUMBER(SEARCH("bench",$C14)),IF($D14>=0.5,IF($D14<0.6,$E14*$F14," ")," ")," ") | T14: =IF(ISNUMBER(SEARCH("bench",$C14)),IF($D14>=0.6,IF($D14<0.7,$E14*$F14," ")," ")," ") | U14: =IF(ISNUMBER(SEARCH("bench",$C14)),IF($D14>=0.7,IF($D14<0.8,$E14*$F14," ")," ")," ") | V14: =IF(ISNUMBER(SEARCH("bench",$C14)),IF($D14>=0.8,IF($D14<0.9,$E14*$F14," ")," ")," ") | W14: =IF(ISNUMBER(SEARCH("bench",$C14)),IF($D14>=0.9,$E14*$F14," ")," ")
C15: Squat | D15: 0.65 | E15: 3 | F15: 1 | G15: ='Start Here'!$F$21*D15 -> 65 | H15: =E15*F15 -> 3 | I15: =G15*H15 -> 195 | N15: =IF(ISNUMBER(SEARCH("squat",$C15)),IF($D15>=0.5,IF($D15<0.6,$E15*$F15," ")," ")," ") | O15: =IF(ISNUMBER(SEARCH("squat",$C15)),IF($D15>=0.6,IF($D15<0.7,$E15*$F15," ")," ")," ") -> 3 | P15: =IF(ISNUMBER(SEARCH("squat",$C15)),IF($D15>=0.7,IF($D15<0.8,$E15*$F15," ")," ")," ") | Q15: =IF(ISNUMBER(SEARCH("squat",$C15)),IF($D15>=0.8,IF($D15<0.9,$E15*$F15," ")," ")," ") | R15: =IF(ISNUMBER(SEARCH("squat",$C15)),IF($D15>=0.9,$E15*$F15," ")," ") | S15: =IF(ISNUMBER(SEARCH("bench",$C15)),IF($D15>=0.5,IF($D15<0.6,$E15*$F15," ")," ")," ") | T15: =IF(ISNUMBER(SEARCH("bench",$C15)),IF($D15>=0.6,IF($D15<0.7,$E15*$F15," ")," ")," ") | U15: =IF(ISNUMBER(SEARCH("bench",$C15)),IF($D15>=0.7,IF($D15<0.8,$E15*$F15," ")," ")," ") | V15: =IF(ISNUMBER(SEARCH("bench",$C15)),IF($D15>=0.8,IF($D15<0.9,$E15*$F15," ")," ")," ") | W15: =IF(ISNUMBER(SEARCH("bench",$C15)),IF($D15>=0.9,$E15*$F15," ")," ")
C16: Squat | D16: 0.75 | E16: 2 | F16: 4 | G16: ='Start Here'!$F$21*D16 -> 75 | H16: =E16*F16 -> 8 | I16: =G16*H16 -> 600 | N16: =IF(ISNUMBER(SEARCH("squat",$C16)),IF($D16>=0.5,IF($D16<0.6,$E16*$F16," ")," ")," ") | O16: =IF(ISNUMBER(SEARCH("squat",$C16)),IF($D16>=0.6,IF($D16<0.7,$E16*$F16," ")," ")," ") | P16: =IF(ISNUMBER(SEARCH("squat",$C16)),IF($D16>=0.7,IF($D16<0.8,$E16*$F16," ")," ")," ") -> 8 | Q16: =IF(ISNUMBER(SEARCH("squat",$C16)),IF($D16>=0.8,IF($D16<0.9,$E16*$F16," ")," ")," ") | R16: =IF(ISNUMBER(SEARCH("squat",$C16)),IF($D16>=0.9,$E16*$F16," ")," ") | S16: =IF(ISNUMBER(SEARCH("bench",$C16)),IF($D16>=0.5,IF($D16<0.6,$E16*$F16," ")," ")," ") | T16: =IF(ISNUMBER(SEARCH("bench",$C16)),IF($D16>=0.6,IF($D16<0.7,$E16*$F16," ")," ")," ") | U16: =IF(ISNUMBER(SEARCH("bench",$C16)),IF($D16>=0.7,IF($D16<0.8,$E16*$F16," ")," ")," ") | V16: =IF(ISNUMBER(SEARCH("bench",$C16)),IF($D16>=0.8,IF($D16<0.9,$E16*$F16," ")," ")," ") | W16: =IF(ISNUMBER(SEARCH("bench",$C16)),IF($D16>=0.9,$E16*$F16," ")," ")
B17: 4 | C17: Chest muscles | E17: 8 | F17: 4
B18: 5 | C18: Abs | E18: 10 | F18: 3
B20: Wednesday | D20: % | E20: Reps | F20: Sets | G20: Weight | AC20: Notes:
B21: 1 | C21: Deadlift to knees w/2s pause | D21: 0.5 | E21: 3 | F21: 1 | G21: ='Start Here'!$F$23*D21 -> 50 | L21: =E21*F21 -> 3 | M21: =G21*L21 -> 150 | S21: =IF(ISNUMBER(SEARCH("bench",$C21)),IF($D21>=0.5,IF($D21<0.6,$E21*$F21," ")," ")," ") | T21: =IF(ISNUMBER(SEARCH("bench",$C21)),IF($D21>=0.6,IF($D21<0.7,$E21*$F21," ")," ")," ") | U21: =IF(ISNUMBER(SEARCH("bench",$C21)),IF($D21>=0.7,IF($D21<0.8,$E21*$F21," ")," ")," ") | V21: =IF(ISNUMBER(SEARCH("bench",$C21)),IF($D21>=0.8,IF($D21<0.9,$E21*$F21," ")," ")," ") | W21: =IF(ISNUMBER(SEARCH("bench",$C21)),IF($D21>=0.9,$E21*$F21," ")," ") | X21: =IF(ISNUMBER(SEARCH("deadlift",$C21)),IF($D21>=0.5,IF($D21<0.6,$E21*$F21," ")," ")," ") -> 3 | Y21: =IF(ISNUMBER(SEARCH("deadlift",$C21)),IF($D21>=0.6,IF($D21<0.7,$E21*$F21," ")," ")," ") | Z21: =IF(ISNUMBER(SEARCH("deadlift",$C21)),IF($D21>=0.7,IF($D21<0.8,$E21*$F21," ")," ")," ") | AA21: =IF(ISNUMBER(SEARCH("deadlift",$C21)),IF($D21>=0.8,IF($D21<0.9,$E21*$F21," ")," ")," ") | AB21: =IF(ISNUMBER(SEARCH("deadlift",$C21)),IF($D21>=0.9,$E21*$F21," ")," ")
C22: Deadlift to knees w/2s pause | D22: 0.6 | E22: 3 | F22: 1 | G22: ='Start Here'!$F$23*D22 -> 60 | L22: =E22*F22 -> 3 | M22: =G22*L22 -> 180 | S22: =IF(ISNUMBER(SEARCH("bench",$C22)),IF($D22>=0.5,IF($D22<0.6,$E22*$F22," ")," ")," ") | T22: =IF(ISNUMBER(SEARCH("bench",$C22)),IF($D22>=0.6,IF($D22<0.7,$E22*$F22," ")," ")," ") | U22: =IF(ISNUMBER(SEARCH("bench",$C22)),IF($D22>=0.7,IF($D22<0.8,$E22*$F22," ")," ")," ") | V22: =IF(ISNUMBER(SEARCH("bench",$C22)),IF($D22>=0.8,IF($D22<0.9,$E22*$F22," ")," ")," ") | W22: =IF(ISNUMBER(SEARCH("bench",$C22)),IF($D22>=0.9,$E22*$F22," ")," ") | X22: =IF(ISNUMBER(SEARCH("deadlift",$C22)),IF($D22>=0.5,IF($D22<0.6,$E22*$F22," ")," ")," ") | Y22: =IF(ISNUMBER(SEARCH("deadlift",$C22)),IF($D22>=0.6,IF($D22<0.7,$E22*$F22," ")," ")," ") -> 3 | Z22: =IF(ISNUMBER(SEARCH("deadlift",$C22)),IF($D22>=0.7,IF($D22<0.8,$E22*$F22," ")," ")," ") | AA22: =IF(ISNUMBER(SEARCH("deadlift",$C22)),IF($D22>=0.8,IF($D22<0.9,$E22*$F22," ")," ")," ") | AB22: =IF(ISNUMBER(SEARCH("deadlift",$C22)),IF($D22>=0.9,$E22*$F22," ")," ")
C23: Deadlift to knees w/2s pause | D23: 0.7 | E23: 3 | F23: 4 | G23: ='Start Here'!$F$23*D23 -> 70 | L23: =E23*F23 -> 12 | M23: =G23*L23 -> 840 | S23: =IF(ISNUMBER(SEARCH("bench",$C23)),IF($D23>=0.5,IF($D23<0.6,$E23*$F23," ")," ")," ") | T23: =IF(ISNUMBER(SEARCH("bench",$C23)),IF($D23>=0.6,IF($D23<0.7,$E23*$F23," ")," ")," ") | U23: =IF(ISNUMBER(SEARCH("bench",$C23)),IF($D23>=0.7,IF($D23<0.8,$E23*$F23," ")," ")," ") | V23: =IF(ISNUMBER(SEARCH("bench",$C23)),IF($D23>=0.8,IF($D23<0.9,$E23*$F23," ")," ")," ") | W23: =IF(ISNUMBER(SEARCH("bench",$C23)),IF($D23>=0.9,$E23*$F23," ")," ") | X23: =IF(ISNUMBER(SEARCH("deadlift",$C23)),IF($D23>=0.5,IF($D23<0.6,$E23*$F23," ")," ")," ") | Y23: =IF(ISNUMBER(SEARCH("deadlift",$C23)),IF($D23>=0.6,IF($D23<0.7,$E23*$F23," ")," ")," ") | Z23: =IF(ISNUMBER(SEARCH("deadlift",$C23)),IF($D23>=0.7,IF($D23<0.8,$E23*$F23," ")," ")," ") -> 12 | AA23: =IF(ISNUMBER(SEARCH("deadlift",$C23)),IF($D23>=0.8,IF($D23<0.9,$E23*$F23," ")," ")," ") | AB23: =IF(ISNUMBER(SEARCH("deadlift",$C23)),IF($D23>=0.9,$E23*$F23," ")," ")
B24: 2 | C24: Bench press | D24: 0.5 | E24: 5 | F24: 1 | G24: ='Start Here'!$F$22*D24 -> 50 | J24: =E24*F24 -> 5 | K24: =G24*J24 -> 250 | S24: =IF(ISNUMBER(SEARCH("bench",$C24)),IF($D24>=0.5,IF($D24<0.6,$E24*$F24," ")," ")," ") -> 5 | T24: =IF(ISNUMBER(SEARCH("bench",$C24)),IF($D24>=0.6,IF($D24<0.7,$E24*$F24," ")," ")," ") | U24: =IF(ISNUMBER(SEARCH("bench",$C24)),IF($D24>=0.7,IF($D24<0.8,$E24*$F24," ")," ")," ") | V24: =IF(ISNUMBER(SEARCH("bench",$C24)),IF($D24>=0.8,IF($D24<0.9,$E24*$F24," ")," ")," ") | W24: =IF(ISNUMBER(SEARCH("bench",$C24)),IF($D24>=0.9,$E24*$F24," ")," ") | X24: =IF(ISNUMBER(SEARCH("deadlift",$C24)),IF($D24>=0.5,IF($D24<0.6,$E24*$F24," ")," ")," ") | Y24: =IF(ISNUMBER(SEARCH("deadlift",$C24)),IF($D24>=0.6,IF($D24<0.7,$E24*$F24," ")," ")," ") | Z24: =IF(ISNUMBER(SEARCH("deadlift",$C24)),IF($D24>=0.7,IF($D24<0.8,$E24*$F24," ")," ")," ") | AA24: =IF(ISNUMBER(SEARCH("deadlift",$C24)),IF($D24>=0.8,IF($D24<0.9,$E24*$F24," ")," ")," ") | AB24: =IF(ISNUMBER(SEARCH("deadlift",$C24)),IF($D24>=0.9,$E24*$F24," ")," ")
C25: Bench press | D25: 0.6 | E25: 5 | F25: 1 | G25: ='Start Here'!$F$22*D25 -> 60 | J25: =E25*F25 -> 5 | K25: =G25*J25 -> 300 | S25: =IF(ISNUMBER(SEARCH("bench",$C25)),IF($D25>=0.5,IF($D25<0.6,$E25*$F25," ")," ")," ") | T25: =IF(ISNUMBER(SEARCH("bench",$C25)),IF($D25>=0.6,IF($D25<0.7,$E25*$F25," ")," ")," ") -> 5 | U25: =IF(ISNUMBER(SEARCH("bench",$C25)),IF($D25>=0.7,IF($D25<0.8,$E25*$F25," ")," ")," ") | V25: =IF(ISNUMBER(SEARCH("bench",$C25)),IF($D25>=0.8,IF($D25<0.9,$E25*$F25," ")," ")," ") | W25: =IF(ISNUMBER(SEARCH("bench",$C25)),IF($D25>=0.9,$E25*$F25," ")," ") | X25: =IF(ISNUMBER(SEARCH("deadlift",$C25)),IF($D25>=0.5,IF($D25<0.6,$E25*$F25," ")," ")," ") | Y25: =IF(ISNUMBER(SEARCH("deadlift",$C25)),IF($D25>=0.6,IF($D25<0.7,$E25*$F25," ")," ")," ") | Z25: =IF(ISNUMBER(SEARCH("deadlift",$C25)),IF($D25>=0.7,IF($D25<0.8,$E25*$F25," ")," ")," ") | AA25: =IF(ISNUMBER(SEARCH("deadlift",$C25)),IF($D25>=0.8,IF($D25<0.9,$E25*$F25," ")," ")," ") | AB25: =IF(ISNUMBER(SEARCH("deadlift",$C25)),IF($D25>=0.9,$E25*$F25," ")," ")
C26: Bench press | D26: 0.7 | E26: 3 | F26: 1 | G26: ='Start Here'!$F$22*D26 -> 70 | J26: =E26*F26 -> 3 | K26: =G26*J26 -> 210 | S26: =IF(ISNUMBER(SEARCH("bench",$C26)),IF($D26>=0.5,IF($D26<0.6,$E26*$F26," ")," ")," ") | T26: =IF(ISNUMBER(SEARCH("bench",$C26)),IF($D26>=0.6,IF($D26<0.7,$E26*$F26," ")," ")," ") | U26: =IF(ISNUMBER(SEARCH("bench",$C26)),IF($D26>=0.7,IF($D26<0.8,$E26*$F26," ")," ")," ") -> 3 | V26: =IF(ISNUMBER(SEARCH("bench",$C26)),IF($D26>=0.8,IF($D26<0.9,$E26*$F26," ")," ")," ") | W26: =IF(ISNUMBER(SEARCH("bench",$C26)),IF($D26>=0.9,$E26*$F26," ")," ") | X26: =IF(ISNUMBER(SEARCH("deadlift",$C26)),IF($D26>=0.5,IF($D26<0.6,$E26*$F26," ")," ")," ") | Y26: =IF(ISNUMBER(SEARCH("deadlift",$C26)),IF($D26>=0.6,IF($D26<0.7,$E26*$F26," ")," ")," ") | Z26: =IF(ISNUMBER(SEARCH("deadlift",$C26)),IF($D26>=0.7,IF($D26<0.8,$E26*$F26," ")," ")," ") | AA26: =IF(ISNUMBER(SEARCH("deadlift",$C26)),IF($D26>=0.8,IF($D26<0.9,$E26*$F26," ")," ")," ") | AB26: =IF(ISNUMBER(SEARCH("deadlift",$C26)),IF($D26>=0.9,$E26*$F26," ")," ")
C27: Bench press | D27: 0.7 | E27: 5 | F27: 1 | G27: ='Start Here'!$F$22*D27 -> 70 | J27: =E27*F27 -> 5 | K27: =G27*J27 -> 350 | S27: =IF(ISNUMBER(SEARCH("bench",$C27)),IF($D27>=0.5,IF($D27<0.6,$E27*$F27," ")," ")," ") | T27: =IF(ISNUMBER(SEARCH("bench",$C27)),IF($D27>=0.6,IF($D27<0.7,$E27*$F27," ")," ")," ") | U27: =IF(ISNUMBER(SEARCH("bench",$C27)),IF($D27>=0.7,IF($D27<0.8,$E27*$F27," ")," ")," ") -> 5 | V27: =IF(ISNUMBER(SEARCH("bench",$C27)),IF($D27>=0.8,IF($D27<0.9,$E27*$F27," ")," ")," ") | W27: =IF(ISNUMBER(SEARCH("bench",$C27)),IF($D27>=0.9,$E27*$F27," ")," ") | X27: =IF(ISNUMBER(SEARCH("deadlift",$C27)),IF($D27>=0.5,IF($D27<0.6,$E27*$F27," ")," ")," ") | Y27: =IF(ISNUMBER(SEARCH("deadlift",$C27)),IF($D27>=0.6,IF($D27<0.7,$E27*$F27," ")," ")," ") | Z27: =IF(ISNUMBER(SEARCH("deadlift",$C27)),IF($D27>=0.7,IF($D27<0.8,$E27*$F27," ")," ")," ") | AA27: =IF(ISNUMBER(SEARCH("deadlift",$C27)),IF($D27>=0.8,IF($D27<0.9,$E27*$F27," ")," ")," ") | AB27: =IF(ISNUMBER(SEARCH("deadlift",$C27)),IF($D27>=0.9,$E27*$F27," ")," ")
C28: Bench press | D28: 0.7 | E28: 7 | F28: 1 | G28: ='Start Here'!$F$22*D28 -> 70 | J28: =E28*F28 -> 7 | K28: =G28*J28 -> 490 | S28: =IF(ISNUMBER(SEARCH("bench",$C28)),IF($D28>=0.5,IF($D28<0.6,$E28*$F28," ")," ")," ") | T28: =IF(ISNUMBER(SEARCH("bench",$C28)),IF($D28>=0.6,IF($D28<0.7,$E28*$F28," ")," ")," ") | U28: =IF(ISNUMBER(SEARCH("bench",$C28)),IF($D28>=0.7,IF($D28<0.8,$E28*$F28," ")," ")," ") -> 7 | V28: =IF(ISNUMBER(SEARCH("bench",$C28)),IF($D28>=0.8,IF($D28<0.9,$E28*$F28," ")," ")," ") | W28: =IF(ISNUMBER(SEARCH("bench",$C28)),IF($D28>=0.9,$E28*$F28," ")," ") | X28: =IF(ISNUMBER(SEARCH("deadlift",$C28)),IF($D28>=0.5,IF($D28<0.6,$E28*$F28," ")," ")," ") | Y28: =IF(ISNUMBER(SEARCH("deadlift",$C28)),IF($D28>=0.6,IF($D28<0.7,$E28*$F28," ")," ")," ") | Z28: =IF(ISNUMBER(SEARCH("deadlift",$C28)),IF($D28>=0.7,IF($D28<0.8,$E28*$F28," ")," ")," ") | AA28: =IF(ISNUMBER(SEARCH("deadlift",$C28)),IF($D28>=0.8,IF($D28<0.9,$E28*$F28," ")," ")," ") | AB28: =IF(ISNUMBER(SEARCH("deadlift",$C28)),IF($D28>=0.9,$E28*$F28," ")," ")
C29: Bench press | D29: 0.7 | E29: 4 | F29: 1 | G29: ='Start Here'!$F$22*D29 -> 70 | J29: =E29*F29 -> 4 | K29: =G29*J29 -> 280 | S29: =IF(ISNUMBER(SEARCH("bench",$C29)),IF($D29>=0.5,IF($D29<0.6,$E29*$F29," ")," ")," ") | T29: =IF(ISNUMBER(SEARCH("bench",$C29)),IF($D29>=0.6,IF($D29<0.7,$E29*$F29," ")," ")," ") | U29: =IF(ISNUMBER(SEARCH("bench",$C29)),IF($D29>=0.7,IF($D29<0.8,$E29*$F29," ")," ")," ") -> 4 | V29: =IF(ISNUMBER(SEARCH("bench",$C29)),IF($D29>=0.8,IF($D29<0.9,$E29*$F29," ")," ")," ") | W29: =IF(ISNUMBER(SEARCH("bench",$C29)),IF($D29>=0.9,$E29*$F29," ")," ") | X29: =IF(ISNUMBER(SEARCH("deadlift",$C29)),IF($D29>=0.5,IF($D29<0.6,$E29*$F29," ")," ")," ") | Y29: =IF(ISNUMBER(SEARCH("deadlift",$C29)),IF($D29>=0.6,IF($D29<0.7,$E29*$F29," ")," ")," ") | Z29: =IF(ISNUMBER(SEARCH("deadlift",$C29)),IF($D29>=0.7,IF($D29<0.8,$E29*$F29," ")," ")," ") | AA29: =IF(ISNUMBER(SEARCH("deadlift",$C29)),IF($D29>=0.8,IF($D29<0.9,$E29*$F29," ")," ")," ") | AB29: =IF(ISNUMBER(SEARCH("deadlift",$C29)),IF($D29>=0.9,$E29*$F29," ")," ")
C30: Bench press | D30: 0.7 | E30: 6 | F30: 1 | G30: ='Start Here'!$F$22*D30 -> 70 | J30: =E30*F30 -> 6 | K30: =G30*J30 -> 420 | S30: =IF(ISNUMBER(SEARCH("bench",$C30)),IF($D30>=0.5,IF($D30<0.6,$E30*$F30," ")," ")," ") | T30: =IF(ISNUMBER(SEARCH("bench",$C30)),IF($D30>=0.6,IF($D30<0.7,$E30*$F30," ")," ")," ") | U30: =IF(ISNUMBER(SEARCH("bench",$C30)),IF($D30>=0.7,IF($D30<0.8,$E30*$F30," ")," ")," ") -> 6 | V30: =IF(ISNUMBER(SEARCH("bench",$C30)),IF($D30>=0.8,IF($D30<0.9,$E30*$F30," ")," ")," ") | W30: =IF(ISNUMBER(SEARCH("bench",$C30)),IF($D30>=0.9,$E30*$F30," ")," ") | X30: =IF(ISNUMBER(SEARCH("deadlift",$C30)),IF($D30>=0.5,IF($D30<0.6,$E30*$F30," ")," ")," ") | Y30: =IF(ISNUMBER(SEARCH("deadlift",$C30)),IF($D30>=0.6,IF($D30<0.7,$E30*$F30," ")," ")," ") | Z30: =IF(ISNUMBER(SEARCH("deadlift",$C30)),IF($D30>=0.7,IF($D30<0.8,$E30*$F30," ")," ")," ") | AA30: =IF(ISNUMBER(SEARCH("deadlift",$C30)),IF($D30>=0.8,IF($D30<0.9,$E30*$F30," ")," ")," ") | AB30: =IF(ISNUMBER(SEARCH("deadlift",$C30)),IF($D30>=0.9,$E30*$F30," ")," ")
C31: Bench press | D31: 0.7 | E31: 8 | F31: 1 | G31: ='Start Here'!$F$22*D31 -> 70 | J31: =E31*F31 -> 8 | K31: =G31*J31 -> 560 | S31: =IF(ISNUMBER(SEARCH("bench",$C31)),IF($D31>=0.5,IF($D31<0.6,$E31*$F31," ")," ")," ") | T31: =IF(ISNUMBER(SEARCH("bench",$C31)),IF($D31>=0.6,IF($D31<0.7,$E31*$F31," ")," ")," ") | U31: =IF(ISNUMBER(SEARCH("bench",$C31)),IF($D31>=0.7,IF($D31<0.8,$E31*$F31," ")," ")," ") -> 8 | V31: =IF(ISNUMBER(SEARCH("bench",$C31)),IF($D31>=0.8,IF($D31<0.9,$E31*$F31," ")," ")," ") | W31: =IF(ISNUMBER(SEARCH("bench",$C31)),IF($D31>=0.9,$E31*$F31," ")," ") | X31: =IF(ISNUMBER(SEARCH("deadlift",$C31)),IF($D31>=0.5,IF($D31<0.6,$E31*$F31," ")," ")," ") | Y31: =IF(ISNUMBER(SEARCH("deadlift",$C31)),IF($D31>=0.6,IF($D31<0.7,$E31*$F31," ")," ")," ") | Z31: =IF(ISNUMBER(SEARCH("deadlift",$C31)),IF($D31>=0.7,IF($D31<0.8,$E31*$F31," ")," ")," ") | AA31: =IF(ISNUMBER(SEARCH("deadlift",$C31)),IF($D31>=0.8,IF($D31<0.9,$E31*$F31," ")," ")," ") | AB31: =IF(ISNUMBER(SEARCH("deadlift",$C31)),IF($D31>=0.9,$E31*$F31," ")," ")
B32: 3 | C32: Deadlift w/pause 5-7cm above knees | D32: 0.55 | E32: 3 | F32: 1 | G32: ='Start Here'!$F$23*D32 -> 55 | L32: =E32*F32 -> 3 | M32: =G32*L32 -> 165 | S32: =IF(ISNUMBER(SEARCH("bench",$C32)),IF($D32>=0.5,IF($D32<0.6,$E32*$F32," ")," ")," ") | T32: =IF(ISNUMBER(SEARCH("bench",$C32)),IF($D32>=0.6,IF($D32<0.7,$E32*$F32," ")," ")," ") | U32: =IF(ISNUMBER(SEARCH("bench",$C32)),IF($D32>=0.7,IF($D32<0.8,$E32*$F32," ")," ")," ") | V32: =IF(ISNUMBER(SEARCH("bench",$C32)),IF($D32>=0.8,IF($D32<0.9,$E32*$F32," ")," ")," ") | W32: =IF(ISNUMBER(SEARCH("bench",$C32)),IF($D32>=0.9,$E32*$F32," ")," ") | X32: =IF(ISNUMBER(SEARCH("deadlift",$C32)),IF($D32>=0.5,IF($D32<0.6,$E32*$F32," ")," ")," ") -> 3 | Y32: =IF(ISNUMBER(SEARCH("deadlift",$C32)),IF($D32>=0.6,IF($D32<0.7,$E32*$F32," ")," ")," ") | Z32: =IF(ISNUMBER(SEARCH("deadlift",$C32)),IF($D32>=0.7,IF($D32<0.8,$E32*$F32," ")," ")," ") | AA32: =IF(ISNUMBER(SEARCH("deadlift",$C32)),IF($D32>=0.8,IF($D32<0.9,$E32*$F32," ")," ")," ") | AB32: =IF(ISNUMBER(SEARCH("deadlift",$C32)),IF($D32>=0.9,$E32*$F32," ")," ")
C33: Deadlift w/pause 5-7cm above knees | D33: 0.65 | E33: 3 | F33: 1 | G33: ='Start Here'!$F$23*D33 -> 65 | L33: =E33*F33 -> 3 | M33: =G33*L33 -> 195 | S33: =IF(ISNUMBER(SEARCH("bench",$C33)),IF($D33>=0.5,IF($D33<0.6,$E33*$F33," ")," ")," ") | T33: =IF(ISNUMBER(SEARCH("bench",$C33)),IF($D33>=0.6,IF($D33<0.7,$E33*$F33," ")," ")," ") | U33: =IF(ISNUMBER(SEARCH("bench",$C33)),IF($D33>=0.7,IF($D33<0.8,$E33*$F33," ")," ")," ") | V33: =IF(ISNUMBER(SEARCH("bench",$C33)),IF($D33>=0.8,IF($D33<0.9,$E33*$F33," ")," ")," ") | W33: =IF(ISNUMBER(SEARCH("bench",$C33)),IF($D33>=0.9,$E33*$F33," ")," ") | X33: =IF(ISNUMBER(SEARCH("deadlift",$C33)),IF($D33>=0.5,IF($D33<0.6,$E33*$F33," ")," ")," ") | Y33: =IF(ISNUMBER(SEARCH("deadlift",$C33)),IF($D33>=0.6,IF($D33<0.7,$E33*$F33," ")," ")," ") -> 3 | Z33: =IF(ISNUMBER(SEARCH("deadlift",$C33)),IF($D33>=0.7,IF($D33<0.8,$E33*$F33," ")," ")," ") | AA33: =IF(ISNUMBER(SEARCH("deadlift",$C33)),IF($D33>=0.8,IF($D33<0.9,$E33*$F33," ")," ")," ") | AB33: =IF(ISNUMBER(SEARCH("deadlift",$C33)),IF($D33>=0.9,$E33*$F33," ")," ")
C34: Deadlift w/pause 5-7cm above knees | D34: 0.75 | E34: 2 | F34: 4 | G34: ='Start Here'!$F$23*D34 -> 75 | L34: =E34*F34 -> 8 | M34: =G34*L34 -> 600 | S34: =IF(ISNUMBER(SEARCH("bench",$C34)),IF($D34>=0.5,IF($D34<0.6,$E34*$F34," ")," ")," ") | T34: =IF(ISNUMBER(SEARCH("bench",$C34)),IF($D34>=0.6,IF($D34<0.7,$E34*$F34," ")," ")," ") | U34: =IF(ISNUMBER(SEARCH("bench",$C34)),IF($D34>=0.7,IF($D34<0.8,$E34*$F34," ")," ")," ") | V34: =IF(ISNUMBER(SEARCH("bench",$C34)),IF($D34>=0.8,IF($D34<0.9,$E34*$F34," ")," ")," ") | W34: =IF(ISNUMBER(SEARCH("bench",$C34)),IF($D34>=0.9,$E34*$F34," ")," ") | X34: =IF(ISNUMBER(SEARCH("deadlift",$C34)),IF($D34>=0.5,IF($D34<0.6,$E34*$F34," ")," ")," ") | Y34: =IF(ISNUMBER(SEARCH("deadlift",$C34)),IF($D34>=0.6,IF($D34<0.7,$E34*$F34," ")," ")," ") | Z34: =IF(ISNUMBER(SEARCH("deadlift",$C34)),IF($D34>=0.7,IF($D34<0.8,$E34*$F34," ")," ")," ") -> 8 | AA34: =IF(ISNUMBER(SEARCH("deadlift",$C34)),IF($D34>=0.8,IF($D34<0.9,$E34*$F34," ")," ")," ") | AB34: =IF(ISNUMBER(SEARCH("deadlift",$C34)),IF($D34>=0.9,$E34*$F34," ")," ")
B35: 4 | C35: Lat muscles | E35: 6 | F35: 4
B36: 5 | C36: Good morning | E36: 5 | F36: 5
B38: Friday | D38: % | E38: Reps | F38: Sets | G38: Weight | AC38: Notes:
B39: 1 | C39: Bench press | D39: 0.5 | E39: 5 | F39: 1 | G39: ='Start Here'!$F$22*D39 -> 50 | J39: =E39*F39 -> 5 | K39: =G39*J39 -> 250 | N39: =IF(ISNUMBER(SEARCH("squat",$C39)),IF($D39>=0.5,IF($D39<0.6,$E39*$F39," ")," ")," ") | O39: =IF(ISNUMBER(SEARCH("squat",$C39)),IF($D39>=0.6,IF($D39<0.7,$E39*$F39," ")," ")," ") | P39: =IF(ISNUMBER(SEARCH("squat",$C39)),IF($D39>=0.7,IF($D39<0.8,$E39*$F39," ")," ")," ") | Q39: =IF(ISNUMBER(SEARCH("squat",$C39)),IF($D39>=0.8,IF($D39<0.9,$E39*$F39," ")," ")," ") | R39: =IF(ISNUMBER(SEARCH("squat",$C39)),IF($D39>=0.9,$E39*$F39," ")," ") | S39: =IF(ISNUMBER(SEARCH("bench",$C39)),IF($D39>=0.5,IF($D39<0.6,$E39*$F39," ")," ")," ") -> 5 | T39: =IF(ISNUMBER(SEARCH("bench",$C39)),IF($D39>=0.6,IF($D39<0.7,$E39*$F39," ")," ")," ") | U39: =IF(ISNUMBER(SEARCH("bench",$C39)),IF($D39>=0.7,IF($D39<0.8,$E39*$F39," ")," ")," ") | V39: =IF(ISNUMBER(SEARCH("bench",$C39)),IF($D39>=0.8,IF($D39<0.9,$E39*$F39," ")," ")," ") | W39: =IF(ISNUMBER(SEARCH("bench",$C39)),IF($D39>=0.9,$E39*$F39," ")," ")
C40: Bench press | D40: 0.6 | E40: 4 | F40: 1 | G40: ='Start Here'!$F$22*D40 -> 60 | J40: =E40*F40 -> 4 | K40: =G40*J40 -> 240 | N40: =IF(ISNUMBER(SEARCH("squat",$C40)),IF($D40>=0.5,IF($D40<0.6,$E40*$F40," ")," ")," ") | O40: =IF(ISNUMBER(SEARCH("squat",$C40)),IF($D40>=0.6,IF($D40<0.7,$E40*$F40," ")," ")," ") | P40: =IF(ISNUMBER(SEARCH("squat",$C40)),IF($D40>=0.7,IF($D40<0.8,$E40*$F40," ")," ")," ") | Q40: =IF(ISNUMBER(SEARCH("squat",$C40)),IF($D40>=0.8,IF($D40<0.9,$E40*$F40," ")," ")," ") | R40: =IF(ISNUMBER(SEARCH("squat",$C40)),IF($D40>=0.9,$E40*$F40," ")," ") | S40: =IF(ISNUMBER(SEARCH("bench",$C40)),IF($D40>=0.5,IF($D40<0.6,$E40*$F40," ")," ")," ") | T40: =IF(ISNUMBER(SEARCH("bench",$C40)),IF($D40>=0.6,IF($D40<0.7,$E40*$F40," ")," ")," ") -> 4 | U40: =IF(ISNUMBER(SEARCH("bench",$C40)),IF($D40>=0.7,IF($D40<0.8,$E40*$F40," ")," ")," ") | V40: =IF(ISNUMBER(SEARCH("bench",$C40)),IF($D40>=0.8,IF($D40<0.9,$E40*$F40," ")," ")," ") | W40: =IF(ISNUMBER(SEARCH("bench",$C40)),IF($D40>=0.9,$E40*$F40," ")," ")
C41: Bench press | D41: 0.7 | E41: 3 | F41: 1 | G41: ='Start Here'!$F$22*D41 -> 70 | J41: =E41*F41 -> 3 | K41: =G41*J41 -> 210 | N41: =IF(ISNUMBER(SEARCH("squat",$C41)),IF($D41>=0.5,IF($D41<0.6,$E41*$F41," ")," ")," ") | O41: =IF(ISNUMBER(SEARCH("squat",$C41)),IF($D41>=0.6,IF($D41<0.7,$E41*$F41," ")," ")," ") | P41: =IF(ISNUMBER(SEARCH("squat",$C41)),IF($D41>=0.7,IF($D41<0.8,$E41*$F41," ")," ")," ") | Q41: =IF(ISNUMBER(SEARCH("squat",$C41)),IF($D41>=0.8,IF($D41<0.9,$E41*$F41," ")," ")," ") | R41: =IF(ISNUMBER(SEARCH("squat",$C41)),IF($D41>=0.9,$E41*$F41," ")," ") | S41: =IF(ISNUMBER(SEARCH("bench",$C41)),IF($D41>=0.5,IF($D41<0.6,$E41*$F41," ")," ")," ") | T41: =IF(ISNUMBER(SEARCH("bench",$C41)),IF($D41>=0.6,IF($D41<0.7,$E41*$F41," ")," ")," ") | U41: =IF(ISNUMBER(SEARCH("bench",$C41)),IF($D41>=0.7,IF($D41<0.8,$E41*$F41," ")," ")," ") -> 3 | V41: =IF(ISNUMBER(SEARCH("bench",$C41)),IF($D41>=0.8,IF($D41<0.9,$E41*$F41," ")," ")," ") | W41: =IF(ISNUMBER(SEARCH("bench",$C41)),IF($D41>=0.9,$E41*$F41," ")," ")
C42: Bench press | D42: 0.75 | E42: 3 | F42: 4 | G42: ='Start Here'!$F$22*D42 -> 75 | J42: =E42*F42 -> 12 | K42: =G42*J42 -> 900 | N42: =IF(ISNUMBER(SEARCH("squat",$C42)),IF($D42>=0.5,IF($D42<0.6,$E42*$F42," ")," ")," ") | O42: =IF(ISNUMBER(SEARCH("squat",$C42)),IF($D42>=0.6,IF($D42<0.7,$E42*$F42," ")," ")," ") | P42: =IF(ISNUMBER(SEARCH("squat",$C42)),IF($D42>=0.7,IF($D42<0.8,$E42*$F42," ")," ")," ") | Q42: =IF(ISNUMBER(SEARCH("squat",$C42)),IF($D42>=0.8,IF($D42<0.9,$E42*$F42," ")," ")," ") | R42: =IF(ISNUMBER(SEARCH("squat",$C42)),IF($D42>=0.9,$E42*$F42," ")," ") | S42: =IF(ISNUMBER(SEARCH("bench",$C42)),IF($D42>=0.5,IF($D42<0.6,$E42*$F42," ")," ")," ") | T42: =IF(ISNUMBER(SEARCH("bench",$C42)),IF($D42>=0.6,IF($D42<0.7,$E42*$F42," ")," ")," ") | U42: =IF(ISNUMBER(SEARCH("bench",$C42)),IF($D42>=0.7,IF($D42<0.8,$E42*$F42," ")," ")," ") -> 12 | V42: =IF(ISNUMBER(SEARCH("bench",$C42)),IF($D42>=0.8,IF($D42<0.9,$E42*$F42," ")," ")," ") | W42: =IF(ISNUMBER(SEARCH("bench",$C42)),IF($D42>=0.9,$E42*$F42," ")," ")
B43: 2 | C43: Squat w/pause at half squat position on the way down | D43: 0.5 | E43: 3 | F43: 1 | G43: ='Start Here'!$F$21*D43 -> 50 | H43: =E43*F43 -> 3 | I43: =G43*H43 -> 150 | N43: =IF(ISNUMBER(SEARCH("squat",$C43)),IF($D43>=0.5,IF($D43<0.6,$E43*$F43," ")," ")," ") -> 3 | O43: =IF(ISNUMBER(SEARCH("squat",$C43)),IF($D43>=0.6,IF($D43<0.7,$E43*$F43," ")," ")," ") | P43: =IF(ISNUMBER(SEARCH("squat",$C43)),IF($D43>=0.7,IF($D43<0.8,$E43*$F43," ")," ")," ") | Q43: =IF(ISNUMBER(SEARCH("squat",$C43)),IF($D43>=0.8,IF($D43<0.9,$E43*$F43," ")," ")," ") | R43: =IF(ISNUMBER(SEARCH("squat",$C43)),IF($D43>=0.9,$E43*$F43," ")," ") | S43: =IF(ISNUMBER(SEARCH("bench",$C43)),IF($D43>=0.5,IF($D43<0.6,$E43*$F43," ")," ")," ") | T43: =IF(ISNUMBER(SEARCH("bench",$C43)),IF($D43>=0.6,IF($D43<0.7,$E43*$F43," ")," ")," ") | U43: =IF(ISNUMBER(SEARCH("bench",$C43)),IF($D43>=0.7,IF($D43<0.8,$E43*$F43," ")," ")," ") | V43: =IF(ISNUMBER(SEARCH("bench",$C43)),IF($D43>=0.8,IF($D43<0.9,$E43*$F43," ")," ")," ") | W43: =IF(ISNUMBER(SEARCH("bench",$C43)),IF($D43>=0.9,$E43*$F43," ")," ")
C44: Squat w/pause at half squat position on the way down | D44: 0.6 | E44: 3 | F44: 1 | G44: ='Start Here'!$F$21*D44 -> 60 | H44: =E44*F44 -> 3 | I44: =G44*H44 -> 180 | N44: =IF(ISNUMBER(SEARCH("squat",$C44)),IF($D44>=0.5,IF($D44<0.6,$E44*$F44," ")," ")," ") | O44: =IF(ISNUMBER(SEARCH("squat",$C44)),IF($D44>=0.6,IF($D44<0.7,$E44*$F44," ")," ")," ") -> 3 | P44: =IF(ISNUMBER(SEARCH("squat",$C44)),IF($D44>=0.7,IF($D44<0.8,$E44*$F44," ")," ")," ") | Q44: =IF(ISNUMBER(SEARCH("squat",$C44)),IF($D44>=0.8,IF($D44<0.9,$E44*$F44," ")," ")," ") | R44: =IF(ISNUMBER(SEARCH("squat",$C44)),IF($D44>=0.9,$E44*$F44," ")," ") | S44: =IF(ISNUMBER(SEARCH("bench",$C44)),IF($D44>=0.5,IF($D44<0.6,$E44*$F44," ")," ")," ") | T44: =IF(ISNUMBER(SEARCH("bench",$C44)),IF($D44>=0.6,IF($D44<0.7,$E44*$F44," ")," ")," ") | U44: =IF(ISNUMBER(SEARCH("bench",$C44)),IF($D44>=0.7,IF($D44<0.8,$E44*$F44," ")," ")," ") | V44: =IF(ISNUMBER(SEARCH("bench",$C44)),IF($D44>=0.8,IF($D44<0.9,$E44*$F44," ")," ")," ") | W44: =IF(ISNUMBER(SEARCH("bench",$C44)),IF($D44>=0.9,$E44*$F44," ")," ")
C45: Squat w/pause at half squat position on the way down | D45: 0.7 | E45: 3 | F45: 4 | G45: ='Start Here'!$F$21*D45 -> 70 | H45: =E45*F45 -> 12 | I45: =G45*H45 -> 840 | N45: =IF(ISNUMBER(SEARCH("squat",$C45)),IF($D45>=0.5,IF($D45<0.6,$E45*$F45," ")," ")," ") | O45: =IF(ISNUMBER(SEARCH("squat",$C45)),IF($D45>=0.6,IF($D45<0.7,$E45*$F45," ")," ")," ") | P45: =IF(ISNUMBER(SEARCH("squat",$C45)),IF($D45>=0.7,IF($D45<0.8,$E45*$F45," ")," ")," ") -> 12 | Q45: =IF(ISNUMBER(SEARCH("squat",$C45)),IF($D45>=0.8,IF($D45<0.9,$E45*$F45," ")," ")," ") | R45: =IF(ISNUMBER(SEARCH("squat",$C45)),IF($D45>=0.9,$E45*$F45," ")," ") | S45: =IF(ISNUMBER(SEARCH("bench",$C45)),IF($D45>=0.5,IF($D45<0.6,$E45*$F45," ")," ")," ") | T45: =IF(ISNUMBER(SEARCH("bench",$C45)),IF($D45>=0.6,IF($D45<0.7,$E45*$F45," ")," ")," ") | U45: =IF(ISNUMBER(SEARCH("bench",$C45)),IF($D45>=0.7,IF($D45<0.8,$E45*$F45," ")," ")," ") | V45: =IF(ISNUMBER(SEARCH("bench",$C45)),IF($D45>=0.8,IF($D45<0.9,$E45*$F45," ")," ")," ") | W45: =IF(ISNUMBER(SEARCH("bench",$C45)),IF($D45>=0.9,$E45*$F45," ")," ")
...

Sheet Prep Cycle II
B2: Preparatory Period II for Class 1 and Above Athletes
B5: WEEK 1 | N5: squat | S5: bench | X5: deadlift
B6: Monday | D6: % | E6: Reps | F6: Sets | G6: Weight | N6: 50-59 | O6: 60-69 | P6: 70-79 | Q6: 80-89 | R6: 90+ | S6: 50-59 | T6: 60-69 | U6: 70-79 | V6: 80-89 | W6: 90+ | X6: 50-59 | Y6: 60-69 | Z6: 70-79 | AA6: 80-89 | AB6: 90+ | AC6: Notes:
B7: 1 | C7: Bench press | D7: 0.5 | E7: 5 | F7: 1 | G7: ='Start Here'!$F$22*D7 -> 50 | J7: =E7*F7 -> 5 | K7: =G7*J7 -> 250 | S7: =IF(ISNUMBER(SEARCH("bench",$C7)),IF($D7>=0.5,IF($D7<0.6,$E7*$F7," ")," ")," ") -> 5 | T7: =IF(ISNUMBER(SEARCH("bench",$C7)),IF($D7>=0.6,IF($D7<0.7,$E7*$F7," ")," ")," ") | U7: =IF(ISNUMBER(SEARCH("bench",$C7)),IF($D7>=0.7,IF($D7<0.8,$E7*$F7," ")," ")," ") | V7: =IF(ISNUMBER(SEARCH("bench",$C7)),IF($D7>=0.8,IF($D7<0.9,$E7*$F7," ")," ")," ") | W7: =IF(ISNUMBER(SEARCH("bench",$C7)),IF($D7>=0.9,$E7*$F7," ")," ")
C8: Bench press | D8: 0.6 | E8: 4 | F8: 1 | G8: ='Start Here'!$F$22*D8 -> 60 | J8: =E8*F8 -> 4 | K8: =G8*J8 -> 240 | S8: =IF(ISNUMBER(SEARCH("bench",$C8)),IF($D8>=0.5,IF($D8<0.6,$E8*$F8," ")," ")," ") | T8: =IF(ISNUMBER(SEARCH("bench",$C8)),IF($D8>=0.6,IF($D8<0.7,$E8*$F8," ")," ")," ") -> 4 | U8: =IF(ISNUMBER(SEARCH("bench",$C8)),IF($D8>=0.7,IF($D8<0.8,$E8*$F8," ")," ")," ") | V8: =IF(ISNUMBER(SEARCH("bench",$C8)),IF($D8>=0.8,IF($D8<0.9,$E8*$F8," ")," ")," ") | W8: =IF(ISNUMBER(SEARCH("bench",$C8)),IF($D8>=0.9,$E8*$F8," ")," ")
C9: Bench press | D9: 0.7 | E9: 3 | F9: 1 | G9: ='Start Here'!$F$22*D9 -> 70 | J9: =E9*F9 -> 3 | K9: =G9*J9 -> 210 | S9: =IF(ISNUMBER(SEARCH("bench",$C9)),IF($D9>=0.5,IF($D9<0.6,$E9*$F9," ")," ")," ") | T9: =IF(ISNUMBER(SEARCH("bench",$C9)),IF($D9>=0.6,IF($D9<0.7,$E9*$F9," ")," ")," ") | U9: =IF(ISNUMBER(SEARCH("bench",$C9)),IF($D9>=0.7,IF($D9<0.8,$E9*$F9," ")," ")," ") -> 3 | V9: =IF(ISNUMBER(SEARCH("bench",$C9)),IF($D9>=0.8,IF($D9<0.9,$E9*$F9," ")," ")," ") | W9: =IF(ISNUMBER(SEARCH("bench",$C9)),IF($D9>=0.9,$E9*$F9," ")," ")
C10: Bench press | D10: 0.8 | E10: 3 | F10: 4 | G10: ='Start Here'!$F$22*D10 -> 80 | J10: =E10*F10 -> 12 | K10: =G10*J10 -> 960 | S10: =IF(ISNUMBER(SEARCH("bench",$C10)),IF($D10>=0.5,IF($D10<0.6,$E10*$F10," ")," ")," ") | T10: =IF(ISNUMBER(SEARCH("bench",$C10)),IF($D10>=0.6,IF($D10<0.7,$E10*$F10," ")," ")," ") | U10: =IF(ISNUMBER(SEARCH("bench",$C10)),IF($D10>=0.7,IF($D10<0.8,$E10*$F10," ")," ")," ") | V10: =IF(ISNUMBER(SEARCH("bench",$C10)),IF($D10>=0.8,IF($D10<0.9,$E10*$F10," ")," ")," ") -> 12 | W10: =IF(ISNUMBER(SEARCH("bench",$C10)),IF($D10>=0.9,$E10*$F10," ")," ")
B11: 2 | C11: Squat | D11: 0.5 | E11: 5 | F11: 1 | G11: ='Start Here'!$F$21*D11 -> 50 | H11: =E11*F11 -> 5 | I11: =G11*H11 -> 250 | N11: =IF(ISNUMBER(SEARCH("squat",$C11)),IF($D11>=0.5,IF($D11<0.6,$E11*$F11," ")," ")," ") -> 5 | O11: =IF(ISNUMBER(SEARCH("squat",$C11)),IF($D11>=0.6,IF($D11<0.7,$E11*$F11," ")," ")," ") | P11: =IF(ISNUMBER(SEARCH("squat",$C11)),IF($D11>=0.7,IF($D11<0.8,$E11*$F11," ")," ")," ") | Q11: =IF(ISNUMBER(SEARCH("squat",$C11)),IF($D11>=0.8,IF($D11<0.9,$E11*$F11," ")," ")," ") | R11: =IF(ISNUMBER(SEARCH("squat",$C11)),IF($D11>=0.9,$E11*$F11," ")," ")
C12: Squat | D12: 0.6 | E12: 5 | F12: 1 | G12: ='Start Here'!$F$21*D12 -> 60 | H12: =E12*F12 -> 5 | I12: =G12*H12 -> 300 | N12: =IF(ISNUMBER(SEARCH("squat",$C12)),IF($D12>=0.5,IF($D12<0.6,$E12*$F12," ")," ")," ") | O12: =IF(ISNUMBER(SEARCH("squat",$C12)),IF($D12>=0.6,IF($D12<0.7,$E12*$F12," ")," ")," ") -> 5 | P12: =IF(ISNUMBER(SEARCH("squat",$C12)),IF($D12>=0.7,IF($D12<0.8,$E12*$F12," ")," ")," ") | Q12: =IF(ISNUMBER(SEARCH("squat",$C12)),IF($D12>=0.8,IF($D12<0.9,$E12*$F12," ")," ")," ") | R12: =IF(ISNUMBER(SEARCH("squat",$C12)),IF($D12>=0.9,$E12*$F12," ")," ")
C13: Squat | D13: 0.7 | E13: 3 | F13: 1 | G13: ='Start Here'!$F$21*D13 -> 70 | H13: =E13*F13 -> 3 | I13: =G13*H13 -> 210 | N13: =IF(ISNUMBER(SEARCH("squat",$C13)),IF($D13>=0.5,IF($D13<0.6,$E13*$F13," ")," ")," ") | O13: =IF(ISNUMBER(SEARCH("squat",$C13)),IF($D13>=0.6,IF($D13<0.7,$E13*$F13," ")," ")," ") | P13: =IF(ISNUMBER(SEARCH("squat",$C13)),IF($D13>=0.7,IF($D13<0.8,$E13*$F13," ")," ")," ") -> 3 | Q13: =IF(ISNUMBER(SEARCH("squat",$C13)),IF($D13>=0.8,IF($D13<0.9,$E13*$F13," ")," ")," ") | R13: =IF(ISNUMBER(SEARCH("squat",$C13)),IF($D13>=0.9,$E13*$F13," ")," ")
C14: Squat | D14: 0.7 | E14: 7 | F14: 1 | G14: ='Start Here'!$F$21*D14 -> 70 | H14: =E14*F14 -> 7 | I14: =G14*H14 -> 490 | N14: =IF(ISNUMBER(SEARCH("squat",$C14)),IF($D14>=0.5,IF($D14<0.6,$E14*$F14," ")," ")," ") | O14: =IF(ISNUMBER(SEARCH("squat",$C14)),IF($D14>=0.6,IF($D14<0.7,$E14*$F14," ")," ")," ") | P14: =IF(ISNUMBER(SEARCH("squat",$C14)),IF($D14>=0.7,IF($D14<0.8,$E14*$F14," ")," ")," ") -> 7 | Q14: =IF(ISNUMBER(SEARCH("squat",$C14)),IF($D14>=0.8,IF($D14<0.9,$E14*$F14," ")," ")," ") | R14: =IF(ISNUMBER(SEARCH("squat",$C14)),IF($D14>=0.9,$E14*$F14," ")," ")
C15: Squat | D15: 0.7 | E15: 4 | F15: 1 | G15: ='Start Here'!$F$21*D15 -> 70 | H15: =E15*F15 -> 4 | I15: =G15*H15 -> 280 | N15: =IF(ISNUMBER(SEARCH("squat",$C15)),IF($D15>=0.5,IF($D15<0.6,$E15*$F15," ")," ")," ") | O15: =IF(ISNUMBER(SEARCH("squat",$C15)),IF($D15>=0.6,IF($D15<0.7,$E15*$F15," ")," ")," ") | P15: =IF(ISNUMBER(SEARCH("squat",$C15)),IF($D15>=0.7,IF($D15<0.8,$E15*$F15," ")," ")," ") -> 4 | Q15: =IF(ISNUMBER(SEARCH("squat",$C15)),IF($D15>=0.8,IF($D15<0.9,$E15*$F15," ")," ")," ") | R15: =IF(ISNUMBER(SEARCH("squat",$C15)),IF($D15>=0.9,$E15*$F15," ")," ")
C16: Squat | D16: 0.7 | E16: 8 | F16: 1 | G16: ='Start Here'!$F$21*D16 -> 70 | H16: =E16*F16 -> 8 | I16: =G16*H16 -> 560 | N16: =IF(ISNUMBER(SEARCH("squat",$C16)),IF($D16>=0.5,IF($D16<0.6,$E16*$F16," ")," ")," ") | O16: =IF(ISNUMBER(SEARCH("squat",$C16)),IF($D16>=0.6,IF($D16<0.7,$E16*$F16," ")," ")," ") | P16: =IF(ISNUMBER(SEARCH("squat",$C16)),IF($D16>=0.7,IF($D16<0.8,$E16*$F16," ")," ")," ") -> 8 | Q16: =IF(ISNUMBER(SEARCH("squat",$C16)),IF($D16>=0.8,IF($D16<0.9,$E16*$F16," ")," ")," ") | R16: =IF(ISNUMBER(SEARCH("squat",$C16)),IF($D16>=0.9,$E16*$F16," ")," ")
C17: Squat | D17: 0.7 | E17: 2 | F17: 1 | G17: ='Start Here'!$F$21*D17 -> 70 | H17: =E17*F17 -> 2 | I17: =G17*H17 -> 140 | N17: =IF(ISNUMBER(SEARCH("squat",$C17)),IF($D17>=0.5,IF($D17<0.6,$E17*$F17," ")," ")," ") | O17: =IF(ISNUMBER(SEARCH("squat",$C17)),IF($D17>=0.6,IF($D17<0.7,$E17*$F17," ")," ")," ") | P17: =IF(ISNUMBER(SEARCH("squat",$C17)),IF($D17>=0.7,IF($D17<0.8,$E17*$F17," ")," ")," ") -> 2 | Q17: =IF(ISNUMBER(SEARCH("squat",$C17)),IF($D17>=0.8,IF($D17<0.9,$E17*$F17," ")," ")," ") | R17: =IF(ISNUMBER(SEARCH("squat",$C17)),IF($D17>=0.9,$E17*$F17," ")," ")
C18: Squat | D18: 0.7 | E18: 5 | F18: 1 | G18: ='Start Here'!$F$21*D18 -> 70 | H18: =E18*F18 -> 5 | I18: =G18*H18 -> 350 | N18: =IF(ISNUMBER(SEARCH("squat",$C18)),IF($D18>=0.5,IF($D18<0.6,$E18*$F18," ")," ")," ") | O18: =IF(ISNUMBER(SEARCH("squat",$C18)),IF($D18>=0.6,IF($D18<0.7,$E18*$F18," ")," ")," ") | P18: =IF(ISNUMBER(SEARCH("squat",$C18)),IF($D18>=0.7,IF($D18<0.8,$E18*$F18," ")," ")," ") -> 5 | Q18: =IF(ISNUMBER(SEARCH("squat",$C18)),IF($D18>=0.8,IF($D18<0.9,$E18*$F18," ")," ")," ") | R18: =IF(ISNUMBER(SEARCH("squat",$C18)),IF($D18>=0.9,$E18*$F18," ")," ")
B19: 3 | C19: Bench press w/board | D19: 0.6 | E19: 3 | F19: 1 | G19: ='Start Here'!$F$22*D19 -> 60 | J19: =E19*F19 -> 3 | K19: =G19*J19 -> 180 | S19: =IF(ISNUMBER(SEARCH("bench",$C19)),IF($D19>=0.5,IF($D19<0.6,$E19*$F19," ")," ")," ") | T19: =IF(ISNUMBER(SEARCH("bench",$C19)),IF($D19>=0.6,IF($D19<0.7,$E19*$F19," ")," ")," ") -> 3 | U19: =IF(ISNUMBER(SEARCH("bench",$C19)),IF($D19>=0.7,IF($D19<0.8,$E19*$F19," ")," ")," ") | V19: =IF(ISNUMBER(SEARCH("bench",$C19)),IF($D19>=0.8,IF($D19<0.9,$E19*$F19," ")," ")," ") | W19: =IF(ISNUMBER(SEARCH("bench",$C19)),IF($D19>=0.9,$E19*$F19," ")," ")
C20: Bench press w/board | D20: 0.7 | E20: 3 | F20: 1 | G20: ='Start Here'!$F$22*D20 -> 70 | J20: =E20*F20 -> 3 | K20: =G20*J20 -> 210 | S20: =IF(ISNUMBER(SEARCH("bench",$C20)),IF($D20>=0.5,IF($D20<0.6,$E20*$F20," ")," ")," ") | T20: =IF(ISNUMBER(SEARCH("bench",$C20)),IF($D20>=0.6,IF($D20<0.7,$E20*$F20," ")," ")," ") | U20: =IF(ISNUMBER(SEARCH("bench",$C20)),IF($D20>=0.7,IF($D20<0.8,$E20*$F20," ")," ")," ") -> 3 | V20: =IF(ISNUMBER(SEARCH("bench",$C20)),IF($D20>=0.8,IF($D20<0.9,$E20*$F20," ")," ")," ") | W20: =IF(ISNUMBER(SEARCH("bench",$C20)),IF($D20>=0.9,$E20*$F20," ")," ")
C21: Bench press w/board | D21: 0.8 | E21: 3 | F21: 2 | G21: ='Start Here'!$F$22*D21 -> 80 | J21: =E21*F21 -> 6 | K21: =G21*J21 -> 480 | S21: =IF(ISNUMBER(SEARCH("bench",$C21)),IF($D21>=0.5,IF($D21<0.6,$E21*$F21," ")," ")," ") | T21: =IF(ISNUMBER(SEARCH("bench",$C21)),IF($D21>=0.6,IF($D21<0.7,$E21*$F21," ")," ")," ") | U21: =IF(ISNUMBER(SEARCH("bench",$C21)),IF($D21>=0.7,IF($D21<0.8,$E21*$F21," ")," ")," ") | V21: =IF(ISNUMBER(SEARCH("bench",$C21)),IF($D21>=0.8,IF($D21<0.9,$E21*$F21," ")," ")," ") -> 6 | W21: =IF(ISNUMBER(SEARCH("bench",$C21)),IF($D21>=0.9,$E21*$F21," ")," ")
C22: Bench press w/board | D22: 0.85 | E22: 2 | F22: 3 | G22: ='Start Here'!$F$22*D22 -> 85 | J22: =E22*F22 -> 6 | K22: =G22*J22 -> 510 | S22: =IF(ISNUMBER(SEARCH("bench",$C22)),IF($D22>=0.5,IF($D22<0.6,$E22*$F22," ")," ")," ") | T22: =IF(ISNUMBER(SEARCH("bench",$C22)),IF($D22>=0.6,IF($D22<0.7,$E22*$F22," ")," ")," ") | U22: =IF(ISNUMBER(SEARCH("bench",$C22)),IF($D22>=0.7,IF($D22<0.8,$E22*$F22," ")," ")," ") | V22: =IF(ISNUMBER(SEARCH("bench",$C22)),IF($D22>=0.8,IF($D22<0.9,$E22*$F22," ")," ")," ") -> 6 | W22: =IF(ISNUMBER(SEARCH("bench",$C22)),IF($D22>=0.9,$E22*$F22," ")," ")
B23: 4 | C23: Chest Muscles | E23: 8 | F23: 4
B24: 5 | C24: Abs | E24: 8 | F24: 3
B26: Wednesday | D26: % | E26: Reps | F26: Sets | G26: Weight | AC26: Notes:
B27: 1 | C27: Deficit deadlift | D27: 0.5 | E27: 3 | F27: 1 | G27: ='Start Here'!$F$23*D27 -> 50 | L27: =E27*F27 -> 3 | M27: =G27*L27 -> 150 | X27: =IF(ISNUMBER(SEARCH("deadlift",$C27)),IF($D27>=0.5,IF($D27<0.6,$E27*$F27," ")," ")," ") -> 3 | Y27: =IF(ISNUMBER(SEARCH("deadlift",$C27)),IF($D27>=0.6,IF($D27<0.7,$E27*$F27," ")," ")," ") | Z27: =IF(ISNUMBER(SEARCH("deadlift",$C27)),IF($D27>=0.7,IF($D27<0.8,$E27*$F27," ")," ")," ") | AA27: =IF(ISNUMBER(SEARCH("deadlift",$C27)),IF($D27>=0.8,IF($D27<0.9,$E27*$F27," ")," ")," ") | AB27: =IF(ISNUMBER(SEARCH("deadlift",$C27)),IF($D27>=0.9,$E27*$F27," ")," ")
C28: Deficit deadlift | D28: 0.6 | E28: 3 | F28: 1 | G28: ='Start Here'!$F$23*D28 -> 60 | L28: =E28*F28 -> 3 | M28: =G28*L28 -> 180 | X28: =IF(ISNUMBER(SEARCH("deadlift",$C28)),IF($D28>=0.5,IF($D28<0.6,$E28*$F28," ")," ")," ") | Y28: =IF(ISNUMBER(SEARCH("deadlift",$C28)),IF($D28>=0.6,IF($D28<0.7,$E28*$F28," ")," ")," ") -> 3 | Z28: =IF(ISNUMBER(SEARCH("deadlift",$C28)),IF($D28>=0.7,IF($D28<0.8,$E28*$F28," ")," ")," ") | AA28: =IF(ISNUMBER(SEARCH("deadlift",$C28)),IF($D28>=0.8,IF($D28<0.9,$E28*$F28," ")," ")," ") | AB28: =IF(ISNUMBER(SEARCH("deadlift",$C28)),IF($D28>=0.9,$E28*$F28," ")," ")
C29: Deficit deadlift | D29: 0.7 | E29: 2 | F29: 4 | G29: ='Start Here'!$F$23*D29 -> 70 | L29: =E29*F29 -> 8 | M29: =G29*L29 -> 560 | X29: =IF(ISNUMBER(SEARCH("deadlift",$C29)),IF($D29>=0.5,IF($D29<0.6,$E29*$F29," ")," ")," ") | Y29: =IF(ISNUMBER(SEARCH("deadlift",$C29)),IF($D29>=0.6,IF($D29<0.7,$E29*$F29," ")," ")," ") | Z29: =IF(ISNUMBER(SEARCH("deadlift",$C29)),IF($D29>=0.7,IF($D29<0.8,$E29*$F29," ")," ")," ") -> 8 | AA29: =IF(ISNUMBER(SEARCH("deadlift",$C29)),IF($D29>=0.8,IF($D29<0.9,$E29*$F29," ")," ")," ") | AB29: =IF(ISNUMBER(SEARCH("deadlift",$C29)),IF($D29>=0.9,$E29*$F29," ")," ")
B30: 2 | C30: Bench press with chains | D30: 0.5 | E30: 3 | F30: 1 | G30: ='Start Here'!$F$22*D30 -> 50 | J30: =E30*F30 -> 3 | K30: =G30*J30 -> 150 | S30: =IF(ISNUMBER(SEARCH("bench",$C30)),IF($D30>=0.5,IF($D30<0.6,$E30*$F30," ")," ")," ") -> 3 | T30: =IF(ISNUMBER(SEARCH("bench",$C30)),IF($D30>=0.6,IF($D30<0.7,$E30*$F30," ")," ")," ") | U30: =IF(ISNUMBER(SEARCH("bench",$C30)),IF($D30>=0.7,IF($D30<0.8,$E30*$F30," ")," ")," ") | V30: =IF(ISNUMBER(SEARCH("bench",$C30)),IF($D30>=0.8,IF($D30<0.9,$E30*$F30," ")," ")," ") | W30: =IF(ISNUMBER(SEARCH("bench",$C30)),IF($D30>=0.9,$E30*$F30," ")," ")
C31: Bench press with chains | D31: 0.6 | E31: 3 | F31: 1 | G31: ='Start Here'!$F$22*D31 -> 60 | J31: =E31*F31 -> 3 | K31: =G31*J31 -> 180 | S31: =IF(ISNUMBER(SEARCH("bench",$C31)),IF($D31>=0.5,IF($D31<0.6,$E31*$F31," ")," ")," ") | T31: =IF(ISNUMBER(SEARCH("bench",$C31)),IF($D31>=0.6,IF($D31<0.7,$E31*$F31," ")," ")," ") -> 3 | U31: =IF(ISNUMBER(SEARCH("bench",$C31)),IF($D31>=0.7,IF($D31<0.8,$E31*$F31," ")," ")," ") | V31: =IF(ISNUMBER(SEARCH("bench",$C31)),IF($D31>=0.8,IF($D31<0.9,$E31*$F31," ")," ")," ") | W31: =IF(ISNUMBER(SEARCH("bench",$C31)),IF($D31>=0.9,$E31*$F31," ")," ")
C32: Bench press with chains | D32: 0.7 | E32: 3 | F32: 1 | G32: ='Start Here'!$F$22*D32 -> 70 | J32: =E32*F32 -> 3 | K32: =G32*J32 -> 210 | S32: =IF(ISNUMBER(SEARCH("bench",$C32)),IF($D32>=0.5,IF($D32<0.6,$E32*$F32," ")," ")," ") | T32: =IF(ISNUMBER(SEARCH("bench",$C32)),IF($D32>=0.6,IF($D32<0.7,$E32*$F32," ")," ")," ") | U32: =IF(ISNUMBER(SEARCH("bench",$C32)),IF($D32>=0.7,IF($D32<0.8,$E32*$F32," ")," ")," ") -> 3 | V32: =IF(ISNUMBER(SEARCH("bench",$C32)),IF($D32>=0.8,IF($D32<0.9,$E32*$F32," ")," ")," ") | W32: =IF(ISNUMBER(SEARCH("bench",$C32)),IF($D32>=0.9,$E32*$F32," ")," ")
C33: Bench press with chains | D33: 0.75 | E33: 2 | F33: 4 | G33: ='Start Here'!$F$22*D33 -> 75 | J33: =E33*F33 -> 8 | K33: =G33*J33 -> 600 | S33: =IF(ISNUMBER(SEARCH("bench",$C33)),IF($D33>=0.5,IF($D33<0.6,$E33*$F33," ")," ")," ") | T33: =IF(ISNUMBER(SEARCH("bench",$C33)),IF($D33>=0.6,IF($D33<0.7,$E33*$F33," ")," ")," ") | U33: =IF(ISNUMBER(SEARCH("bench",$C33)),IF($D33>=0.7,IF($D33<0.8,$E33*$F33," ")," ")," ") -> 8 | V33: =IF(ISNUMBER(SEARCH("bench",$C33)),IF($D33>=0.8,IF($D33<0.9,$E33*$F33," ")," ")," ") | W33: =IF(ISNUMBER(SEARCH("bench",$C33)),IF($D33>=0.9,$E33*$F33," ")," ")
B34: 3 | C34: Deadlift off boxes, bar is at 5 cm below knees | D34: 0.6 | E34: 3 | F34: 1 | G34: ='Start Here'!$F$23*D34 -> 60 | L34: =E34*F34 -> 3 | M34: =G34*L34 -> 180 | X34: =IF(ISNUMBER(SEARCH("deadlift",$C34)),IF($D34>=0.5,IF($D34<0.6,$E34*$F34," ")," ")," ") | Y34: =IF(ISNUMBER(SEARCH("deadlift",$C34)),IF($D34>=0.6,IF($D34<0.7,$E34*$F34," ")," ")," ") -> 3 | Z34: =IF(ISNUMBER(SEARCH("deadlift",$C34)),IF($D34>=0.7,IF($D34<0.8,$E34*$F34," ")," ")," ") | AA34: =IF(ISNUMBER(SEARCH("deadlift",$C34)),IF($D34>=0.8,IF($D34<0.9,$E34*$F34," ")," ")," ") | AB34: =IF(ISNUMBER(SEARCH("deadlift",$C34)),IF($D34>=0.9,$E34*$F34," ")," ")
C35: Deadlift off boxes, bar is at 5 cm below knees | D35: 0.7 | E35: 3 | F35: 1 | G35: ='Start Here'!$F$23*D35 -> 70 | L35: =E35*F35 -> 3 | M35: =G35*L35 -> 210 | X35: =IF(ISNUMBER(SEARCH("deadlift",$C35)),IF($D35>=0.5,IF($D35<0.6,$E35*$F35," ")," ")," ") | Y35: =IF(ISNUMBER(SEARCH("deadlift",$C35)),IF($D35>=0.6,IF($D35<0.7,$E35*$F35," ")," ")," ") | Z35: =IF(ISNUMBER(SEARCH("deadlift",$C35)),IF($D35>=0.7,IF($D35<0.8,$E35*$F35," ")," ")," ") -> 3 | AA35: =IF(ISNUMBER(SEARCH("deadlift",$C35)),IF($D35>=0.8,IF($D35<0.9,$E35*$F35," ")," ")," ") | AB35: =IF(ISNUMBER(SEARCH("deadlift",$C35)),IF($D35>=0.9,$E35*$F35," ")," ")
C36: Deadlift off boxes, bar is at 5 cm below knees | D36: 0.8 | E36: 3 | F36: 2 | G36: ='Start Here'!$F$23*D36 -> 80 | L36: =E36*F36 -> 6 | M36: =G36*L36 -> 480 | X36: =IF(ISNUMBER(SEARCH("deadlift",$C36)),IF($D36>=0.5,IF($D36<0.6,$E36*$F36," ")," ")," ") | Y36: =IF(ISNUMBER(SEARCH("deadlift",$C36)),IF($D36>=0.6,IF($D36<0.7,$E36*$F36," ")," ")," ") | Z36: =IF(ISNUMBER(SEARCH("deadlift",$C36)),IF($D36>=0.7,IF($D36<0.8,$E36*$F36," ")," ")," ") | AA36: =IF(ISNUMBER(SEARCH("deadlift",$C36)),IF($D36>=0.8,IF($D36<0.9,$E36*$F36," ")," ")," ") -> 6 | AB36: =IF(ISNUMBER(SEARCH("deadlift",$C36)),IF($D36>=0.9,$E36*$F36," ")," ")
C37: Deadlift off boxes, bar is at 5 cm below knees | D37: 0.85 | E37: 3 | F37: 3 | G37: ='Start Here'!$F$23*D37 -> 85 | L37: =E37*F37 -> 9 | M37: =G37*L37 -> 765 | X37: =IF(ISNUMBER(SEARCH("deadlift",$C37)),IF($D37>=0.5,IF($D37<0.6,$E37*$F37," ")," ")," ") | Y37: =IF(ISNUMBER(SEARCH("deadlift",$C37)),IF($D37>=0.6,IF($D37<0.7,$E37*$F37," ")," ")," ") | Z37: =IF(ISNUMBER(SEARCH("deadlift",$C37)),IF($D37>=0.7,IF($D37<0.8,$E37*$F37," ")," ")," ") | AA37: =IF(ISNUMBER(SEARCH("deadlift",$C37)),IF($D37>=0.8,IF($D37<0.9,$E37*$F37," ")," ")," ") -> 9 | AB37: =IF(ISNUMBER(SEARCH("deadlift",$C37)),IF($D37>=0.9,$E37*$F37," ")," ")
B38: 4 | C38: Lat Muscles | E38: 6 | F38: 5
B39: 5 | C39: Dips | E39: 5 | F39: 5
B40: 6 | C40: Goodmorning | E40: 5 | F40: 5
B42: Friday | D42: % | E42: Reps | F42: Sets | G42: Weight | AC42: Notes:
B43: 1 | C43: Bench press | D43: 0.55 | E43: 5 | F43: 1 | G43: ='Start Here'!$F$22*D43 -> 55 | J43: =E43*F43 -> 5 | K43: =G43*J43 -> 275 | S43: =IF(ISNUMBER(SEARCH("bench",$C43)),IF($D43>=0.5,IF($D43<0.6,$E43*$F43," ")," ")," ") -> 5 | T43: =IF(ISNUMBER(SEARCH("bench",$C43)),IF($D43>=0.6,IF($D43<0.7,$E43*$F43," ")," ")," ") | U43: =IF(ISNUMBER(SEARCH("bench",$C43)),IF($D43>=0.7,IF($D43<0.8,$E43*$F43," ")," ")," ") | V43: =IF(ISNUMBER(SEARCH("bench",$C43)),IF($D43>=0.8,IF($D43<0.9,$E43*$F43," ")," ")," ") | W43: =IF(ISNUMBER(SEARCH("bench",$C43)),IF($D43>=0.9,$E43*$F43," ")," ")
C44: Bench press | D44: 0.65 | E44: 4 | F44: 1 | G44: ='Start Here'!$F$22*D44 -> 65 | J44: =E44*F44 -> 4 | K44: =G44*J44 -> 260 | S44: =IF(ISNUMBER(SEARCH("bench",$C44)),IF($D44>=0.5,IF($D44<0.6,$E44*$F44," ")," ")," ") | T44: =IF(ISNUMBER(SEARCH("bench",$C44)),IF($D44>=0.6,IF($D44<0.7,$E44*$F44," ")," ")," ") -> 4 | U44: =IF(ISNUMBER(SEARCH("bench",$C44)),IF($D44>=0.7,IF($D44<0.8,$E44*$F44," ")," ")," ") | V44: =IF(ISNUMBER(SEARCH("bench",$C44)),IF($D44>=0.8,IF($D44<0.9,$E44*$F44," ")," ")," ") | W44: =IF(ISNUMBER(SEARCH("bench",$C44)),IF($D44>=0.9,$E44*$F44," ")," ")
C45: Bench press | D45: 0.75 | E45: 3 | F45: 1 | G45: ='Start Here'!$F$22*D45 -> 75 | J45: =E45*F45 -> 3 | K45: =G45*J45 -> 225 | S45: =IF(ISNUMBER(SEARCH("bench",$C45)),IF($D45>=0.5,IF($D45<0.6,$E45*$F45," ")," ")," ") | T45: =IF(ISNUMBER(SEARCH("bench",$C45)),IF($D45>=0.6,IF($D45<0.7,$E45*$F45," ")," ")," ") | U45: =IF(ISNUMBER(SEARCH("bench",$C45)),IF($D45>=0.7,IF($D45<0.8,$E45*$F45," ")," ")," ") -> 3 | V45: =IF(ISNUMBER(SEARCH("bench",$C45)),IF($D45>=0.8,IF($D45<0.9,$E45*$F45," ")," ")," ") | W45: =IF(ISNUMBER(SEARCH("bench",$C45)),IF($D45>=0.9,$E45*$F45," ")," ")
...

Sheet Prep Cycle III
B2: Preparatory Period III for Class 1 and Above Athletes
B5: WEEK 1 | N5: squat | S5: bench | X5: deadlift
B6: Monday | D6: % | E6: Reps | F6: Sets | G6: Weight | N6: 50-59 | O6: 60-69 | P6: 70-79 | Q6: 80-89 | R6: 90+ | S6: 50-59 | T6: 60-69 | U6: 70-79 | V6: 80-89 | W6: 90+ | X6: 50-59 | Y6: 60-69 | Z6: 70-79 | AA6: 80-89 | AB6: 90+ | AC6: Notes:
B7: 1 | C7: Squat | D7: 0.55 | E7: 5 | F7: 1 | G7: ='Start Here'!$F$21*D7 -> 55 | H7: =E7*F7 -> 5 | I7: =G7*H7 -> 275 | N7: =IF(ISNUMBER(SEARCH("squat",$C7)),IF($D7>=0.5,IF($D7<0.6,$E7*$F7," ")," ")," ") -> 5 | O7: =IF(ISNUMBER(SEARCH("squat",$C7)),IF($D7>=0.6,IF($D7<0.7,$E7*$F7," ")," ")," ") | P7: =IF(ISNUMBER(SEARCH("squat",$C7)),IF($D7>=0.7,IF($D7<0.8,$E7*$F7," ")," ")," ") | Q7: =IF(ISNUMBER(SEARCH("squat",$C7)),IF($D7>=0.8,IF($D7<0.9,$E7*$F7," ")," ")," ") | R7: =IF(ISNUMBER(SEARCH("squat",$C7)),IF($D7>=0.9,$E7*$F7," ")," ")
C8: Squat | D8: 0.65 | E8: 4 | F8: 1 | G8: ='Start Here'!$F$21*D8 -> 65 | H8: =E8*F8 -> 4 | I8: =G8*H8 -> 260 | N8: =IF(ISNUMBER(SEARCH("squat",$C8)),IF($D8>=0.5,IF($D8<0.6,$E8*$F8," ")," ")," ") | O8: =IF(ISNUMBER(SEARCH("squat",$C8)),IF($D8>=0.6,IF($D8<0.7,$E8*$F8," ")," ")," ") -> 4 | P8: =IF(ISNUMBER(SEARCH("squat",$C8)),IF($D8>=0.7,IF($D8<0.8,$E8*$F8," ")," ")," ") | Q8: =IF(ISNUMBER(SEARCH("squat",$C8)),IF($D8>=0.8,IF($D8<0.9,$E8*$F8," ")," ")," ") | R8: =IF(ISNUMBER(SEARCH("squat",$C8)),IF($D8>=0.9,$E8*$F8," ")," ")
C9: Squat | D9: 0.75 | E9: 3 | F9: 1 | G9: ='Start Here'!$F$21*D9 -> 75 | H9: =E9*F9 -> 3 | I9: =G9*H9 -> 225 | N9: =IF(ISNUMBER(SEARCH("squat",$C9)),IF($D9>=0.5,IF($D9<0.6,$E9*$F9," ")," ")," ") | O9: =IF(ISNUMBER(SEARCH("squat",$C9)),IF($D9>=0.6,IF($D9<0.7,$E9*$F9," ")," ")," ") | P9: =IF(ISNUMBER(SEARCH("squat",$C9)),IF($D9>=0.7,IF($D9<0.8,$E9*$F9," ")," ")," ") -> 3 | Q9: =IF(ISNUMBER(SEARCH("squat",$C9)),IF($D9>=0.8,IF($D9<0.9,$E9*$F9," ")," ")," ") | R9: =IF(ISNUMBER(SEARCH("squat",$C9)),IF($D9>=0.9,$E9*$F9," ")," ")
C10: Squat | D10: 0.85 | E10: 2 | F10: 3 | G10: ='Start Here'!$F$21*D10 -> 85 | H10: =E10*F10 -> 6 | I10: =G10*H10 -> 510 | N10: =IF(ISNUMBER(SEARCH("squat",$C10)),IF($D10>=0.5,IF($D10<0.6,$E10*$F10," ")," ")," ") | O10: =IF(ISNUMBER(SEARCH("squat",$C10)),IF($D10>=0.6,IF($D10<0.7,$E10*$F10," ")," ")," ") | P10: =IF(ISNUMBER(SEARCH("squat",$C10)),IF($D10>=0.7,IF($D10<0.8,$E10*$F10," ")," ")," ") | Q10: =IF(ISNUMBER(SEARCH("squat",$C10)),IF($D10>=0.8,IF($D10<0.9,$E10*$F10," ")," ")," ") -> 6 | R10: =IF(ISNUMBER(SEARCH("squat",$C10)),IF($D10>=0.9,$E10*$F10," ")," ")
B11: 2 | C11: Bench press | D11: 0.5 | E11: 5 | F11: 1 | G11: ='Start Here'!$F$22*D11 -> 50 | J11: =E11*F11 -> 5 | K11: =G11*J11 -> 250 | S11: =IF(ISNUMBER(SEARCH("bench",$C11)),IF($D11>=0.5,IF($D11<0.6,$E11*$F11," ")," ")," ") -> 5 | T11: =IF(ISNUMBER(SEARCH("bench",$C11)),IF($D11>=0.6,IF($D11<0.7,$E11*$F11," ")," ")," ") | U11: =IF(ISNUMBER(SEARCH("bench",$C11)),IF($D11>=0.7,IF($D11<0.8,$E11*$F11," ")," ")," ") | V11: =IF(ISNUMBER(SEARCH("bench",$C11)),IF($D11>=0.8,IF($D11<0.9,$E11*$F11," ")," ")," ") | W11: =IF(ISNUMBER(SEARCH("bench",$C11)),IF($D11>=0.9,$E11*$F11," ")," ")
C12: Bench press | D12: 0.6 | E12: 4 | F12: 1 | G12: ='Start Here'!$F$22*D12 -> 60 | J12: =E12*F12 -> 4 | K12: =G12*J12 -> 240 | S12: =IF(ISNUMBER(SEARCH("bench",$C12)),IF($D12>=0.5,IF($D12<0.6,$E12*$F12," ")," ")," ") | T12: =IF(ISNUMBER(SEARCH("bench",$C12)),IF($D12>=0.6,IF($D12<0.7,$E12*$F12," ")," ")," ") -> 4 | U12: =IF(ISNUMBER(SEARCH("bench",$C12)),IF($D12>=0.7,IF($D12<0.8,$E12*$F12," ")," ")," ") | V12: =IF(ISNUMBER(SEARCH("bench",$C12)),IF($D12>=0.8,IF($D12<0.9,$E12*$F12," ")," ")," ") | W12: =IF(ISNUMBER(SEARCH("bench",$C12)),IF($D12>=0.9,$E12*$F12," ")," ")
C13: Bench press | D13: 0.7 | E13: 3 | F13: 1 | G13: ='Start Here'!$F$22*D13 -> 70 | J13: =E13*F13 -> 3 | K13: =G13*J13 -> 210 | S13: =IF(ISNUMBER(SEARCH("bench",$C13)),IF($D13>=0.5,IF($D13<0.6,$E13*$F13," ")," ")," ") | T13: =IF(ISNUMBER(SEARCH("bench",$C13)),IF($D13>=0.6,IF($D13<0.7,$E13*$F13," ")," ")," ") | U13: =IF(ISNUMBER(SEARCH("bench",$C13)),IF($D13>=0.7,IF($D13<0.8,$E13*$F13," ")," ")," ") -> 3 | V13: =IF(ISNUMBER(SEARCH("bench",$C13)),IF($D13>=0.8,IF($D13<0.9,$E13*$F13," ")," ")," ") | W13: =IF(ISNUMBER(SEARCH("bench",$C13)),IF($D13>=0.9,$E13*$F13," ")," ")
C14: Bench press | D14: 0.8 | E14: 2 | F14: 4 | G14: ='Start Here'!$F$22*D14 -> 80 | J14: =E14*F14 -> 8 | K14: =G14*J14 -> 640 | S14: =IF(ISNUMBER(SEARCH("bench",$C14)),IF($D14>=0.5,IF($D14<0.6,$E14*$F14," ")," ")," ") | T14: =IF(ISNUMBER(SEARCH("bench",$C14)),IF($D14>=0.6,IF($D14<0.7,$E14*$F14," ")," ")," ") | U14: =IF(ISNUMBER(SEARCH("bench",$C14)),IF($D14>=0.7,IF($D14<0.8,$E14*$F14," ")," ")," ") | V14: =IF(ISNUMBER(SEARCH("bench",$C14)),IF($D14>=0.8,IF($D14<0.9,$E14*$F14," ")," ")," ") -> 8 | W14: =IF(ISNUMBER(SEARCH("bench",$C14)),IF($D14>=0.9,$E14*$F14," ")," ")
B15: 4 | C15: Squat | D15: 0.5 | E15: 3 | F15: 1 | G15: ='Start Here'!$F$21*D15 -> 50 | H15: =E15*F15 -> 3 | I15: =G15*H15 -> 150 | N15: =IF(ISNUMBER(SEARCH("squat",$C15)),IF($D15>=0.5,IF($D15<0.6,$E15*$F15," ")," ")," ") -> 3 | O15: =IF(ISNUMBER(SEARCH("squat",$C15)),IF($D15>=0.6,IF($D15<0.7,$E15*$F15," ")," ")," ") | P15: =IF(ISNUMBER(SEARCH("squat",$C15)),IF($D15>=0.7,IF($D15<0.8,$E15*$F15," ")," ")," ") | Q15: =IF(ISNUMBER(SEARCH("squat",$C15)),IF($D15>=0.8,IF($D15<0.9,$E15*$F15," ")," ")," ") | R15: =IF(ISNUMBER(SEARCH("squat",$C15)),IF($D15>=0.9,$E15*$F15," ")," ")
C16: Squat | D16: 0.6 | E16: 3 | F16: 1 | G16: ='Start Here'!$F$21*D16 -> 60 | H16: =E16*F16 -> 3 | I16: =G16*H16 -> 180 | N16: =IF(ISNUMBER(SEARCH("squat",$C16)),IF($D16>=0.5,IF($D16<0.6,$E16*$F16," ")," ")," ") | O16: =IF(ISNUMBER(SEARCH("squat",$C16)),IF($D16>=0.6,IF($D16<0.7,$E16*$F16," ")," ")," ") -> 3 | P16: =IF(ISNUMBER(SEARCH("squat",$C16)),IF($D16>=0.7,IF($D16<0.8,$E16*$F16," ")," ")," ") | Q16: =IF(ISNUMBER(SEARCH("squat",$C16)),IF($D16>=0.8,IF($D16<0.9,$E16*$F16," ")," ")," ") | R16: =IF(ISNUMBER(SEARCH("squat",$C16)),IF($D16>=0.9,$E16*$F16," ")," ")
C17: Squat | D17: 0.7 | E17: 3 | F17: 1 | G17: ='Start Here'!$F$21*D17 -> 70 | H17: =E17*F17 -> 3 | I17: =G17*H17 -> 210 | N17: =IF(ISNUMBER(SEARCH("squat",$C17)),IF($D17>=0.5,IF($D17<0.6,$E17*$F17," ")," ")," ") | O17: =IF(ISNUMBER(SEARCH("squat",$C17)),IF($D17>=0.6,IF($D17<0.7,$E17*$F17," ")," ")," ") | P17: =IF(ISNUMBER(SEARCH("squat",$C17)),IF($D17>=0.7,IF($D17<0.8,$E17*$F17," ")," ")," ") -> 3 | Q17: =IF(ISNUMBER(SEARCH("squat",$C17)),IF($D17>=0.8,IF($D17<0.9,$E17*$F17," ")," ")," ") | R17: =IF(ISNUMBER(SEARCH("squat",$C17)),IF($D17>=0.9,$E17*$F17," ")," ")
